Workbook

Sheet Tabelas
C1: BABY ROO COMERCIO DE ALIMENTOS EIRELI
C2: CNPJ: 34.282.307.0001-44
C3: INSC. ESTADUAL: 90821939-25
C4: ENDEREÇO: Rua Grã Nicco, 113 - sala 501, bloco 2 - Mossunguê, Curitiba - PR, 81200-200
B6: Nome / Razão Social: | J6: Nr. pedido | L6: E-mail XML:
B7: Endereço: | L7: Municipio: | Q7: UF: | R7: PR
B8: CNPJ: | G8: Inscrição Estadual: | J8: Regime SIMPLES? | K8: NÃO | L8: Fone contato com (DDD) | Q8: CEP:
B9: 0325FARMA+ESPECIALv
B10: Descrição | D10: Código | E10: Embalagem | F10: Validade | G10: PSC | H10: NCM | I10: Ean 13 | J10: Dun 14 | K10: Crédito ICMS (%) | L10: Valor Unit. | M10: Valor Caixa | N10: SUBSTITUIÇÃO TRIBUTÁRIA | O10: IPI | P10: Valor Caixa + ST | Q10: TOTAL Caixas | R10: Valor TOTAL | S10: Valor TOTAL + ST (*)
B11: Salgadinho Integral Orgânico Queijo Papapa Era Uma Vez 40g | D11: 5670 | E11: 18 x 40g | F11: 9 meses | G11: =VLOOKUP($R$7,PSC!$A$2:$Q$31,15,FALSE) -> 7.99 | H11: 1904.10.00 | I11: 7898969895811 | J11: 17898969895818 | K11: =VLOOKUP($R$7,'ST EXTRUSADOS'!A:B,2,FALSE) -> 0.12 | L11: =VLOOKUP($R$7,PREÇOS!$A$2:$Q$31,15,FALSE) -> 5.8275 | M11: =L11*18 -> 104.895 | N11: =IF($K$8="SIM",VLOOKUP($R$7,'ST EXTRUSADOS'!$A$1:$J$31,10,FALSE),VLOOKUP($R$7,'ST EXTRUSADOS'!$A$1:$J$31,9,FALSE)) -> 1.2177435 | O11: 0 | P11: =(L11+N11)*18 -> 126.81438 | R11: =Q11*M11 -> 0 | S11: =Q11*P11 -> 0
B12: Salgadinho Integral Orgânico Cebola & Salsa Papapa Era Uma Vez 40g | D12: 5671 | E12: 18 x 40g | F12: 9 meses | G12: =VLOOKUP($R$7,PSC!$A$2:$Q$31,15,FALSE) -> 7.99 | H12: 1904.10.00 | I12: 7898969895804 | J12: 17898969895801 | K12: =VLOOKUP($R$7,'ST EXTRUSADOS'!A:B,2,FALSE) -> 0.12 | L12: =VLOOKUP($R$7,PREÇOS!$A$2:$Q$31,15,FALSE) -> 5.8275 | M12: =L12*18 -> 104.895 | N12: =IF($K$8="SIM",VLOOKUP($R$7,'ST EXTRUSADOS'!$A$1:$J$31,10,FALSE),VLOOKUP($R$7,'ST EXTRUSADOS'!$A$1:$J$31,9,FALSE)) -> 1.2177435 | O12: 0 | P12: =(L12+N12)*18 -> 126.81438 | R12: =Q12*M12 -> 0 | S12: =Q12*P12 -> 0
B13: Salgadinho Integral Orgânico Churrasco Papapa Era Uma Vez 40g | D13: 5673 | E13: 18 x 40g | F13: 9 meses | G13: =VLOOKUP($R$7,PSC!$A$2:$Q$31,15,FALSE) -> 7.99 | H13: 1904.10.00 | I13: 7898969895798 | J13: 17898969895795 | K13: =VLOOKUP($R$7,'ST EXTRUSADOS'!A:B,2,FALSE) -> 0.12 | L13: =VLOOKUP($R$7,PREÇOS!$A$2:$Q$31,15,FALSE) -> 5.8275 | M13: =L13*18 -> 104.895 | N13: =IF($K$8="SIM",VLOOKUP($R$7,'ST EXTRUSADOS'!$A$1:$J$31,10,FALSE),VLOOKUP($R$7,'ST EXTRUSADOS'!$A$1:$J$31,9,FALSE)) -> 1.2177435 | O13: 0 | P13: =(L13+N13)*18 -> 126.81438 | R13: =Q13*M13 -> 0 | S13: =Q13*P13 -> 0
B15: Biscoito Recheado de Frutas Amarelas Papapa Era Uma Vez 30g | D15: 5677 | E15: 8x30g | F15: 10 meses | G15: =VLOOKUP($R$7,PSC!$A$2:$Q$31,16,FALSE) -> 8.6 | H15: 1905.90.20 | I15: 7898969895828 | J15: 17898969895917 | K15: =VLOOKUP($R$7,'ST RECHEADOS'!A:B,2,FALSE) -> 0.12 | L15: =VLOOKUP($R$7,PREÇOS!$A$2:$Q$31,16,FALSE) -> 6.51 | M15: =L15*8 -> 52.08 | N15: =IF($K$8="SIM",VLOOKUP($R$7,'ST RECHEADOS'!$A$1:$J$31,10,FALSE),VLOOKUP($R$7,'ST RECHEADOS'!$A$1:$J$31,9,FALSE)) -> 0 | O15: 0 | P15: =(L15+N15)*8 -> 52.08 | R15: =Q15*M15 -> 0 | S15: =Q15*P15 -> 0
B16: Biscoito Recheado de Morango Papapa Era Uma Vez 30g | D16: 5678 | E16: 8x30g | F16: 10 meses | G16: =VLOOKUP($R$7,PSC!$A$2:$Q$31,16,FALSE) -> 8.6 | H16: 1905.90.20 | I16: 7898969895835 | J16: 17898969895900 | K16: =VLOOKUP($R$7,'ST RECHEADOS'!A:B,2,FALSE) -> 0.12 | L16: =VLOOKUP($R$7,PREÇOS!$A$2:$Q$31,16,FALSE) -> 6.51 | M16: =L16*8 -> 52.08 | N16: =IF($K$8="SIM",VLOOKUP($R$7,'ST RECHEADOS'!$A$1:$J$31,10,FALSE),VLOOKUP($R$7,'ST RECHEADOS'!$A$1:$J$31,9,FALSE)) -> 0 | O16: 0 | P16: =(L16+N16)*8 -> 52.08 | R16: =Q16*M16 -> 0 | S16: =Q16*P16 -> 0
B18: Bebida de Laranja Papapa Era Uma Vez 200ml | D18: 5680 | E18: 27 x 200 ml | F18: 8 meses | G18: =VLOOKUP($R$7,PSC!$A$2:$Q$31,17,FALSE) -> 4.99 | H18: 2202.99.00 | I18: 7898969895880 | J18: 17898969895887 | K18: =VLOOKUP($R$7,'ST BISCOTTI'!A:B,2,FALSE) -> 0.12 | L18: =VLOOKUP($R$7,PREÇOS!$A$2:$Q$31,17,FALSE) -> 3.7275 | M18: =L18*27 -> 100.6425 | N18: 0 | O18: 0 | P18: =(L18+N18)*27 -> 100.6425 | R18: =Q18*M18 -> 0 | S18: =Q18*P18 -> 0
B19: Bebida de Uva Papapa Era Uma Vez 200ml | D19: 5681 | E19: 27 x 200 ml | F19: 8 meses | G19: =VLOOKUP($R$7,PSC!$A$2:$Q$31,17,FALSE) -> 4.99 | H19: 2202.99.00 | I19: 7898969895859 | J19: 17898969895856 | K19: =VLOOKUP($R$7,'ST BISCOTTI'!A:B,2,FALSE) -> 0.12 | L19: =VLOOKUP($R$7,PREÇOS!$A$2:$Q$31,17,FALSE) -> 3.7275 | M19: =L19*27 -> 100.6425 | N19: 0 | O19: 0 | P19: =(L19+N19)*27 -> 100.6425 | R19: =Q19*M19 -> 0 | S19: =Q19*P19 -> 0
B20: Bebida de Morango Papapa Era Uma Vez 200ml | D20: 5682 | E20: 27 x 200 ml | F20: 8 meses | G20: =VLOOKUP($R$7,PSC!$A$2:$Q$31,17,FALSE) -> 4.99 | H20: 2202.99.00 | I20: 7898969895866 | J20: 17898969895863 | K20: =VLOOKUP($R$7,'ST BISCOTTI'!A:B,2,FALSE) -> 0.12 | L20: =VLOOKUP($R$7,PREÇOS!$A$2:$Q$31,17,FALSE) -> 3.7275 | M20: =L20*27 -> 100.6425 | N20: 0 | O20: 0 | P20: =(L20+N20)*27 -> 100.6425 | R20: =Q20*M20 -> 0 | S20: =Q20*P20 -> 0
B21: Bebida de Maçã Papapa Era Uma Vez 200ml | D21: 5683 | E21: 27 x 200 ml | F21: 8 meses | G21: =VLOOKUP($R$7,PSC!$A$2:$Q$31,17,FALSE) -> 4.99 | H21: 2202.99.00 | I21: 7898969895873 | J21: 17898969895870 | K21: =VLOOKUP($R$7,'ST BISCOTTI'!A:B,2,FALSE) -> 0.12 | L21: =VLOOKUP($R$7,PREÇOS!$A$2:$Q$31,17,FALSE) -> 3.7275 | M21: =L21*27 -> 100.6425 | N21: 0 | O21: 0 | P21: =(L21+N21)*27 -> 100.6425 | R21: =Q21*M21 -> 0 | S21: =Q21*P21 -> 0
B23: Bebida Láctea UHT Chocolate Papapa Era Uma Vez 200ml | D23: 5310 | E23: 27 x 200 ml | F23: 6 meses | G23: =VLOOKUP($R$7,PSC!$A$2:$T$31,18,FALSE) -> 5.99 | H23: 2202.99.00 | I23: 7898969895897 | J23: 17898969895894 | K23: =VLOOKUP($R$7,'ST BISCOTTI'!A:B,2,FALSE) -> 0.12 | L23: =VLOOKUP($R$7,PREÇOS!$A$2:$T$31,18,FALSE) -> 4.3575 | M23: =L23*27 -> 117.6525 | N23: 0 | O23: 0 | P23: =(L23+N23)*27 -> 117.6525 | R23: =Q23*M23 -> 0 | S23: =Q23*P23 -> 0
B25: Kit De Talheres Infantil - Azul | D25: 5641 | E25: 1un | F25: Indeterminado | G25: =VLOOKUP($R$7,PSC!$A$2:$V$31,19,FALSE) -> 36 | H25: 3924.10.00 | I25: 7898969895644 | J25: 17898969895641 | K25: =VLOOKUP($R$7,'ST BISCOITINHOS'!A:B,2,FALSE) -> 0.12 | L25: =VLOOKUP($R$7,PREÇOS!$A$2:$V$31,19,FALSE) -> 17.945455 | M25: =L25 -> 17.945455 | N25: 0 | O25: =L25*6.5% -> 1.1664545 | P25: =(L25+N25+O25) -> 19.111909 | R25: =Q25*M25 -> 0 | S25: =Q25*P25 -> 0
B26: Kit De Talheres Infantil - Verde | D26: 5658 | E26: 1un | F26: Indeterminado | G26: =VLOOKUP($R$7,PSC!$A$2:$V$31,19,FALSE) -> 36 | H26: 3924.10.00 | I26: 7898969895651 | J26: 17898969895658 | K26: =VLOOKUP($R$7,'ST BISCOITINHOS'!A:B,2,FALSE) -> 0.12 | L26: =VLOOKUP($R$7,PREÇOS!$A$2:$V$31,19,FALSE) -> 17.945455 | M26: =L26 -> 17.945455 | N26: 0 | O26: =L26*6.5% -> 1.1664545 | P26: =(L26+N26+O26) -> 19.111909 | R26: =Q26*M26 -> 0 | S26: =Q26*P26 -> 0
B27: Kit De Talheres Infantil - Rosa | D27: 5665 | E27: 1un | F27: Indeterminado | G27: =VLOOKUP($R$7,PSC!$A$2:$V$31,19,FALSE) -> 36 | H27: 3924.10.00 | I27: 7898969895668 | J27: 17898969895665 | K27: =VLOOKUP($R$7,'ST BISCOITINHOS'!A:B,2,FALSE) -> 0.12 | L27: =VLOOKUP($R$7,PREÇOS!$A$2:$V$31,19,FALSE) -> 17.945455 | M27: =L27 -> 17.945455 | N27: 0 | O27: =L27*6.5% -> 1.1664545 | P27: =(L27+N27+O27) -> 19.111909 | R27: =Q27*M27 -> 0 | S27: =Q27*P27 -> 0
B28: Babador Infantil Com Bolso - Azul | D28: 5733 | E28: 1un | F28: Indeterminado | G28: =VLOOKUP($R$7,PSC!$A$2:$V$31,21,FALSE) -> 27 | H28: 3924.10.00 | I28: 7898969895736 | J28: 17898969895733 | K28: =VLOOKUP($R$7,'ST BISCOITINHOS'!A:B,2,FALSE) -> 0.12 | L28: =VLOOKUP($R$7,PREÇOS!$A$2:$V$31,20,FALSE) -> 15.702273 | M28: =L28 -> 15.702273 | N28: 0 | O28: =L28*6.5% -> 1.0206477 | P28: =(L28+N28+O28) -> 16.72292 | R28: =Q28*M28 -> 0 | S28: =Q28*P28 -> 0
B29: Babador Infantil Com Bolso - Verde | D29: 5740 | E29: 1un | F29: Indeterminado | G29: =VLOOKUP($R$7,PSC!$A$2:$V$31,21,FALSE) -> 27 | H29: 3924.10.00 | I29: 7898969895743 | J29: 17898969895740 | K29: =VLOOKUP($R$7,'ST BISCOITINHOS'!A:B,2,FALSE) -> 0.12 | L29: =VLOOKUP($R$7,PREÇOS!$A$2:$V$31,20,FALSE) -> 15.702273 | M29: =L29 -> 15.702273 | N29: 0 | O29: =L29*6.5% -> 1.0206477 | P29: =(L29+N29+O29) -> 16.72292 | R29: =Q29*M29 -> 0 | S29: =Q29*P29 -> 0
B30: Babador Infantil Com Bolso - Rosa | D30: 5757 | E30: 1un | F30: Indeterminado | G30: =VLOOKUP($R$7,PSC!$A$2:$V$31,21,FALSE) -> 27 | H30: 3924.10.00 | I30: 7898969895750 | J30: 17898969895757 | K30: =VLOOKUP($R$7,'ST BISCOITINHOS'!A:B,2,FALSE) -> 0.12 | L30: =VLOOKUP($R$7,PREÇOS!$A$2:$V$31,20,FALSE) -> 15.702273 | M30: =L30 -> 15.702273 | N30: 0 | O30: =L30*6.5% -> 1.0206477 | P30: =(L30+N30+O30) -> 16.72292 | R30: =Q30*M30 -> 0 | S30: =Q30*P30 -> 0
B31: Bowl Infantil Com Ventosa - Azul | D31: 5702 | E31: 1un | F31: Indeterminado | G31: =VLOOKUP($R$7,PSC!$A$2:$V$31,20,FALSE) -> 36 | H31: 3924.10.00 | I31: 7898969895705 | J31: 17898969895702 | K31: =VLOOKUP($R$7,'ST BISCOITINHOS'!A:B,2,FALSE) -> 0.12 | L31: =VLOOKUP($R$7,PREÇOS!$A$2:$V$31,21,FALSE) -> 20.188636 | M31: =L31 -> 20.188636 | N31: 0 | O31: =L31*6.5% -> 1.3122614 | P31: =(L31+N31+O31) -> 21.500898 | R31: =Q31*M31 -> 0 | S31: =Q31*P31 -> 0
B32: Bowl Infantil Com Ventosa - Verde | D32: 5719 | E32: 1un | F32: Indeterminado | G32: =VLOOKUP($R$7,PSC!$A$2:$V$31,20,FALSE) -> 36 | H32: 3924.10.00 | I32: 7898969895712 | J32: 17898969895719 | K32: =VLOOKUP($R$7,'ST BISCOITINHOS'!A:B,2,FALSE) -> 0.12 | L32: =VLOOKUP($R$7,PREÇOS!$A$2:$V$31,21,FALSE) -> 20.188636 | M32: =L32 -> 20.188636 | N32: 0 | O32: =L32*6.5% -> 1.3122614 | P32: =(L32+N32+O32) -> 21.500898 | R32: =Q32*M32 -> 0 | S32: =Q32*P32 -> 0
B33: Bowl Infantil Com Ventosa - Rosa | D33: 5726 | E33: 1un | F33: Indeterminado | G33: =VLOOKUP($R$7,PSC!$A$2:$V$31,20,FALSE) -> 36 | H33: 3924.10.00 | I33: 7898969895729 | J33: 17898969895726 | K33: =VLOOKUP($R$7,'ST BISCOITINHOS'!A:B,2,FALSE) -> 0.12 | L33: =VLOOKUP($R$7,PREÇOS!$A$2:$V$31,21,FALSE) -> 20.188636 | M33: =L33 -> 20.188636 | N33: 0 | O33: =L33*6.5% -> 1.3122614 | P33: =(L33+N33+O33) -> 21.500898 | R33: =Q33*M33 -> 0 | S33: =Q33*P33 -> 0
B34: Pratinho Infantil Com Ventosa - Azul | D34: 5675 | E34: 1un | F34: Indeterminado | G34: =VLOOKUP($R$7,PSC!$A$2:$V$31,22,FALSE) -> 48 | H34: 3924.10.00 | I34: 7898969895675 | J34: 17898969895672 | K34: =VLOOKUP($R$7,'ST BISCOITINHOS'!A:B,2,FALSE) -> 0.12 | L34: =VLOOKUP($R$7,PREÇOS!$A$2:$V$31,22,FALSE) -> 30.608216 | M34: =L34 -> 30.608216 | N34: 0 | O34: =L34*6.5% -> 1.989534 | P34: =(L34+N34+O34) -> 32.59775 | R34: =Q34*M34 -> 0 | S34: =Q34*P34 -> 0
B35: Pratinho Infantil Com Ventosa - Verde | D35: 5689 | E35: 1un | F35: Indeterminado | G35: =VLOOKUP($R$7,PSC!$A$2:$V$31,22,FALSE) -> 48 | H35: 3924.10.00 | I35: 7898969895682 | J35: 17898969895689 | K35: =VLOOKUP($R$7,'ST BISCOITINHOS'!A:B,2,FALSE) -> 0.12 | L35: =VLOOKUP($R$7,PREÇOS!$A$2:$V$31,22,FALSE) -> 30.608216 | M35: =L35 -> 30.608216 | N35: 0 | O35: =L35*6.5% -> 1.989534 | P35: =(L35+N35+O35) -> 32.59775 | R35: =Q35*M35 -> 0 | S35: =Q35*P35 -> 0
B36: Pratinho Infantil Com Ventosa - Rosa | D36: 5696 | E36: 1un | F36: Indeterminado | G36: =VLOOKUP($R$7,PSC!$A$2:$V$31,22,FALSE) -> 48 | H36: 3924.10.00 | I36: 7898969895699 | J36: 17898969895696 | K36: =VLOOKUP($R$7,'ST BISCOITINHOS'!A:B,2,FALSE) -> 0.12 | L36: =VLOOKUP($R$7,PREÇOS!$A$2:$V$31,22,FALSE) -> 30.608216 | M36: =L36 -> 30.608216 | N36: 0 | O36: =L36*6.5% -> 1.989534 | P36: =(L36+N36+O36) -> 32.59775 | R36: =Q36*M36 -> 0 | S36: =Q36*P36 -> 0
M37: (*) quando inside ST o valor do imposto é adicionado nesta coluna
P39: VALOR TOTAL PRODUTOS (R$): | S39: =SUM(R11:R36) -> 0
P41: VALOR ST (R$): | S41: =S43-S39 -> 0
P43: VALOR TOTAL PEDIDO (R$): | S43: =SUM(S11:S36) -> 0

Sheet Planilha1
C2: SIM
C3: NÃO

Sheet ST BISCOITINHOS
A1: Estado | B1: Aliquota interestadual | C1: Aliquota interna | D1: MVA (normal) | E1: MVA (simples) | F1: Ajustada (normal) | G1: Ajustada (simples) | H1: Preço | I1: ST Normal | J1: ST Simples
A2: AC | B2: 0.04 | C2: 0.04 | H2: =PREÇOS!D3 -> 10.8768 | I2: =IF(F2=0,,H2*(1+F2)*C2-(H2*B2)) -> 0 | J2: =IF(G2=0,IF(F2=0,,H2*(1+F2)*C2-(H2*B2)),H2*(1+G2)*C2-(H2*B2)) -> 0
A3: AL | B3: 0.04 | C3: 0.2 | D3: 0.3 | F3: 0.56 | H3: =PREÇOS!D4 -> 10.8768 | I3: =IF(F3=0,,H3*(1+F3)*C3-(H3*B3)) -> 2.9584896 | J3: =IF(G3=0,IF(F3=0,,H3*(1+F3)*C3-(H3*B3)),H3*(1+G3)*C3-(H3*B3)) -> 2.9584896
A4: AM | B4: 0.04 | C4: 0.04 | H4: =PREÇOS!D5 -> 10.8768 | I4: =IF(F4=0,,H4*(1+F4)*C4-(H4*B4)) -> 0 | J4: =IF(G4=0,IF(F4=0,,H4*(1+F4)*C4-(H4*B4)),H4*(1+G4)*C4-(H4*B4)) -> 0
A5: AP | B5: 0.04 | C5: 0.18 | D5: 0.34 | F5: 0.5688 | H5: =PREÇOS!D6 -> 10.8768 | I5: =IF(F5=0,,H5*(1+F5)*C5-(H5*B5)) -> 2.6363623 | J5: =IF(G5=0,IF(F5=0,,H5*(1+F5)*C5-(H5*B5)),H5*(1+G5)*C5-(H5*B5)) -> 2.6363623
A6: BA | B6: 0.04 | C6: 0.04 | H6: =PREÇOS!D7 -> 10.8768 | I6: =IF(F6=0,,H6*(1+F6)*C6-(H6*B6)) -> 0 | J6: =IF(G6=0,IF(F6=0,,H6*(1+F6)*C6-(H6*B6)),H6*(1+G6)*C6-(H6*B6)) -> 0
A7: CE | B7: 0.04 | C7: 0.04 | H7: =PREÇOS!D8 -> 10.8768 | I7: =IF(F7=0,,H7*(1+F7)*C7-(H7*B7)) -> 0 | J7: =IF(G7=0,IF(F7=0,,H7*(1+F7)*C7-(H7*B7)),H7*(1+G7)*C7-(H7*B7)) -> 0
A8: DF | B8: 0.04 | C8: 0.04 | H8: =PREÇOS!D9 -> 10.8768 | I8: =IF(F8=0,,H8*(1+F8)*C8-(H8*B8)) -> 0 | J8: =IF(G8=0,IF(F8=0,,H8*(1+F8)*C8-(H8*B8)),H8*(1+G8)*C8-(H8*B8)) -> 0
A9: ES | B9: 0.04 | C9: 0.04 | H9: =PREÇOS!D10 -> 10.8768 | I9: =IF(F9=0,,H9*(1+F9)*C9-(H9*B9)) -> 0 | J9: =IF(G9=0,IF(F9=0,,H9*(1+F9)*C9-(H9*B9)),H9*(1+G9)*C9-(H9*B9)) -> 0
A10: GO | B10: 0.04 | C10: 0.04 | H10: =PREÇOS!D11 -> 10.8768 | I10: =IF(F10=0,,H10*(1+F10)*C10-(H10*B10)) -> 0 | J10: =IF(G10=0,IF(F10=0,,H10*(1+F10)*C10-(H10*B10)),H10*(1+G10)*C10-(H10*B10)) -> 0
A11: MA | B11: 0.04 | C11: 0.04 | H11: =PREÇOS!D12 -> 10.8768 | I11: =IF(F11=0,,H11*(1+F11)*C11-(H11*B11)) -> 0 | J11: =IF(G11=0,IF(F11=0,,H11*(1+F11)*C11-(H11*B11)),H11*(1+G11)*C11-(H11*B11)) -> 0
A12: MG | B12: 0.04 | C12: 0.18 | D12: 0.25 | F12: 0.3636 | H12: =PREÇOS!D13 -> 10.8768 | I12: =IF(F12=0,,H12*(1+F12)*C12-(H12*B12)) -> 2.2346168 | J12: =IF(G12=0,IF(F12=0,,H12*(1+F12)*C12-(H12*B12)),H12*(1+G12)*C12-(H12*B12)) -> 2.2346168
A13: MS | B13: 0.04 | C13: 0.04 | H13: =PREÇOS!D14 -> 10.8768 | I13: =IF(F13=0,,H13*(1+F13)*C13-(H13*B13)) -> 0 | J13: =IF(G13=0,IF(F13=0,,H13*(1+F13)*C13-(H13*B13)),H13*(1+G13)*C13-(H13*B13)) -> 0
A14: MT | B14: 0.04 | C14: 0.04 | H14: =PREÇOS!D15 -> 10.8768 | I14: =IF(F14=0,,H14*(1+F14)*C14-(H14*B14)) -> 0 | J14: =IF(G14=0,IF(F14=0,,H14*(1+F14)*C14-(H14*B14)),H14*(1+G14)*C14-(H14*B14)) -> 0
A15: PA | B15: 0.04 | C15: 0.04 | H15: =PREÇOS!D16 -> 10.8768 | I15: =IF(F15=0,,H15*(1+F15)*C15-(H15*B15)) -> 0 | J15: =IF(G15=0,IF(F15=0,,H15*(1+F15)*C15-(H15*B15)),H15*(1+G15)*C15-(H15*B15)) -> 0
A16: PB | B16: 0.04 | C16: 0.04 | H16: =PREÇOS!D17 -> 10.8768 | I16: =IF(F16=0,,H16*(1+F16)*C16-(H16*B16)) -> 0 | J16: =IF(G16=0,IF(F16=0,,H16*(1+F16)*C16-(H16*B16)),H16*(1+G16)*C16-(H16*B16)) -> 0
A17: PE | B17: 0.04 | C17: 0.04 | H17: =PREÇOS!D18 -> 10.8768 | I17: =IF(F17=0,,H17*(1+F17)*C17-(H17*B17)) -> 0 | J17: =IF(G17=0,IF(F17=0,,H17*(1+F17)*C17-(H17*B17)),H17*(1+G17)*C17-(H17*B17)) -> 0
A18: PI | B18: 0.04 | C18: 0.04 | H18: =PREÇOS!D19 -> 10.8768 | I18: =IF(F18=0,,H18*(1+F18)*C18-(H18*B18)) -> 0 | J18: =IF(G18=0,IF(F18=0,,H18*(1+F18)*C18-(H18*B18)),H18*(1+G18)*C18-(H18*B18)) -> 0
A19: PR | B19: 0.12 | C19: 0.12 | H19: =PREÇOS!D20 -> 11.9171 | I19: =IF(F19=0,,H19*(1+F19)*C19-(H19*B19)) -> 0 | J19: =IF(G19=0,IF(F19=0,,H19*(1+F19)*C19-(H19*B19)),H19*(1+G19)*C19-(H19*B19)) -> 0
A20: RJ | B20: 0.04 | C20: 0.22 | D20: 0.352 | F20: 0.664 | H20: =PREÇOS!D21 -> 10.8768 | I20: =IF(F20=0,,H20*(1+F20)*C20-(H20*B20)) -> 3.5467069 | J20: =IF(G20=0,IF(F20=0,,H20*(1+F20)*C20-(H20*B20)),H20*(1+G20)*C20-(H20*B20)) -> 3.5467069
A21: RN | B21: 0.04 | C21: 0.04 | H21: =PREÇOS!D22 -> 10.8768 | I21: =IF(F21=0,,H21*(1+F21)*C21-(H21*B21)) -> 0 | J21: =IF(G21=0,IF(F21=0,,H21*(1+F21)*C21-(H21*B21)),H21*(1+G21)*C21-(H21*B21)) -> 0
A22: RO | B22: 0.04 | C22: 0.04 | H22: =PREÇOS!D23 -> 10.8768 | I22: =IF(F22=0,,H22*(1+F22)*C22-(H22*B22)) -> 0 | J22: =IF(G22=0,IF(F22=0,,H22*(1+F22)*C22-(H22*B22)),H22*(1+G22)*C22-(H22*B22)) -> 0
A23: RR | B23: 0.04 | C23: 0.04 | H23: =PREÇOS!D24 -> 10.8768 | I23: =IF(F23=0,,H23*(1+F23)*C23-(H23*B23)) -> 0 | J23: =IF(G23=0,IF(F23=0,,H23*(1+F23)*C23-(H23*B23)),H23*(1+G23)*C23-(H23*B23)) -> 0
A24: RS | B24: 0.04 | C24: 0.04 | H24: =PREÇOS!D25 -> 10.8768 | I24: =IF(F24=0,,H24*(1+F24)*C24-(H24*B24)) -> 0 | J24: =IF(G24=0,IF(F24=0,,H24*(1+F24)*C24-(H24*B24)),H24*(1+G24)*C24-(H24*B24)) -> 0
A25: SC | B25: 0.04 | C25: 0.04 | H25: =PREÇOS!D26 -> 10.8768 | I25: =IF(F25=0,,H25*(1+F25)*C25-(H25*B25)) -> 0 | J25: =IF(G25=0,IF(F25=0,,H25*(1+F25)*C25-(H25*B25)),H25*(1+G25)*C25-(H25*B25)) -> 0
A26: SE | B26: 0.04 | C26: 0.04 | H26: =PREÇOS!D27 -> 10.8768 | I26: =IF(F26=0,,H26*(1+F26)*C26-(H26*B26)) -> 0 | J26: =IF(G26=0,IF(F26=0,,H26*(1+F26)*C26-(H26*B26)),H26*(1+G26)*C26-(H26*B26)) -> 0
A27: SP | B27: 0.04 | C27: 0.18 | D27: 0.4832 | F27: 0.618 | H27: =PREÇOS!D28 -> 10.8768 | I27: =IF(F27=0,,H27*(1+F27)*C27-(H27*B27)) -> 2.7326872 | J27: =IF(G27=0,IF(F27=0,,H27*(1+F27)*C27-(H27*B27)),H27*(1+G27)*C27-(H27*B27)) -> 2.7326872
A28: SP/Atacado | B28: =B27 -> 0.04 | C28: =C27 -> 0.18 | D28: =D27 -> 0.4832 | E28: =E27 -> 0 | F28: =F27 -> 0.618 | G28: =G27 -> 0 | H28: =PREÇOS!D29 -> 10.8768 | I28: =IF(F28=0,,H28*(1+F28)*C28-(H28*B28)) -> 2.7326872 | J28: =IF(G28=0,IF(F28=0,,H28*(1+F28)*C28-(H28*B28)),H28*(1+G28)*C28-(H28*B28)) -> 2.7326872
A29: TO | B29: 0.04 | C29: 0.04 | H29: =PREÇOS!D30 -> 10.8768 | I29: =IF(F29=0,,H29*(1+F29)*C29-(H29*B29)) -> 0 | J29: =IF(G29=0,IF(F29=0,,H29*(1+F29)*C29-(H29*B29)),H29*(1+G29)*C29-(H29*B29)) -> 0
A30: EX | H30: =PREÇOS!D31 -> 9.4348 | I30: =IF(F30=0,,H30*(1+F30)*C30-(H30*B30)) -> 0 | J30: =IF(G30=0,IF(F30=0,,H30*(1+F30)*C30-(H30*B30)),H30*(1+G30)*C30-(H30*B30)) -> 0

Sheet ST PAPAPASTA
A1: Estado | B1: Aliquota interestadual | C1: Aliquota interna | D1: MVA (normal) | E1: MVA (simples) | F1: Ajustada (normal) | G1: Ajustada (simples) | H1: Preço | I1: ST Normal | J1: ST Simples
A2: AC | B2: 0.07 | C2: 0.07 | H2: =PREÇOS!E3 -> 7.19 | I2: =IF(F2=0,,H2*(1+F2)*C2-(H2*B2)) -> 0 | J2: =IF(G2=0,IF(F2=0,,H2*(1+F2)*C2-(H2*B2)),H2*(1+G2)*C2-(H2*B2)) -> 0
A3: AL | B3: 0.07 | C3: 0.19 | D3: 0.2 | F3: 0.361 | H3: =PREÇOS!E4 -> 7.19 | I3: =IF(F3=0,,H3*(1+F3)*C3-(H3*B3)) -> 1.3559621 | J3: =IF(G3=0,IF(F3=0,,H3*(1+F3)*C3-(H3*B3)),H3*(1+G3)*C3-(H3*B3)) -> 1.3559621
A4: AM | B4: 0.07 | C4: 0.07 | H4: =PREÇOS!E5 -> 7.19 | I4: =IF(F4=0,,H4*(1+F4)*C4-(H4*B4)) -> 0 | J4: =IF(G4=0,IF(F4=0,,H4*(1+F4)*C4-(H4*B4)),H4*(1+G4)*C4-(H4*B4)) -> 0
A5: AP | B5: 0.07 | C5: 0.18 | D5: 0.38 | F5: 0.5651 | H5: =PREÇOS!E6 -> 7.19 | I5: =IF(F5=0,,H5*(1+F5)*C5-(H5*B5)) -> 1.5222524 | J5: =IF(G5=0,IF(F5=0,,H5*(1+F5)*C5-(H5*B5)),H5*(1+G5)*C5-(H5*B5)) -> 1.5222524
A6: BA | B6: 0.07 | C6: 0.07 | H6: =PREÇOS!E7 -> 7.19 | I6: =IF(F6=0,,H6*(1+F6)*C6-(H6*B6)) -> 0 | J6: =IF(G6=0,IF(F6=0,,H6*(1+F6)*C6-(H6*B6)),H6*(1+G6)*C6-(H6*B6)) -> 0
A7: CE | B7: 0.07 | C7: 0.07 | H7: =PREÇOS!E8 -> 7.19 | I7: =IF(F7=0,,H7*(1+F7)*C7-(H7*B7)) -> 0 | J7: =IF(G7=0,IF(F7=0,,H7*(1+F7)*C7-(H7*B7)),H7*(1+G7)*C7-(H7*B7)) -> 0
A8: DF | B8: 0.07 | C8: 0.07 | H8: =PREÇOS!E9 -> 7.19 | I8: =IF(F8=0,,H8*(1+F8)*C8-(H8*B8)) -> 0 | J8: =IF(G8=0,IF(F8=0,,H8*(1+F8)*C8-(H8*B8)),H8*(1+G8)*C8-(H8*B8)) -> 0
A9: ES | B9: 0.07 | C9: 0.07 | H9: =PREÇOS!E10 -> 7.19 | I9: =IF(F9=0,,H9*(1+F9)*C9-(H9*B9)) -> 0 | J9: =IF(G9=0,IF(F9=0,,H9*(1+F9)*C9-(H9*B9)),H9*(1+G9)*C9-(H9*B9)) -> 0
A10: GO | B10: 0.07 | C10: 0.07 | H10: =PREÇOS!E11 -> 7.19 | I10: =IF(F10=0,,H10*(1+F10)*C10-(H10*B10)) -> 0 | J10: =IF(G10=0,IF(F10=0,,H10*(1+F10)*C10-(H10*B10)),H10*(1+G10)*C10-(H10*B10)) -> 0
A11: MA | B11: 0.07 | C11: 0.07 | H11: =PREÇOS!E12 -> 7.19 | I11: =IF(F11=0,,H11*(1+F11)*C11-(H11*B11)) -> 0 | J11: =IF(G11=0,IF(F11=0,,H11*(1+F11)*C11-(H11*B11)),H11*(1+G11)*C11-(H11*B11)) -> 0
A12: MG | B12: 0.12 | C12: 0.18 | D12: 0.35 | F12: 0.35 | H12: =PREÇOS!E13 -> 7.67 | I12: =IF(F12=0,,H12*(1+F12)*C12-(H12*B12)) -> 0.94341 | J12: =IF(G12=0,IF(F12=0,,H12*(1+F12)*C12-(H12*B12)),H12*(1+G12)*C12-(H12*B12)) -> 0.94341
A13: MS | B13: 0.07 | C13: 0.07 | H13: =PREÇOS!E14 -> 7.19 | I13: =IF(F13=0,,H13*(1+F13)*C13-(H13*B13)) -> 0 | J13: =IF(G13=0,IF(F13=0,,H13*(1+F13)*C13-(H13*B13)),H13*(1+G13)*C13-(H13*B13)) -> 0
A14: MT | B14: 0.07 | C14: 0.17 | D14: 0.3545 | F14: 0.3545 | H14: =PREÇOS!E15 -> 7.19 | I14: =IF(F14=0,,H14*(1+F14)*C14-(H14*B14)) -> 1.1523054 | J14: =IF(G14=0,IF(F14=0,,H14*(1+F14)*C14-(H14*B14)),H14*(1+G14)*C14-(H14*B14)) -> 1.1523054
A15: PA | B15: 0.07 | C15: 0.07 | H15: =PREÇOS!E16 -> 7.19 | I15: =IF(F15=0,,H15*(1+F15)*C15-(H15*B15)) -> 0 | J15: =IF(G15=0,IF(F15=0,,H15*(1+F15)*C15-(H15*B15)),H15*(1+G15)*C15-(H15*B15)) -> 0
A16: PB | B16: 0.07 | C16: 0.07 | H16: =PREÇOS!E17 -> 7.19 | I16: =IF(F16=0,,H16*(1+F16)*C16-(H16*B16)) -> 0 | J16: =IF(G16=0,IF(F16=0,,H16*(1+F16)*C16-(H16*B16)),H16*(1+G16)*C16-(H16*B16)) -> 0
A17: PE | B17: 0.07 | C17: 0.07 | H17: =PREÇOS!E18 -> 7.19 | I17: =IF(F17=0,,H17*(1+F17)*C17-(H17*B17)) -> 0 | J17: =IF(G17=0,IF(F17=0,,H17*(1+F17)*C17-(H17*B17)),H17*(1+G17)*C17-(H17*B17)) -> 0
A18: PI | B18: 0.07 | C18: 0.07 | H18: =PREÇOS!E19 -> 7.19 | I18: =IF(F18=0,,H18*(1+F18)*C18-(H18*B18)) -> 0 | J18: =IF(G18=0,IF(F18=0,,H18*(1+F18)*C18-(H18*B18)),H18*(1+G18)*C18-(H18*B18)) -> 0
A19: PR | B19: 0.12 | C19: 0.12 | H19: =PREÇOS!E20 -> 7.67 | I19: =IF(F19=0,,H19*(1+F19)*C19-(H19*B19)) -> 0 | J19: =IF(G19=0,IF(F19=0,,H19*(1+F19)*C19-(H19*B19)),H19*(1+G19)*C19-(H19*B19)) -> 0
A20: RJ | B20: 0.12 | C20: 0.12 | H20: =PREÇOS!E21 -> 7.67 | I20: =IF(F20=0,,H20*(1+F20)*C20-(H20*B20)) -> 0 | J20: =IF(G20=0,IF(F20=0,,H20*(1+F20)*C20-(H20*B20)),H20*(1+G20)*C20-(H20*B20)) -> 0
A21: RN | B21: 0.07 | C21: 0.07 | H21: =PREÇOS!E22 -> 7.19 | I21: =IF(F21=0,,H21*(1+F21)*C21-(H21*B21)) -> 0 | J21: =IF(G21=0,IF(F21=0,,H21*(1+F21)*C21-(H21*B21)),H21*(1+G21)*C21-(H21*B21)) -> 0
A22: RO | B22: 0.07 | C22: 0.07 | H22: =PREÇOS!E23 -> 7.19 | I22: =IF(F22=0,,H22*(1+F22)*C22-(H22*B22)) -> 0 | J22: =IF(G22=0,IF(F22=0,,H22*(1+F22)*C22-(H22*B22)),H22*(1+G22)*C22-(H22*B22)) -> 0
A23: RR | B23: 0.07 | C23: 0.07 | H23: =PREÇOS!E24 -> 7.19 | I23: =IF(F23=0,,H23*(1+F23)*C23-(H23*B23)) -> 0 | J23: =IF(G23=0,IF(F23=0,,H23*(1+F23)*C23-(H23*B23)),H23*(1+G23)*C23-(H23*B23)) -> 0
A24: RS | B24: 0.12 | C24: 0.12 | H24: =PREÇOS!E25 -> 7.67 | I24: =IF(F24=0,,H24*(1+F24)*C24-(H24*B24)) -> 0 | J24: =IF(G24=0,IF(F24=0,,H24*(1+F24)*C24-(H24*B24)),H24*(1+G24)*C24-(H24*B24)) -> 0
A25: SC | B25: 0.12 | C25: 0.12 | H25: =PREÇOS!E26 -> 7.67 | I25: =IF(F25=0,,H25*(1+F25)*C25-(H25*B25)) -> 0 | J25: =IF(G25=0,IF(F25=0,,H25*(1+F25)*C25-(H25*B25)),H25*(1+G25)*C25-(H25*B25)) -> 0
A26: SE | B26: 0.07 | C26: 0.07 | H26: =PREÇOS!E27 -> 7.19 | I26: =IF(F26=0,,H26*(1+F26)*C26-(H26*B26)) -> 0 | J26: =IF(G26=0,IF(F26=0,,H26*(1+F26)*C26-(H26*B26)),H26*(1+G26)*C26-(H26*B26)) -> 0
A27: SP | B27: 0.12 | C27: 0.12 | H27: =PREÇOS!E28 -> 7.67 | I27: =IF(F27=0,,H27*(1+F27)*C27-(H27*B27)) -> 0 | J27: =IF(G27=0,IF(F27=0,,H27*(1+F27)*C27-(H27*B27)),H27*(1+G27)*C27-(H27*B27)) -> 0
A28: SP/Atacado | B28: =B27 -> 0.12 | C28: =C27 -> 0.12 | D28: =D27 -> 0 | E28: =E27 -> 0 | F28: =F27 -> 0 | G28: =G27 -> 0 | H28: =PREÇOS!E29 -> 7.67 | I28: =IF(F28=0,,H28*(1+F28)*C28-(H28*B28)) -> 0 | J28: =IF(G28=0,IF(F28=0,,H28*(1+F28)*C28-(H28*B28)),H28*(1+G28)*C28-(H28*B28)) -> 0
A29: TO | B29: 0.07 | C29: 0.07 | H29: =PREÇOS!E30 -> 7.19 | I29: =IF(F29=0,,H29*(1+F29)*C29-(H29*B29)) -> 0 | J29: =IF(G29=0,IF(F29=0,,H29*(1+F29)*C29-(H29*B29)),H29*(1+G29)*C29-(H29*B29)) -> 0
A30: EX | H30: =PREÇOS!E31 -> 6.03 | I30: =IF(F30=0,,H30*(1+F30)*C30-(H30*B30)) -> 0 | J30: =IF(G30=0,IF(F30=0,,H30*(1+F30)*C30-(H30*B30)),H30*(1+G30)*C30-(H30*B30)) -> 0

Sheet ST PALITINHOS
A1: Estado | B1: Aliquota interestadual | C1: Aliquota interna | D1: MVA (normal) | E1: MVA (simples) | F1: Ajustada (normal) | G1: Ajustada (simples) | H1: Preço | I1: ST Normal | J1: ST Simples
A2: AC | B2: 0.07 | C2: 0.07 | H2: =PREÇOS!C3 -> 3.2 | I2: =IF(F2=0,,H2*(1+F2)*C2-(H2*B2)) -> 0 | J2: =IF(G2=0,IF(F2=0,,H2*(1+F2)*C2-(H2*B2)),H2*(1+G2)*C2-(H2*B2)) -> 0
A3: AL | B3: 0.07 | C3: 0.19 | D3: 0.5432 | F3: 0.794 | H3: =PREÇOS!C4 -> 3.2 | I3: =IF(F3=0,,H3*(1+F3)*C3-(H3*B3)) -> 0.866752 | J3: =IF(G3=0,IF(F3=0,,H3*(1+F3)*C3-(H3*B3)),H3*(1+G3)*C3-(H3*B3)) -> 0.866752
A4: AM | B4: 0.07 | C4: 0.18 | H4: =PREÇOS!C5 -> 3.2 | I4: =IF(F4=0,,H4*(1+F4)*C4-(H4*B4)) -> 0 | J4: =IF(G4=0,IF(F4=0,,H4*(1+F4)*C4-(H4*B4)),H4*(1+G4)*C4-(H4*B4)) -> 0
A5: AP | B5: 0.07 | C5: 0.18 | D5: 0.41 | F5: 0.5991 | H5: =PREÇOS!C6 -> 3.2 | I5: =IF(F5=0,,H5*(1+F5)*C5-(H5*B5)) -> 0.6970816 | J5: =IF(G5=0,IF(F5=0,,H5*(1+F5)*C5-(H5*B5)),H5*(1+G5)*C5-(H5*B5)) -> 0.6970816
A6: BA | B6: 0.07 | C6: 0.07 | H6: =PREÇOS!C7 -> 3.2 | I6: =IF(F6=0,,H6*(1+F6)*C6-(H6*B6)) -> 0 | J6: =IF(G6=0,IF(F6=0,,H6*(1+F6)*C6-(H6*B6)),H6*(1+G6)*C6-(H6*B6)) -> 0
A7: CE | B7: 0.07 | C7: 0.07 | H7: =PREÇOS!C8 -> 3.2 | I7: =IF(F7=0,,H7*(1+F7)*C7-(H7*B7)) -> 0 | J7: =IF(G7=0,IF(F7=0,,H7*(1+F7)*C7-(H7*B7)),H7*(1+G7)*C7-(H7*B7)) -> 0
A8: DF | B8: 0.07 | C8: 0.07 | H8: =PREÇOS!C9 -> 3.2 | I8: =IF(F8=0,,H8*(1+F8)*C8-(H8*B8)) -> 0 | J8: =IF(G8=0,IF(F8=0,,H8*(1+F8)*C8-(H8*B8)),H8*(1+G8)*C8-(H8*B8)) -> 0
A9: ES | B9: 0.07 | C9: 0.07 | H9: =PREÇOS!C10 -> 3.2 | I9: =IF(F9=0,,H9*(1+F9)*C9-(H9*B9)) -> 0 | J9: =IF(G9=0,IF(F9=0,,H9*(1+F9)*C9-(H9*B9)),H9*(1+G9)*C9-(H9*B9)) -> 0
A10: GO | B10: 0.07 | C10: 0.07 | H10: =PREÇOS!C11 -> 3.2 | I10: =IF(F10=0,,H10*(1+F10)*C10-(H10*B10)) -> 0 | J10: =IF(G10=0,IF(F10=0,,H10*(1+F10)*C10-(H10*B10)),H10*(1+G10)*C10-(H10*B10)) -> 0
A11: MA | B11: 0.07 | C11: 0.07 | H11: =PREÇOS!C12 -> 3.2 | I11: =IF(F11=0,,H11*(1+F11)*C11-(H11*B11)) -> 0 | J11: =IF(G11=0,IF(F11=0,,H11*(1+F11)*C11-(H11*B11)),H11*(1+G11)*C11-(H11*B11)) -> 0
A12: MG | B12: 0.12 | C12: 0.18 | D12: 0.4 | F12: 0.5024 | H12: =PREÇOS!C13 -> 3.41 | I12: =IF(F12=0,,H12*(1+F12)*C12-(H12*B12)) -> 0.51297312 | J12: =IF(G12=0,IF(F12=0,,H12*(1+F12)*C12-(H12*B12)),H12*(1+G12)*C12-(H12*B12)) -> 0.51297312
A13: MS | B13: 0.07 | C13: 0.07 | H13: =PREÇOS!C14 -> 3.2 | I13: =IF(F13=0,,H13*(1+F13)*C13-(H13*B13)) -> 0 | J13: =IF(G13=0,IF(F13=0,,H13*(1+F13)*C13-(H13*B13)),H13*(1+G13)*C13-(H13*B13)) -> 0
A14: MT | B14: 0.07 | C14: 0.17 | D14: 0.4552 | F14: 0.6305 | H14: =PREÇOS!C15 -> 3.2 | I14: =IF(F14=0,,H14*(1+F14)*C14-(H14*B14)) -> 0.662992 | J14: =IF(G14=0,IF(F14=0,,H14*(1+F14)*C14-(H14*B14)),H14*(1+G14)*C14-(H14*B14)) -> 0.662992
A15: PA | B15: 0.07 | C15: 0.07 | H15: =PREÇOS!C16 -> 3.2 | I15: =IF(F15=0,,H15*(1+F15)*C15-(H15*B15)) -> 0 | J15: =IF(G15=0,IF(F15=0,,H15*(1+F15)*C15-(H15*B15)),H15*(1+G15)*C15-(H15*B15)) -> 0
A16: PB | B16: 0.07 | C16: 0.07 | H16: =PREÇOS!C17 -> 3.2 | I16: =IF(F16=0,,H16*(1+F16)*C16-(H16*B16)) -> 0 | J16: =IF(G16=0,IF(F16=0,,H16*(1+F16)*C16-(H16*B16)),H16*(1+G16)*C16-(H16*B16)) -> 0
A17: PE | B17: 0.07 | C17: 0.07 | H17: =PREÇOS!C18 -> 3.2 | I17: =IF(F17=0,,H17*(1+F17)*C17-(H17*B17)) -> 0 | J17: =IF(G17=0,IF(F17=0,,H17*(1+F17)*C17-(H17*B17)),H17*(1+G17)*C17-(H17*B17)) -> 0
A18: PI | B18: 0.07 | C18: 0.07 | H18: =PREÇOS!C19 -> 3.2 | I18: =IF(F18=0,,H18*(1+F18)*C18-(H18*B18)) -> 0 | J18: =IF(G18=0,IF(F18=0,,H18*(1+F18)*C18-(H18*B18)),H18*(1+G18)*C18-(H18*B18)) -> 0
A19: PR | B19: 0.12 | C19: 0.195 | D19: 0.5432 | E19: 0.163 | F19: 0.687 | G19: 0.1968 | H19: =PREÇOS!C20 -> 3.41 | I19: =IF(F19=0,,H19*(1+F19)*C19-(H19*B19)) -> 0.71257065 | J19: =IF(G19=0,IF(F19=0,,H19*(1+F19)*C19-(H19*B19)),H19*(1+G19)*C19-(H19*B19)) -> 0.38661216
A20: RJ | B20: 0.12 | C20: 0.22 | D20: 0.4698 | F20: 0.6582 | H20: =PREÇOS!C21 -> 3.41 | I20: =IF(F20=0,,H20*(1+F20)*C20-(H20*B20)) -> 0.83478164 | J20: =IF(G20=0,IF(F20=0,,H20*(1+F20)*C20-(H20*B20)),H20*(1+G20)*C20-(H20*B20)) -> 0.83478164
A21: RN | B21: 0.07 | C21: 0.07 | H21: =PREÇOS!C22 -> 3.2 | I21: =IF(F21=0,,H21*(1+F21)*C21-(H21*B21)) -> 0 | J21: =IF(G21=0,IF(F21=0,,H21*(1+F21)*C21-(H21*B21)),H21*(1+G21)*C21-(H21*B21)) -> 0
A22: RO | B22: 0.07 | C22: 0.07 | H22: =PREÇOS!C23 -> 3.2 | I22: =IF(F22=0,,H22*(1+F22)*C22-(H22*B22)) -> 0 | J22: =IF(G22=0,IF(F22=0,,H22*(1+F22)*C22-(H22*B22)),H22*(1+G22)*C22-(H22*B22)) -> 0
A23: RR | B23: 0.07 | C23: 0.07 | H23: =PREÇOS!C24 -> 3.2 | I23: =IF(F23=0,,H23*(1+F23)*C23-(H23*B23)) -> 0 | J23: =IF(G23=0,IF(F23=0,,H23*(1+F23)*C23-(H23*B23)),H23*(1+G23)*C23-(H23*B23)) -> 0
A24: RS | B24: 0.12 | C24: 0.12 | H24: =PREÇOS!C25 -> 3.41 | I24: =IF(F24=0,,H24*(1+F24)*C24-(H24*B24)) -> 0 | J24: =IF(G24=0,IF(F24=0,,H24*(1+F24)*C24-(H24*B24)),H24*(1+G24)*C24-(H24*B24)) -> 0
A25: SC | B25: 0.12 | C25: 0.12 | H25: =PREÇOS!C26 -> 3.41 | I25: =IF(F25=0,,H25*(1+F25)*C25-(H25*B25)) -> 0 | J25: =IF(G25=0,IF(F25=0,,H25*(1+F25)*C25-(H25*B25)),H25*(1+G25)*C25-(H25*B25)) -> 0
A26: SE | B26: 0.07 | C26: 0.07 | H26: =PREÇOS!C27 -> 3.2 | I26: =IF(F26=0,,H26*(1+F26)*C26-(H26*B26)) -> 0 | J26: =IF(G26=0,IF(F26=0,,H26*(1+F26)*C26-(H26*B26)),H26*(1+G26)*C26-(H26*B26)) -> 0
A27: SP | B27: 0.12 | C27: 0.18 | H27: =PREÇOS!C28 -> 3.41 | I27: =IF(F27=0,,H27*(1+F27)*C27-(H27*B27)) -> 0 | J27: =IF(G27=0,IF(F27=0,,H27*(1+F27)*C27-(H27*B27)),H27*(1+G27)*C27-(H27*B27)) -> 0 | K27: comunicado enviado 1/26 - suspensão da ST para palitinhos
A28: SP/Atacado | B28: =B27 -> 0.12 | C28: =C27 -> 0.18 | D28: =D27 -> 0 | E28: =E27 -> 0 | F28: =F27 -> 0 | G28: =G27 -> 0 | H28: =PREÇOS!C29 -> 3.41 | I28: =IF(F28=0,,H28*(1+F28)*C28-(H28*B28)) -> 0 | J28: =IF(G28=0,IF(F28=0,,H28*(1+F28)*C28-(H28*B28)),H28*(1+G28)*C28-(H28*B28)) -> 0
A29: TO | B29: 0.07 | C29: 0.07 | H29: =PREÇOS!C30 -> 3.2 | I29: =IF(F29=0,,H29*(1+F29)*C29-(H29*B29)) -> 0 | J29: =IF(G29=0,IF(F29=0,,H29*(1+F29)*C29-(H29*B29)),H29*(1+G29)*C29-(H29*B29)) -> 0
A30: EX | H30: =PREÇOS!C31 -> 2.68 | I30: =IF(F30=0,,H30*(1+F30)*C30-(H30*B30)) -> 0 | J30: =IF(G30=0,IF(F30=0,,H30*(1+F30)*C30-(H30*B30)),H30*(1+G30)*C30-(H30*B30)) -> 0

Sheet ST EXTRUSADOS
A1: Estado | B1: Aliquota interestadual | C1: Aliquota interna | D1: MVA (normal) | E1: MVA (simples) | F1: Ajustada (normal) | G1: Ajustada (simples) | H1: Preço | I1: ST Normal | J1: ST Simples
A2: AC | B2: 0.07 | C2: 0.07 | H2: =PREÇOS!O3 -> 5.5141935 | I2: =IF(F2=0,,H2*(1+F2)*C2-(H2*B2)) -> 0 | J2: =IF(G2=0,IF(F2=0,,H2*(1+F2)*C2-(H2*B2)),H2*(1+G2)*C2-(H2*B2)) -> 0
A3: AL | B3: 0.07 | C3: 0.19 | D3: 0.5432 | F3: 0.794 | H3: =PREÇOS!O4 -> 5.5141935 | I3: =IF(F3=0,,H3*(1+F3)*C3-(H3*B3)) -> 1.4935745 | J3: =IF(G3=0,IF(F3=0,,H3*(1+F3)*C3-(H3*B3)),H3*(1+G3)*C3-(H3*B3)) -> 1.4935745
A4: AM | B4: 0.07 | C4: 0.18 | H4: =PREÇOS!O5 -> 5.5141935 | I4: =IF(F4=0,,H4*(1+F4)*C4-(H4*B4)) -> 0 | J4: =IF(G4=0,IF(F4=0,,H4*(1+F4)*C4-(H4*B4)),H4*(1+G4)*C4-(H4*B4)) -> 0
A5: AP | B5: 0.07 | C5: 0.18 | D5: 0.41 | F5: 0.5991 | H5: =PREÇOS!O6 -> 5.5141935 | I5: =IF(F5=0,,H5*(1+F5)*C5-(H5*B5)) -> 1.2012009 | J5: =IF(G5=0,IF(F5=0,,H5*(1+F5)*C5-(H5*B5)),H5*(1+G5)*C5-(H5*B5)) -> 1.2012009
A6: BA | B6: 0.07 | C6: 0.07 | H6: =PREÇOS!O7 -> 5.5141935 | I6: =IF(F6=0,,H6*(1+F6)*C6-(H6*B6)) -> 0 | J6: =IF(G6=0,IF(F6=0,,H6*(1+F6)*C6-(H6*B6)),H6*(1+G6)*C6-(H6*B6)) -> 0
A7: CE | B7: 0.07 | C7: 0.07 | H7: =PREÇOS!O8 -> 5.5141935 | I7: =IF(F7=0,,H7*(1+F7)*C7-(H7*B7)) -> 0 | J7: =IF(G7=0,IF(F7=0,,H7*(1+F7)*C7-(H7*B7)),H7*(1+G7)*C7-(H7*B7)) -> 0
A8: DF | B8: 0.07 | C8: 0.07 | H8: =PREÇOS!O9 -> 5.5141935 | I8: =IF(F8=0,,H8*(1+F8)*C8-(H8*B8)) -> 0 | J8: =IF(G8=0,IF(F8=0,,H8*(1+F8)*C8-(H8*B8)),H8*(1+G8)*C8-(H8*B8)) -> 0
A9: ES | B9: 0.07 | C9: 0.07 | H9: =PREÇOS!O10 -> 5.5141935 | I9: =IF(F9=0,,H9*(1+F9)*C9-(H9*B9)) -> 0 | J9: =IF(G9=0,IF(F9=0,,H9*(1+F9)*C9-(H9*B9)),H9*(1+G9)*C9-(H9*B9)) -> 0
A10: GO | B10: 0.07 | C10: 0.07 | H10: =PREÇOS!O11 -> 5.5141935 | I10: =IF(F10=0,,H10*(1+F10)*C10-(H10*B10)) -> 0 | J10: =IF(G10=0,IF(F10=0,,H10*(1+F10)*C10-(H10*B10)),H10*(1+G10)*C10-(H10*B10)) -> 0
A11: MA | B11: 0.07 | C11: 0.07 | H11: =PREÇOS!O12 -> 5.5141935 | I11: =IF(F11=0,,H11*(1+F11)*C11-(H11*B11)) -> 0 | J11: =IF(G11=0,IF(F11=0,,H11*(1+F11)*C11-(H11*B11)),H11*(1+G11)*C11-(H11*B11)) -> 0
A12: MG | B12: 0.12 | C12: 0.18 | D12: 0.4 | F12: 0.5024 | H12: =PREÇOS!O13 -> 5.8275 | I12: =IF(F12=0,,H12*(1+F12)*C12-(H12*B12)) -> 0.87664248 | J12: =IF(G12=0,IF(F12=0,,H12*(1+F12)*C12-(H12*B12)),H12*(1+G12)*C12-(H12*B12)) -> 0.87664248
A13: MS | B13: 0.07 | C13: 0.07 | H13: =PREÇOS!O14 -> 5.5141935 | I13: =IF(F13=0,,H13*(1+F13)*C13-(H13*B13)) -> 0 | J13: =IF(G13=0,IF(F13=0,,H13*(1+F13)*C13-(H13*B13)),H13*(1+G13)*C13-(H13*B13)) -> 0
A14: MT | B14: 0.07 | C14: 0.17 | D14: 0.4552 | F14: 0.6305 | H14: =PREÇOS!O15 -> 5.5141935 | I14: =IF(F14=0,,H14*(1+F14)*C14-(H14*B14)) -> 1.1424582 | J14: =IF(G14=0,IF(F14=0,,H14*(1+F14)*C14-(H14*B14)),H14*(1+G14)*C14-(H14*B14)) -> 1.1424582
A15: PA | B15: 0.07 | C15: 0.07 | H15: =PREÇOS!O16 -> 5.5141935 | I15: =IF(F15=0,,H15*(1+F15)*C15-(H15*B15)) -> 0 | J15: =IF(G15=0,IF(F15=0,,H15*(1+F15)*C15-(H15*B15)),H15*(1+G15)*C15-(H15*B15)) -> 0
A16: PB | B16: 0.07 | C16: 0.07 | H16: =PREÇOS!O17 -> 5.5141935 | I16: =IF(F16=0,,H16*(1+F16)*C16-(H16*B16)) -> 0 | J16: =IF(G16=0,IF(F16=0,,H16*(1+F16)*C16-(H16*B16)),H16*(1+G16)*C16-(H16*B16)) -> 0
A17: PE | B17: 0.07 | C17: 0.07 | H17: =PREÇOS!O18 -> 5.5141935 | I17: =IF(F17=0,,H17*(1+F17)*C17-(H17*B17)) -> 0 | J17: =IF(G17=0,IF(F17=0,,H17*(1+F17)*C17-(H17*B17)),H17*(1+G17)*C17-(H17*B17)) -> 0
A18: PI | B18: 0.07 | C18: 0.07 | H18: =PREÇOS!O19 -> 5.5141935 | I18: =IF(F18=0,,H18*(1+F18)*C18-(H18*B18)) -> 0 | J18: =IF(G18=0,IF(F18=0,,H18*(1+F18)*C18-(H18*B18)),H18*(1+G18)*C18-(H18*B18)) -> 0
A19: PR | B19: 0.12 | C19: 0.195 | D19: 0.5432 | E19: 0.163 | F19: 0.687 | G19: 0.1968 | H19: =PREÇOS!O20 -> 5.8275 | I19: =IF(F19=0,,H19*(1+F19)*C19-(H19*B19)) -> 1.2177435 | J19: =IF(G19=0,IF(F19=0,,H19*(1+F19)*C19-(H19*B19)),H19*(1+G19)*C19-(H19*B19)) -> 0.66069864
A20: RJ | B20: 0.12 | C20: 0.22 | D20: 0.4698 | F20: 0.6582 | H20: =PREÇOS!O21 -> 5.8275 | I20: =IF(F20=0,,H20*(1+F20)*C20-(H20*B20)) -> 1.4265953 | J20: =IF(G20=0,IF(F20=0,,H20*(1+F20)*C20-(H20*B20)),H20*(1+G20)*C20-(H20*B20)) -> 1.4265953
A21: RN | B21: 0.07 | C21: 0.07 | H21: =PREÇOS!O22 -> 5.5141935 | I21: =IF(F21=0,,H21*(1+F21)*C21-(H21*B21)) -> 0 | J21: =IF(G21=0,IF(F21=0,,H21*(1+F21)*C21-(H21*B21)),H21*(1+G21)*C21-(H21*B21)) -> 0
A22: RO | B22: 0.07 | C22: 0.07 | H22: =PREÇOS!O23 -> 5.5141935 | I22: =IF(F22=0,,H22*(1+F22)*C22-(H22*B22)) -> 0 | J22: =IF(G22=0,IF(F22=0,,H22*(1+F22)*C22-(H22*B22)),H22*(1+G22)*C22-(H22*B22)) -> 0
A23: RR | B23: 0.07 | C23: 0.07 | H23: =PREÇOS!O24 -> 5.5141935 | I23: =IF(F23=0,,H23*(1+F23)*C23-(H23*B23)) -> 0 | J23: =IF(G23=0,IF(F23=0,,H23*(1+F23)*C23-(H23*B23)),H23*(1+G23)*C23-(H23*B23)) -> 0
A24: RS | B24: 0.12 | C24: 0.12 | H24: =PREÇOS!O25 -> 5.8275 | I24: =IF(F24=0,,H24*(1+F24)*C24-(H24*B24)) -> 0 | J24: =IF(G24=0,IF(F24=0,,H24*(1+F24)*C24-(H24*B24)),H24*(1+G24)*C24-(H24*B24)) -> 0
A25: SC | B25: 0.12 | C25: 0.12 | H25: =PREÇOS!O26 -> 5.8275 | I25: =IF(F25=0,,H25*(1+F25)*C25-(H25*B25)) -> 0 | J25: =IF(G25=0,IF(F25=0,,H25*(1+F25)*C25-(H25*B25)),H25*(1+G25)*C25-(H25*B25)) -> 0
A26: SE | B26: 0.07 | C26: 0.07 | H26: =PREÇOS!O27 -> 5.5141935 | I26: =IF(F26=0,,H26*(1+F26)*C26-(H26*B26)) -> 0 | J26: =IF(G26=0,IF(F26=0,,H26*(1+F26)*C26-(H26*B26)),H26*(1+G26)*C26-(H26*B26)) -> 0
A27: SP | B27: 0.12 | C27: 0.18 | H27: =PREÇOS!O28 -> 5.8275 | I27: =IF(F27=0,,H27*(1+F27)*C27-(H27*B27)) -> 0 | J27: =IF(G27=0,IF(F27=0,,H27*(1+F27)*C27-(H27*B27)),H27*(1+G27)*C27-(H27*B27)) -> 0 | K27: comunicado enviado 1/26 - suspensão da ST para palitinhos
A28: SP/Atacado | B28: =B27 -> 0.12 | C28: =C27 -> 0.18 | D28: =D27 -> 0 | E28: =E27 -> 0 | F28: =F27 -> 0 | G28: =G27 -> 0 | H28: =PREÇOS!O29 -> 5.8275 | I28: =IF(F28=0,,H28*(1+F28)*C28-(H28*B28)) -> 0 | J28: =IF(G28=0,IF(F28=0,,H28*(1+F28)*C28-(H28*B28)),H28*(1+G28)*C28-(H28*B28)) -> 0
A29: TO | B29: 0.07 | C29: 0.07 | H29: =PREÇOS!O30 -> 5.5141935 | I29: =IF(F29=0,,H29*(1+F29)*C29-(H29*B29)) -> 0 | J29: =IF(G29=0,IF(F29=0,,H29*(1+F29)*C29-(H29*B29)),H29*(1+G29)*C29-(H29*B29)) -> 0
A30: EX | H30: =PREÇOS!O31 -> 5.5141935 | I30: =IF(F30=0,,H30*(1+F30)*C30-(H30*B30)) -> 0 | J30: =IF(G30=0,IF(F30=0,,H30*(1+F30)*C30-(H30*B30)),H30*(1+G30)*C30-(H30*B30)) -> 0

Sheet ST BISCOTTI
A1: Estado | B1: Aliquota interestadual | C1: Aliquota interna | D1: MVA (normal) | E1: MVA (simples) | F1: Ajustada (normal) | G1: Ajustada (simples) | H1: Preço | I1: ST Normal | J1: ST Simples
A2: AC | B2: 0.07 | C2: 0.19 | H2: =PREÇOS!H3 -> 6.88 | I2: =IF(F2=0,,H2*(1+F2)*C2-(H2*B2)) -> 0 | J2: =IF(G2=0,IF(F2=0,,H2*(1+F2)*C2-(H2*B2)),H2*(1+G2)*C2-(H2*B2)) -> 0
A3: AL | B3: 0.07 | C3: 0.2 | F3: 0.5113 | H3: =PREÇOS!H4 -> 6.88 | I3: =IF(F3=0,,H3*(1+F3)*C3-(H3*B3)) -> 1.5979488 | J3: =IF(G3=0,IF(F3=0,,H3*(1+F3)*C3-(H3*B3)),H3*(1+G3)*C3-(H3*B3)) -> 1.5979488
A4: AM | B4: 0.07 | C4: 0.2 | H4: =PREÇOS!H5 -> 6.88 | I4: =IF(F4=0,,H4*(1+F4)*C4-(H4*B4)) -> 0 | J4: =IF(G4=0,IF(F4=0,,H4*(1+F4)*C4-(H4*B4)),H4*(1+G4)*C4-(H4*B4)) -> 0
A5: AP | B5: 0.07 | C5: 0.18 | F5: 0.5198 | H5: =PREÇOS!H6 -> 6.88 | I5: =IF(F5=0,,H5*(1+F5)*C5-(H5*B5)) -> 1.4005203 | J5: =IF(G5=0,IF(F5=0,,H5*(1+F5)*C5-(H5*B5)),H5*(1+G5)*C5-(H5*B5)) -> 1.4005203
A6: BA | B6: 0.07 | C6: 0.19 | H6: =PREÇOS!H7 -> 6.88 | I6: =IF(F6=0,,H6*(1+F6)*C6-(H6*B6)) -> 0 | J6: =IF(G6=0,IF(F6=0,,H6*(1+F6)*C6-(H6*B6)),H6*(1+G6)*C6-(H6*B6)) -> 0
A7: CE | B7: 0.07 | C7: 0.2 | H7: =PREÇOS!H8 -> 6.88 | I7: =IF(F7=0,,H7*(1+F7)*C7-(H7*B7)) -> 0 | J7: =IF(G7=0,IF(F7=0,,H7*(1+F7)*C7-(H7*B7)),H7*(1+G7)*C7-(H7*B7)) -> 0
A8: DF | B8: 0.07 | C8: 0.18 | H8: =PREÇOS!H9 -> 6.88 | I8: =IF(F8=0,,H8*(1+F8)*C8-(H8*B8)) -> 0 | J8: =IF(G8=0,IF(F8=0,,H8*(1+F8)*C8-(H8*B8)),H8*(1+G8)*C8-(H8*B8)) -> 0
A9: ES | B9: 0.07 | C9: 0.17 | H9: =PREÇOS!H10 -> 6.88 | I9: =IF(F9=0,,H9*(1+F9)*C9-(H9*B9)) -> 0 | J9: =IF(G9=0,IF(F9=0,,H9*(1+F9)*C9-(H9*B9)),H9*(1+G9)*C9-(H9*B9)) -> 0
A10: GO | B10: 0.07 | C10: 0.17 | H10: =PREÇOS!H11 -> 6.88 | I10: =IF(F10=0,,H10*(1+F10)*C10-(H10*B10)) -> 0 | J10: =IF(G10=0,IF(F10=0,,H10*(1+F10)*C10-(H10*B10)),H10*(1+G10)*C10-(H10*B10)) -> 0
A11: MA | B11: 0.07 | C11: 0.2 | H11: =PREÇOS!H12 -> 6.88 | I11: =IF(F11=0,,H11*(1+F11)*C11-(H11*B11)) -> 0 | J11: =IF(G11=0,IF(F11=0,,H11*(1+F11)*C11-(H11*B11)),H11*(1+G11)*C11-(H11*B11)) -> 0
A12: MG | B12: 0.12 | C12: 0.12 | F12: 0.25 | H12: =PREÇOS!H13 -> 7.35 | I12: =IF(F12=0,,H12*(1+F12)*C12-(H12*B12)) -> 0.2205 | J12: =IF(G12=0,IF(F12=0,,H12*(1+F12)*C12-(H12*B12)),H12*(1+G12)*C12-(H12*B12)) -> 0.2205
A13: MS | B13: 0.07 | C13: 0.17 | H13: =PREÇOS!H14 -> 6.88 | I13: =IF(F13=0,,H13*(1+F13)*C13-(H13*B13)) -> 0 | J13: =IF(G13=0,IF(F13=0,,H13*(1+F13)*C13-(H13*B13)),H13*(1+G13)*C13-(H13*B13)) -> 0
A14: MT | B14: 0.07 | C14: 0.17 | F14: 0.3978 | H14: =PREÇOS!H15 -> 6.88 | I14: =IF(F14=0,,H14*(1+F14)*C14-(H14*B14)) -> 1.1532669 | J14: =IF(G14=0,IF(F14=0,,H14*(1+F14)*C14-(H14*B14)),H14*(1+G14)*C14-(H14*B14)) -> 1.1532669
A15: PA | B15: 0.07 | C15: 0.19 | H15: =PREÇOS!H16 -> 6.88 | I15: =IF(F15=0,,H15*(1+F15)*C15-(H15*B15)) -> 0 | J15: =IF(G15=0,IF(F15=0,,H15*(1+F15)*C15-(H15*B15)),H15*(1+G15)*C15-(H15*B15)) -> 0
A16: PB | B16: 0.07 | C16: 0.18 | H16: =PREÇOS!H17 -> 6.88 | I16: =IF(F16=0,,H16*(1+F16)*C16-(H16*B16)) -> 0 | J16: =IF(G16=0,IF(F16=0,,H16*(1+F16)*C16-(H16*B16)),H16*(1+G16)*C16-(H16*B16)) -> 0
A17: PE | B17: 0.07 | C17: 0.18 | H17: =PREÇOS!H18 -> 6.88 | I17: =IF(F17=0,,H17*(1+F17)*C17-(H17*B17)) -> 0 | J17: =IF(G17=0,IF(F17=0,,H17*(1+F17)*C17-(H17*B17)),H17*(1+G17)*C17-(H17*B17)) -> 0
A18: PI | B18: 0.07 | C18: 0.21 | H18: =PREÇOS!H19 -> 6.88 | I18: =IF(F18=0,,H18*(1+F18)*C18-(H18*B18)) -> 0 | J18: =IF(G18=0,IF(F18=0,,H18*(1+F18)*C18-(H18*B18)),H18*(1+G18)*C18-(H18*B18)) -> 0
A19: PR | B19: 0.12 | C19: 0.12 | H19: =PREÇOS!H20 -> 7.35 | I19: =IF(F19=0,,H19*(1+F19)*C19-(H19*B19)) -> 0 | J19: =IF(G19=0,IF(F19=0,,H19*(1+F19)*C19-(H19*B19)),H19*(1+G19)*C19-(H19*B19)) -> 0
A20: RJ | B20: 0.12 | C20: 0.22 | F20: 0.5253 | H20: =PREÇOS!H21 -> 7.35 | I20: =IF(F20=0,,H20*(1+F20)*C20-(H20*B20)) -> 1.5844101 | J20: =IF(G20=0,IF(F20=0,,H20*(1+F20)*C20-(H20*B20)),H20*(1+G20)*C20-(H20*B20)) -> 1.5844101
A21: RN | B21: 0.07 | C21: 0.2 | H21: =PREÇOS!H22 -> 6.88 | I21: =IF(F21=0,,H21*(1+F21)*C21-(H21*B21)) -> 0 | J21: =IF(G21=0,IF(F21=0,,H21*(1+F21)*C21-(H21*B21)),H21*(1+G21)*C21-(H21*B21)) -> 0
A22: RO | B22: 0.07 | C22: 0.175 | H22: =PREÇOS!H23 -> 6.88 | I22: =IF(F22=0,,H22*(1+F22)*C22-(H22*B22)) -> 0 | J22: =IF(G22=0,IF(F22=0,,H22*(1+F22)*C22-(H22*B22)),H22*(1+G22)*C22-(H22*B22)) -> 0
A23: RR | B23: 0.07 | C23: 0.2 | H23: =PREÇOS!H24 -> 6.88 | I23: =IF(F23=0,,H23*(1+F23)*C23-(H23*B23)) -> 0 | J23: =IF(G23=0,IF(F23=0,,H23*(1+F23)*C23-(H23*B23)),H23*(1+G23)*C23-(H23*B23)) -> 0
A24: RS | B24: 0.12 | C24: 0.17 | H24: =PREÇOS!H25 -> 7.35 | I24: =IF(F24=0,,H24*(1+F24)*C24-(H24*B24)) -> 0 | J24: =IF(G24=0,IF(F24=0,,H24*(1+F24)*C24-(H24*B24)),H24*(1+G24)*C24-(H24*B24)) -> 0
A25: SC | B25: 0.12 | C25: 0.17 | H25: =PREÇOS!H26 -> 7.35 | I25: =IF(F25=0,,H25*(1+F25)*C25-(H25*B25)) -> 0 | J25: =IF(G25=0,IF(F25=0,,H25*(1+F25)*C25-(H25*B25)),H25*(1+G25)*C25-(H25*B25)) -> 0
A26: SE | B26: 0.07 | C26: 0.2 | H26: =PREÇOS!H27 -> 6.88 | I26: =IF(F26=0,,H26*(1+F26)*C26-(H26*B26)) -> 0 | J26: =IF(G26=0,IF(F26=0,,H26*(1+F26)*C26-(H26*B26)),H26*(1+G26)*C26-(H26*B26)) -> 0
A27: SP | B27: 0.12 | C27: 0.18 | D27: 0.5917 | F27: 0.5917 | H27: =PREÇOS!H28 -> 7.35 | I27: =IF(F27=0,,H27*(1+F27)*C27-(H27*B27)) -> 1.2238191 | J27: =IF(G27=0,IF(F27=0,,H27*(1+F27)*C27-(H27*B27)),H27*(1+G27)*C27-(H27*B27)) -> 1.2238191
A28: SP/Atacado | B28: =B27 -> 0.12 | C28: =C27 -> 0.18 | D28: 0.4832 | E28: =E27 -> 0 | F28: 0.4832 | G28: =G27 -> 0 | H28: =PREÇOS!H29 -> 7.35 | I28: =IF(F28=0,,H28*(1+F28)*C28-(H28*B28)) -> 1.0802736 | J28: =IF(G28=0,IF(F28=0,,H28*(1+F28)*C28-(H28*B28)),H28*(1+G28)*C28-(H28*B28)) -> 1.0802736
A29: TO | B29: 0.07 | C29: 0.2 | H29: =PREÇOS!H30 -> 6.88 | I29: =IF(F29=0,,H29*(1+F29)*C29-(H29*B29)) -> 0 | J29: =IF(G29=0,IF(F29=0,,H29*(1+F29)*C29-(H29*B29)),H29*(1+G29)*C29-(H29*B29)) -> 0
A30: EX

Sheet ST CEREAL
A1: Estado | B1: Aliquota interestadual | C1: Aliquota interna | D1: MVA (normal) | E1: MVA (simples) | F1: Ajustada (normal) | G1: Ajustada (simples) | H1: Preço | I1: ST Normal | J1: ST Simples
A2: AC | B2: 0.07 | C2: 0.17 | H2: =PREÇOS!G3 -> 7.05 | I2: =IF(F2=0,,H2*(1+F2)*C2-(H2*B2)) -> 0 | J2: =IF(G2=0,IF(F2=0,,H2*(1+F2)*C2-(H2*B2)),H2*(1+G2)*C2-(H2*B2)) -> 0
A3: AL | B3: 0.07 | C3: 0.2 | F3: 0.71 | H3: =PREÇOS!G4 -> 7.05 | I3: =IF(F3=0,,H3*(1+F3)*C3-(H3*B3)) -> 1.9176 | J3: =IF(G3=0,IF(F3=0,,H3*(1+F3)*C3-(H3*B3)),H3*(1+G3)*C3-(H3*B3)) -> 1.9176
A4: AM | B4: 0.07 | C4: 0.2 | F4: 0.5538 | H4: =PREÇOS!G5 -> 7.05 | I4: =IF(F4=0,,H4*(1+F4)*C4-(H4*B4)) -> 1.697358 | J4: =IF(G4=0,IF(F4=0,,H4*(1+F4)*C4-(H4*B4)),H4*(1+G4)*C4-(H4*B4)) -> 1.697358
A5: AP | B5: 0.07 | C5: 0.18 | H5: =PREÇOS!G6 -> 7.05 | I5: =IF(F5=0,,H5*(1+F5)*C5-(H5*B5)) -> 0 | J5: =IF(G5=0,IF(F5=0,,H5*(1+F5)*C5-(H5*B5)),H5*(1+G5)*C5-(H5*B5)) -> 0
A6: BA | B6: 0.07 | C6: 0.19 | H6: =PREÇOS!G7 -> 7.05 | I6: =IF(F6=0,,H6*(1+F6)*C6-(H6*B6)) -> 0 | J6: =IF(G6=0,IF(F6=0,,H6*(1+F6)*C6-(H6*B6)),H6*(1+G6)*C6-(H6*B6)) -> 0
A7: CE | B7: 0.07 | C7: 0.2 | H7: =PREÇOS!G8 -> 7.05 | I7: =IF(F7=0,,H7*(1+F7)*C7-(H7*B7)) -> 0 | J7: =IF(G7=0,IF(F7=0,,H7*(1+F7)*C7-(H7*B7)),H7*(1+G7)*C7-(H7*B7)) -> 0
A8: DF | B8: 0.07 | C8: 0.18 | H8: =PREÇOS!G9 -> 7.05 | I8: =IF(F8=0,,H8*(1+F8)*C8-(H8*B8)) -> 0 | J8: =IF(G8=0,IF(F8=0,,H8*(1+F8)*C8-(H8*B8)),H8*(1+G8)*C8-(H8*B8)) -> 0
A9: ES | B9: 0.07 | C9: 0.17 | H9: =PREÇOS!G10 -> 7.05 | I9: =IF(F9=0,,H9*(1+F9)*C9-(H9*B9)) -> 0 | J9: =IF(G9=0,IF(F9=0,,H9*(1+F9)*C9-(H9*B9)),H9*(1+G9)*C9-(H9*B9)) -> 0
A10: GO | B10: 0.07 | C10: 0.17 | H10: =PREÇOS!G11 -> 7.05 | I10: =IF(F10=0,,H10*(1+F10)*C10-(H10*B10)) -> 0 | J10: =IF(G10=0,IF(F10=0,,H10*(1+F10)*C10-(H10*B10)),H10*(1+G10)*C10-(H10*B10)) -> 0
A11: MA | B11: 0.07 | C11: 0.2 | H11: =PREÇOS!G12 -> 7.05 | I11: =IF(F11=0,,H11*(1+F11)*C11-(H11*B11)) -> 0 | J11: =IF(G11=0,IF(F11=0,,H11*(1+F11)*C11-(H11*B11)),H11*(1+G11)*C11-(H11*B11)) -> 0
A12: MG | B12: 0.12 | C12: 0.18 | F12: 0.4488 | H12: =PREÇOS!G13 -> 7.5 | I12: =IF(F12=0,,H12*(1+F12)*C12-(H12*B12)) -> 1.05588 | J12: =IF(G12=0,IF(F12=0,,H12*(1+F12)*C12-(H12*B12)),H12*(1+G12)*C12-(H12*B12)) -> 1.05588
A13: MS | B13: 0.07 | C13: 0.17 | H13: =PREÇOS!G14 -> 7.05 | I13: =IF(F13=0,,H13*(1+F13)*C13-(H13*B13)) -> 0 | J13: =IF(G13=0,IF(F13=0,,H13*(1+F13)*C13-(H13*B13)),H13*(1+G13)*C13-(H13*B13)) -> 0
A14: MT | B14: 0.07 | C14: 0.17 | F14: 0.4552 | H14: =PREÇOS!G15 -> 7.05 | I14: =IF(F14=0,,H14*(1+F14)*C14-(H14*B14)) -> 1.2505572 | J14: =IF(G14=0,IF(F14=0,,H14*(1+F14)*C14-(H14*B14)),H14*(1+G14)*C14-(H14*B14)) -> 1.2505572
A15: PA | B15: 0.07 | C15: 0.19 | H15: =PREÇOS!G16 -> 7.05 | I15: =IF(F15=0,,H15*(1+F15)*C15-(H15*B15)) -> 0 | J15: =IF(G15=0,IF(F15=0,,H15*(1+F15)*C15-(H15*B15)),H15*(1+G15)*C15-(H15*B15)) -> 0
A16: PB | B16: 0.07 | C16: 0.18 | H16: =PREÇOS!G17 -> 7.05 | I16: =IF(F16=0,,H16*(1+F16)*C16-(H16*B16)) -> 0 | J16: =IF(G16=0,IF(F16=0,,H16*(1+F16)*C16-(H16*B16)),H16*(1+G16)*C16-(H16*B16)) -> 0
A17: PE | B17: 0.07 | C17: 0.18 | H17: =PREÇOS!G18 -> 7.05 | I17: =IF(F17=0,,H17*(1+F17)*C17-(H17*B17)) -> 0 | J17: =IF(G17=0,IF(F17=0,,H17*(1+F17)*C17-(H17*B17)),H17*(1+G17)*C17-(H17*B17)) -> 0
A18: PI | B18: 0.07 | C18: 0.21 | H18: =PREÇOS!G19 -> 7.05 | I18: =IF(F18=0,,H18*(1+F18)*C18-(H18*B18)) -> 0 | J18: =IF(G18=0,IF(F18=0,,H18*(1+F18)*C18-(H18*B18)),H18*(1+G18)*C18-(H18*B18)) -> 0
A19: PR | B19: 0.12 | C19: 0.195 | F19: 0.608 | H19: =PREÇOS!G20 -> 7.5 | I19: =IF(F19=0,,H19*(1+F19)*C19-(H19*B19)) -> 1.4517 | J19: =IF(G19=0,IF(F19=0,,H19*(1+F19)*C19-(H19*B19)),H19*(1+G19)*C19-(H19*B19)) -> 1.4517
A20: RJ | B20: 0.12 | C20: 0.22 | F20: 0.5473 | H20: =PREÇOS!G21 -> 7.5 | I20: =IF(F20=0,,H20*(1+F20)*C20-(H20*B20)) -> 1.653045 | J20: =IF(G20=0,IF(F20=0,,H20*(1+F20)*C20-(H20*B20)),H20*(1+G20)*C20-(H20*B20)) -> 1.653045
A21: RN | B21: 0.07 | C21: 0.2 | H21: =PREÇOS!G22 -> 7.05 | I21: =IF(F21=0,,H21*(1+F21)*C21-(H21*B21)) -> 0 | J21: =IF(G21=0,IF(F21=0,,H21*(1+F21)*C21-(H21*B21)),H21*(1+G21)*C21-(H21*B21)) -> 0
A22: RO | B22: 0.07 | C22: 0.175 | H22: =PREÇOS!G23 -> 7.05 | I22: =IF(F22=0,,H22*(1+F22)*C22-(H22*B22)) -> 0 | J22: =IF(G22=0,IF(F22=0,,H22*(1+F22)*C22-(H22*B22)),H22*(1+G22)*C22-(H22*B22)) -> 0
A23: RR | B23: 0.07 | C23: 0.2 | H23: =PREÇOS!G24 -> 7.05 | I23: =IF(F23=0,,H23*(1+F23)*C23-(H23*B23)) -> 0 | J23: =IF(G23=0,IF(F23=0,,H23*(1+F23)*C23-(H23*B23)),H23*(1+G23)*C23-(H23*B23)) -> 0
A24: RS | B24: 0.12 | C24: 0.17 | H24: =PREÇOS!G25 -> 7.5 | I24: =IF(F24=0,,H24*(1+F24)*C24-(H24*B24)) -> 0 | J24: =IF(G24=0,IF(F24=0,,H24*(1+F24)*C24-(H24*B24)),H24*(1+G24)*C24-(H24*B24)) -> 0
A25: SC | B25: 0.12 | C25: 0.17 | H25: =PREÇOS!G26 -> 7.5 | I25: =IF(F25=0,,H25*(1+F25)*C25-(H25*B25)) -> 0 | J25: =IF(G25=0,IF(F25=0,,H25*(1+F25)*C25-(H25*B25)),H25*(1+G25)*C25-(H25*B25)) -> 0
A26: SE | B26: 0.07 | C26: 0.2 | H26: =PREÇOS!G27 -> 7.05 | I26: =IF(F26=0,,H26*(1+F26)*C26-(H26*B26)) -> 0 | J26: =IF(G26=0,IF(F26=0,,H26*(1+F26)*C26-(H26*B26)),H26*(1+G26)*C26-(H26*B26)) -> 0
A27: SP | B27: 0.12 | C27: 0.18 | F27: 0.463 | H27: =PREÇOS!G28 -> 7.5 | I27: =IF(F27=0,,H27*(1+F27)*C27-(H27*B27)) -> 1.07505 | J27: =IF(G27=0,IF(F27=0,,H27*(1+F27)*C27-(H27*B27)),H27*(1+G27)*C27-(H27*B27)) -> 1.07505
A28: SP/Atacado | B28: =B27 -> 0.12 | C28: =C27 -> 0.18 | D28: =D27 -> 0 | E28: =E27 -> 0 | F28: =F27 -> 0.463 | G28: =G27 -> 0 | H28: =PREÇOS!G29 -> 7.5 | I28: =IF(F28=0,,H28*(1+F28)*C28-(H28*B28)) -> 1.07505 | J28: =IF(G28=0,IF(F28=0,,H28*(1+F28)*C28-(H28*B28)),H28*(1+G28)*C28-(H28*B28)) -> 1.07505
A29: TO | B29: 0.07 | C29: 0.2 | H29: =PREÇOS!G30 -> 7.05 | I29: =IF(F29=0,,H29*(1+F29)*C29-(H29*B29)) -> 0 | J29: =IF(G29=0,IF(F29=0,,H29*(1+F29)*C29-(H29*B29)),H29*(1+G29)*C29-(H29*B29)) -> 0
A30: EX | H30: =PREÇOS!G31 -> 5.9 | I30: =IF(F30=0,,H30*(1+F30)*C30-(H30*B30)) -> 0 | J30: =IF(G30=0,IF(F30=0,,H30*(1+F30)*C30-(H30*B30)),H30*(1+G30)*C30-(H30*B30)) -> 0

Sheet ST CEREAL SABOR POUCH 170
A1: Estado | B1: Aliquota interestadual | C1: Aliquota interna | D1: MVA (normal) | E1: MVA (simples) | F1: Ajustada (normal) | G1: Ajustada (simples) | H1: Preço | I1: ST Normal | J1: ST Simples
A2: AC | B2: 0.07 | C2: 0.17 | H2: =PREÇOS!J3 -> 5.7 | I2: =IF(F2=0,,H2*(1+F2)*C2-(H2*B2)) -> 0 | J2: =IF(G2=0,IF(F2=0,,H2*(1+F2)*C2-(H2*B2)),H2*(1+G2)*C2-(H2*B2)) -> 0
A3: AL | B3: 0.07 | C3: 0.2 | F3: 0.71 | H3: =PREÇOS!J4 -> 5.7 | I3: =IF(F3=0,,H3*(1+F3)*C3-(H3*B3)) -> 1.5504 | J3: =IF(G3=0,IF(F3=0,,H3*(1+F3)*C3-(H3*B3)),H3*(1+G3)*C3-(H3*B3)) -> 1.5504
A4: AM | B4: 0.07 | C4: 0.2 | F4: 0.5538 | H4: =PREÇOS!J5 -> 5.7 | I4: =IF(F4=0,,H4*(1+F4)*C4-(H4*B4)) -> 1.372332 | J4: =IF(G4=0,IF(F4=0,,H4*(1+F4)*C4-(H4*B4)),H4*(1+G4)*C4-(H4*B4)) -> 1.372332
A5: AP | B5: 0.07 | C5: 0.18 | H5: =PREÇOS!J6 -> 5.7 | I5: =IF(F5=0,,H5*(1+F5)*C5-(H5*B5)) -> 0 | J5: =IF(G5=0,IF(F5=0,,H5*(1+F5)*C5-(H5*B5)),H5*(1+G5)*C5-(H5*B5)) -> 0
A6: BA | B6: 0.07 | C6: 0.19 | H6: =PREÇOS!J7 -> 5.7 | I6: =IF(F6=0,,H6*(1+F6)*C6-(H6*B6)) -> 0 | J6: =IF(G6=0,IF(F6=0,,H6*(1+F6)*C6-(H6*B6)),H6*(1+G6)*C6-(H6*B6)) -> 0
A7: CE | B7: 0.07 | C7: 0.2 | H7: =PREÇOS!J8 -> 5.7 | I7: =IF(F7=0,,H7*(1+F7)*C7-(H7*B7)) -> 0 | J7: =IF(G7=0,IF(F7=0,,H7*(1+F7)*C7-(H7*B7)),H7*(1+G7)*C7-(H7*B7)) -> 0
A8: DF | B8: 0.07 | C8: 0.18 | H8: =PREÇOS!J9 -> 5.7 | I8: =IF(F8=0,,H8*(1+F8)*C8-(H8*B8)) -> 0 | J8: =IF(G8=0,IF(F8=0,,H8*(1+F8)*C8-(H8*B8)),H8*(1+G8)*C8-(H8*B8)) -> 0
A9: ES | B9: 0.07 | C9: 0.17 | H9: =PREÇOS!J10 -> 5.2 | I9: =IF(F9=0,,H9*(1+F9)*C9-(H9*B9)) -> 0 | J9: =IF(G9=0,IF(F9=0,,H9*(1+F9)*C9-(H9*B9)),H9*(1+G9)*C9-(H9*B9)) -> 0
A10: GO | B10: 0.07 | C10: 0.17 | H10: =PREÇOS!J11 -> 5.7 | I10: =IF(F10=0,,H10*(1+F10)*C10-(H10*B10)) -> 0 | J10: =IF(G10=0,IF(F10=0,,H10*(1+F10)*C10-(H10*B10)),H10*(1+G10)*C10-(H10*B10)) -> 0
A11: MA | B11: 0.07 | C11: 0.2 | H11: =PREÇOS!J12 -> 5.7 | I11: =IF(F11=0,,H11*(1+F11)*C11-(H11*B11)) -> 0 | J11: =IF(G11=0,IF(F11=0,,H11*(1+F11)*C11-(H11*B11)),H11*(1+G11)*C11-(H11*B11)) -> 0
A12: MG | B12: 0.12 | C12: 0.18 | F12: 0.4488 | H12: =PREÇOS!J13 -> 5.5 | I12: =IF(F12=0,,H12*(1+F12)*C12-(H12*B12)) -> 0.774312 | J12: =IF(G12=0,IF(F12=0,,H12*(1+F12)*C12-(H12*B12)),H12*(1+G12)*C12-(H12*B12)) -> 0.774312
A13: MS | B13: 0.07 | C13: 0.17 | H13: =PREÇOS!J14 -> 5.7 | I13: =IF(F13=0,,H13*(1+F13)*C13-(H13*B13)) -> 0 | J13: =IF(G13=0,IF(F13=0,,H13*(1+F13)*C13-(H13*B13)),H13*(1+G13)*C13-(H13*B13)) -> 0
A14: MT | B14: 0.07 | C14: 0.17 | F14: 0.4552 | H14: =PREÇOS!J15 -> 5.7 | I14: =IF(F14=0,,H14*(1+F14)*C14-(H14*B14)) -> 1.0110888 | J14: =IF(G14=0,IF(F14=0,,H14*(1+F14)*C14-(H14*B14)),H14*(1+G14)*C14-(H14*B14)) -> 1.0110888
A15: PA | B15: 0.07 | C15: 0.19 | H15: =PREÇOS!J16 -> 5.7 | I15: =IF(F15=0,,H15*(1+F15)*C15-(H15*B15)) -> 0 | J15: =IF(G15=0,IF(F15=0,,H15*(1+F15)*C15-(H15*B15)),H15*(1+G15)*C15-(H15*B15)) -> 0
A16: PB | B16: 0.07 | C16: 0.18 | H16: =PREÇOS!J17 -> 5.7 | I16: =IF(F16=0,,H16*(1+F16)*C16-(H16*B16)) -> 0 | J16: =IF(G16=0,IF(F16=0,,H16*(1+F16)*C16-(H16*B16)),H16*(1+G16)*C16-(H16*B16)) -> 0
A17: PE | B17: 0.07 | C17: 0.18 | H17: =PREÇOS!J18 -> 5.7 | I17: =IF(F17=0,,H17*(1+F17)*C17-(H17*B17)) -> 0 | J17: =IF(G17=0,IF(F17=0,,H17*(1+F17)*C17-(H17*B17)),H17*(1+G17)*C17-(H17*B17)) -> 0
A18: PI | B18: 0.07 | C18: 0.21 | H18: =PREÇOS!J19 -> 5.7 | I18: =IF(F18=0,,H18*(1+F18)*C18-(H18*B18)) -> 0 | J18: =IF(G18=0,IF(F18=0,,H18*(1+F18)*C18-(H18*B18)),H18*(1+G18)*C18-(H18*B18)) -> 0
A19: PR | B19: 0.12 | C19: 0.195 | F19: 0.608 | H19: =PREÇOS!J20 -> 5.5 | I19: =IF(F19=0,,H19*(1+F19)*C19-(H19*B19)) -> 1.06458 | J19: =IF(G19=0,IF(F19=0,,H19*(1+F19)*C19-(H19*B19)),H19*(1+G19)*C19-(H19*B19)) -> 1.06458
A20: RJ | B20: 0.12 | C20: 0.22 | F20: 0.5473 | H20: =PREÇOS!J21 -> 5.5 | I20: =IF(F20=0,,H20*(1+F20)*C20-(H20*B20)) -> 1.212233 | J20: =IF(G20=0,IF(F20=0,,H20*(1+F20)*C20-(H20*B20)),H20*(1+G20)*C20-(H20*B20)) -> 1.212233
A21: RN | B21: 0.07 | C21: 0.2 | H21: =PREÇOS!J22 -> 5.7 | I21: =IF(F21=0,,H21*(1+F21)*C21-(H21*B21)) -> 0 | J21: =IF(G21=0,IF(F21=0,,H21*(1+F21)*C21-(H21*B21)),H21*(1+G21)*C21-(H21*B21)) -> 0
A22: RO | B22: 0.07 | C22: 0.175 | H22: =PREÇOS!J23 -> 5.7 | I22: =IF(F22=0,,H22*(1+F22)*C22-(H22*B22)) -> 0 | J22: =IF(G22=0,IF(F22=0,,H22*(1+F22)*C22-(H22*B22)),H22*(1+G22)*C22-(H22*B22)) -> 0
A23: RR | B23: 0.07 | C23: 0.2 | H23: =PREÇOS!J24 -> 5.7 | I23: =IF(F23=0,,H23*(1+F23)*C23-(H23*B23)) -> 0 | J23: =IF(G23=0,IF(F23=0,,H23*(1+F23)*C23-(H23*B23)),H23*(1+G23)*C23-(H23*B23)) -> 0
A24: RS | B24: 0.12 | C24: 0.17 | H24: =PREÇOS!J25 -> 5.5 | I24: =IF(F24=0,,H24*(1+F24)*C24-(H24*B24)) -> 0 | J24: =IF(G24=0,IF(F24=0,,H24*(1+F24)*C24-(H24*B24)),H24*(1+G24)*C24-(H24*B24)) -> 0
A25: SC | B25: 0.12 | C25: 0.17 | H25: =PREÇOS!J26 -> 5.5 | I25: =IF(F25=0,,H25*(1+F25)*C25-(H25*B25)) -> 0 | J25: =IF(G25=0,IF(F25=0,,H25*(1+F25)*C25-(H25*B25)),H25*(1+G25)*C25-(H25*B25)) -> 0
A26: SE | B26: 0.07 | C26: 0.2 | H26: =PREÇOS!J27 -> 5.7 | I26: =IF(F26=0,,H26*(1+F26)*C26-(H26*B26)) -> 0 | J26: =IF(G26=0,IF(F26=0,,H26*(1+F26)*C26-(H26*B26)),H26*(1+G26)*C26-(H26*B26)) -> 0
A27: SP | B27: 0.12 | C27: 0.18 | F27: 0.463 | H27: =PREÇOS!J28 -> 5.5 | I27: =IF(F27=0,,H27*(1+F27)*C27-(H27*B27)) -> 0.78837 | J27: =IF(G27=0,IF(F27=0,,H27*(1+F27)*C27-(H27*B27)),H27*(1+G27)*C27-(H27*B27)) -> 0.78837
A28: SP/Atacado | B28: =B27 -> 0.12 | C28: =C27 -> 0.18 | D28: =D27 -> 0 | E28: =E27 -> 0 | F28: =F27 -> 0.463 | G28: =G27 -> 0 | H28: =PREÇOS!J29 -> 5.5 | I28: =IF(F28=0,,H28*(1+F28)*C28-(H28*B28)) -> 0.78837 | J28: =IF(G28=0,IF(F28=0,,H28*(1+F28)*C28-(H28*B28)),H28*(1+G28)*C28-(H28*B28)) -> 0.78837
A29: TO | B29: 0.07 | C29: 0.2 | H29: =PREÇOS!J30 -> 5.7 | I29: =IF(F29=0,,H29*(1+F29)*C29-(H29*B29)) -> 0 | J29: =IF(G29=0,IF(F29=0,,H29*(1+F29)*C29-(H29*B29)),H29*(1+G29)*C29-(H29*B29)) -> 0
A30: EX | H30: =PREÇOS!J31 -> 4.33 | I30: =IF(F30=0,,H30*(1+F30)*C30-(H30*B30)) -> 0 | J30: =IF(G30=0,IF(F30=0,,H30*(1+F30)*C30-(H30*B30)),H30*(1+G30)*C30-(H30*B30)) -> 0

Sheet ST MULTI 170 POUCH
A1: Estado | B1: Aliquota interestadual | C1: Aliquota interna | D1: MVA (normal) | E1: MVA (simples) | F1: Ajustada (normal) | G1: Ajustada (simples) | H1: Preço | I1: ST Normal | J1: ST Simples
A2: AC | B2: 0.07 | C2: 0.17 | H2: =PREÇOS!K3 -> 4.7 | I2: =IF(F2=0,,H2*(1+F2)*C2-(H2*B2)) -> 0 | J2: =IF(G2=0,IF(F2=0,,H2*(1+F2)*C2-(H2*B2)),H2*(1+G2)*C2-(H2*B2)) -> 0
A3: AL | B3: 0.07 | C3: 0.2 | F3: 0.71 | H3: =PREÇOS!K4 -> 4.7 | I3: =IF(F3=0,,H3*(1+F3)*C3-(H3*B3)) -> 1.2784 | J3: =IF(G3=0,IF(F3=0,,H3*(1+F3)*C3-(H3*B3)),H3*(1+G3)*C3-(H3*B3)) -> 1.2784
A4: AM | B4: 0.07 | C4: 0.2 | F4: 0.5538 | H4: =PREÇOS!K5 -> 4.7 | I4: =IF(F4=0,,H4*(1+F4)*C4-(H4*B4)) -> 1.131572 | J4: =IF(G4=0,IF(F4=0,,H4*(1+F4)*C4-(H4*B4)),H4*(1+G4)*C4-(H4*B4)) -> 1.131572
A5: AP | B5: 0.07 | C5: 0.18 | H5: =PREÇOS!K6 -> 4.7 | I5: =IF(F5=0,,H5*(1+F5)*C5-(H5*B5)) -> 0 | J5: =IF(G5=0,IF(F5=0,,H5*(1+F5)*C5-(H5*B5)),H5*(1+G5)*C5-(H5*B5)) -> 0
A6: BA | B6: 0.07 | C6: 0.19 | H6: =PREÇOS!K7 -> 4.7 | I6: =IF(F6=0,,H6*(1+F6)*C6-(H6*B6)) -> 0 | J6: =IF(G6=0,IF(F6=0,,H6*(1+F6)*C6-(H6*B6)),H6*(1+G6)*C6-(H6*B6)) -> 0
A7: CE | B7: 0.07 | C7: 0.2 | H7: =PREÇOS!K8 -> 4.7 | I7: =IF(F7=0,,H7*(1+F7)*C7-(H7*B7)) -> 0 | J7: =IF(G7=0,IF(F7=0,,H7*(1+F7)*C7-(H7*B7)),H7*(1+G7)*C7-(H7*B7)) -> 0
A8: DF | B8: 0.07 | C8: 0.18 | H8: =PREÇOS!K9 -> 4.7 | I8: =IF(F8=0,,H8*(1+F8)*C8-(H8*B8)) -> 0 | J8: =IF(G8=0,IF(F8=0,,H8*(1+F8)*C8-(H8*B8)),H8*(1+G8)*C8-(H8*B8)) -> 0
A9: ES | B9: 0.07 | C9: 0.17 | H9: =PREÇOS!K10 -> 5.2 | I9: =IF(F9=0,,H9*(1+F9)*C9-(H9*B9)) -> 0 | J9: =IF(G9=0,IF(F9=0,,H9*(1+F9)*C9-(H9*B9)),H9*(1+G9)*C9-(H9*B9)) -> 0
A10: GO | B10: 0.07 | C10: 0.17 | H10: =PREÇOS!K11 -> 4.7 | I10: =IF(F10=0,,H10*(1+F10)*C10-(H10*B10)) -> 0 | J10: =IF(G10=0,IF(F10=0,,H10*(1+F10)*C10-(H10*B10)),H10*(1+G10)*C10-(H10*B10)) -> 0
A11: MA | B11: 0.07 | C11: 0.2 | H11: =PREÇOS!K12 -> 4.7 | I11: =IF(F11=0,,H11*(1+F11)*C11-(H11*B11)) -> 0 | J11: =IF(G11=0,IF(F11=0,,H11*(1+F11)*C11-(H11*B11)),H11*(1+G11)*C11-(H11*B11)) -> 0
A12: MG | B12: 0.12 | C12: 0.18 | F12: 0.4488 | H12: =PREÇOS!K13 -> 5.5 | I12: =IF(F12=0,,H12*(1+F12)*C12-(H12*B12)) -> 0.774312 | J12: =IF(G12=0,IF(F12=0,,H12*(1+F12)*C12-(H12*B12)),H12*(1+G12)*C12-(H12*B12)) -> 0.774312
A13: MS | B13: 0.07 | C13: 0.17 | H13: =PREÇOS!K14 -> 4.7 | I13: =IF(F13=0,,H13*(1+F13)*C13-(H13*B13)) -> 0 | J13: =IF(G13=0,IF(F13=0,,H13*(1+F13)*C13-(H13*B13)),H13*(1+G13)*C13-(H13*B13)) -> 0
A14: MT | B14: 0.07 | C14: 0.17 | F14: 0.4552 | H14: =PREÇOS!K15 -> 4.7 | I14: =IF(F14=0,,H14*(1+F14)*C14-(H14*B14)) -> 0.8337048 | J14: =IF(G14=0,IF(F14=0,,H14*(1+F14)*C14-(H14*B14)),H14*(1+G14)*C14-(H14*B14)) -> 0.8337048
A15: PA | B15: 0.07 | C15: 0.19 | H15: =PREÇOS!K16 -> 4.7 | I15: =IF(F15=0,,H15*(1+F15)*C15-(H15*B15)) -> 0 | J15: =IF(G15=0,IF(F15=0,,H15*(1+F15)*C15-(H15*B15)),H15*(1+G15)*C15-(H15*B15)) -> 0
A16: PB | B16: 0.07 | C16: 0.18 | H16: =PREÇOS!K17 -> 4.7 | I16: =IF(F16=0,,H16*(1+F16)*C16-(H16*B16)) -> 0 | J16: =IF(G16=0,IF(F16=0,,H16*(1+F16)*C16-(H16*B16)),H16*(1+G16)*C16-(H16*B16)) -> 0
A17: PE | B17: 0.07 | C17: 0.18 | H17: =PREÇOS!K18 -> 4.7 | I17: =IF(F17=0,,H17*(1+F17)*C17-(H17*B17)) -> 0 | J17: =IF(G17=0,IF(F17=0,,H17*(1+F17)*C17-(H17*B17)),H17*(1+G17)*C17-(H17*B17)) -> 0
A18: PI | B18: 0.07 | C18: 0.21 | H18: =PREÇOS!K19 -> 4.7 | I18: =IF(F18=0,,H18*(1+F18)*C18-(H18*B18)) -> 0 | J18: =IF(G18=0,IF(F18=0,,H18*(1+F18)*C18-(H18*B18)),H18*(1+G18)*C18-(H18*B18)) -> 0
A19: PR | B19: 0.12 | C19: 0.195 | F19: 0.608 | H19: =PREÇOS!K20 -> 5.5 | I19: =IF(F19=0,,H19*(1+F19)*C19-(H19*B19)) -> 1.06458 | J19: =IF(G19=0,IF(F19=0,,H19*(1+F19)*C19-(H19*B19)),H19*(1+G19)*C19-(H19*B19)) -> 1.06458
A20: RJ | B20: 0.12 | C20: 0.22 | F20: 0.5473 | H20: =PREÇOS!K21 -> 5.5 | I20: =IF(F20=0,,H20*(1+F20)*C20-(H20*B20)) -> 1.212233 | J20: =IF(G20=0,IF(F20=0,,H20*(1+F20)*C20-(H20*B20)),H20*(1+G20)*C20-(H20*B20)) -> 1.212233
A21: RN | B21: 0.07 | C21: 0.2 | H21: =PREÇOS!K22 -> 4.7 | I21: =IF(F21=0,,H21*(1+F21)*C21-(H21*B21)) -> 0 | J21: =IF(G21=0,IF(F21=0,,H21*(1+F21)*C21-(H21*B21)),H21*(1+G21)*C21-(H21*B21)) -> 0
A22: RO | B22: 0.07 | C22: 0.175 | H22: =PREÇOS!K23 -> 4.7 | I22: =IF(F22=0,,H22*(1+F22)*C22-(H22*B22)) -> 0 | J22: =IF(G22=0,IF(F22=0,,H22*(1+F22)*C22-(H22*B22)),H22*(1+G22)*C22-(H22*B22)) -> 0
A23: RR | B23: 0.07 | C23: 0.2 | H23: =PREÇOS!K24 -> 4.7 | I23: =IF(F23=0,,H23*(1+F23)*C23-(H23*B23)) -> 0 | J23: =IF(G23=0,IF(F23=0,,H23*(1+F23)*C23-(H23*B23)),H23*(1+G23)*C23-(H23*B23)) -> 0
A24: RS | B24: 0.12 | C24: 0.17 | H24: =PREÇOS!K25 -> 5.5 | I24: =IF(F24=0,,H24*(1+F24)*C24-(H24*B24)) -> 0 | J24: =IF(G24=0,IF(F24=0,,H24*(1+F24)*C24-(H24*B24)),H24*(1+G24)*C24-(H24*B24)) -> 0
A25: SC | B25: 0.12 | C25: 0.17 | H25: =PREÇOS!K26 -> 5.5 | I25: =IF(F25=0,,H25*(1+F25)*C25-(H25*B25)) -> 0 | J25: =IF(G25=0,IF(F25=0,,H25*(1+F25)*C25-(H25*B25)),H25*(1+G25)*C25-(H25*B25)) -> 0
A26: SE | B26: 0.07 | C26: 0.2 | H26: =PREÇOS!K27 -> 4.7 | I26: =IF(F26=0,,H26*(1+F26)*C26-(H26*B26)) -> 0 | J26: =IF(G26=0,IF(F26=0,,H26*(1+F26)*C26-(H26*B26)),H26*(1+G26)*C26-(H26*B26)) -> 0
A27: SP | B27: 0.12 | C27: 0.18 | F27: 0.463 | H27: =PREÇOS!K28 -> 5.5 | I27: =IF(F27=0,,H27*(1+F27)*C27-(H27*B27)) -> 0.78837 | J27: =IF(G27=0,IF(F27=0,,H27*(1+F27)*C27-(H27*B27)),H27*(1+G27)*C27-(H27*B27)) -> 0.78837
A28: SP/Atacado | B28: =B27 -> 0.12 | C28: =C27 -> 0.18 | D28: =D27 -> 0 | E28: =E27 -> 0 | F28: =F27 -> 0.463 | G28: =G27 -> 0 | H28: =PREÇOS!K29 -> 5.5 | I28: =IF(F28=0,,H28*(1+F28)*C28-(H28*B28)) -> 0.78837 | J28: =IF(G28=0,IF(F28=0,,H28*(1+F28)*C28-(H28*B28)),H28*(1+G28)*C28-(H28*B28)) -> 0.78837
A29: TO | B29: 0.07 | C29: 0.2 | H29: =PREÇOS!K30 -> 4.7 | I29: =IF(F29=0,,H29*(1+F29)*C29-(H29*B29)) -> 0 | J29: =IF(G29=0,IF(F29=0,,H29*(1+F29)*C29-(H29*B29)),H29*(1+G29)*C29-(H29*B29)) -> 0
A30: EX | H30: =PREÇOS!K31 -> 4.33 | I30: =IF(F30=0,,H30*(1+F30)*C30-(H30*B30)) -> 0 | J30: =IF(G30=0,IF(F30=0,,H30*(1+F30)*C30-(H30*B30)),H30*(1+G30)*C30-(H30*B30)) -> 0

Sheet ST MULTI 500 POUCH
A1: Estado | B1: Aliquota interestadual | C1: Aliquota interna | D1: MVA (normal) | E1: MVA (simples) | F1: Ajustada (normal) | G1: Ajustada (simples) | H1: Preço | I1: ST Normal | J1: ST Simples
A2: AC | B2: 0.07 | C2: 0.17 | H2: =PREÇOS!L3 -> 12 | I2: =IF(F2=0,,H2*(1+F2)*C2-(H2*B2)) -> 0 | J2: =IF(G2=0,IF(F2=0,,H2*(1+F2)*C2-(H2*B2)),H2*(1+G2)*C2-(H2*B2)) -> 0
A3: AL | B3: 0.07 | C3: 0.2 | F3: 0.71 | H3: =PREÇOS!L4 -> 12 | I3: =IF(F3=0,,H3*(1+F3)*C3-(H3*B3)) -> 3.264 | J3: =IF(G3=0,IF(F3=0,,H3*(1+F3)*C3-(H3*B3)),H3*(1+G3)*C3-(H3*B3)) -> 3.264
