Workbook

Sheet Tabelas
C1: BABY ROO COMERCIO DE ALIMENTOS EIRELI
C2: CNPJ: 34.282.307.0001-44
C3: INSC. ESTADUAL: 90821939-25
C4: ENDEREÇO: Rua Grã Nicco, 113 - sala 501, bloco 2 - Mossunguê, Curitiba - PR, 81200-200
B6: Nome / Razão Social: | J6: Nr. pedido | L6: E-mail XML:
B7: Endereço: | L7: Municipio: | Q7: UF: | R7: PR
B8: CNPJ: | G8: Inscrição Estadual: | J8: Regime SIMPLES? | K8: NÃO | L8: Fone contato com (DDD) | Q8: CEP:
B9: =PREÇOS!A1 -> 0325E
B10: Descrição | D10: Código | E10: Embalagem | F10: Validade | G10: PSC | H10: NCM | I10: Ean 13 | J10: Dun 14 | K10: Crédito ICMS (%) | L10: Valor Unit. | M10: Valor Caixa | N10: SUBSTITUIÇÃO TRIBUTÁRIA UN | O10: IPI | P10: Valor Caixa + ST | Q10: TOTAL Caixas | R10: Valor TOTAL | S10: Valor TOTAL + ST (*)
B11: Papinha Papapa Carne Arroz Legumes 120g | D11: 5313 | E11: 12 x 120g | F11: 12 meses | G11: =VLOOKUP($R$7,'PSC PAPAPA'!$A$2:$L$31,9,FALSE) -> 13.49 | H11: 2104.20.00 | I11: 7898969895316 | J11: 17898969895313 | K11: =VLOOKUP($R$7,'ST BISCOITINHOS'!A:B,2,FALSE) -> 0.12 | L11: =VLOOKUP($R$7,PREÇOS!$A$2:$L$31,9,FALSE)*90% -> 8.0091 | M11: =L11*12 -> 96.1092 | N11: 0 | O11: 0 | P11: =(L11+N11)*12 -> 96.1092 | R11: =Q11*M11 -> 0 | S11: =Q11*P11 -> 0
B12: Papinha Papapa Frango Grão Vegetais 120g | D12: 5320 | E12: 12 x 120g | F12: 12 meses | G12: =VLOOKUP($R$7,'PSC PAPAPA'!$A$2:$L$31,9,FALSE) -> 13.49 | H12: 2104.20.00 | I12: 7898969895323 | J12: 17898969895320 | K12: =VLOOKUP($R$7,'ST BISCOITINHOS'!A:B,2,FALSE) -> 0.12 | L12: =VLOOKUP($R$7,PREÇOS!$A$2:$L$31,9,FALSE)*90% -> 8.0091 | M12: =L12*12 -> 96.1092 | N12: 0 | O12: 0 | P12: =(L12+N12)*12 -> 96.1092 | R12: =Q12*M12 -> 0 | S12: =Q12*P12 -> 0
B14: Papinha Papapa Iogurte Frutas Amarelas e Banana 100g | D14: 5563 | E14: 16 x 100g | F14: 15 meses | G14: =VLOOKUP($R$7,'PSC PAPAPA'!$A$2:$M$31,13,FALSE) -> 9.49 | H14: 2104.20.00 | I14: 7898969895569 | J14: 27898969895563 | K14: =VLOOKUP($R$7,'ST BISCOITINHOS'!A:B,2,FALSE) -> 0.12 | L14: =VLOOKUP($R$7,PREÇOS!$A$2:$M$31,13,FALSE)*90% -> 5.103 | M14: =L14*16 -> 81.648 | N14: 0 | O14: 0 | P14: =M14 -> 81.648 | R14: =Q14*M14 -> 0 | S14: =Q14*P14 -> 0
B15: Papinha Papapa Iogurte Frutas Vermelhas e Banana 100g | D15: 5570 | E15: 16 x 100g | F15: 15 meses | G15: =VLOOKUP($R$7,'PSC PAPAPA'!$A$2:$M$31,13,FALSE) -> 9.49 | H15: 2104.20.00 | I15: 7898969895576 | J15: 27898969895570 | K15: =VLOOKUP($R$7,'ST BISCOITINHOS'!A:B,2,FALSE) -> 0.12 | L15: =VLOOKUP($R$7,PREÇOS!$A$2:$M$31,13,FALSE)*90% -> 5.103 | M15: =L15*16 -> 81.648 | N15: 0 | O15: 0 | P15: =M15 -> 81.648 | R15: =Q15*M15 -> 0 | S15: =Q15*P15 -> 0
B17: Papinha Papapá Org Maçã Ameixa 100g | D17: 17898994908729 | E17: 12 x 100g | F17: 16 meses | G17: =VLOOKUP($R$7,'PSC PAPAPA'!$A$2:$L$31,2,FALSE) -> 9.49 | H17: 2104.20.00 | I17: 7898994908722 | J17: 17898994908729 | K17: =VLOOKUP($R$7,'ST BISCOITINHOS'!A:B,2,FALSE) -> 0.12 | L17: =VLOOKUP($R$7,PREÇOS!$A$2:$L$31,2,FALSE)*90% -> 5.616 | M17: =L17*12 -> 67.392 | N17: 0 | O17: 0 | P17: =M17 -> 67.392 | R17: =Q17*M17 -> 0 | S17: =Q17*P17 -> 0
B18: Papinha Papapá Org Banana Mirtilo Quinoa 100g | D18: 17898994908736 | E18: 12 x 100g | F18: 16 meses | G18: =VLOOKUP($R$7,'PSC PAPAPA'!$A$2:$L$31,2,FALSE) -> 9.49 | H18: 2104.20.00 | I18: 7898994908739 | J18: 17898994908736 | K18: =VLOOKUP($R$7,'ST BISCOITINHOS'!A:B,2,FALSE) -> 0.12 | L18: =VLOOKUP($R$7,PREÇOS!$A$2:$L$31,2,FALSE)*90% -> 5.616 | M18: =L18*12 -> 67.392 | N18: 0 | O18: 0 | P18: =M18 -> 67.392 | R18: =Q18*M18 -> 0 | S18: =Q18*P18 -> 0
B19: Papinha Papapá Org Manga 100g | D19: 17898994908712 | E19: 12 x 100g | F19: 16 meses | G19: =VLOOKUP($R$7,'PSC PAPAPA'!$A$2:$L$31,2,FALSE) -> 9.49 | H19: 2104.20.00 | I19: 7898994908715 | J19: 17898994908712 | K19: =VLOOKUP($R$7,'ST BISCOITINHOS'!A:B,2,FALSE) -> 0.12 | L19: =VLOOKUP($R$7,PREÇOS!$A$2:$L$31,2,FALSE)*90% -> 5.616 | M19: =L19*12 -> 67.392 | N19: 0 | O19: 0 | P19: =M19 -> 67.392 | R19: =Q19*M19 -> 0 | S19: =Q19*P19 -> 0
B20: Papinha Papapá Org Pera Espinafre Abobrinha 100g | D20: 17898994908750 | E20: 12 x 100g | F20: 16 meses | G20: =VLOOKUP($R$7,'PSC PAPAPA'!$A$2:$L$31,2,FALSE) -> 9.49 | H20: 2104.20.00 | I20: 7898994908753 | J20: 17898994908750 | K20: =VLOOKUP($R$7,'ST BISCOITINHOS'!A:B,2,FALSE) -> 0.12 | L20: =VLOOKUP($R$7,PREÇOS!$A$2:$L$31,2,FALSE)*90% -> 5.616 | M20: =L20*12 -> 67.392 | N20: 0 | O20: 0 | P20: =M20 -> 67.392 | R20: =Q20*M20 -> 0 | S20: =Q20*P20 -> 0
B21: Papinha Papapá Org Maçã B. Doce Cenoura 100g | D21: 27898994908757 | E21: 12 x 100g | F21: 16 meses | G21: =VLOOKUP($R$7,'PSC PAPAPA'!$A$2:$L$31,2,FALSE) -> 9.49 | H21: 2104.20.00 | I21: 7898994908746 | J21: 27898994908757 | K21: =VLOOKUP($R$7,'ST BISCOITINHOS'!A:B,2,FALSE) -> 0.12 | L21: =VLOOKUP($R$7,PREÇOS!$A$2:$L$31,2,FALSE)*90% -> 5.616 | M21: =L21*12 -> 67.392 | N21: 0 | O21: 0 | P21: =M21 -> 67.392 | R21: =Q21*M21 -> 0 | S21: =Q21*P21 -> 0
B22: Papinha Papapá Org Morango Maçã 100g | D22: 5306 | E22: 12 x 100g | F22: 16 meses | G22: =VLOOKUP($R$7,'PSC PAPAPA'!$A$2:$L$31,2,FALSE) -> 9.49 | H22: 2104.20.00 | I22: 7898969895309 | J22: 17898969895306 | K22: =VLOOKUP($R$7,'ST BISCOITINHOS'!A:B,2,FALSE) -> 0.12 | L22: =VLOOKUP($R$7,PREÇOS!$A$2:$L$31,2,FALSE)*90% -> 5.616 | M22: =L22*12 -> 67.392 | N22: 0 | O22: 0 | P22: =M22 -> 67.392 | R22: =Q22*M22 -> 0 | S22: =Q22*P22 -> 0
B24: Biscoito inf Papapá org. Beterraba 20g | D24: 5085 | E24: 16 x 20g | F24: 9 meses | G24: =VLOOKUP($R$7,'PSC PAPAPA'!$A$2:$L$31,3,FALSE) -> 5.79 | H24: 1904.10.00 | I24: 7898969895088 | J24: 17898969895085 | K24: =VLOOKUP($R$7,'ST PALITINHOS'!A:B,2,FALSE) -> 0.12 | L24: =VLOOKUP($R$7,PREÇOS!$A$2:$L$31,3,FALSE)*90% -> 3.402 | M24: =L24*16 -> 54.432 | N24: =IF($K$8="SIM",VLOOKUP($R$7,'ST PALITINHOS'!$A$1:$J$31,10,FALSE),VLOOKUP($R$7,'ST PALITINHOS'!$A$1:$J$31,9,FALSE)) -> 0.7898877 | O24: 0 | P24: =(L24+N24)*16 -> 67.070203 | R24: =Q24*M24 -> 0 | S24: =Q24*P24 -> 0
B25: Biscoito inf Papapá org. Cenoura 20g | D25: 5078 | E25: 16 x 20g | F25: 9 meses | G25: =VLOOKUP($R$7,'PSC PAPAPA'!$A$2:$L$31,3,FALSE) -> 5.79 | H25: 1904.10.00 | I25: 7898969895071 | J25: 17898969895078 | K25: =VLOOKUP($R$7,'ST PALITINHOS'!A:B,2,FALSE) -> 0.12 | L25: =VLOOKUP($R$7,PREÇOS!$A$2:$L$31,3,FALSE)*90% -> 3.402 | M25: =L25*16 -> 54.432 | N25: =IF($K$8="SIM",VLOOKUP($R$7,'ST PALITINHOS'!$A$1:$J$31,10,FALSE),VLOOKUP($R$7,'ST PALITINHOS'!$A$1:$J$31,9,FALSE)) -> 0.7898877 | O25: 0 | P25: =(L25+N25)*16 -> 67.070203 | R25: =Q25*M25 -> 0 | S25: =Q25*P25 -> 0
B26: Biscoito inf Papapá org. Tomate/Manjericão 20g | D26: 5061 | E26: 16 x 20g | F26: 9 meses | G26: =VLOOKUP($R$7,'PSC PAPAPA'!$A$2:$L$31,3,FALSE) -> 5.79 | H26: 1904.10.00 | I26: 7898969895064 | J26: 17898969895061 | K26: =VLOOKUP($R$7,'ST PALITINHOS'!A:B,2,FALSE) -> 0.12 | L26: =VLOOKUP($R$7,PREÇOS!$A$2:$L$31,3,FALSE)*90% -> 3.402 | M26: =L26*16 -> 54.432 | N26: =IF($K$8="SIM",VLOOKUP($R$7,'ST PALITINHOS'!$A$1:$J$31,10,FALSE),VLOOKUP($R$7,'ST PALITINHOS'!$A$1:$J$31,9,FALSE)) -> 0.7898877 | O26: 0 | P26: =(L26+N26)*16 -> 67.070203 | R26: =Q26*M26 -> 0 | S26: =Q26*P26 -> 0
B28: Biscoito Inf Papapá dent. Maçã e Abóbora 36g | D28: 8774 | E28: 12 x 36g | F28: 15 meses | G28: =VLOOKUP($R$7,'PSC PAPAPA'!$A$2:$L$31,4,FALSE) -> 19.99 | H28: 1905.90.20 | I28: 7898994908777 | J28: 17898994908774 | K28: =VLOOKUP($R$7,'ST BISCOITINHOS'!A:B,2,FALSE) -> 0.12 | L28: =VLOOKUP($R$7,PREÇOS!$A$2:$L$31,4,FALSE)*90% -> 11.66166 | M28: =L28*12 -> 139.93992 | N28: =IF($K$8="SIM",VLOOKUP($R$7,'ST BISCOITINHOS'!$A$1:$J$31,10,FALSE),VLOOKUP($R$7,'ST BISCOITINHOS'!$A$1:$J$31,9,FALSE)) -> 0 | O28: 0 | P28: =(L28+N28)*12 -> 139.93992 | R28: =Q28*M28 -> 0 | S28: =Q28*P28 -> 0
B29: Biscoito Inf Papapá dent Vegetais 36g | D29: 8767 | E29: 12 x 36g | F29: 15 meses | G29: =VLOOKUP($R$7,'PSC PAPAPA'!$A$2:$L$31,4,FALSE) -> 19.99 | H29: 1905.90.20 | I29: 7898994908760 | J29: 17898994908767 | K29: =VLOOKUP($R$7,'ST BISCOITINHOS'!A:B,2,FALSE) -> 0.12 | L29: =VLOOKUP($R$7,PREÇOS!$A$2:$L$31,4,FALSE)*90% -> 11.66166 | M29: =L29*12 -> 139.93992 | N29: =IF($K$8="SIM",VLOOKUP($R$7,'ST BISCOITINHOS'!$A$1:$J$31,10,FALSE),VLOOKUP($R$7,'ST BISCOITINHOS'!$A$1:$J$31,9,FALSE)) -> 0 | O29: 0 | P29: =(L29+N29)*12 -> 139.93992 | R29: =Q29*M29 -> 0 | S29: =Q29*P29 -> 0
B31: Macarrao Inf Papapá m. Elbow Quinoa 200g | D31: 5290 | E31: 12 x 200g | F31: 14 meses | G31: =VLOOKUP($R$7,'PSC PAPAPA'!$A$2:$L$31,5,FALSE) -> 13.69 | H31: 19.02.19.00 | I31: 7898969895293 | J31: 17898969895293 | K31: =VLOOKUP($R$7,'ST PAPAPASTA'!A:B,2,FALSE) -> 0.12 | L31: =VLOOKUP($R$7,PREÇOS!$A$2:$L$31,5,FALSE)*90% -> 7.605 | M31: =L31*12 -> 91.26 | N31: =IF($K$8="SIM",VLOOKUP($R$7,'ST PAPAPASTA'!$A$1:$J$31,10,FALSE),VLOOKUP($R$7,'ST PAPAPASTA'!$A$1:$J$31,9,FALSE)) -> 0 | O31: 0 | P31: =(L31+N31)*12 -> 91.26 | R31: =Q31*M31 -> 0 | S31: =Q31*P31 -> 0
B32: Macarrao Inf Papapá m. Fusilli Vegetais 200g | D32: 5283 | E32: 12 x 200g | F32: 14 meses | G32: =VLOOKUP($R$7,'PSC PAPAPA'!$A$2:$L$31,5,FALSE) -> 13.69 | H32: 19.02.19.00 | I32: 7898969895286 | J32: 17898969895286 | K32: =VLOOKUP($R$7,'ST PAPAPASTA'!A:B,2,FALSE) -> 0.12 | L32: =VLOOKUP($R$7,PREÇOS!$A$2:$L$31,5,FALSE)*90% -> 7.605 | M32: =L32*12 -> 91.26 | N32: =IF($K$8="SIM",VLOOKUP($R$7,'ST PAPAPASTA'!$A$1:$J$31,10,FALSE),VLOOKUP($R$7,'ST PAPAPASTA'!$A$1:$J$31,9,FALSE)) -> 0 | O32: 0 | P32: =(L32+N32)*12 -> 91.26 | R32: =Q32*M32 -> 0 | S32: =Q32*P32 -> 0
B34: Sopinha Papapá org Lentinha Carne Legumes 180g | D34: 5276 | E34: 6 x 180g | F34: 16 meses | G34: =VLOOKUP($R$7,'PSC PAPAPA'!$A$2:$L$31,6,FALSE) -> 17.99 | H34: 2104.20.00 | I34: 7898969895279 | J34: 17898969895276 | K34: =VLOOKUP($R$7,'ST PAPAPASTA'!A:B,2,FALSE) -> 0.12 | L34: =VLOOKUP($R$7,PREÇOS!$A$2:$L$31,6,FALSE)*90% -> 10.62 | M34: =L34*6 -> 63.72 | N34: 0 | O34: 0 | P34: =(L34+N34)*6 -> 63.72 | R34: =Q34*M34 -> 0 | S34: =Q34*P34 -> 0
B35: Risotinho Papapá org Arroz quinoa frango 180g | D35: 5269 | E35: 6 x 180g | F35: 16 meses | G35: =VLOOKUP($R$7,'PSC PAPAPA'!$A$2:$L$31,6,FALSE) -> 17.99 | H35: 2104.20.00 | I35: 7898969895262 | J35: 17898969895269 | K35: =VLOOKUP($R$7,'ST PAPAPASTA'!A:B,2,FALSE) -> 0.12 | L35: =VLOOKUP($R$7,PREÇOS!$A$2:$L$31,6,FALSE)*90% -> 10.62 | M35: =L35*6 -> 63.72 | N35: 0 | O35: 0 | P35: =(L35+N35)*6 -> 63.72 | R35: =Q35*M35 -> 0 | S35: =Q35*P35 -> 0
B36: Caseirinho Papapá org Arroz feijão carne leg. 180g | D36: 5252 | E36: 6 x 180g | F36: 16 meses | G36: =VLOOKUP($R$7,'PSC PAPAPA'!$A$2:$L$31,6,FALSE) -> 17.99 | H36: 2104.20.00 | I36: 7898969895255 | J36: 17898969895252 | K36: =VLOOKUP($R$7,'ST PAPAPASTA'!A:B,2,FALSE) -> 0.12 | L36: =VLOOKUP($R$7,PREÇOS!$A$2:$L$31,6,FALSE)*90% -> 10.62 | M36: =L36*6 -> 63.72 | N36: 0 | O36: 0 | P36: =(L36+N36)*6 -> 63.72 | R36: =Q36*M36 -> 0 | S36: =Q36*P36 -> 0
B38: Cereal Infantil Papapá Aveia - Morango e Beterraba sache 170g | D38: 5402 | E38: 12 x 170g | F38: 12 meses | G38: =VLOOKUP($R$7,'PSC PAPAPA'!$A$2:$L$31,10,FALSE) -> 9.99 | H38: 19.01.10.30 | I38: 7898969895408 | J38: 27898969895402 | K38: =VLOOKUP($R$7,'ST CEREAL SABOR POUCH 170'!A:B,2,FALSE) -> 0.12 | L38: =VLOOKUP($R$7,PREÇOS!$A$2:$L$31,10,FALSE)*90% -> 5.535 | M38: =L38*12 -> 66.42 | N38: =IF($K$8="SIM",VLOOKUP($R$7,'ST CEREAL SABOR POUCH 170'!$A$1:$J$31,10,FALSE),VLOOKUP($R$7,'ST CEREAL SABOR POUCH 170'!$A$1:$J$31,9,FALSE)) -> 1.190394 | O38: 0 | P38: =(L38+N38)*12 -> 80.704728 | R38: =Q38*M38 -> 0 | S38: =Q38*P38 -> 0
B39: Cereal Infantil Papapá Aveia - Banana e Ameixa sache 170g | D39: 5419 | E39: 12 x 170g | F39: 12 meses | G39: =VLOOKUP($R$7,'PSC PAPAPA'!$A$2:$L$31,10,FALSE) -> 9.99 | H39: 19.01.10.30 | I39: 7898969895415 | J39: 27898969895419 | K39: =VLOOKUP($R$7,'ST CEREAL SABOR POUCH 170'!A:B,2,FALSE) -> 0.12 | L39: =VLOOKUP($R$7,PREÇOS!$A$2:$L$31,10,FALSE)*90% -> 5.535 | M39: =L39*12 -> 66.42 | N39: =IF($K$8="SIM",VLOOKUP($R$7,'ST CEREAL SABOR POUCH 170'!$A$1:$J$31,10,FALSE),VLOOKUP($R$7,'ST CEREAL SABOR POUCH 170'!$A$1:$J$31,9,FALSE)) -> 1.190394 | O39: 0 | P39: =(L39+N39)*12 -> 80.704728 | R39: =Q39*M39 -> 0 | S39: =Q39*P39 -> 0
B40: Cereal Infantil Papapá Aveia - Multicereais sache 170g | D40: 5429 | E40: 12 x 170g | F40: 12 meses | G40: =VLOOKUP($R$7,'PSC PAPAPA'!$A$2:$L$31,11,FALSE) -> 9.99 | H40: 19.01.10.30 | I40: 7898969895422 | J40: 17898969895429 | K40: =VLOOKUP($R$7,'ST MULTI 170 POUCH'!A:B,2,FALSE) -> 0.12 | L40: =VLOOKUP($R$7,PREÇOS!$A$2:$L$31,11,FALSE)*90% -> 5.535 | M40: =L40*12 -> 66.42 | N40: =IF($K$8="SIM",VLOOKUP($R$7,'ST MULTI 170 POUCH'!$A$1:$J$31,10,FALSE),VLOOKUP($R$7,'ST MULTI 170 POUCH'!$A$1:$J$31,9,FALSE)) -> 1.190394 | O40: 0 | P40: =(L40+N40)*12 -> 80.704728 | R40: =Q40*M40 -> 0 | S40: =Q40*P40 -> 0
B41: Cereal Infantil Papapá Aveia - Multicereais sache 500g | D41: 5399 | E41: 12 x 500g | F41: 12 meses | G41: =VLOOKUP($R$7,'PSC PAPAPA'!$A$2:$L$31,12,FALSE) -> 24.99 | H41: 19.01.10.30 | I41: 7898969895392 | J41: 17898969895399 | K41: =VLOOKUP($R$7,'ST MULTI 500 POUCH'!A:B,2,FALSE) -> 0.12 | L41: =VLOOKUP($R$7,PREÇOS!$A$2:$L$31,12,FALSE)*90% -> 13.491 | M41: =L41*12 -> 161.892 | N41: =IF($K$8="SIM",VLOOKUP($R$7,'ST MULTI 500 POUCH'!$A$1:$J$31,10,FALSE),VLOOKUP($R$7,'ST MULTI 500 POUCH'!$A$1:$J$31,9,FALSE)) -> 2.9014644 | O41: 0 | P41: =(L41+N41)*12 -> 196.70957 | R41: =Q41*M41 -> 0 | S41: =Q41*P41 -> 0
B43: Biscoito Infantil Papapá Biscotti com Laranja e Cenoura 60g | D43: 5375 | E43: 12 x 60g | F43: 10 meses | G43: =VLOOKUP($R$7,'PSC PAPAPA'!$A$2:$L$31,8,FALSE) -> 13.49 | H43: 1905.90.20 | I43: 7898969895378 | J43: 17898969895375 | K43: =VLOOKUP($R$7,'ST BISCOTTI'!A:B,2,FALSE) -> 0.12 | L43: =VLOOKUP($R$7,PREÇOS!$A$2:$L$31,8,FALSE)*90% -> 7.56 | M43: =L43*12 -> 90.72 | N43: =IF($K$8="SIM",VLOOKUP($R$7,'ST BISCOTTI'!$A$1:$J$31,10,FALSE),VLOOKUP($R$7,'ST BISCOTTI'!$A$1:$J$31,9,FALSE)) -> 0 | O43: 0 | P43: =(L43+N43)*12 -> 90.72 | R43: =Q43*M43 -> 0 | S43: =Q43*P43 -> 0
B44: Biscoito Infantil Papapá Biscotti com Maçã e Canela 60g | D44: 5351 | E44: 12 x 60g | F44: 10 meses | G44: =VLOOKUP($R$7,'PSC PAPAPA'!$A$2:$L$31,8,FALSE) -> 13.49 | H44: 1905.90.20 | I44: 7898969895354 | J44: 17898969895351 | K44: =VLOOKUP($R$7,'ST BISCOTTI'!A:B,2,FALSE) -> 0.12 | L44: =VLOOKUP($R$7,PREÇOS!$A$2:$L$31,8,FALSE)*90% -> 7.56 | M44: =L44*12 -> 90.72 | N44: =IF($K$8="SIM",VLOOKUP($R$7,'ST BISCOTTI'!$A$1:$J$31,10,FALSE),VLOOKUP($R$7,'ST BISCOTTI'!$A$1:$J$31,9,FALSE)) -> 0 | O44: 0 | P44: =(L44+N44)*12 -> 90.72 | R44: =Q44*M44 -> 0 | S44: =Q44*P44 -> 0
B45: Biscoito Infantil Papapá Biscotti com Banana e Cacau 60g | D45: 5368 | E45: 12 x 60g | F45: 10 meses | G45: =VLOOKUP($R$7,'PSC PAPAPA'!$A$2:$L$31,8,FALSE) -> 13.49 | H45: 1905.90.20 | I45: 7898969895361 | J45: 17898969895368 | K45: =VLOOKUP($R$7,'ST BISCOTTI'!A:B,2,FALSE) -> 0.12 | L45: =VLOOKUP($R$7,PREÇOS!$A$2:$L$31,8,FALSE)*90% -> 7.56 | M45: =L45*12 -> 90.72 | N45: =IF($K$8="SIM",VLOOKUP($R$7,'ST BISCOTTI'!$A$1:$J$31,10,FALSE),VLOOKUP($R$7,'ST BISCOTTI'!$A$1:$J$31,9,FALSE)) -> 0 | O45: 0 | P45: =(L45+N45)*12 -> 90.72 | R45: =Q45*M45 -> 0 | S45: =Q45*P45 -> 0
B46: Biscoito Infantil Papapá Biscotti Goiaba 60g | D46: 5597 | E46: 12 x 60g | F46: 10 meses | G46: =VLOOKUP($R$7,'PSC PAPAPA'!$A$2:$L$31,8,FALSE) -> 13.49 | H46: 1905.90.20 | I46: 7898969895590 | J46: 17898969895597 | K46: =VLOOKUP($R$7,'ST BISCOTTI'!A:B,2,FALSE) -> 0.12 | L46: =VLOOKUP($R$7,PREÇOS!$A$2:$L$31,8,FALSE)*90% -> 7.56 | M46: =L46*12 -> 90.72 | N46: =IF($K$8="SIM",VLOOKUP($R$7,'ST BISCOTTI'!$A$1:$J$31,10,FALSE),VLOOKUP($R$7,'ST BISCOTTI'!$A$1:$J$31,9,FALSE)) -> 0 | O46: 0 | P46: =(L46+N46)*12 -> 90.72 | R46: =Q46*M46 -> 0 | S46: =Q46*P46 -> 0
B47: Biscoito Infantil Papapá Biscotti com Maracujá e Camomila 60g | D47: 5580 | E47: 12 x 60g | F47: 10 meses | G47: =VLOOKUP($R$7,'PSC PAPAPA'!$A$2:$L$31,8,FALSE) -> 13.49 | H47: 1905.90.20 | I47: 7898969895583 | J47: 17898969895580 | K47: =VLOOKUP($R$7,'ST BISCOTTI'!A:B,2,FALSE) -> 0.12 | L47: =VLOOKUP($R$7,PREÇOS!$A$2:$L$31,8,FALSE)*90% -> 7.56 | M47: =L47*12 -> 90.72 | N47: =IF($K$8="SIM",VLOOKUP($R$7,'ST BISCOTTI'!$A$1:$J$31,10,FALSE),VLOOKUP($R$7,'ST BISCOTTI'!$A$1:$J$31,9,FALSE)) -> 0 | O47: 0 | P47: =(L47+N47)*12 -> 90.72 | R47: =Q47*M47 -> 0 | S47: =Q47*P47 -> 0
B49: Sopinha Papapá Frango Arroz Legumes 240g (2x 120g) | D49: 5610 | E49: 6 x 240g | F49: 12 meses | G49: 18.99 | H49: 2104.20.00 | I49: 7898969895613 | J49: 17898969895610 | K49: =VLOOKUP($R$7,'ST PAPAPASTA'!A:B,2,FALSE) -> 0.12 | L49: =VLOOKUP($R$7,PREÇOS!$A$2:$N$31,14,FALSE)*90% -> 11.6424 | M49: =L49*6 -> 69.8544 | N49: 0 | O49: 0 | P49: =(L49+N49)*6 -> 69.8544 | R49: =Q49*M49 -> 0 | S49: =Q49*P49 -> 0
B50: Sopinha Papapá Carne Macarrao Legumes 240g (2x 120g) | D50: 5634 | E50: 6 x 240g | F50: 12 meses | G50: 18.99 | H50: 2104.20.00 | I50: 7898969895637 | J50: 17898969895634 | K50: =VLOOKUP($R$7,'ST PAPAPASTA'!A:B,2,FALSE) -> 0.12 | L50: =VLOOKUP($R$7,PREÇOS!$A$2:$N$31,14,FALSE)*90% -> 11.6424 | M50: =L50*6 -> 69.8544 | N50: 0 | O50: 0 | P50: =(L50+N50)*6 -> 69.8544 | R50: =Q50*M50 -> 0 | S50: =Q50*P50 -> 0
...

Sheet Planilha1
C2: SIM
C3: NÃO

Sheet ST BISCOITINHOS
A1: Estado | B1: Aliquota interestadual | C1: Aliquota interna | D1: MVA (normal) | E1: MVA (simples) | F1: Ajustada (normal) | G1: Ajustada (simples) | H1: Preço | I1: ST Normal | J1: ST Simples
A2: AC | B2: 0.04 | C2: 0.04 | H2: =PREÇOS!D3 -> 11.8141 | I2: =IF(F2=0,,H2*(1+F2)*C2-(H2*B2)) -> 0 | J2: =IF(G2=0,IF(F2=0,,H2*(1+F2)*C2-(H2*B2)),H2*(1+G2)*C2-(H2*B2)) -> 0
A3: AL | B3: 0.04 | C3: 0.2 | D3: 0.3 | F3: 0.56 | H3: =PREÇOS!D4 -> 11.8141 | I3: =IF(F3=0,,H3*(1+F3)*C3-(H3*B3)) -> 3.2134352 | J3: =IF(G3=0,IF(F3=0,,H3*(1+F3)*C3-(H3*B3)),H3*(1+G3)*C3-(H3*B3)) -> 3.2134352
A4: AM | B4: 0.04 | C4: 0.04 | H4: =PREÇOS!D5 -> 11.8141 | I4: =IF(F4=0,,H4*(1+F4)*C4-(H4*B4)) -> 0 | J4: =IF(G4=0,IF(F4=0,,H4*(1+F4)*C4-(H4*B4)),H4*(1+G4)*C4-(H4*B4)) -> 0
A5: AP | B5: 0.04 | C5: 0.18 | D5: 0.34 | F5: 0.5688 | H5: =PREÇOS!D6 -> 11.8141 | I5: =IF(F5=0,,H5*(1+F5)*C5-(H5*B5)) -> 2.8635488 | J5: =IF(G5=0,IF(F5=0,,H5*(1+F5)*C5-(H5*B5)),H5*(1+G5)*C5-(H5*B5)) -> 2.8635488
A6: BA | B6: 0.04 | C6: 0.04 | H6: =PREÇOS!D7 -> 11.8141 | I6: =IF(F6=0,,H6*(1+F6)*C6-(H6*B6)) -> 0 | J6: =IF(G6=0,IF(F6=0,,H6*(1+F6)*C6-(H6*B6)),H6*(1+G6)*C6-(H6*B6)) -> 0
A7: CE | B7: 0.04 | C7: 0.04 | H7: =PREÇOS!D8 -> 11.8141 | I7: =IF(F7=0,,H7*(1+F7)*C7-(H7*B7)) -> 0 | J7: =IF(G7=0,IF(F7=0,,H7*(1+F7)*C7-(H7*B7)),H7*(1+G7)*C7-(H7*B7)) -> 0
A8: DF | B8: 0.04 | C8: 0.04 | H8: =PREÇOS!D9 -> 11.8141 | I8: =IF(F8=0,,H8*(1+F8)*C8-(H8*B8)) -> 0 | J8: =IF(G8=0,IF(F8=0,,H8*(1+F8)*C8-(H8*B8)),H8*(1+G8)*C8-(H8*B8)) -> 0
A9: ES | B9: 0.04 | C9: 0.04 | H9: =PREÇOS!D10 -> 11.8141 | I9: =IF(F9=0,,H9*(1+F9)*C9-(H9*B9)) -> 0 | J9: =IF(G9=0,IF(F9=0,,H9*(1+F9)*C9-(H9*B9)),H9*(1+G9)*C9-(H9*B9)) -> 0
A10: GO | B10: 0.04 | C10: 0.04 | H10: =PREÇOS!D11 -> 11.8141 | I10: =IF(F10=0,,H10*(1+F10)*C10-(H10*B10)) -> 0 | J10: =IF(G10=0,IF(F10=0,,H10*(1+F10)*C10-(H10*B10)),H10*(1+G10)*C10-(H10*B10)) -> 0
A11: MA | B11: 0.04 | C11: 0.04 | H11: =PREÇOS!D12 -> 11.8141 | I11: =IF(F11=0,,H11*(1+F11)*C11-(H11*B11)) -> 0 | J11: =IF(G11=0,IF(F11=0,,H11*(1+F11)*C11-(H11*B11)),H11*(1+G11)*C11-(H11*B11)) -> 0
A12: MG | B12: 0.04 | C12: 0.18 | D12: 0.25 | F12: 0.3636 | H12: =PREÇOS!D13 -> 11.8141 | I12: =IF(F12=0,,H12*(1+F12)*C12-(H12*B12)) -> 2.4271832 | J12: =IF(G12=0,IF(F12=0,,H12*(1+F12)*C12-(H12*B12)),H12*(1+G12)*C12-(H12*B12)) -> 2.4271832
A13: MS | B13: 0.04 | C13: 0.04 | H13: =PREÇOS!D14 -> 11.8141 | I13: =IF(F13=0,,H13*(1+F13)*C13-(H13*B13)) -> 0 | J13: =IF(G13=0,IF(F13=0,,H13*(1+F13)*C13-(H13*B13)),H13*(1+G13)*C13-(H13*B13)) -> 0
A14: MT | B14: 0.04 | C14: 0.04 | H14: =PREÇOS!D15 -> 11.8141 | I14: =IF(F14=0,,H14*(1+F14)*C14-(H14*B14)) -> 0 | J14: =IF(G14=0,IF(F14=0,,H14*(1+F14)*C14-(H14*B14)),H14*(1+G14)*C14-(H14*B14)) -> 0
A15: PA | B15: 0.04 | C15: 0.04 | H15: =PREÇOS!D16 -> 11.8141 | I15: =IF(F15=0,,H15*(1+F15)*C15-(H15*B15)) -> 0 | J15: =IF(G15=0,IF(F15=0,,H15*(1+F15)*C15-(H15*B15)),H15*(1+G15)*C15-(H15*B15)) -> 0
A16: PB | B16: 0.04 | C16: 0.04 | H16: =PREÇOS!D17 -> 11.8141 | I16: =IF(F16=0,,H16*(1+F16)*C16-(H16*B16)) -> 0 | J16: =IF(G16=0,IF(F16=0,,H16*(1+F16)*C16-(H16*B16)),H16*(1+G16)*C16-(H16*B16)) -> 0
A17: PE | B17: 0.04 | C17: 0.04 | H17: =PREÇOS!D18 -> 11.8141 | I17: =IF(F17=0,,H17*(1+F17)*C17-(H17*B17)) -> 0 | J17: =IF(G17=0,IF(F17=0,,H17*(1+F17)*C17-(H17*B17)),H17*(1+G17)*C17-(H17*B17)) -> 0
A18: PI | B18: 0.04 | C18: 0.04 | H18: =PREÇOS!D19 -> 11.8141 | I18: =IF(F18=0,,H18*(1+F18)*C18-(H18*B18)) -> 0 | J18: =IF(G18=0,IF(F18=0,,H18*(1+F18)*C18-(H18*B18)),H18*(1+G18)*C18-(H18*B18)) -> 0
A19: PR | B19: 0.12 | C19: 0.12 | H19: =PREÇOS!D20 -> 12.9574 | I19: =IF(F19=0,,H19*(1+F19)*C19-(H19*B19)) -> 0 | J19: =IF(G19=0,IF(F19=0,,H19*(1+F19)*C19-(H19*B19)),H19*(1+G19)*C19-(H19*B19)) -> 0
A20: RJ | B20: 0.04 | C20: 0.22 | D20: 0.352 | F20: 0.664 | H20: =PREÇOS!D21 -> 11.8141 | I20: =IF(F20=0,,H20*(1+F20)*C20-(H20*B20)) -> 3.8523417 | J20: =IF(G20=0,IF(F20=0,,H20*(1+F20)*C20-(H20*B20)),H20*(1+G20)*C20-(H20*B20)) -> 3.8523417
A21: RN | B21: 0.04 | C21: 0.04 | H21: =PREÇOS!D22 -> 11.8141 | I21: =IF(F21=0,,H21*(1+F21)*C21-(H21*B21)) -> 0 | J21: =IF(G21=0,IF(F21=0,,H21*(1+F21)*C21-(H21*B21)),H21*(1+G21)*C21-(H21*B21)) -> 0
A22: RO | B22: 0.04 | C22: 0.04 | H22: =PREÇOS!D23 -> 11.8141 | I22: =IF(F22=0,,H22*(1+F22)*C22-(H22*B22)) -> 0 | J22: =IF(G22=0,IF(F22=0,,H22*(1+F22)*C22-(H22*B22)),H22*(1+G22)*C22-(H22*B22)) -> 0
A23: RR | B23: 0.04 | C23: 0.04 | H23: =PREÇOS!D24 -> 11.8141 | I23: =IF(F23=0,,H23*(1+F23)*C23-(H23*B23)) -> 0 | J23: =IF(G23=0,IF(F23=0,,H23*(1+F23)*C23-(H23*B23)),H23*(1+G23)*C23-(H23*B23)) -> 0
A24: RS | B24: 0.04 | C24: 0.04 | H24: =PREÇOS!D25 -> 11.8141 | I24: =IF(F24=0,,H24*(1+F24)*C24-(H24*B24)) -> 0 | J24: =IF(G24=0,IF(F24=0,,H24*(1+F24)*C24-(H24*B24)),H24*(1+G24)*C24-(H24*B24)) -> 0
A25: SC | B25: 0.04 | C25: 0.04 | H25: =PREÇOS!D26 -> 11.8141 | I25: =IF(F25=0,,H25*(1+F25)*C25-(H25*B25)) -> 0 | J25: =IF(G25=0,IF(F25=0,,H25*(1+F25)*C25-(H25*B25)),H25*(1+G25)*C25-(H25*B25)) -> 0
A26: SE | B26: 0.04 | C26: 0.04 | H26: =PREÇOS!D27 -> 11.8141 | I26: =IF(F26=0,,H26*(1+F26)*C26-(H26*B26)) -> 0 | J26: =IF(G26=0,IF(F26=0,,H26*(1+F26)*C26-(H26*B26)),H26*(1+G26)*C26-(H26*B26)) -> 0
A27: SP | B27: 0.04 | C27: 0.18 | D27: 0.4832 | F27: 0.618 | H27: =PREÇOS!D28 -> 11.8141 | I27: =IF(F27=0,,H27*(1+F27)*C27-(H27*B27)) -> 2.9681745 | J27: =IF(G27=0,IF(F27=0,,H27*(1+F27)*C27-(H27*B27)),H27*(1+G27)*C27-(H27*B27)) -> 2.9681745
A28: SP/Atacado | B28: =B27 -> 0.04 | C28: =C27 -> 0.18 | D28: =D27 -> 0.4832 | E28: =E27 -> 0 | F28: =F27 -> 0.618 | G28: =G27 -> 0 | H28: =PREÇOS!D29 -> 11.8141 | I28: =IF(F28=0,,H28*(1+F28)*C28-(H28*B28)) -> 2.9681745 | J28: =IF(G28=0,IF(F28=0,,H28*(1+F28)*C28-(H28*B28)),H28*(1+G28)*C28-(H28*B28)) -> 2.9681745
A29: TO | B29: 0.04 | C29: 0.04 | H29: =PREÇOS!D30 -> 11.8141 | I29: =IF(F29=0,,H29*(1+F29)*C29-(H29*B29)) -> 0 | J29: =IF(G29=0,IF(F29=0,,H29*(1+F29)*C29-(H29*B29)),H29*(1+G29)*C29-(H29*B29)) -> 0
A30: EX | H30: =PREÇOS!D31 -> 0 | I30: =IF(F30=0,,H30*(1+F30)*C30-(H30*B30)) -> 0 | J30: =IF(G30=0,IF(F30=0,,H30*(1+F30)*C30-(H30*B30)),H30*(1+G30)*C30-(H30*B30)) -> 0

Sheet ST PAPAPASTA
A1: Estado | B1: Aliquota interestadual | C1: Aliquota interna | D1: MVA (normal) | E1: MVA (simples) | F1: Ajustada (normal) | G1: Ajustada (simples) | H1: Preço | I1: ST Normal | J1: ST Simples
A2: AC | B2: 0.07 | C2: 0.07 | H2: =PREÇOS!E3 -> 7.93 | I2: =IF(F2=0,,H2*(1+F2)*C2-(H2*B2)) -> 0 | J2: =IF(G2=0,IF(F2=0,,H2*(1+F2)*C2-(H2*B2)),H2*(1+G2)*C2-(H2*B2)) -> 0
A3: AL | B3: 0.07 | C3: 0.19 | D3: 0.2 | F3: 0.361 | H3: =PREÇOS!E4 -> 7.93 | I3: =IF(F3=0,,H3*(1+F3)*C3-(H3*B3)) -> 1.4955187 | J3: =IF(G3=0,IF(F3=0,,H3*(1+F3)*C3-(H3*B3)),H3*(1+G3)*C3-(H3*B3)) -> 1.4955187
A4: AM | B4: 0.07 | C4: 0.07 | H4: =PREÇOS!E5 -> 7.93 | I4: =IF(F4=0,,H4*(1+F4)*C4-(H4*B4)) -> 0 | J4: =IF(G4=0,IF(F4=0,,H4*(1+F4)*C4-(H4*B4)),H4*(1+G4)*C4-(H4*B4)) -> 0
A5: AP | B5: 0.07 | C5: 0.18 | D5: 0.38 | F5: 0.5651 | H5: =PREÇOS!E6 -> 7.93 | I5: =IF(F5=0,,H5*(1+F5)*C5-(H5*B5)) -> 1.6789237 | J5: =IF(G5=0,IF(F5=0,,H5*(1+F5)*C5-(H5*B5)),H5*(1+G5)*C5-(H5*B5)) -> 1.6789237
A6: BA | B6: 0.07 | C6: 0.07 | H6: =PREÇOS!E7 -> 7.93 | I6: =IF(F6=0,,H6*(1+F6)*C6-(H6*B6)) -> 0 | J6: =IF(G6=0,IF(F6=0,,H6*(1+F6)*C6-(H6*B6)),H6*(1+G6)*C6-(H6*B6)) -> 0
A7: CE | B7: 0.07 | C7: 0.07 | H7: =PREÇOS!E8 -> 7.93 | I7: =IF(F7=0,,H7*(1+F7)*C7-(H7*B7)) -> 0 | J7: =IF(G7=0,IF(F7=0,,H7*(1+F7)*C7-(H7*B7)),H7*(1+G7)*C7-(H7*B7)) -> 0
A8: DF | B8: 0.07 | C8: 0.07 | H8: =PREÇOS!E9 -> 7.93 | I8: =IF(F8=0,,H8*(1+F8)*C8-(H8*B8)) -> 0 | J8: =IF(G8=0,IF(F8=0,,H8*(1+F8)*C8-(H8*B8)),H8*(1+G8)*C8-(H8*B8)) -> 0
A9: ES | B9: 0.07 | C9: 0.07 | H9: =PREÇOS!E10 -> 7.93 | I9: =IF(F9=0,,H9*(1+F9)*C9-(H9*B9)) -> 0 | J9: =IF(G9=0,IF(F9=0,,H9*(1+F9)*C9-(H9*B9)),H9*(1+G9)*C9-(H9*B9)) -> 0
A10: GO | B10: 0.07 | C10: 0.07 | H10: =PREÇOS!E11 -> 7.93 | I10: =IF(F10=0,,H10*(1+F10)*C10-(H10*B10)) -> 0 | J10: =IF(G10=0,IF(F10=0,,H10*(1+F10)*C10-(H10*B10)),H10*(1+G10)*C10-(H10*B10)) -> 0
A11: MA | B11: 0.07 | C11: 0.07 | H11: =PREÇOS!E12 -> 7.93 | I11: =IF(F11=0,,H11*(1+F11)*C11-(H11*B11)) -> 0 | J11: =IF(G11=0,IF(F11=0,,H11*(1+F11)*C11-(H11*B11)),H11*(1+G11)*C11-(H11*B11)) -> 0
A12: MG | B12: 0.12 | C12: 0.18 | D12: 0.35 | F12: 0.35 | H12: =PREÇOS!E13 -> 8.45 | I12: =IF(F12=0,,H12*(1+F12)*C12-(H12*B12)) -> 1.03935 | J12: =IF(G12=0,IF(F12=0,,H12*(1+F12)*C12-(H12*B12)),H12*(1+G12)*C12-(H12*B12)) -> 1.03935
A13: MS | B13: 0.07 | C13: 0.07 | H13: =PREÇOS!E14 -> 7.93 | I13: =IF(F13=0,,H13*(1+F13)*C13-(H13*B13)) -> 0 | J13: =IF(G13=0,IF(F13=0,,H13*(1+F13)*C13-(H13*B13)),H13*(1+G13)*C13-(H13*B13)) -> 0
A14: MT | B14: 0.07 | C14: 0.17 | D14: 0.3545 | F14: 0.3545 | H14: =PREÇOS!E15 -> 7.93 | I14: =IF(F14=0,,H14*(1+F14)*C14-(H14*B14)) -> 1.2709015 | J14: =IF(G14=0,IF(F14=0,,H14*(1+F14)*C14-(H14*B14)),H14*(1+G14)*C14-(H14*B14)) -> 1.2709015
A15: PA | B15: 0.07 | C15: 0.07 | H15: =PREÇOS!E16 -> 7.93 | I15: =IF(F15=0,,H15*(1+F15)*C15-(H15*B15)) -> 0 | J15: =IF(G15=0,IF(F15=0,,H15*(1+F15)*C15-(H15*B15)),H15*(1+G15)*C15-(H15*B15)) -> 0
A16: PB | B16: 0.07 | C16: 0.07 | H16: =PREÇOS!E17 -> 7.93 | I16: =IF(F16=0,,H16*(1+F16)*C16-(H16*B16)) -> 0 | J16: =IF(G16=0,IF(F16=0,,H16*(1+F16)*C16-(H16*B16)),H16*(1+G16)*C16-(H16*B16)) -> 0
A17: PE | B17: 0.07 | C17: 0.07 | H17: =PREÇOS!E18 -> 7.93 | I17: =IF(F17=0,,H17*(1+F17)*C17-(H17*B17)) -> 0 | J17: =IF(G17=0,IF(F17=0,,H17*(1+F17)*C17-(H17*B17)),H17*(1+G17)*C17-(H17*B17)) -> 0
A18: PI | B18: 0.07 | C18: 0.07 | H18: =PREÇOS!E19 -> 7.93 | I18: =IF(F18=0,,H18*(1+F18)*C18-(H18*B18)) -> 0 | J18: =IF(G18=0,IF(F18=0,,H18*(1+F18)*C18-(H18*B18)),H18*(1+G18)*C18-(H18*B18)) -> 0
A19: PR | B19: 0.12 | C19: 0.12 | H19: =PREÇOS!E20 -> 8.45 | I19: =IF(F19=0,,H19*(1+F19)*C19-(H19*B19)) -> 0 | J19: =IF(G19=0,IF(F19=0,,H19*(1+F19)*C19-(H19*B19)),H19*(1+G19)*C19-(H19*B19)) -> 0
A20: RJ | B20: 0.12 | C20: 0.12 | H20: =PREÇOS!E21 -> 8.45 | I20: =IF(F20=0,,H20*(1+F20)*C20-(H20*B20)) -> 0 | J20: =IF(G20=0,IF(F20=0,,H20*(1+F20)*C20-(H20*B20)),H20*(1+G20)*C20-(H20*B20)) -> 0
A21: RN | B21: 0.07 | C21: 0.07 | H21: =PREÇOS!E22 -> 7.93 | I21: =IF(F21=0,,H21*(1+F21)*C21-(H21*B21)) -> 0 | J21: =IF(G21=0,IF(F21=0,,H21*(1+F21)*C21-(H21*B21)),H21*(1+G21)*C21-(H21*B21)) -> 0
A22: RO | B22: 0.07 | C22: 0.07 | H22: =PREÇOS!E23 -> 7.93 | I22: =IF(F22=0,,H22*(1+F22)*C22-(H22*B22)) -> 0 | J22: =IF(G22=0,IF(F22=0,,H22*(1+F22)*C22-(H22*B22)),H22*(1+G22)*C22-(H22*B22)) -> 0
A23: RR | B23: 0.07 | C23: 0.07 | H23: =PREÇOS!E24 -> 7.93 | I23: =IF(F23=0,,H23*(1+F23)*C23-(H23*B23)) -> 0 | J23: =IF(G23=0,IF(F23=0,,H23*(1+F23)*C23-(H23*B23)),H23*(1+G23)*C23-(H23*B23)) -> 0
A24: RS | B24: 0.12 | C24: 0.12 | H24: =PREÇOS!E25 -> 8.45 | I24: =IF(F24=0,,H24*(1+F24)*C24-(H24*B24)) -> 0 | J24: =IF(G24=0,IF(F24=0,,H24*(1+F24)*C24-(H24*B24)),H24*(1+G24)*C24-(H24*B24)) -> 0
A25: SC | B25: 0.12 | C25: 0.12 | H25: =PREÇOS!E26 -> 8.45 | I25: =IF(F25=0,,H25*(1+F25)*C25-(H25*B25)) -> 0 | J25: =IF(G25=0,IF(F25=0,,H25*(1+F25)*C25-(H25*B25)),H25*(1+G25)*C25-(H25*B25)) -> 0
A26: SE | B26: 0.07 | C26: 0.07 | H26: =PREÇOS!E27 -> 7.93 | I26: =IF(F26=0,,H26*(1+F26)*C26-(H26*B26)) -> 0 | J26: =IF(G26=0,IF(F26=0,,H26*(1+F26)*C26-(H26*B26)),H26*(1+G26)*C26-(H26*B26)) -> 0
A27: SP | B27: 0.12 | C27: 0.12 | H27: =PREÇOS!E28 -> 8.45 | I27: =IF(F27=0,,H27*(1+F27)*C27-(H27*B27)) -> 0 | J27: =IF(G27=0,IF(F27=0,,H27*(1+F27)*C27-(H27*B27)),H27*(1+G27)*C27-(H27*B27)) -> 0
A28: SP/Atacado | B28: =B27 -> 0.12 | C28: =C27 -> 0.12 | D28: =D27 -> 0 | E28: =E27 -> 0 | F28: =F27 -> 0 | G28: =G27 -> 0 | H28: =PREÇOS!E29 -> 8.45 | I28: =IF(F28=0,,H28*(1+F28)*C28-(H28*B28)) -> 0 | J28: =IF(G28=0,IF(F28=0,,H28*(1+F28)*C28-(H28*B28)),H28*(1+G28)*C28-(H28*B28)) -> 0
A29: TO | B29: 0.07 | C29: 0.07 | H29: =PREÇOS!E30 -> 7.93 | I29: =IF(F29=0,,H29*(1+F29)*C29-(H29*B29)) -> 0 | J29: =IF(G29=0,IF(F29=0,,H29*(1+F29)*C29-(H29*B29)),H29*(1+G29)*C29-(H29*B29)) -> 0
A30: EX | H30: =PREÇOS!E31 -> 0 | I30: =IF(F30=0,,H30*(1+F30)*C30-(H30*B30)) -> 0 | J30: =IF(G30=0,IF(F30=0,,H30*(1+F30)*C30-(H30*B30)),H30*(1+G30)*C30-(H30*B30)) -> 0

Sheet ST PALITINHOS
A1: Estado | B1: Aliquota interestadual | C1: Aliquota interna | D1: MVA (normal) | E1: MVA (simples) | F1: Ajustada (normal) | G1: Ajustada (simples) | H1: Preço | I1: ST Normal | J1: ST Simples
A2: AC | B2: 0.07 | C2: 0.07 | H2: =PREÇOS!C3 -> 3.57 | I2: =IF(F2=0,,H2*(1+F2)*C2-(H2*B2)) -> 0 | J2: =IF(G2=0,IF(F2=0,,H2*(1+F2)*C2-(H2*B2)),H2*(1+G2)*C2-(H2*B2)) -> 0
A3: AL | B3: 0.07 | C3: 0.19 | D3: 0.5432 | F3: 0.794 | H3: =PREÇOS!C4 -> 3.57 | I3: =IF(F3=0,,H3*(1+F3)*C3-(H3*B3)) -> 0.9669702 | J3: =IF(G3=0,IF(F3=0,,H3*(1+F3)*C3-(H3*B3)),H3*(1+G3)*C3-(H3*B3)) -> 0.9669702
A4: AM | B4: 0.07 | C4: 0.18 | H4: =PREÇOS!C5 -> 3.57 | I4: =IF(F4=0,,H4*(1+F4)*C4-(H4*B4)) -> 0 | J4: =IF(G4=0,IF(F4=0,,H4*(1+F4)*C4-(H4*B4)),H4*(1+G4)*C4-(H4*B4)) -> 0
A5: AP | B5: 0.07 | C5: 0.18 | D5: 0.41 | F5: 0.5991 | H5: =PREÇOS!C6 -> 3.57 | I5: =IF(F5=0,,H5*(1+F5)*C5-(H5*B5)) -> 0.77768166 | J5: =IF(G5=0,IF(F5=0,,H5*(1+F5)*C5-(H5*B5)),H5*(1+G5)*C5-(H5*B5)) -> 0.77768166
A6: BA | B6: 0.07 | C6: 0.07 | H6: =PREÇOS!C7 -> 3.57 | I6: =IF(F6=0,,H6*(1+F6)*C6-(H6*B6)) -> 0 | J6: =IF(G6=0,IF(F6=0,,H6*(1+F6)*C6-(H6*B6)),H6*(1+G6)*C6-(H6*B6)) -> 0
A7: CE | B7: 0.07 | C7: 0.07 | H7: =PREÇOS!C8 -> 3.57 | I7: =IF(F7=0,,H7*(1+F7)*C7-(H7*B7)) -> 0 | J7: =IF(G7=0,IF(F7=0,,H7*(1+F7)*C7-(H7*B7)),H7*(1+G7)*C7-(H7*B7)) -> 0
A8: DF | B8: 0.07 | C8: 0.07 | H8: =PREÇOS!C9 -> 3.57 | I8: =IF(F8=0,,H8*(1+F8)*C8-(H8*B8)) -> 0 | J8: =IF(G8=0,IF(F8=0,,H8*(1+F8)*C8-(H8*B8)),H8*(1+G8)*C8-(H8*B8)) -> 0
A9: ES | B9: 0.07 | C9: 0.07 | H9: =PREÇOS!C10 -> 3.57 | I9: =IF(F9=0,,H9*(1+F9)*C9-(H9*B9)) -> 0 | J9: =IF(G9=0,IF(F9=0,,H9*(1+F9)*C9-(H9*B9)),H9*(1+G9)*C9-(H9*B9)) -> 0
A10: GO | B10: 0.07 | C10: 0.07 | H10: =PREÇOS!C11 -> 3.57 | I10: =IF(F10=0,,H10*(1+F10)*C10-(H10*B10)) -> 0 | J10: =IF(G10=0,IF(F10=0,,H10*(1+F10)*C10-(H10*B10)),H10*(1+G10)*C10-(H10*B10)) -> 0
A11: MA | B11: 0.07 | C11: 0.07 | H11: =PREÇOS!C12 -> 3.57 | I11: =IF(F11=0,,H11*(1+F11)*C11-(H11*B11)) -> 0 | J11: =IF(G11=0,IF(F11=0,,H11*(1+F11)*C11-(H11*B11)),H11*(1+G11)*C11-(H11*B11)) -> 0
A12: MG | B12: 0.12 | C12: 0.18 | D12: 0.4 | F12: 0.5024 | H12: =PREÇOS!C13 -> 3.78 | I12: =IF(F12=0,,H12*(1+F12)*C12-(H12*B12)) -> 0.56863296 | J12: =IF(G12=0,IF(F12=0,,H12*(1+F12)*C12-(H12*B12)),H12*(1+G12)*C12-(H12*B12)) -> 0.56863296
A13: MS | B13: 0.07 | C13: 0.07 | H13: =PREÇOS!C14 -> 3.57 | I13: =IF(F13=0,,H13*(1+F13)*C13-(H13*B13)) -> 0 | J13: =IF(G13=0,IF(F13=0,,H13*(1+F13)*C13-(H13*B13)),H13*(1+G13)*C13-(H13*B13)) -> 0
A14: MT | B14: 0.07 | C14: 0.17 | D14: 0.4552 | F14: 0.6305 | H14: =PREÇOS!C15 -> 3.57 | I14: =IF(F14=0,,H14*(1+F14)*C14-(H14*B14)) -> 0.73965045 | J14: =IF(G14=0,IF(F14=0,,H14*(1+F14)*C14-(H14*B14)),H14*(1+G14)*C14-(H14*B14)) -> 0.73965045
A15: PA | B15: 0.07 | C15: 0.07 | H15: =PREÇOS!C16 -> 3.57 | I15: =IF(F15=0,,H15*(1+F15)*C15-(H15*B15)) -> 0 | J15: =IF(G15=0,IF(F15=0,,H15*(1+F15)*C15-(H15*B15)),H15*(1+G15)*C15-(H15*B15)) -> 0
A16: PB | B16: 0.07 | C16: 0.07 | H16: =PREÇOS!C17 -> 3.57 | I16: =IF(F16=0,,H16*(1+F16)*C16-(H16*B16)) -> 0 | J16: =IF(G16=0,IF(F16=0,,H16*(1+F16)*C16-(H16*B16)),H16*(1+G16)*C16-(H16*B16)) -> 0
A17: PE | B17: 0.07 | C17: 0.07 | H17: =PREÇOS!C18 -> 3.57 | I17: =IF(F17=0,,H17*(1+F17)*C17-(H17*B17)) -> 0 | J17: =IF(G17=0,IF(F17=0,,H17*(1+F17)*C17-(H17*B17)),H17*(1+G17)*C17-(H17*B17)) -> 0
A18: PI | B18: 0.07 | C18: 0.07 | H18: =PREÇOS!C19 -> 3.57 | I18: =IF(F18=0,,H18*(1+F18)*C18-(H18*B18)) -> 0 | J18: =IF(G18=0,IF(F18=0,,H18*(1+F18)*C18-(H18*B18)),H18*(1+G18)*C18-(H18*B18)) -> 0
A19: PR | B19: 0.12 | C19: 0.195 | D19: 0.5432 | E19: 0.163 | F19: 0.687 | G19: 0.1968 | H19: =PREÇOS!C20 -> 3.78 | I19: =IF(F19=0,,H19*(1+F19)*C19-(H19*B19)) -> 0.7898877 | J19: =IF(G19=0,IF(F19=0,,H19*(1+F19)*C19-(H19*B19)),H19*(1+G19)*C19-(H19*B19)) -> 0.42856128
A20: RJ | B20: 0.12 | C20: 0.22 | D20: 0.4698 | F20: 0.6582 | H20: =PREÇOS!C21 -> 3.78 | I20: =IF(F20=0,,H20*(1+F20)*C20-(H20*B20)) -> 0.92535912 | J20: =IF(G20=0,IF(F20=0,,H20*(1+F20)*C20-(H20*B20)),H20*(1+G20)*C20-(H20*B20)) -> 0.92535912
A21: RN | B21: 0.07 | C21: 0.07 | H21: =PREÇOS!C22 -> 3.57 | I21: =IF(F21=0,,H21*(1+F21)*C21-(H21*B21)) -> 0 | J21: =IF(G21=0,IF(F21=0,,H21*(1+F21)*C21-(H21*B21)),H21*(1+G21)*C21-(H21*B21)) -> 0
A22: RO | B22: 0.07 | C22: 0.07 | H22: =PREÇOS!C23 -> 3.57 | I22: =IF(F22=0,,H22*(1+F22)*C22-(H22*B22)) -> 0 | J22: =IF(G22=0,IF(F22=0,,H22*(1+F22)*C22-(H22*B22)),H22*(1+G22)*C22-(H22*B22)) -> 0
A23: RR | B23: 0.07 | C23: 0.07 | H23: =PREÇOS!C24 -> 3.57 | I23: =IF(F23=0,,H23*(1+F23)*C23-(H23*B23)) -> 0 | J23: =IF(G23=0,IF(F23=0,,H23*(1+F23)*C23-(H23*B23)),H23*(1+G23)*C23-(H23*B23)) -> 0
A24: RS | B24: 0.12 | C24: 0.12 | H24: =PREÇOS!C25 -> 3.78 | I24: =IF(F24=0,,H24*(1+F24)*C24-(H24*B24)) -> 0 | J24: =IF(G24=0,IF(F24=0,,H24*(1+F24)*C24-(H24*B24)),H24*(1+G24)*C24-(H24*B24)) -> 0
A25: SC | B25: 0.12 | C25: 0.12 | H25: =PREÇOS!C26 -> 3.78 | I25: =IF(F25=0,,H25*(1+F25)*C25-(H25*B25)) -> 0 | J25: =IF(G25=0,IF(F25=0,,H25*(1+F25)*C25-(H25*B25)),H25*(1+G25)*C25-(H25*B25)) -> 0
A26: SE | B26: 0.07 | C26: 0.07 | H26: =PREÇOS!C27 -> 3.57 | I26: =IF(F26=0,,H26*(1+F26)*C26-(H26*B26)) -> 0 | J26: =IF(G26=0,IF(F26=0,,H26*(1+F26)*C26-(H26*B26)),H26*(1+G26)*C26-(H26*B26)) -> 0
A27: SP | B27: 0.12 | C27: 0.18 | H27: =PREÇOS!C28 -> 3.78 | I27: =IF(F27=0,,H27*(1+F27)*C27-(H27*B27)) -> 0 | J27: =IF(G27=0,IF(F27=0,,H27*(1+F27)*C27-(H27*B27)),H27*(1+G27)*C27-(H27*B27)) -> 0
A28: SP/Atacado | B28: =B27 -> 0.12 | C28: =C27 -> 0.18 | H28: =PREÇOS!C29 -> 3.78 | I28: =IF(F28=0,,H28*(1+F28)*C28-(H28*B28)) -> 0 | J28: =IF(G28=0,IF(F28=0,,H28*(1+F28)*C28-(H28*B28)),H28*(1+G28)*C28-(H28*B28)) -> 0
A29: TO | B29: 0.07 | C29: 0.07 | H29: =PREÇOS!C30 -> 3.57 | I29: =IF(F29=0,,H29*(1+F29)*C29-(H29*B29)) -> 0 | J29: =IF(G29=0,IF(F29=0,,H29*(1+F29)*C29-(H29*B29)),H29*(1+G29)*C29-(H29*B29)) -> 0
A30: EX | H30: =PREÇOS!C31 -> 0 | I30: =IF(F30=0,,H30*(1+F30)*C30-(H30*B30)) -> 0 | J30: =IF(G30=0,IF(F30=0,,H30*(1+F30)*C30-(H30*B30)),H30*(1+G30)*C30-(H30*B30)) -> 0

Sheet ST BISCOTTI
A1: Estado | B1: Aliquota interestadual | C1: Aliquota interna | D1: MVA (normal) | E1: MVA (simples) | F1: Ajustada (normal) | G1: Ajustada (simples) | H1: Preço | I1: ST Normal | J1: ST Simples
A2: AC | B2: 0.07 | C2: =VLOOKUP(A2,[2]DIFAL!$C$13:$H$39,6,) -> 0.19 | H2: =PREÇOS!H3 -> 7.93 | I2: =IF(F2=0,,H2*(1+F2)*C2-(H2*B2)) -> 0 | J2: =IF(G2=0,IF(F2=0,,H2*(1+F2)*C2-(H2*B2)),H2*(1+G2)*C2-(H2*B2)) -> 0
A3: AL | B3: 0.07 | C3: 0.2 | F3: 0.5113 | H3: =PREÇOS!H4 -> 7.93 | I3: =IF(F3=0,,H3*(1+F3)*C3-(H3*B3)) -> 1.8418218 | J3: =IF(G3=0,IF(F3=0,,H3*(1+F3)*C3-(H3*B3)),H3*(1+G3)*C3-(H3*B3)) -> 1.8418218
A4: AM | B4: 0.07 | C4: =VLOOKUP(A4,[2]DIFAL!$C$13:$H$39,6,) -> 0.2 | H4: =PREÇOS!H5 -> 7.93 | I4: =IF(F4=0,,H4*(1+F4)*C4-(H4*B4)) -> 0 | J4: =IF(G4=0,IF(F4=0,,H4*(1+F4)*C4-(H4*B4)),H4*(1+G4)*C4-(H4*B4)) -> 0
A5: AP | B5: 0.07 | C5: =VLOOKUP(A5,[2]DIFAL!$C$13:$H$39,5,) -> 0.18 | F5: 0.5198 | H5: =PREÇOS!H6 -> 7.93 | I5: =IF(F5=0,,H5*(1+F5)*C5-(H5*B5)) -> 1.6142625 | J5: =IF(G5=0,IF(F5=0,,H5*(1+F5)*C5-(H5*B5)),H5*(1+G5)*C5-(H5*B5)) -> 1.6142625
A6: BA | B6: 0.07 | C6: =VLOOKUP(A6,[2]DIFAL!$C$13:$H$39,6,) -> 0.19 | H6: =PREÇOS!H7 -> 7.93 | I6: =IF(F6=0,,H6*(1+F6)*C6-(H6*B6)) -> 0 | J6: =IF(G6=0,IF(F6=0,,H6*(1+F6)*C6-(H6*B6)),H6*(1+G6)*C6-(H6*B6)) -> 0
A7: CE | B7: 0.07 | C7: =VLOOKUP(A7,[2]DIFAL!$C$13:$H$39,6,) -> 0.2 | H7: =PREÇOS!H8 -> 7.93 | I7: =IF(F7=0,,H7*(1+F7)*C7-(H7*B7)) -> 0 | J7: =IF(G7=0,IF(F7=0,,H7*(1+F7)*C7-(H7*B7)),H7*(1+G7)*C7-(H7*B7)) -> 0
A8: DF | B8: 0.07 | C8: =VLOOKUP(A8,[2]DIFAL!$C$13:$H$39,5,) -> 0.18 | H8: =PREÇOS!H9 -> 7.93 | I8: =IF(F8=0,,H8*(1+F8)*C8-(H8*B8)) -> 0 | J8: =IF(G8=0,IF(F8=0,,H8*(1+F8)*C8-(H8*B8)),H8*(1+G8)*C8-(H8*B8)) -> 0
A9: ES | B9: 0.07 | C9: =VLOOKUP(A9,[2]DIFAL!$C$13:$H$39,5,) -> 0.17 | H9: =PREÇOS!H10 -> 7.93 | I9: =IF(F9=0,,H9*(1+F9)*C9-(H9*B9)) -> 0 | J9: =IF(G9=0,IF(F9=0,,H9*(1+F9)*C9-(H9*B9)),H9*(1+G9)*C9-(H9*B9)) -> 0
A10: GO | B10: 0.07 | C10: =VLOOKUP(A10,[2]DIFAL!$C$13:$H$39,5,) -> 0.17 | H10: =PREÇOS!H11 -> 7.93 | I10: =IF(F10=0,,H10*(1+F10)*C10-(H10*B10)) -> 0 | J10: =IF(G10=0,IF(F10=0,,H10*(1+F10)*C10-(H10*B10)),H10*(1+G10)*C10-(H10*B10)) -> 0
A11: MA | B11: 0.07 | C11: =VLOOKUP(A11,[2]DIFAL!$C$13:$H$39,6,) -> 0.2 | H11: =PREÇOS!H12 -> 7.93 | I11: =IF(F11=0,,H11*(1+F11)*C11-(H11*B11)) -> 0 | J11: =IF(G11=0,IF(F11=0,,H11*(1+F11)*C11-(H11*B11)),H11*(1+G11)*C11-(H11*B11)) -> 0
A12: MG | B12: 0.12 | C12: 0.12 | F12: 0.25 | H12: =PREÇOS!H13 -> 8.4 | I12: =IF(F12=0,,H12*(1+F12)*C12-(H12*B12)) -> 0.252 | J12: =IF(G12=0,IF(F12=0,,H12*(1+F12)*C12-(H12*B12)),H12*(1+G12)*C12-(H12*B12)) -> 0.252
A13: MS | B13: 0.07 | C13: =VLOOKUP(A13,[2]DIFAL!$C$13:$H$39,5,) -> 0.17 | H13: =PREÇOS!H14 -> 7.93 | I13: =IF(F13=0,,H13*(1+F13)*C13-(H13*B13)) -> 0 | J13: =IF(G13=0,IF(F13=0,,H13*(1+F13)*C13-(H13*B13)),H13*(1+G13)*C13-(H13*B13)) -> 0
A14: MT | B14: 0.07 | C14: =VLOOKUP(A14,[2]DIFAL!$C$13:$H$39,5,) -> 0.17 | F14: 0.3978 | H14: =PREÇOS!H15 -> 7.93 | I14: =IF(F14=0,,H14*(1+F14)*C14-(H14*B14)) -> 1.3292742 | J14: =IF(G14=0,IF(F14=0,,H14*(1+F14)*C14-(H14*B14)),H14*(1+G14)*C14-(H14*B14)) -> 1.3292742
A15: PA | B15: 0.07 | C15: =VLOOKUP(A15,[2]DIFAL!$C$13:$H$39,6,) -> 0.19 | H15: =PREÇOS!H16 -> 7.93 | I15: =IF(F15=0,,H15*(1+F15)*C15-(H15*B15)) -> 0 | J15: =IF(G15=0,IF(F15=0,,H15*(1+F15)*C15-(H15*B15)),H15*(1+G15)*C15-(H15*B15)) -> 0
A16: PB | B16: 0.07 | C16: =VLOOKUP(A16,[2]DIFAL!$C$13:$H$39,5,) -> 0.18 | H16: =PREÇOS!H17 -> 7.93 | I16: =IF(F16=0,,H16*(1+F16)*C16-(H16*B16)) -> 0 | J16: =IF(G16=0,IF(F16=0,,H16*(1+F16)*C16-(H16*B16)),H16*(1+G16)*C16-(H16*B16)) -> 0
A17: PE | B17: 0.07 | C17: =VLOOKUP(A17,[2]DIFAL!$C$13:$H$39,5,) -> 0.18 | H17: =PREÇOS!H18 -> 7.93 | I17: =IF(F17=0,,H17*(1+F17)*C17-(H17*B17)) -> 0 | J17: =IF(G17=0,IF(F17=0,,H17*(1+F17)*C17-(H17*B17)),H17*(1+G17)*C17-(H17*B17)) -> 0
A18: PI | B18: 0.07 | C18: =VLOOKUP(A18,[2]DIFAL!$C$13:$H$39,6,) -> 0.21 | H18: =PREÇOS!H19 -> 7.93 | I18: =IF(F18=0,,H18*(1+F18)*C18-(H18*B18)) -> 0 | J18: =IF(G18=0,IF(F18=0,,H18*(1+F18)*C18-(H18*B18)),H18*(1+G18)*C18-(H18*B18)) -> 0
A19: PR | B19: 0.12 | C19: 0.12 | H19: =PREÇOS!H20 -> 8.4 | I19: =IF(F19=0,,H19*(1+F19)*C19-(H19*B19)) -> 0 | J19: =IF(G19=0,IF(F19=0,,H19*(1+F19)*C19-(H19*B19)),H19*(1+G19)*C19-(H19*B19)) -> 0
A20: RJ | B20: 0.12 | C20: 0.22 | F20: 0.5253 | H20: =PREÇOS!H21 -> 8.4 | I20: =IF(F20=0,,H20*(1+F20)*C20-(H20*B20)) -> 1.8107544 | J20: =IF(G20=0,IF(F20=0,,H20*(1+F20)*C20-(H20*B20)),H20*(1+G20)*C20-(H20*B20)) -> 1.8107544
A21: RN | B21: 0.07 | C21: =VLOOKUP(A21,[2]DIFAL!$C$13:$H$39,6,) -> 0.2 | H21: =PREÇOS!H22 -> 7.93 | I21: =IF(F21=0,,H21*(1+F21)*C21-(H21*B21)) -> 0 | J21: =IF(G21=0,IF(F21=0,,H21*(1+F21)*C21-(H21*B21)),H21*(1+G21)*C21-(H21*B21)) -> 0
A22: RO | B22: 0.07 | C22: =VLOOKUP(A22,[2]DIFAL!$C$13:$H$39,5,) -> 0.175 | H22: =PREÇOS!H23 -> 7.93 | I22: =IF(F22=0,,H22*(1+F22)*C22-(H22*B22)) -> 0 | J22: =IF(G22=0,IF(F22=0,,H22*(1+F22)*C22-(H22*B22)),H22*(1+G22)*C22-(H22*B22)) -> 0
A23: RR | B23: 0.07 | C23: =VLOOKUP(A23,[2]DIFAL!$C$13:$H$39,6,) -> 0.2 | H23: =PREÇOS!H24 -> 7.93 | I23: =IF(F23=0,,H23*(1+F23)*C23-(H23*B23)) -> 0 | J23: =IF(G23=0,IF(F23=0,,H23*(1+F23)*C23-(H23*B23)),H23*(1+G23)*C23-(H23*B23)) -> 0
A24: RS | B24: 0.12 | C24: =VLOOKUP(A24,[2]DIFAL!$C$13:$H$39,5,) -> 0.17 | H24: =PREÇOS!H25 -> 8.4 | I24: =IF(F24=0,,H24*(1+F24)*C24-(H24*B24)) -> 0 | J24: =IF(G24=0,IF(F24=0,,H24*(1+F24)*C24-(H24*B24)),H24*(1+G24)*C24-(H24*B24)) -> 0
A25: SC | B25: 0.12 | C25: =VLOOKUP(A25,[2]DIFAL!$C$13:$H$39,5,) -> 0.17 | H25: =PREÇOS!H26 -> 8.4 | I25: =IF(F25=0,,H25*(1+F25)*C25-(H25*B25)) -> 0 | J25: =IF(G25=0,IF(F25=0,,H25*(1+F25)*C25-(H25*B25)),H25*(1+G25)*C25-(H25*B25)) -> 0
A26: SE | B26: 0.07 | C26: 0.2 | H26: =PREÇOS!H27 -> 7.93 | I26: =IF(F26=0,,H26*(1+F26)*C26-(H26*B26)) -> 0 | J26: =IF(G26=0,IF(F26=0,,H26*(1+F26)*C26-(H26*B26)),H26*(1+G26)*C26-(H26*B26)) -> 0
A27: SP | B27: 0.12 | C27: =VLOOKUP(A27,[2]DIFAL!$C$13:$H$39,5,) -> 0.18 | D27: 0.5917 | F27: 0.5917 | H27: =PREÇOS!H28 -> 8.4 | I27: =IF(F27=0,,H27*(1+F27)*C27-(H27*B27)) -> 1.3986504 | J27: =IF(G27=0,IF(F27=0,,H27*(1+F27)*C27-(H27*B27)),H27*(1+G27)*C27-(H27*B27)) -> 1.3986504
A28: SP/Atacado | B28: =B27 -> 0.12 | C28: =C27 -> 0.18 | D28: 0.4832 | E28: =E27 -> 0 | F28: 0.4832 | G28: =G27 -> 0 | H28: =PREÇOS!H29 -> 8.4 | I28: =IF(F28=0,,H28*(1+F28)*C28-(H28*B28)) -> 1.2345984 | J28: =IF(G28=0,IF(F28=0,,H28*(1+F28)*C28-(H28*B28)),H28*(1+G28)*C28-(H28*B28)) -> 1.2345984
A29: TO | B29: 0.07 | C29: =VLOOKUP(A29,[2]DIFAL!$C$13:$H$39,6,) -> 0.2 | H29: =PREÇOS!H30 -> 7.93 | I29: =IF(F29=0,,H29*(1+F29)*C29-(H29*B29)) -> 0 | J29: =IF(G29=0,IF(F29=0,,H29*(1+F29)*C29-(H29*B29)),H29*(1+G29)*C29-(H29*B29)) -> 0
A30: EX

Sheet ST CEREAL
A1: Estado | B1: Aliquota interestadual | C1: Aliquota interna | D1: MVA (normal) | E1: MVA (simples) | F1: Ajustada (normal) | G1: Ajustada (simples) | H1: Preço | I1: ST Normal | J1: ST Simples
A2: AC | B2: =VLOOKUP(A2,[2]DIFAL!$C$13:$E$39,3,0) -> 0.07 | C2: 0.17 | H2: =PREÇOS!G3 -> 7.85 | I2: =IF(F2=0,,H2*(1+F2)*C2-(H2*B2)) -> 0 | J2: =IF(G2=0,IF(F2=0,,H2*(1+F2)*C2-(H2*B2)),H2*(1+G2)*C2-(H2*B2)) -> 0
A3: AL | B3: =VLOOKUP(A3,[2]DIFAL!$C$13:$E$39,3,0) -> 0.07 | C3: 0.2 | F3: 0.71 | H3: =PREÇOS!G4 -> 7.85 | I3: =IF(F3=0,,H3*(1+F3)*C3-(H3*B3)) -> 2.1352 | J3: =IF(G3=0,IF(F3=0,,H3*(1+F3)*C3-(H3*B3)),H3*(1+G3)*C3-(H3*B3)) -> 2.1352
A4: AM | B4: =VLOOKUP(A4,[2]DIFAL!$C$13:$E$39,3,0) -> 0.07 | C4: 0.2 | F4: 0.5538 | H4: =PREÇOS!G5 -> 7.85 | I4: =IF(F4=0,,H4*(1+F4)*C4-(H4*B4)) -> 1.889966 | J4: =IF(G4=0,IF(F4=0,,H4*(1+F4)*C4-(H4*B4)),H4*(1+G4)*C4-(H4*B4)) -> 1.889966
A5: AP | B5: =VLOOKUP(A5,[2]DIFAL!$C$13:$E$39,3,0) -> 0.07 | C5: 0.18 | H5: =PREÇOS!G6 -> 7.85 | I5: =IF(F5=0,,H5*(1+F5)*C5-(H5*B5)) -> 0 | J5: =IF(G5=0,IF(F5=0,,H5*(1+F5)*C5-(H5*B5)),H5*(1+G5)*C5-(H5*B5)) -> 0
A6: BA | B6: =VLOOKUP(A6,[2]DIFAL!$C$13:$E$39,3,0) -> 0.07 | C6: 0.19 | H6: =PREÇOS!G7 -> 7.85 | I6: =IF(F6=0,,H6*(1+F6)*C6-(H6*B6)) -> 0 | J6: =IF(G6=0,IF(F6=0,,H6*(1+F6)*C6-(H6*B6)),H6*(1+G6)*C6-(H6*B6)) -> 0
A7: CE | B7: =VLOOKUP(A7,[2]DIFAL!$C$13:$E$39,3,0) -> 0.07 | C7: 0.2 | H7: =PREÇOS!G8 -> 7.85 | I7: =IF(F7=0,,H7*(1+F7)*C7-(H7*B7)) -> 0 | J7: =IF(G7=0,IF(F7=0,,H7*(1+F7)*C7-(H7*B7)),H7*(1+G7)*C7-(H7*B7)) -> 0
A8: DF | B8: =VLOOKUP(A8,[2]DIFAL!$C$13:$E$39,3,0) -> 0.07 | C8: 0.18 | H8: =PREÇOS!G9 -> 7.85 | I8: =IF(F8=0,,H8*(1+F8)*C8-(H8*B8)) -> 0 | J8: =IF(G8=0,IF(F8=0,,H8*(1+F8)*C8-(H8*B8)),H8*(1+G8)*C8-(H8*B8)) -> 0
A9: ES | B9: =VLOOKUP(A9,[2]DIFAL!$C$13:$E$39,3,0) -> 0.07 | C9: 0.17 | H9: =PREÇOS!G10 -> 7.85 | I9: =IF(F9=0,,H9*(1+F9)*C9-(H9*B9)) -> 0 | J9: =IF(G9=0,IF(F9=0,,H9*(1+F9)*C9-(H9*B9)),H9*(1+G9)*C9-(H9*B9)) -> 0
A10: GO | B10: =VLOOKUP(A10,[2]DIFAL!$C$13:$E$39,3,0) -> 0.07 | C10: 0.17 | H10: =PREÇOS!G11 -> 7.85 | I10: =IF(F10=0,,H10*(1+F10)*C10-(H10*B10)) -> 0 | J10: =IF(G10=0,IF(F10=0,,H10*(1+F10)*C10-(H10*B10)),H10*(1+G10)*C10-(H10*B10)) -> 0
A11: MA | B11: =VLOOKUP(A11,[2]DIFAL!$C$13:$E$39,3,0) -> 0.07 | C11: 0.2 | H11: =PREÇOS!G12 -> 7.85 | I11: =IF(F11=0,,H11*(1+F11)*C11-(H11*B11)) -> 0 | J11: =IF(G11=0,IF(F11=0,,H11*(1+F11)*C11-(H11*B11)),H11*(1+G11)*C11-(H11*B11)) -> 0
A12: MG | B12: =VLOOKUP(A12,[2]DIFAL!$C$13:$E$39,3,0) -> 0.12 | C12: 0.18 | F12: 0.4488 | H12: =PREÇOS!G13 -> 8.3 | I12: =IF(F12=0,,H12*(1+F12)*C12-(H12*B12)) -> 1.1685072 | J12: =IF(G12=0,IF(F12=0,,H12*(1+F12)*C12-(H12*B12)),H12*(1+G12)*C12-(H12*B12)) -> 1.1685072
A13: MS | B13: =VLOOKUP(A13,[2]DIFAL!$C$13:$E$39,3,0) -> 0.07 | C13: 0.17 | H13: =PREÇOS!G14 -> 7.85 | I13: =IF(F13=0,,H13*(1+F13)*C13-(H13*B13)) -> 0 | J13: =IF(G13=0,IF(F13=0,,H13*(1+F13)*C13-(H13*B13)),H13*(1+G13)*C13-(H13*B13)) -> 0
A14: MT | B14: =VLOOKUP(A14,[2]DIFAL!$C$13:$E$39,3,0) -> 0.07 | C14: 0.17 | F14: 0.4552 | H14: =PREÇOS!G15 -> 7.85 | I14: =IF(F14=0,,H14*(1+F14)*C14-(H14*B14)) -> 1.3924644 | J14: =IF(G14=0,IF(F14=0,,H14*(1+F14)*C14-(H14*B14)),H14*(1+G14)*C14-(H14*B14)) -> 1.3924644
A15: PA | B15: =VLOOKUP(A15,[2]DIFAL!$C$13:$E$39,3,0) -> 0.07 | C15: 0.19 | H15: =PREÇOS!G16 -> 7.85 | I15: =IF(F15=0,,H15*(1+F15)*C15-(H15*B15)) -> 0 | J15: =IF(G15=0,IF(F15=0,,H15*(1+F15)*C15-(H15*B15)),H15*(1+G15)*C15-(H15*B15)) -> 0
A16: PB | B16: =VLOOKUP(A16,[2]DIFAL!$C$13:$E$39,3,0) -> 0.07 | C16: 0.18 | H16: =PREÇOS!G17 -> 7.85 | I16: =IF(F16=0,,H16*(1+F16)*C16-(H16*B16)) -> 0 | J16: =IF(G16=0,IF(F16=0,,H16*(1+F16)*C16-(H16*B16)),H16*(1+G16)*C16-(H16*B16)) -> 0
A17: PE | B17: =VLOOKUP(A17,[2]DIFAL!$C$13:$E$39,3,0) -> 0.07 | C17: 0.18 | H17: =PREÇOS!G18 -> 7.85 | I17: =IF(F17=0,,H17*(1+F17)*C17-(H17*B17)) -> 0 | J17: =IF(G17=0,IF(F17=0,,H17*(1+F17)*C17-(H17*B17)),H17*(1+G17)*C17-(H17*B17)) -> 0
A18: PI | B18: =VLOOKUP(A18,[2]DIFAL!$C$13:$E$39,3,0) -> 0.07 | C18: 0.21 | H18: =PREÇOS!G19 -> 7.85 | I18: =IF(F18=0,,H18*(1+F18)*C18-(H18*B18)) -> 0 | J18: =IF(G18=0,IF(F18=0,,H18*(1+F18)*C18-(H18*B18)),H18*(1+G18)*C18-(H18*B18)) -> 0
A19: PR | B19: 0.12 | C19: 0.195 | F19: 0.608 | H19: =PREÇOS!G20 -> 8.3 | I19: =IF(F19=0,,H19*(1+F19)*C19-(H19*B19)) -> 1.606548 | J19: =IF(G19=0,IF(F19=0,,H19*(1+F19)*C19-(H19*B19)),H19*(1+G19)*C19-(H19*B19)) -> 1.606548
A20: RJ | B20: =VLOOKUP(A20,[2]DIFAL!$C$13:$E$39,3,0) -> 0.12 | C20: 0.22 | F20: 0.5473 | H20: =PREÇOS!G21 -> 8.3 | I20: =IF(F20=0,,H20*(1+F20)*C20-(H20*B20)) -> 1.8293698 | J20: =IF(G20=0,IF(F20=0,,H20*(1+F20)*C20-(H20*B20)),H20*(1+G20)*C20-(H20*B20)) -> 1.8293698
A21: RN | B21: =VLOOKUP(A21,[2]DIFAL!$C$13:$E$39,3,0) -> 0.07 | C21: 0.2 | H21: =PREÇOS!G22 -> 7.85 | I21: =IF(F21=0,,H21*(1+F21)*C21-(H21*B21)) -> 0 | J21: =IF(G21=0,IF(F21=0,,H21*(1+F21)*C21-(H21*B21)),H21*(1+G21)*C21-(H21*B21)) -> 0
A22: RO | B22: =VLOOKUP(A22,[2]DIFAL!$C$13:$E$39,3,0) -> 0.07 | C22: 0.175 | H22: =PREÇOS!G23 -> 7.85 | I22: =IF(F22=0,,H22*(1+F22)*C22-(H22*B22)) -> 0 | J22: =IF(G22=0,IF(F22=0,,H22*(1+F22)*C22-(H22*B22)),H22*(1+G22)*C22-(H22*B22)) -> 0
A23: RR | B23: =VLOOKUP(A23,[2]DIFAL!$C$13:$E$39,3,0) -> 0.07 | C23: 0.2 | H23: =PREÇOS!G24 -> 7.85 | I23: =IF(F23=0,,H23*(1+F23)*C23-(H23*B23)) -> 0 | J23: =IF(G23=0,IF(F23=0,,H23*(1+F23)*C23-(H23*B23)),H23*(1+G23)*C23-(H23*B23)) -> 0
A24: RS | B24: =VLOOKUP(A24,[2]DIFAL!$C$13:$E$39,3,0) -> 0.12 | C24: 0.17 | H24: =PREÇOS!G25 -> 8.3 | I24: =IF(F24=0,,H24*(1+F24)*C24-(H24*B24)) -> 0 | J24: =IF(G24=0,IF(F24=0,,H24*(1+F24)*C24-(H24*B24)),H24*(1+G24)*C24-(H24*B24)) -> 0
A25: SC | B25: =VLOOKUP(A25,[2]DIFAL!$C$13:$E$39,3,0) -> 0.12 | C25: 0.17 | H25: =PREÇOS!G26 -> 8.3 | I25: =IF(F25=0,,H25*(1+F25)*C25-(H25*B25)) -> 0 | J25: =IF(G25=0,IF(F25=0,,H25*(1+F25)*C25-(H25*B25)),H25*(1+G25)*C25-(H25*B25)) -> 0
A26: SE | B26: =VLOOKUP(A26,[2]DIFAL!$C$13:$E$39,3,0) -> 0.07 | C26: 0.2 | H26: =PREÇOS!G27 -> 7.85 | I26: =IF(F26=0,,H26*(1+F26)*C26-(H26*B26)) -> 0 | J26: =IF(G26=0,IF(F26=0,,H26*(1+F26)*C26-(H26*B26)),H26*(1+G26)*C26-(H26*B26)) -> 0
A27: SP | B27: =VLOOKUP(A27,[2]DIFAL!$C$13:$E$39,3,0) -> 0.12 | C27: 0.18 | F27: 0.463 | H27: =PREÇOS!G28 -> 8.3 | I27: =IF(F27=0,,H27*(1+F27)*C27-(H27*B27)) -> 1.189722 | J27: =IF(G27=0,IF(F27=0,,H27*(1+F27)*C27-(H27*B27)),H27*(1+G27)*C27-(H27*B27)) -> 1.189722
A28: SP/Atacado | B28: =B27 -> 0.12 | C28: =C27 -> 0.18 | D28: =D27 -> 0 | E28: =E27 -> 0 | F28: =F27 -> 0.463 | G28: =G27 -> 0 | H28: =PREÇOS!G29 -> 8.3 | I28: =IF(F28=0,,H28*(1+F28)*C28-(H28*B28)) -> 1.189722 | J28: =IF(G28=0,IF(F28=0,,H28*(1+F28)*C28-(H28*B28)),H28*(1+G28)*C28-(H28*B28)) -> 1.189722
A29: TO | B29: =VLOOKUP(A29,[2]DIFAL!$C$13:$E$39,3,0) -> 0.07 | C29: 0.2 | H29: =PREÇOS!G30 -> 7.85 | I29: =IF(F29=0,,H29*(1+F29)*C29-(H29*B29)) -> 0 | J29: =IF(G29=0,IF(F29=0,,H29*(1+F29)*C29-(H29*B29)),H29*(1+G29)*C29-(H29*B29)) -> 0
A30: EX | H30: =PREÇOS!G31 -> 0 | I30: =IF(F30=0,,H30*(1+F30)*C30-(H30*B30)) -> 0 | J30: =IF(G30=0,IF(F30=0,,H30*(1+F30)*C30-(H30*B30)),H30*(1+G30)*C30-(H30*B30)) -> 0

Sheet ST CEREAL SABOR POUCH 170
A1: Estado | B1: Aliquota interestadual | C1: Aliquota interna | D1: MVA (normal) | E1: MVA (simples) | F1: Ajustada (normal) | G1: Ajustada (simples) | H1: Preço | I1: ST Normal | J1: ST Simples
A2: AC | B2: =VLOOKUP(A2,[2]DIFAL!$C$13:$E$39,3,0) -> 0.07 | C2: 0.17 | H2: =PREÇOS!J3 -> 6.35 | I2: =IF(F2=0,,H2*(1+F2)*C2-(H2*B2)) -> 0 | J2: =IF(G2=0,IF(F2=0,,H2*(1+F2)*C2-(H2*B2)),H2*(1+G2)*C2-(H2*B2)) -> 0
A3: AL | B3: =VLOOKUP(A3,[2]DIFAL!$C$13:$E$39,3,0) -> 0.07 | C3: 0.2 | F3: 0.71 | H3: =PREÇOS!J4 -> 6.35 | I3: =IF(F3=0,,H3*(1+F3)*C3-(H3*B3)) -> 1.7272 | J3: =IF(G3=0,IF(F3=0,,H3*(1+F3)*C3-(H3*B3)),H3*(1+G3)*C3-(H3*B3)) -> 1.7272
A4: AM | B4: =VLOOKUP(A4,[2]DIFAL!$C$13:$E$39,3,0) -> 0.07 | C4: 0.2 | F4: 0.5538 | H4: =PREÇOS!J5 -> 6.35 | I4: =IF(F4=0,,H4*(1+F4)*C4-(H4*B4)) -> 1.528826 | J4: =IF(G4=0,IF(F4=0,,H4*(1+F4)*C4-(H4*B4)),H4*(1+G4)*C4-(H4*B4)) -> 1.528826
A5: AP | B5: =VLOOKUP(A5,[2]DIFAL!$C$13:$E$39,3,0) -> 0.07 | C5: 0.18 | H5: =PREÇOS!J6 -> 6.35 | I5: =IF(F5=0,,H5*(1+F5)*C5-(H5*B5)) -> 0 | J5: =IF(G5=0,IF(F5=0,,H5*(1+F5)*C5-(H5*B5)),H5*(1+G5)*C5-(H5*B5)) -> 0
A6: BA | B6: =VLOOKUP(A6,[2]DIFAL!$C$13:$E$39,3,0) -> 0.07 | C6: 0.19 | H6: =PREÇOS!J7 -> 6.35 | I6: =IF(F6=0,,H6*(1+F6)*C6-(H6*B6)) -> 0 | J6: =IF(G6=0,IF(F6=0,,H6*(1+F6)*C6-(H6*B6)),H6*(1+G6)*C6-(H6*B6)) -> 0
A7: CE | B7: =VLOOKUP(A7,[2]DIFAL!$C$13:$E$39,3,0) -> 0.07 | C7: 0.2 | H7: =PREÇOS!J8 -> 6.35 | I7: =IF(F7=0,,H7*(1+F7)*C7-(H7*B7)) -> 0 | J7: =IF(G7=0,IF(F7=0,,H7*(1+F7)*C7-(H7*B7)),H7*(1+G7)*C7-(H7*B7)) -> 0
A8: DF | B8: =VLOOKUP(A8,[2]DIFAL!$C$13:$E$39,3,0) -> 0.07 | C8: 0.18 | H8: =PREÇOS!J9 -> 6.35 | I8: =IF(F8=0,,H8*(1+F8)*C8-(H8*B8)) -> 0 | J8: =IF(G8=0,IF(F8=0,,H8*(1+F8)*C8-(H8*B8)),H8*(1+G8)*C8-(H8*B8)) -> 0
A9: ES | B9: =VLOOKUP(A9,[2]DIFAL!$C$13:$E$39,3,0) -> 0.07 | C9: 0.17 | H9: =PREÇOS!J10 -> 5.82 | I9: =IF(F9=0,,H9*(1+F9)*C9-(H9*B9)) -> 0 | J9: =IF(G9=0,IF(F9=0,,H9*(1+F9)*C9-(H9*B9)),H9*(1+G9)*C9-(H9*B9)) -> 0
A10: GO | B10: =VLOOKUP(A10,[2]DIFAL!$C$13:$E$39,3,0) -> 0.07 | C10: 0.17 | H10: =PREÇOS!J11 -> 6.35 | I10: =IF(F10=0,,H10*(1+F10)*C10-(H10*B10)) -> 0 | J10: =IF(G10=0,IF(F10=0,,H10*(1+F10)*C10-(H10*B10)),H10*(1+G10)*C10-(H10*B10)) -> 0
A11: MA | B11: =VLOOKUP(A11,[2]DIFAL!$C$13:$E$39,3,0) -> 0.07 | C11: 0.2 | H11: =PREÇOS!J12 -> 6.35 | I11: =IF(F11=0,,H11*(1+F11)*C11-(H11*B11)) -> 0 | J11: =IF(G11=0,IF(F11=0,,H11*(1+F11)*C11-(H11*B11)),H11*(1+G11)*C11-(H11*B11)) -> 0
A12: MG | B12: =VLOOKUP(A12,[2]DIFAL!$C$13:$E$39,3,0) -> 0.12 | C12: 0.18 | F12: 0.4488 | H12: =PREÇOS!J13 -> 6.15 | I12: =IF(F12=0,,H12*(1+F12)*C12-(H12*B12)) -> 0.8658216 | J12: =IF(G12=0,IF(F12=0,,H12*(1+F12)*C12-(H12*B12)),H12*(1+G12)*C12-(H12*B12)) -> 0.8658216
A13: MS | B13: =VLOOKUP(A13,[2]DIFAL!$C$13:$E$39,3,0) -> 0.07 | C13: 0.17 | H13: =PREÇOS!J14 -> 6.35 | I13: =IF(F13=0,,H13*(1+F13)*C13-(H13*B13)) -> 0 | J13: =IF(G13=0,IF(F13=0,,H13*(1+F13)*C13-(H13*B13)),H13*(1+G13)*C13-(H13*B13)) -> 0
A14: MT | B14: =VLOOKUP(A14,[2]DIFAL!$C$13:$E$39,3,0) -> 0.07 | C14: 0.17 | F14: 0.4552 | H14: =PREÇOS!J15 -> 6.35 | I14: =IF(F14=0,,H14*(1+F14)*C14-(H14*B14)) -> 1.1263884 | J14: =IF(G14=0,IF(F14=0,,H14*(1+F14)*C14-(H14*B14)),H14*(1+G14)*C14-(H14*B14)) -> 1.1263884
A15: PA | B15: =VLOOKUP(A15,[2]DIFAL!$C$13:$E$39,3,0) -> 0.07 | C15: 0.19 | H15: =PREÇOS!J16 -> 6.35 | I15: =IF(F15=0,,H15*(1+F15)*C15-(H15*B15)) -> 0 | J15: =IF(G15=0,IF(F15=0,,H15*(1+F15)*C15-(H15*B15)),H15*(1+G15)*C15-(H15*B15)) -> 0
A16: PB | B16: =VLOOKUP(A16,[2]DIFAL!$C$13:$E$39,3,0) -> 0.07 | C16: 0.18 | H16: =PREÇOS!J17 -> 6.35 | I16: =IF(F16=0,,H16*(1+F16)*C16-(H16*B16)) -> 0 | J16: =IF(G16=0,IF(F16=0,,H16*(1+F16)*C16-(H16*B16)),H16*(1+G16)*C16-(H16*B16)) -> 0
A17: PE | B17: =VLOOKUP(A17,[2]DIFAL!$C$13:$E$39,3,0) -> 0.07 | C17: 0.18 | H17: =PREÇOS!J18 -> 6.35 | I17: =IF(F17=0,,H17*(1+F17)*C17-(H17*B17)) -> 0 | J17: =IF(G17=0,IF(F17=0,,H17*(1+F17)*C17-(H17*B17)),H17*(1+G17)*C17-(H17*B17)) -> 0
A18: PI | B18: =VLOOKUP(A18,[2]DIFAL!$C$13:$E$39,3,0) -> 0.07 | C18: 0.21 | H18: =PREÇOS!J19 -> 6.35 | I18: =IF(F18=0,,H18*(1+F18)*C18-(H18*B18)) -> 0 | J18: =IF(G18=0,IF(F18=0,,H18*(1+F18)*C18-(H18*B18)),H18*(1+G18)*C18-(H18*B18)) -> 0
A19: PR | B19: 0.12 | C19: 0.195 | F19: 0.608 | H19: =PREÇOS!J20 -> 6.15 | I19: =IF(F19=0,,H19*(1+F19)*C19-(H19*B19)) -> 1.190394 | J19: =IF(G19=0,IF(F19=0,,H19*(1+F19)*C19-(H19*B19)),H19*(1+G19)*C19-(H19*B19)) -> 1.190394
A20: RJ | B20: =VLOOKUP(A20,[2]DIFAL!$C$13:$E$39,3,0) -> 0.12 | C20: 0.22 | F20: 0.5473 | H20: =PREÇOS!J21 -> 6.15 | I20: =IF(F20=0,,H20*(1+F20)*C20-(H20*B20)) -> 1.3554969 | J20: =IF(G20=0,IF(F20=0,,H20*(1+F20)*C20-(H20*B20)),H20*(1+G20)*C20-(H20*B20)) -> 1.3554969
A21: RN | B21: =VLOOKUP(A21,[2]DIFAL!$C$13:$E$39,3,0) -> 0.07 | C21: 0.2 | H21: =PREÇOS!J22 -> 6.35 | I21: =IF(F21=0,,H21*(1+F21)*C21-(H21*B21)) -> 0 | J21: =IF(G21=0,IF(F21=0,,H21*(1+F21)*C21-(H21*B21)),H21*(1+G21)*C21-(H21*B21)) -> 0
A22: RO | B22: =VLOOKUP(A22,[2]DIFAL!$C$13:$E$39,3,0) -> 0.07 | C22: 0.175 | H22: =PREÇOS!J23 -> 6.35 | I22: =IF(F22=0,,H22*(1+F22)*C22-(H22*B22)) -> 0 | J22: =IF(G22=0,IF(F22=0,,H22*(1+F22)*C22-(H22*B22)),H22*(1+G22)*C22-(H22*B22)) -> 0
A23: RR | B23: =VLOOKUP(A23,[2]DIFAL!$C$13:$E$39,3,0) -> 0.07 | C23: 0.2 | H23: =PREÇOS!J24 -> 6.35 | I23: =IF(F23=0,,H23*(1+F23)*C23-(H23*B23)) -> 0 | J23: =IF(G23=0,IF(F23=0,,H23*(1+F23)*C23-(H23*B23)),H23*(1+G23)*C23-(H23*B23)) -> 0
A24: RS | B24: =VLOOKUP(A24,[2]DIFAL!$C$13:$E$39,3,0) -> 0.12 | C24: 0.17 | H24: =PREÇOS!J25 -> 6.15 | I24: =IF(F24=0,,H24*(1+F24)*C24-(H24*B24)) -> 0 | J24: =IF(G24=0,IF(F24=0,,H24*(1+F24)*C24-(H24*B24)),H24*(1+G24)*C24-(H24*B24)) -> 0
A25: SC | B25: =VLOOKUP(A25,[2]DIFAL!$C$13:$E$39,3,0) -> 0.12 | C25: 0.17 | H25: =PREÇOS!J26 -> 6.15 | I25: =IF(F25=0,,H25*(1+F25)*C25-(H25*B25)) -> 0 | J25: =IF(G25=0,IF(F25=0,,H25*(1+F25)*C25-(H25*B25)),H25*(1+G25)*C25-(H25*B25)) -> 0
A26: SE | B26: =VLOOKUP(A26,[2]DIFAL!$C$13:$E$39,3,0) -> 0.07 | C26: 0.2 | H26: =PREÇOS!J27 -> 6.35 | I26: =IF(F26=0,,H26*(1+F26)*C26-(H26*B26)) -> 0 | J26: =IF(G26=0,IF(F26=0,,H26*(1+F26)*C26-(H26*B26)),H26*(1+G26)*C26-(H26*B26)) -> 0
A27: SP | B27: =VLOOKUP(A27,[2]DIFAL!$C$13:$E$39,3,0) -> 0.12 | C27: 0.18 | F27: 0.463 | H27: =PREÇOS!J28 -> 6.15 | I27: =IF(F27=0,,H27*(1+F27)*C27-(H27*B27)) -> 0.881541 | J27: =IF(G27=0,IF(F27=0,,H27*(1+F27)*C27-(H27*B27)),H27*(1+G27)*C27-(H27*B27)) -> 0.881541
A28: SP/Atacado | B28: =B27 -> 0.12 | C28: =C27 -> 0.18 | D28: =D27 -> 0 | E28: =E27 -> 0 | F28: =F27 -> 0.463 | G28: =G27 -> 0 | H28: =PREÇOS!J29 -> 6.15 | I28: =IF(F28=0,,H28*(1+F28)*C28-(H28*B28)) -> 0.881541 | J28: =IF(G28=0,IF(F28=0,,H28*(1+F28)*C28-(H28*B28)),H28*(1+G28)*C28-(H28*B28)) -> 0.881541
A29: TO | B29: =VLOOKUP(A29,[2]DIFAL!$C$13:$E$39,3,0) -> 0.07 | C29: 0.2 | H29: =PREÇOS!J30 -> 6.35 | I29: =IF(F29=0,,H29*(1+F29)*C29-(H29*B29)) -> 0 | J29: =IF(G29=0,IF(F29=0,,H29*(1+F29)*C29-(H29*B29)),H29*(1+G29)*C29-(H29*B29)) -> 0
A30: EX | H30: =PREÇOS!J31 -> 0 | I30: =IF(F30=0,,H30*(1+F30)*C30-(H30*B30)) -> 0 | J30: =IF(G30=0,IF(F30=0,,H30*(1+F30)*C30-(H30*B30)),H30*(1+G30)*C30-(H30*B30)) -> 0

Sheet ST MULTI 170 POUCH
A1: Estado | B1: Aliquota interestadual | C1: Aliquota interna | D1: MVA (normal) | E1: MVA (simples) | F1: Ajustada (normal) | G1: Ajustada (simples) | H1: Preço | I1: ST Normal | J1: ST Simples
A2: AC | B2: =VLOOKUP(A2,[2]DIFAL!$C$13:$E$39,3,0) -> 0.07 | C2: 0.17 | H2: =PREÇOS!K3 -> 5.25 | I2: =IF(F2=0,,H2*(1+F2)*C2-(H2*B2)) -> 0 | J2: =IF(G2=0,IF(F2=0,,H2*(1+F2)*C2-(H2*B2)),H2*(1+G2)*C2-(H2*B2)) -> 0
A3: AL | B3: =VLOOKUP(A3,[2]DIFAL!$C$13:$E$39,3,0) -> 0.07 | C3: 0.2 | F3: 0.71 | H3: =PREÇOS!K4 -> 5.25 | I3: =IF(F3=0,,H3*(1+F3)*C3-(H3*B3)) -> 1.428 | J3: =IF(G3=0,IF(F3=0,,H3*(1+F3)*C3-(H3*B3)),H3*(1+G3)*C3-(H3*B3)) -> 1.428
A4: AM | B4: =VLOOKUP(A4,[2]DIFAL!$C$13:$E$39,3,0) -> 0.07 | C4: 0.2 | F4: 0.5538 | H4: =PREÇOS!K5 -> 5.25 | I4: =IF(F4=0,,H4*(1+F4)*C4-(H4*B4)) -> 1.26399 | J4: =IF(G4=0,IF(F4=0,,H4*(1+F4)*C4-(H4*B4)),H4*(1+G4)*C4-(H4*B4)) -> 1.26399
A5: AP | B5: =VLOOKUP(A5,[2]DIFAL!$C$13:$E$39,3,0) -> 0.07 | C5: 0.18 | H5: =PREÇOS!K6 -> 5.25 | I5: =IF(F5=0,,H5*(1+F5)*C5-(H5*B5)) -> 0 | J5: =IF(G5=0,IF(F5=0,,H5*(1+F5)*C5-(H5*B5)),H5*(1+G5)*C5-(H5*B5)) -> 0
A6: BA | B6: =VLOOKUP(A6,[2]DIFAL!$C$13:$E$39,3,0) -> 0.07 | C6: 0.19 | H6: =PREÇOS!K7 -> 5.25 | I6: =IF(F6=0,,H6*(1+F6)*C6-(H6*B6)) -> 0 | J6: =IF(G6=0,IF(F6=0,,H6*(1+F6)*C6-(H6*B6)),H6*(1+G6)*C6-(H6*B6)) -> 0
A7: CE | B7: =VLOOKUP(A7,[2]DIFAL!$C$13:$E$39,3,0) -> 0.07 | C7: 0.2 | H7: =PREÇOS!K8 -> 5.25 | I7: =IF(F7=0,,H7*(1+F7)*C7-(H7*B7)) -> 0 | J7: =IF(G7=0,IF(F7=0,,H7*(1+F7)*C7-(H7*B7)),H7*(1+G7)*C7-(H7*B7)) -> 0
A8: DF | B8: =VLOOKUP(A8,[2]DIFAL!$C$13:$E$39,3,0) -> 0.07 | C8: 0.18 | H8: =PREÇOS!K9 -> 5.25 | I8: =IF(F8=0,,H8*(1+F8)*C8-(H8*B8)) -> 0 | J8: =IF(G8=0,IF(F8=0,,H8*(1+F8)*C8-(H8*B8)),H8*(1+G8)*C8-(H8*B8)) -> 0
A9: ES | B9: =VLOOKUP(A9,[2]DIFAL!$C$13:$E$39,3,0) -> 0.07 | C9: 0.17 | H9: =PREÇOS!K10 -> 5.82 | I9: =IF(F9=0,,H9*(1+F9)*C9-(H9*B9)) -> 0 | J9: =IF(G9=0,IF(F9=0,,H9*(1+F9)*C9-(H9*B9)),H9*(1+G9)*C9-(H9*B9)) -> 0
A10: GO | B10: =VLOOKUP(A10,[2]DIFAL!$C$13:$E$39,3,0) -> 0.07 | C10: 0.17 | H10: =PREÇOS!K11 -> 5.25 | I10: =IF(F10=0,,H10*(1+F10)*C10-(H10*B10)) -> 0 | J10: =IF(G10=0,IF(F10=0,,H10*(1+F10)*C10-(H10*B10)),H10*(1+G10)*C10-(H10*B10)) -> 0
A11: MA | B11: =VLOOKUP(A11,[2]DIFAL!$C$13:$E$39,3,0) -> 0.07 | C11: 0.2 | H11: =PREÇOS!K12 -> 5.25 | I11: =IF(F11=0,,H11*(1+F11)*C11-(H11*B11)) -> 0 | J11: =IF(G11=0,IF(F11=0,,H11*(1+F11)*C11-(H11*B11)),H11*(1+G11)*C11-(H11*B11)) -> 0
A12: MG | B12: =VLOOKUP(A12,[2]DIFAL!$C$13:$E$39,3,0) -> 0.12 | C12: 0.18 | F12: 0.4488 | H12: =PREÇOS!K13 -> 6.15 | I12: =IF(F12=0,,H12*(1+F12)*C12-(H12*B12)) -> 0.8658216 | J12: =IF(G12=0,IF(F12=0,,H12*(1+F12)*C12-(H12*B12)),H12*(1+G12)*C12-(H12*B12)) -> 0.8658216
A13: MS | B13: =VLOOKUP(A13,[2]DIFAL!$C$13:$E$39,3,0) -> 0.07 | C13: 0.17 | H13: =PREÇOS!K14 -> 5.25 | I13: =IF(F13=0,,H13*(1+F13)*C13-(H13*B13)) -> 0 | J13: =IF(G13=0,IF(F13=0,,H13*(1+F13)*C13-(H13*B13)),H13*(1+G13)*C13-(H13*B13)) -> 0
A14: MT | B14: =VLOOKUP(A14,[2]DIFAL!$C$13:$E$39,3,0) -> 0.07 | C14: 0.17 | F14: 0.4552 | H14: =PREÇOS!K15 -> 5.25 | I14: =IF(F14=0,,H14*(1+F14)*C14-(H14*B14)) -> 0.931266 | J14: =IF(G14=0,IF(F14=0,,H14*(1+F14)*C14-(H14*B14)),H14*(1+G14)*C14-(H14*B14)) -> 0.931266
A15: PA | B15: =VLOOKUP(A15,[2]DIFAL!$C$13:$E$39,3,0) -> 0.07 | C15: 0.19 | H15: =PREÇOS!K16 -> 5.25 | I15: =IF(F15=0,,H15*(1+F15)*C15-(H15*B15)) -> 0 | J15: =IF(G15=0,IF(F15=0,,H15*(1+F15)*C15-(H15*B15)),H15*(1+G15)*C15-(H15*B15)) -> 0
A16: PB | B16: =VLOOKUP(A16,[2]DIFAL!$C$13:$E$39,3,0) -> 0.07 | C16: 0.18 | H16: =PREÇOS!K17 -> 5.25 | I16: =IF(F16=0,,H16*(1+F16)*C16-(H16*B16)) -> 0 | J16: =IF(G16=0,IF(F16=0,,H16*(1+F16)*C16-(H16*B16)),H16*(1+G16)*C16-(H16*B16)) -> 0
A17: PE | B17: =VLOOKUP(A17,[2]DIFAL!$C$13:$E$39,3,0) -> 0.07 | C17: 0.18 | H17: =PREÇOS!K18 -> 5.25 | I17: =IF(F17=0,,H17*(1+F17)*C17-(H17*B17)) -> 0 | J17: =IF(G17=0,IF(F17=0,,H17*(1+F17)*C17-(H17*B17)),H17*(1+G17)*C17-(H17*B17)) -> 0
A18: PI | B18: =VLOOKUP(A18,[2]DIFAL!$C$13:$E$39,3,0) -> 0.07 | C18: 0.21 | H18: =PREÇOS!K19 -> 5.25 | I18: =IF(F18=0,,H18*(1+F18)*C18-(H18*B18)) -> 0 | J18: =IF(G18=0,IF(F18=0,,H18*(1+F18)*C18-(H18*B18)),H18*(1+G18)*C18-(H18*B18)) -> 0
A19: PR | B19: 0.12 | C19: 0.195 | F19: 0.608 | H19: =PREÇOS!K20 -> 6.15 | I19: =IF(F19=0,,H19*(1+F19)*C19-(H19*B19)) -> 1.190394 | J19: =IF(G19=0,IF(F19=0,,H19*(1+F19)*C19-(H19*B19)),H19*(1+G19)*C19-(H19*B19)) -> 1.190394
