Workbook
Name ListaUF: PREÇOS!$A$3:$A$29

Sheet Tabelas
C1: BABY ROO COMERCIO DE ALIMENTOS EIRELI
C2: CNPJ: 34.282.307.0001-44
C3: INSC. ESTADUAL: 90821939-25
C4: ENDEREÇO: Rua Grã Nicco, 113 - sala 501, bloco 2 - Mossunguê, Curitiba - PR, 81200-200
L6: UF | M6: RS
B8: 0626E
B9: Descrição | D9: Código | E9: TOTAL Caixas | F9: TOTAL Itens | G9: Crédito ICMS (%) | H9: Valor Unit. | I9: Valor Caixa | J9: SUBSTITUIÇÃO TRIBUTÁRIA UN | K9: IPI | L9: Valor Caixa + ST | M9: Valor TOTAL | N9: Valor TOTAL + ST (*) | O9: Preço Sugerido
B10: Papinha Papapa Carne Arroz Legumes 120g | D10: 5313 | F10: =E10*12 -> 0 | G10: =VLOOKUP($M$6,'ST BISCOITINHOS'!A:B,2,FALSE) -> 0.04 | H10: =VLOOKUP($M$6,PREÇOS!$A$2:$L$31,9,FALSE) -> 8.9 | I10: =H10*12 -> 106.8 | J10: 0 | K10: 0 | L10: =(H10+J10+K10)*12 -> 106.8 | M10: =E10*I10 -> 0 | N10: =E10*L10 -> 0 | O10: =VLOOKUP($M$6,PSC!$A$2:$L$31,9,FALSE) -> 13.49
B11: Papinha Papapa Frango Grão Vegetais 120g | D11: 5320 | F11: =E11*12 -> 0 | G11: =VLOOKUP($M$6,'ST BISCOITINHOS'!A:B,2,FALSE) -> 0.04 | H11: =VLOOKUP($M$6,PREÇOS!$A$2:$L$31,9,FALSE) -> 8.9 | I11: =H11*12 -> 106.8 | J11: 0 | K11: 0 | L11: =(H11+J11+K11)*12 -> 106.8 | M11: =E11*I11 -> 0 | N11: =E11*L11 -> 0 | O11: =VLOOKUP($M$6,PSC!$A$2:$L$31,9,FALSE) -> 13.49
B13: Papinha Papapa Iogurte Frutas Amarelas e Banana 100g | D13: 5566 | F13: =E13*16 -> 0 | G13: =VLOOKUP($M$6,'ST BISCOITINHOS'!A:B,2,FALSE) -> 0.04 | H13: =VLOOKUP($M$6,PREÇOS!$A$2:$M$31,13,FALSE) -> 6.24 | I13: =H13*16 -> 99.84 | J13: 0 | K13: 0 | L13: =(H13+J13+K13)*16 -> 99.84 | M13: =E13*I13 -> 0 | N13: =E13*L13 -> 0 | O13: =VLOOKUP($M$6,PSC!$A$2:$M$31,13,FALSE) -> 9.49
B14: Papinha Papapa Iogurte Frutas Vermelhas e Banana 100g | D14: 5573 | F14: =E14*16 -> 0 | G14: =VLOOKUP($M$6,'ST BISCOITINHOS'!A:B,2,FALSE) -> 0.04 | H14: =VLOOKUP($M$6,PREÇOS!$A$2:$M$31,13,FALSE) -> 6.24 | I14: =H14*16 -> 99.84 | J14: 0 | K14: 0 | L14: =(H14+J14+K14)*16 -> 99.84 | M14: =E14*I14 -> 0 | N14: =E14*L14 -> 0 | O14: =VLOOKUP($M$6,PSC!$A$2:$M$31,13,FALSE) -> 9.49
B16: Papinha Papapá Org Maçã Ameixa 100g | D16: 17898994908729 | F16: =E16*12 -> 0 | G16: =VLOOKUP($M$6,'ST BISCOITINHOS'!A:B,2,FALSE) -> 0.04 | H16: =VLOOKUP($M$6,PREÇOS!$A$2:$L$31,2,FALSE) -> 6.24 | I16: =H16*12 -> 74.88 | J16: 0 | K16: 0 | L16: =(H16+J16+K16)*12 -> 74.88 | M16: =E16*I16 -> 0 | N16: =E16*L16 -> 0 | O16: =VLOOKUP($M$6,PSC!$A$2:$L$31,2,FALSE) -> 9.49
B17: Papinha Papapá Org Banana Mirtilo Quinoa 100g | D17: 17898994908736 | F17: =E17*12 -> 0 | G17: =VLOOKUP($M$6,'ST BISCOITINHOS'!A:B,2,FALSE) -> 0.04 | H17: =VLOOKUP($M$6,PREÇOS!$A$2:$L$31,2,FALSE) -> 6.24 | I17: =H17*12 -> 74.88 | J17: 0 | K17: 0 | L17: =(H17+J17+K17)*12 -> 74.88 | M17: =E17*I17 -> 0 | N17: =E17*L17 -> 0 | O17: =VLOOKUP($M$6,PSC!$A$2:$L$31,2,FALSE) -> 9.49
B18: Papinha Papapá Org Manga 100g | D18: 17898994908712 | F18: =E18*12 -> 0 | G18: =VLOOKUP($M$6,'ST BISCOITINHOS'!A:B,2,FALSE) -> 0.04 | H18: =VLOOKUP($M$6,PREÇOS!$A$2:$L$31,2,FALSE) -> 6.24 | I18: =H18*12 -> 74.88 | J18: 0 | K18: 0 | L18: =(H18+J18+K18)*12 -> 74.88 | M18: =E18*I18 -> 0 | N18: =E18*L18 -> 0 | O18: =VLOOKUP($M$6,PSC!$A$2:$L$31,2,FALSE) -> 9.49
B19: Papinha Papapá Org Pera Espinafre Abobrinha 100g | D19: 17898994908750 | F19: =E19*12 -> 0 | G19: =VLOOKUP($M$6,'ST BISCOITINHOS'!A:B,2,FALSE) -> 0.04 | H19: =VLOOKUP($M$6,PREÇOS!$A$2:$L$31,2,FALSE) -> 6.24 | I19: =H19*12 -> 74.88 | J19: 0 | K19: 0 | L19: =(H19+J19+K19)*12 -> 74.88 | M19: =E19*I19 -> 0 | N19: =E19*L19 -> 0 | O19: =VLOOKUP($M$6,PSC!$A$2:$L$31,2,FALSE) -> 9.49
B20: Papinha Papapá Org Maçã B. Doce Cenoura 100g | D20: 27898994908757 | F20: =E20*12 -> 0 | G20: =VLOOKUP($M$6,'ST BISCOITINHOS'!A:B,2,FALSE) -> 0.04 | H20: =VLOOKUP($M$6,PREÇOS!$A$2:$L$31,2,FALSE) -> 6.24 | I20: =H20*12 -> 74.88 | J20: 0 | K20: 0 | L20: =(H20+J20+K20)*12 -> 74.88 | M20: =E20*I20 -> 0 | N20: =E20*L20 -> 0 | O20: =VLOOKUP($M$6,PSC!$A$2:$L$31,2,FALSE) -> 9.49
B21: Papinha Papapá Org Morango Maçã 100g | D21: 5306 | F21: =E21*12 -> 0 | G21: =VLOOKUP($M$6,'ST BISCOITINHOS'!A:B,2,FALSE) -> 0.04 | H21: =VLOOKUP($M$6,PREÇOS!$A$2:$L$31,2,FALSE) -> 6.24 | I21: =H21*12 -> 74.88 | J21: 0 | K21: 0 | L21: =(H21+J21+K21)*12 -> 74.88 | M21: =E21*I21 -> 0 | N21: =E21*L21 -> 0 | O21: =VLOOKUP($M$6,PSC!$A$2:$L$31,2,FALSE) -> 9.49
B23: Biscoito inf Papapá org. Beterraba 20g | D23: 5085 | F23: =E23*16 -> 0 | G23: =VLOOKUP($M$6,'ST PALITINHOS'!A:B,2,FALSE) -> 0.12 | H23: =VLOOKUP($M$6,PREÇOS!$A$2:$L$31,3,FALSE) -> 3.9312 | I23: =H23*16 -> 62.8992 | J23: =IF($G$7="SIM",VLOOKUP($M$6,'ST PALITINHOS'!$A$1:$J$31,10,FALSE),VLOOKUP($M$6,'ST PALITINHOS'!$A$1:$J$31,9,FALSE)) -> 0 | K23: 0 | L23: =(H23+J23+K23)*16 -> 62.8992 | M23: =E23*I23 -> 0 | N23: =E23*L23 -> 0 | O23: =VLOOKUP($M$6,PSC!$A$2:$L$31,3,FALSE) -> 5.99
B24: Biscoito inf Papapá org. Cenoura 20g | D24: 5078 | F24: =E24*16 -> 0 | G24: =VLOOKUP($M$6,'ST PALITINHOS'!A:B,2,FALSE) -> 0.12 | H24: =VLOOKUP($M$6,PREÇOS!$A$2:$L$31,3,FALSE) -> 3.9312 | I24: =H24*16 -> 62.8992 | J24: =IF($G$7="SIM",VLOOKUP($M$6,'ST PALITINHOS'!$A$1:$J$31,10,FALSE),VLOOKUP($M$6,'ST PALITINHOS'!$A$1:$J$31,9,FALSE)) -> 0 | K24: 0 | L24: =(H24+J24+K24)*16 -> 62.8992 | M24: =E24*I24 -> 0 | N24: =E24*L24 -> 0 | O24: =VLOOKUP($M$6,PSC!$A$2:$L$31,3,FALSE) -> 5.99
B25: Biscoito inf Papapá org. Tomate/Manjericão 20g | D25: 5061 | F25: =E25*16 -> 0 | G25: =VLOOKUP($M$6,'ST PALITINHOS'!A:B,2,FALSE) -> 0.12 | H25: =VLOOKUP($M$6,PREÇOS!$A$2:$L$31,3,FALSE) -> 3.9312 | I25: =H25*16 -> 62.8992 | J25: =IF($G$7="SIM",VLOOKUP($M$6,'ST PALITINHOS'!$A$1:$J$31,10,FALSE),VLOOKUP($M$6,'ST PALITINHOS'!$A$1:$J$31,9,FALSE)) -> 0 | K25: 0 | L25: =(H25+J25+K25)*16 -> 62.8992 | M25: =E25*I25 -> 0 | N25: =E25*L25 -> 0 | O25: =VLOOKUP($M$6,PSC!$A$2:$L$31,3,FALSE) -> 5.99
B27: Biscoito Inf Papapá dent. Maçã e Abóbora 36g | D27: 8774 | F27: =E27*12 -> 0 | G27: =VLOOKUP($M$6,'ST BISCOITINHOS'!A:B,2,FALSE) -> 0.04 | H27: =VLOOKUP($M$6,PREÇOS!$A$2:$L$31,4,FALSE) -> 13.3488 | I27: =H27*12 -> 160.1856 | J27: =IF($G$7="SIM",VLOOKUP($M$6,'ST BISCOITINHOS'!$A$1:$J$31,10,FALSE),VLOOKUP($M$6,'ST BISCOITINHOS'!$A$1:$J$31,9,FALSE)) -> 0 | K27: 0 | L27: =(H27+J27+K27)*12 -> 160.1856 | M27: =E27*I27 -> 0 | N27: =E27*L27 -> 0 | O27: =VLOOKUP($M$6,PSC!$A$2:$L$31,4,FALSE) -> 19.99
B28: Biscoito Inf Papapá dent Vegetais 36g | D28: 8767 | F28: =E28*12 -> 0 | G28: =VLOOKUP($M$6,'ST BISCOITINHOS'!A:B,2,FALSE) -> 0.04 | H28: =VLOOKUP($M$6,PREÇOS!$A$2:$L$31,4,FALSE) -> 13.3488 | I28: =H28*12 -> 160.1856 | J28: =IF($G$7="SIM",VLOOKUP($M$6,'ST BISCOITINHOS'!$A$1:$J$31,10,FALSE),VLOOKUP($M$6,'ST BISCOITINHOS'!$A$1:$J$31,9,FALSE)) -> 0 | K28: 0 | L28: =(H28+J28+K28)*12 -> 160.1856 | M28: =E28*I28 -> 0 | N28: =E28*L28 -> 0 | O28: =VLOOKUP($M$6,PSC!$A$2:$L$31,4,FALSE) -> 19.99
B30: Macarrao Inf Papapá m. Elbow Quinoa 200g | D30: 5290 | F30: =E30*12 -> 0 | G30: =VLOOKUP($M$6,'ST PAPAPASTA'!A:B,2,FALSE) -> 0.12 | H30: =VLOOKUP($M$6,PREÇOS!$A$2:$L$31,5,FALSE) -> 8.619 | I30: =H30*12 -> 103.428 | J30: =IF($G$7="SIM",VLOOKUP($M$6,'ST PAPAPASTA'!$A$1:$J$31,10,FALSE),VLOOKUP($M$6,'ST PAPAPASTA'!$A$1:$J$31,9,FALSE)) -> 0 | K30: 0 | L30: =(H30+J30+K30)*12 -> 103.428 | M30: =E30*I30 -> 0 | N30: =E30*L30 -> 0 | O30: =VLOOKUP($M$6,PSC!$A$2:$L$31,5,FALSE) -> 12.49
B31: Macarrao Inf Papapá m. Fusilli Vegetais 200g | D31: 5283 | F31: =E31*12 -> 0 | G31: =VLOOKUP($M$6,'ST PAPAPASTA'!A:B,2,FALSE) -> 0.12 | H31: =VLOOKUP($M$6,PREÇOS!$A$2:$L$31,5,FALSE) -> 8.619 | I31: =H31*12 -> 103.428 | J31: =IF($G$7="SIM",VLOOKUP($M$6,'ST PAPAPASTA'!$A$1:$J$31,10,FALSE),VLOOKUP($M$6,'ST PAPAPASTA'!$A$1:$J$31,9,FALSE)) -> 0 | K31: 0 | L31: =(H31+J31+K31)*12 -> 103.428 | M31: =E31*I31 -> 0 | N31: =E31*L31 -> 0 | O31: =VLOOKUP($M$6,PSC!$A$2:$L$31,5,FALSE) -> 12.49
B33: Sopinha Papapá org Lentinha Carne Legumes 180g | D33: 5276 | F33: =E33*6 -> 0 | G33: =VLOOKUP($M$6,'ST PAPAPASTA'!A:B,2,FALSE) -> 0.12 | H33: =VLOOKUP($M$6,PREÇOS!$A$2:$L$31,6,FALSE) -> 12.39 | I33: =H33*6 -> 74.34 | J33: 0 | K33: 0 | L33: =(H33+J33+K33)*6 -> 74.34 | M33: =E33*I33 -> 0 | N33: =E33*L33 -> 0 | O33: =VLOOKUP($M$6,PSC!$A$2:$L$31,6,FALSE) -> 18.99
B34: Risotinho Papapá org Arroz quinoa frango 180g | D34: 5269 | F34: =E34*6 -> 0 | G34: =VLOOKUP($M$6,'ST PAPAPASTA'!A:B,2,FALSE) -> 0.12 | H34: =VLOOKUP($M$6,PREÇOS!$A$2:$L$31,6,FALSE) -> 12.39 | I34: =H34*6 -> 74.34 | J34: 0 | K34: 0 | L34: =(H34+J34+K34)*6 -> 74.34 | M34: =E34*I34 -> 0 | N34: =E34*L34 -> 0 | O34: =VLOOKUP($M$6,PSC!$A$2:$L$31,6,FALSE) -> 18.99
B35: Caseirinho Papapá org Arroz feijão carne leg. 180g | D35: 5252 | F35: =E35*6 -> 0 | G35: =VLOOKUP($M$6,'ST PAPAPASTA'!A:B,2,FALSE) -> 0.12 | H35: =VLOOKUP($M$6,PREÇOS!$A$2:$L$31,6,FALSE) -> 12.39 | I35: =H35*6 -> 74.34 | J35: 0 | K35: 0 | L35: =(H35+J35+K35)*6 -> 74.34 | M35: =E35*I35 -> 0 | N35: =E35*L35 -> 0 | O35: =VLOOKUP($M$6,PSC!$A$2:$L$31,6,FALSE) -> 18.99
B37: Cereal Infantil Papapá Aveia - Morango e Beterraba sache 170g | D37: 5402 | F37: =E37*12 -> 0 | G37: =VLOOKUP($M$6,'ST CEREAL SABOR POUCH 170'!A:B,2,FALSE) -> 0.12 | H37: =VLOOKUP($M$6,PREÇOS!$A$2:$L$31,10,FALSE) -> 6.765 | I37: =H37*12 -> 81.18 | J37: =IF($G$7="SIM",VLOOKUP($M$6,'ST CEREAL SABOR POUCH 170'!$A$1:$J$31,10,FALSE),VLOOKUP($M$6,'ST CEREAL SABOR POUCH 170'!$A$1:$J$31,9,FALSE)) -> 0 | K37: 0 | L37: =(H37+J37+K37)*12 -> 81.18 | M37: =E37*I37 -> 0 | N37: =E37*L37 -> 0 | O37: =VLOOKUP($M$6,PSC!$A$2:$L$31,10,FALSE) -> 9.99
B38: Cereal Infantil Papapá Aveia - Banana e Ameixa sache 170g | D38: 5419 | F38: =E38*12 -> 0 | G38: =VLOOKUP($M$6,'ST CEREAL SABOR POUCH 170'!A:B,2,FALSE) -> 0.12 | H38: =VLOOKUP($M$6,PREÇOS!$A$2:$L$31,10,FALSE) -> 6.765 | I38: =H38*12 -> 81.18 | J38: =IF($G$7="SIM",VLOOKUP($M$6,'ST CEREAL SABOR POUCH 170'!$A$1:$J$31,10,FALSE),VLOOKUP($M$6,'ST CEREAL SABOR POUCH 170'!$A$1:$J$31,9,FALSE)) -> 0 | K38: 0 | L38: =(H38+J38+K38)*12 -> 81.18 | M38: =E38*I38 -> 0 | N38: =E38*L38 -> 0 | O38: =VLOOKUP($M$6,PSC!$A$2:$L$31,10,FALSE) -> 9.99
B39: Cereal Infantil Papapá Aveia - Multicereais sache 170g | D39: 5429 | F39: =E39*12 -> 0 | G39: =VLOOKUP($M$6,'ST MULTI 170 POUCH'!A:B,2,FALSE) -> 0.12 | H39: =VLOOKUP($M$6,PREÇOS!$A$2:$L$31,11,FALSE) -> 6.765 | I39: =H39*12 -> 81.18 | J39: =IF($G$7="SIM",VLOOKUP($M$6,'ST MULTI 170 POUCH'!$A$1:$J$31,10,FALSE),VLOOKUP($M$6,'ST MULTI 170 POUCH'!$A$1:$J$31,9,FALSE)) -> 0 | K39: 0 | L39: =(H39+J39+K39)*12 -> 81.18 | M39: =E39*I39 -> 0 | N39: =E39*L39 -> 0 | O39: =VLOOKUP($M$6,PSC!$A$2:$L$31,11,FALSE) -> 9.99
B40: Cereal Infantil Papapá Aveia - Multicereais sache 500g | D40: 5399 | F40: =E40*12 -> 0 | G40: =VLOOKUP($M$6,'ST MULTI 500 POUCH'!A:B,2,FALSE) -> 0.12 | H40: =VLOOKUP($M$6,PREÇOS!$A$2:$L$31,12,FALSE) -> 16.1892 | I40: =H40*12 -> 194.2704 | J40: =IF($G$7="SIM",VLOOKUP($M$6,'ST MULTI 500 POUCH'!$A$1:$J$31,10,FALSE),VLOOKUP($M$6,'ST MULTI 500 POUCH'!$A$1:$J$31,9,FALSE)) -> 0 | K40: 0 | L40: =(H40+J40+K40)*12 -> 194.2704 | M40: =E40*I40 -> 0 | N40: =E40*L40 -> 0 | O40: =VLOOKUP($M$6,PSC!$A$2:$L$31,12,FALSE) -> 23.99
B42: Biscoito Infantil Papapá Biscotti com Laranja e Cenoura 60g | D42: 5375 | F42: =E42*12 -> 0 | G42: =VLOOKUP($M$6,'ST BISCOTTI'!A:B,2,FALSE) -> 0.12 | H42: =VLOOKUP($M$6,PREÇOS!$A$2:$L$31,8,FALSE) -> 8.988 | I42: =H42*12 -> 107.856 | J42: =IF($G$7="SIM",VLOOKUP($M$6,'ST BISCOTTI'!$A$1:$J$31,10,FALSE),VLOOKUP($M$6,'ST BISCOTTI'!$A$1:$J$31,9,FALSE)) -> 0 | K42: 0 | L42: =(H42+J42+K42)*12 -> 107.856 | M42: =E42*I42 -> 0 | N42: =E42*L42 -> 0 | O42: =VLOOKUP($M$6,PSC!$A$2:$L$31,8,FALSE) -> 13.49
B43: Biscoito Infantil Papapá Biscotti com Maçã e Canela 60g | D43: 5351 | F43: =E43*12 -> 0 | G43: =VLOOKUP($M$6,'ST BISCOTTI'!A:B,2,FALSE) -> 0.12 | H43: =VLOOKUP($M$6,PREÇOS!$A$2:$L$31,8,FALSE) -> 8.988 | I43: =H43*12 -> 107.856 | J43: =IF($G$7="SIM",VLOOKUP($M$6,'ST BISCOTTI'!$A$1:$J$31,10,FALSE),VLOOKUP($M$6,'ST BISCOTTI'!$A$1:$J$31,9,FALSE)) -> 0 | K43: 0 | L43: =(H43+J43+K43)*12 -> 107.856 | M43: =E43*I43 -> 0 | N43: =E43*L43 -> 0 | O43: =VLOOKUP($M$6,PSC!$A$2:$L$31,8,FALSE) -> 13.49
B44: Biscoito Infantil Papapá Biscotti com Banana e Cacau 60g | D44: 5368 | F44: =E44*12 -> 0 | G44: =VLOOKUP($M$6,'ST BISCOTTI'!A:B,2,FALSE) -> 0.12 | H44: =VLOOKUP($M$6,PREÇOS!$A$2:$L$31,8,FALSE) -> 8.988 | I44: =H44*12 -> 107.856 | J44: =IF($G$7="SIM",VLOOKUP($M$6,'ST BISCOTTI'!$A$1:$J$31,10,FALSE),VLOOKUP($M$6,'ST BISCOTTI'!$A$1:$J$31,9,FALSE)) -> 0 | K44: 0 | L44: =(H44+J44+K44)*12 -> 107.856 | M44: =E44*I44 -> 0 | N44: =E44*L44 -> 0 | O44: =VLOOKUP($M$6,PSC!$A$2:$L$31,8,FALSE) -> 13.49
B45: Biscoito Infantil Papapá Biscotti Goiaba 60g | D45: 5597 | F45: =E45*12 -> 0 | G45: =VLOOKUP($M$6,'ST BISCOTTI'!A:B,2,FALSE) -> 0.12 | H45: =VLOOKUP($M$6,PREÇOS!$A$2:$L$31,8,FALSE) -> 8.988 | I45: =H45*12 -> 107.856 | J45: =IF($G$7="SIM",VLOOKUP($M$6,'ST BISCOTTI'!$A$1:$J$31,10,FALSE),VLOOKUP($M$6,'ST BISCOTTI'!$A$1:$J$31,9,FALSE)) -> 0 | K45: 0 | L45: =(H45+J45+K45)*12 -> 107.856 | M45: =E45*I45 -> 0 | N45: =E45*L45 -> 0 | O45: =VLOOKUP($M$6,PSC!$A$2:$L$31,8,FALSE) -> 13.49
B46: Biscoito Infantil Papapá Biscotti com Maracujá e Camomila 60g | D46: 5580 | F46: =E46*12 -> 0 | G46: =VLOOKUP($M$6,'ST BISCOTTI'!A:B,2,FALSE) -> 0.12 | H46: =VLOOKUP($M$6,PREÇOS!$A$2:$L$31,8,FALSE) -> 8.988 | I46: =H46*12 -> 107.856 | J46: =IF($G$7="SIM",VLOOKUP($M$6,'ST BISCOTTI'!$A$1:$J$31,10,FALSE),VLOOKUP($M$6,'ST BISCOTTI'!$A$1:$J$31,9,FALSE)) -> 0 | K46: 0 | L46: =(H46+J46+K46)*12 -> 107.856 | M46: =E46*I46 -> 0 | N46: =E46*L46 -> 0 | O46: =VLOOKUP($M$6,PSC!$A$2:$L$31,8,FALSE) -> 13.49
B48: Sopinha Papapá Frango Arroz Legumes 240g (2x 120g) | D48: 5610 | F48: =E48*6 -> 0 | G48: =VLOOKUP($M$6,'ST BISCOTTI'!A:B,2,FALSE) -> 0.12 | H48: =VLOOKUP($M$6,PREÇOS!$A$2:$N$31,14,FALSE) -> 12.94 | I48: =H48*6 -> 77.64 | J48: 0 | K48: 0 | L48: =(H48+J48+K48)*6 -> 77.64 | M48: =E48*I48 -> 0 | N48: =E48*L48 -> 0 | O48: 18.99
B49: Sopinha Papapá Carne Macarrao Legumes 240g (2x 120g) | D49: 5634 | F49: =E49*6 -> 0 | G49: =VLOOKUP($M$6,'ST BISCOTTI'!A:B,2,FALSE) -> 0.12 | H49: =VLOOKUP($M$6,PREÇOS!$A$2:$N$31,14,FALSE) -> 12.94 | I49: =H49*6 -> 77.64 | J49: 0 | K49: 0 | L49: =(H49+J49+K49)*6 -> 77.64 | M49: =E49*I49 -> 0 | N49: =E49*L49 -> 0 | O49: 18.99
B50: Sopinha Papapá Carne Mandioq Leg 240g (2x 120g) | D50: 5627 | F50: =E50*6 -> 0 | G50: =VLOOKUP($M$6,'ST BISCOTTI'!A:B,2,FALSE) -> 0.12 | H50: =VLOOKUP($M$6,PREÇOS!$A$2:$N$31,14,FALSE) -> 12.94 | I50: =H50*6 -> 77.64 | J50: 0 | K50: 0 | L50: =(H50+J50+K50)*6 -> 77.64 | M50: =E50*I50 -> 0 | N50: =E50*L50 -> 0 | O50: 18.99
B51: Sopinha Papapá Feijão Carne Leg 240g (2x 120g) | D51: 5603 | F51: =E51*6 -> 0 | G51: =VLOOKUP($M$6,'ST BISCOTTI'!A:B,2,FALSE) -> 0.12 | H51: =VLOOKUP($M$6,PREÇOS!$A$2:$N$31,14,FALSE) -> 12.94 | I51: =H51*6 -> 77.64 | J51: 0 | K51: 0 | L51: =(H51+J51+K51)*6 -> 77.64 | M51: =E51*I51 -> 0 | N51: =E51*L51 -> 0 | O51: 18.99
...

Sheet Cadastro
C1: BABY ROO COMERCIO DE ALIMENTOS EIRELI
C2: CNPJ: 34.282.307.0001-44
C3: INSC. ESTADUAL: 90821939-25
C4: ENDEREÇO: Rua Grã Nicco, 113 - sala 501, bloco 2 - Mossunguê, Curitiba - PR, 81200-200
R5: PR
B6: ESPECIAL | L6: E-mail XML:
B7: Descrição | D7: Código | E7: Embalagem | F7: Validade | G7: PSC | H7: NCM | I7: Ean 13 | J7: Dun 14 | K7: Crédito ICMS (%) | L7: Valor Unit. | M7: Valor Caixa | N7: SUBSTITUIÇÃO TRIBUTÁRIA* | O7: IPI* | P7: Valor Caixa + ST + IPI | Q7: TOTAL Caixas | R7: Valor TOTAL | S7: Valor TOTAL + ST (*)
B8: Papinha Papapa Carne Arroz Legumes 120g | D8: 5313 | E8: 12 x 120g | F8: 12 meses | G8: =VLOOKUP($R$5,'PSC PAPAPA'!$A$2:$L$31,9,FALSE) -> 13.49 | H8: 2104.20.00 | I8: 7898969895316 | J8: 17898969895313 | K8: =VLOOKUP($R$5,'ST BISCOITINHOS'!A:B,2,FALSE) -> 0.12 | L8: =VLOOKUP($R$5,PREÇOS!$A$2:$L$31,9,FALSE) -> 9.7090909 | M8: =L11*12 -> 81.687273 | N8: 0 | O8: 0 | P8: =(L11+N11+O11)*12 -> 81.687273 | R8: =Q11*M11 -> 0 | S8: =Q11*P11 -> 0
B9: Papinha Papapa Frango Grão Vegetais 120g | D9: 5320 | E9: 12 x 120g | F9: 12 meses | G9: =VLOOKUP($R$5,'PSC PAPAPA'!$A$2:$L$31,9,FALSE) -> 13.49 | H9: 2104.20.00 | I9: 7898969895323 | J9: 17898969895320 | K9: =VLOOKUP($R$5,'ST BISCOITINHOS'!A:B,2,FALSE) -> 0.12 | L9: =VLOOKUP($R$5,PREÇOS!$A$2:$L$31,9,FALSE) -> 9.7090909 | M9: =L12*12 -> 81.687273 | N9: 0 | O9: 0 | P9: =(L12+N12+O12)*12 -> 81.687273 | R9: =Q12*M12 -> 0 | S9: =Q12*P12 -> 0
B11: Papinha Papapa Iogurte Frutas Amarelas e Banana 100g | D11: 5563 | E11: 16 x 100g | F11: 15 meses | G11: =VLOOKUP($R$5,'PSC PAPAPA'!$A$2:$M$31,13,FALSE) -> 9.49 | H11: 2104.20.00 | I11: 7898969895569 | J11: 27898969895563 | K11: =VLOOKUP($R$5,'ST BISCOITINHOS'!A:B,2,FALSE) -> 0.12 | L11: =VLOOKUP($R$5,PREÇOS!$A$2:$M$31,13,FALSE) -> 6.8072727 | M11: =L14*16 -> 108.91636 | N11: 0 | O11: 0 | P11: =(L14+N14+O14)*16 -> 108.91636 | R11: =Q14*M14 -> 0 | S11: =Q14*P14 -> 0
B12: Papinha Papapa Iogurte Frutas Vermelhas e Banana 100g | D12: 5570 | E12: 16 x 100g | F12: 15 meses | G12: =VLOOKUP($R$5,'PSC PAPAPA'!$A$2:$M$31,13,FALSE) -> 9.49 | H12: 2104.20.00 | I12: 7898969895576 | J12: 27898969895570 | K12: =VLOOKUP($R$5,'ST BISCOITINHOS'!A:B,2,FALSE) -> 0.12 | L12: =VLOOKUP($R$5,PREÇOS!$A$2:$M$31,13,FALSE) -> 6.8072727 | M12: =L15*16 -> 108.91636 | N12: 0 | O12: 0 | P12: =(L15+N15+O15)*16 -> 108.91636 | R12: =Q15*M15 -> 0 | S12: =Q15*P15 -> 0
B14: Papinha Papapá Org Maçã Ameixa 100g | D14: 17898994908729 | E14: 12 x 100g | F14: 16 meses | G14: =VLOOKUP($R$5,'PSC PAPAPA'!$A$2:$L$31,2,FALSE) -> 9.49 | H14: 2104.20.00 | I14: 7898994908722 | J14: 17898994908729 | K14: =VLOOKUP($R$5,'ST BISCOITINHOS'!A:B,2,FALSE) -> 0.12 | L14: =VLOOKUP($R$5,PREÇOS!$A$2:$L$31,2,FALSE) -> 6.8072727 | M14: =L17*12 -> 81.687273 | N14: 0 | O14: 0 | P14: =(L17+N17+O17)*12 -> 81.687273 | R14: =Q17*M17 -> 0 | S14: =Q17*P17 -> 0
B15: Papinha Papapá Org Banana Mirtilo Quinoa 100g | D15: 17898994908736 | E15: 12 x 100g | F15: 16 meses | G15: =VLOOKUP($R$5,'PSC PAPAPA'!$A$2:$L$31,2,FALSE) -> 9.49 | H15: 2104.20.00 | I15: 7898994908739 | J15: 17898994908736 | K15: =VLOOKUP($R$5,'ST BISCOITINHOS'!A:B,2,FALSE) -> 0.12 | L15: =VLOOKUP($R$5,PREÇOS!$A$2:$L$31,2,FALSE) -> 6.8072727 | M15: =L18*12 -> 81.687273 | N15: 0 | O15: 0 | P15: =(L18+N18+O18)*12 -> 81.687273 | R15: =Q18*M18 -> 0 | S15: =Q18*P18 -> 0
B16: Papinha Papapá Org Manga 100g | D16: 17898994908712 | E16: 12 x 100g | F16: 16 meses | G16: =VLOOKUP($R$5,'PSC PAPAPA'!$A$2:$L$31,2,FALSE) -> 9.49 | H16: 2104.20.00 | I16: 7898994908715 | J16: 17898994908712 | K16: =VLOOKUP($R$5,'ST BISCOITINHOS'!A:B,2,FALSE) -> 0.12 | L16: =VLOOKUP($R$5,PREÇOS!$A$2:$L$31,2,FALSE) -> 6.8072727 | M16: =L19*12 -> 81.687273 | N16: 0 | O16: 0 | P16: =(L19+N19+O19)*12 -> 81.687273 | R16: =Q19*M19 -> 0 | S16: =Q19*P19 -> 0
B17: Papinha Papapá Org Pera Espinafre Abobrinha 100g | D17: 17898994908750 | E17: 12 x 100g | F17: 16 meses | G17: =VLOOKUP($R$5,'PSC PAPAPA'!$A$2:$L$31,2,FALSE) -> 9.49 | H17: 2104.20.00 | I17: 7898994908753 | J17: 17898994908750 | K17: =VLOOKUP($R$5,'ST BISCOITINHOS'!A:B,2,FALSE) -> 0.12 | L17: =VLOOKUP($R$5,PREÇOS!$A$2:$L$31,2,FALSE) -> 6.8072727 | M17: =L20*12 -> 0 | N17: 0 | O17: 0 | P17: =(L20+N20+O20)*12 -> 0 | R17: =Q20*M20 -> 0 | S17: =Q20*P20 -> 0
B18: Papinha Papapá Org Maçã B. Doce Cenoura 100g | D18: 27898994908757 | E18: 12 x 100g | F18: 16 meses | G18: =VLOOKUP($R$5,'PSC PAPAPA'!$A$2:$L$31,2,FALSE) -> 9.49 | H18: 2104.20.00 | I18: 7898994908746 | J18: 27898994908757 | K18: =VLOOKUP($R$5,'ST BISCOITINHOS'!A:B,2,FALSE) -> 0.12 | L18: =VLOOKUP($R$5,PREÇOS!$A$2:$L$31,2,FALSE) -> 6.8072727 | M18: =L21*12 -> 47.1744 | N18: 0 | O18: 0 | P18: =(L21+N21+O21)*12 -> 57.032198 | R18: =Q21*M21 -> 0 | S18: =Q21*P21 -> 0
B19: Papinha Papapá Org Morango Maçã 100g | D19: 5306 | E19: 12 x 100g | F19: 16 meses | G19: =VLOOKUP($R$5,'PSC PAPAPA'!$A$2:$L$31,2,FALSE) -> 9.49 | H19: 2104.20.00 | I19: 7898969895309 | J19: 17898969895306 | K19: =VLOOKUP($R$5,'ST BISCOITINHOS'!A:B,2,FALSE) -> 0.12 | L19: =VLOOKUP($R$5,PREÇOS!$A$2:$L$31,2,FALSE) -> 6.8072727 | M19: =L22*12 -> 47.1744 | N19: 0 | O19: 0 | P19: =(L22+N22+O22)*12 -> 57.032198 | R19: =Q22*M22 -> 0 | S19: =Q22*P22 -> 0
B21: Biscoito inf Papapá org. Beterraba 20g | D21: 5085 | E21: 16 x 20g | F21: 9 meses | G21: =VLOOKUP($R$5,'PSC PAPAPA'!$A$2:$L$31,3,FALSE) -> 5.99 | H21: 1904.10.00 | I21: 7898969895088 | J21: 17898969895085 | K21: =VLOOKUP($R$5,'ST PALITINHOS'!A:B,2,FALSE) -> 0.12 | L21: =VLOOKUP($R$5,PREÇOS!$A$2:$L$31,3,FALSE) -> 3.9312 | M21: =L24*16 -> 0 | N21: =IF($K$8="SIM",VLOOKUP($R$5,'ST PALITINHOS'!$A$1:$J$31,10,FALSE),VLOOKUP($R$5,'ST PALITINHOS'!$A$1:$J$31,9,FALSE)) -> 0.82148321 | O21: 0 | P21: =(L24+N24+O24)*16 -> 0 | R21: =Q24*M24 -> 0 | S21: =Q24*P24 -> 0
B22: Biscoito inf Papapá org. Cenoura 20g | D22: 5078 | E22: 16 x 20g | F22: 9 meses | G22: =VLOOKUP($R$5,'PSC PAPAPA'!$A$2:$L$31,3,FALSE) -> 5.99 | H22: 1904.10.00 | I22: 7898969895071 | J22: 17898969895078 | K22: =VLOOKUP($R$5,'ST PALITINHOS'!A:B,2,FALSE) -> 0.12 | L22: =VLOOKUP($R$5,PREÇOS!$A$2:$L$31,3,FALSE) -> 3.9312 | M22: =L25*16 -> 232.99724 | N22: =IF($K$8="SIM",VLOOKUP($R$5,'ST PALITINHOS'!$A$1:$J$31,10,FALSE),VLOOKUP($R$5,'ST PALITINHOS'!$A$1:$J$31,9,FALSE)) -> 0.82148321 | O22: 0 | P22: =(L25+N25+O25)*16 -> 232.99724 | R22: =Q25*M25 -> 0 | S22: =Q25*P25 -> 0
B23: Biscoito inf Papapá org. Tomate/Manjericão 20g | D23: 5061 | E23: 16 x 20g | F23: 9 meses | G23: =VLOOKUP($R$5,'PSC PAPAPA'!$A$2:$L$31,3,FALSE) -> 5.99 | H23: 1904.10.00 | I23: 7898969895064 | J23: 17898969895061 | K23: =VLOOKUP($R$5,'ST PALITINHOS'!A:B,2,FALSE) -> 0.12 | L23: =VLOOKUP($R$5,PREÇOS!$A$2:$L$31,3,FALSE) -> 3.9312 | M23: =L26*16 -> 232.99724 | N23: =IF($K$8="SIM",VLOOKUP($R$5,'ST PALITINHOS'!$A$1:$J$31,10,FALSE),VLOOKUP($R$5,'ST PALITINHOS'!$A$1:$J$31,9,FALSE)) -> 0.82148321 | O23: 0 | P23: =(L26+N26+O26)*16 -> 232.99724 | R23: =Q26*M26 -> 0 | S23: =Q26*P26 -> 0
B25: Biscoito Inf Papapá dent. Maçã e Abóbora 36g | D25: 8774 | E25: 12 x 36g | F25: 15 meses | G25: =VLOOKUP($R$5,'PSC PAPAPA'!$A$2:$L$31,4,FALSE) -> 19.99 | H25: 1905.90.20 | I25: 7898994908777 | J25: 17898994908774 | K25: =VLOOKUP($R$5,'ST BISCOITINHOS'!A:B,2,FALSE) -> 0.12 | L25: =VLOOKUP($R$5,PREÇOS!$A$2:$L$31,4,FALSE) -> 14.562327 | M25: =L28*12 -> 103.428 | N25: =IF($K$8="SIM",VLOOKUP($R$5,'ST BISCOITINHOS'!$A$1:$J$31,10,FALSE),VLOOKUP($R$5,'ST BISCOITINHOS'!$A$1:$J$31,9,FALSE)) -> 0 | O25: 0 | P25: =(L28+N28+O28)*12 -> 103.428 | R25: =Q28*M28 -> 0 | S25: =Q28*P28 -> 0
B26: Biscoito Inf Papapá dent Vegetais 36g | D26: 8767 | E26: 12 x 36g | F26: 15 meses | G26: =VLOOKUP($R$5,'PSC PAPAPA'!$A$2:$L$31,4,FALSE) -> 19.99 | H26: 1905.90.20 | I26: 7898994908760 | J26: 17898994908767 | K26: =VLOOKUP($R$5,'ST BISCOITINHOS'!A:B,2,FALSE) -> 0.12 | L26: =VLOOKUP($R$5,PREÇOS!$A$2:$L$31,4,FALSE) -> 14.562327 | M26: =L29*12 -> 103.428 | N26: =IF($K$8="SIM",VLOOKUP($R$5,'ST BISCOITINHOS'!$A$1:$J$31,10,FALSE),VLOOKUP($R$5,'ST BISCOITINHOS'!$A$1:$J$31,9,FALSE)) -> 0 | O26: 0 | P26: =(L29+N29+O29)*12 -> 103.428 | R26: =Q29*M29 -> 0 | S26: =Q29*P29 -> 0
B28: Macarrao Inf Papapá m. Elbow Quinoa 200g | D28: 5290 | E28: 12 x 200g | F28: 14 meses | G28: =VLOOKUP($R$5,'PSC PAPAPA'!$A$2:$L$31,5,FALSE) -> 12.49 | H28: 19.02.19.00 | I28: 7898969895293 | J28: 17898969895293 | K28: =VLOOKUP($R$5,'ST PAPAPASTA'!A:B,2,FALSE) -> 0.12 | L28: =VLOOKUP($R$5,PREÇOS!$A$2:$L$31,5,FALSE) -> 8.619 | M28: =L31*12 -> 148.68 | N28: =IF($K$8="SIM",VLOOKUP($R$5,'ST PAPAPASTA'!$A$1:$J$31,10,FALSE),VLOOKUP($R$5,'ST PAPAPASTA'!$A$1:$J$31,9,FALSE)) -> 0 | O28: 0 | P28: =(L31+N31+O31)*12 -> 148.68 | R28: =Q31*M31 -> 0 | S28: =Q31*P31 -> 0
B29: Macarrao Inf Papapá m. Fusilli Vegetais 200g | D29: 5283 | E29: 12 x 200g | F29: 14 meses | G29: =VLOOKUP($R$5,'PSC PAPAPA'!$A$2:$L$31,5,FALSE) -> 12.49 | H29: 19.02.19.00 | I29: 7898969895286 | J29: 17898969895286 | K29: =VLOOKUP($R$5,'ST PAPAPASTA'!A:B,2,FALSE) -> 0.12 | L29: =VLOOKUP($R$5,PREÇOS!$A$2:$L$31,5,FALSE) -> 8.619 | M29: =L32*12 -> 148.68 | N29: =IF($K$8="SIM",VLOOKUP($R$5,'ST PAPAPASTA'!$A$1:$J$31,10,FALSE),VLOOKUP($R$5,'ST PAPAPASTA'!$A$1:$J$31,9,FALSE)) -> 0 | O29: 0 | P29: =(L32+N32+O32)*12 -> 148.68 | R29: =Q32*M32 -> 0 | S29: =Q32*P32 -> 0
B31: Sopinha Papapá org Lentinha Carne Legumes 180g | D31: 5276 | E31: 6 x 180g | F31: 16 meses | G31: =VLOOKUP($R$5,'PSC PAPAPA'!$A$2:$L$31,6,FALSE) -> 18.99 | H31: 2104.20.00 | I31: 7898969895279 | J31: 17898969895276 | K31: =VLOOKUP($R$5,'ST PAPAPASTA'!A:B,2,FALSE) -> 0.12 | L31: =VLOOKUP($R$5,PREÇOS!$A$2:$L$31,6,FALSE) -> 12.39 | M31: =L34*6 -> 0 | N31: 0 | O31: 0 | P31: =(L34+N34+O34)*6 -> 0 | R31: =Q34*M34 -> 0 | S31: =Q34*P34 -> 0
B32: Risotinho Papapá org Arroz quinoa frango 180g | D32: 5269 | E32: 6 x 180g | F32: 16 meses | G32: =VLOOKUP($R$5,'PSC PAPAPA'!$A$2:$L$31,6,FALSE) -> 18.99 | H32: 2104.20.00 | I32: 7898969895262 | J32: 17898969895269 | K32: =VLOOKUP($R$5,'ST PAPAPASTA'!A:B,2,FALSE) -> 0.12 | L32: =VLOOKUP($R$5,PREÇOS!$A$2:$L$31,6,FALSE) -> 12.39 | M32: =L35*6 -> 40.59 | N32: 0 | O32: 0 | P32: =(L35+N35+O35)*6 -> 48.4466 | R32: =Q35*M35 -> 0 | S32: =Q35*P35 -> 0
B33: Caseirinho Papapá org Arroz feijão carne leg. 180g | D33: 5252 | E33: 6 x 180g | F33: 16 meses | G33: =VLOOKUP($R$5,'PSC PAPAPA'!$A$2:$L$31,6,FALSE) -> 18.99 | H33: 2104.20.00 | I33: 7898969895255 | J33: 17898969895252 | K33: =VLOOKUP($R$5,'ST PAPAPASTA'!A:B,2,FALSE) -> 0.12 | L33: =VLOOKUP($R$5,PREÇOS!$A$2:$L$31,6,FALSE) -> 12.39 | M33: =L36*6 -> 40.59 | N33: 0 | O33: 0 | P33: =(L36+N36+O36)*6 -> 48.4466 | R33: =Q36*M36 -> 0 | S33: =Q36*P36 -> 0
B35: Cereal Infantil Papapá Aveia - Morango e Beterraba sache 170g | D35: 5402 | E35: 12 x 170g | F35: 12 meses | G35: =VLOOKUP($R$5,'PSC PAPAPA'!$A$2:$L$31,10,FALSE) -> 9.99 | H35: 19.01.10.30 | I35: 7898969895408 | J35: 27898969895402 | K35: =VLOOKUP($R$5,'ST CEREAL SABOR POUCH 170'!A:B,2,FALSE) -> 0.12 | L35: =VLOOKUP($R$5,PREÇOS!$A$2:$L$31,10,FALSE) -> 6.765 | M35: =L38*12 -> 194.2704 | N35: =IF($K$8="SIM",VLOOKUP($R$5,'ST CEREAL SABOR POUCH 170'!$A$1:$J$31,10,FALSE),VLOOKUP($R$5,'ST CEREAL SABOR POUCH 170'!$A$1:$J$31,9,FALSE)) -> 1.3094334 | O35: 0 | P35: =(L38+N38+O38)*12 -> 231.87338 | R35: =Q38*M38 -> 0 | S35: =Q38*P38 -> 0
B36: Cereal Infantil Papapá Aveia - Banana e Ameixa sache 170g | D36: 5419 | E36: 12 x 170g | F36: 12 meses | G36: =VLOOKUP($R$5,'PSC PAPAPA'!$A$2:$L$31,10,FALSE) -> 9.99 | H36: 19.01.10.30 | I36: 7898969895415 | J36: 27898969895419 | K36: =VLOOKUP($R$5,'ST CEREAL SABOR POUCH 170'!A:B,2,FALSE) -> 0.12 | L36: =VLOOKUP($R$5,PREÇOS!$A$2:$L$31,10,FALSE) -> 6.765 | M36: =L39*12 -> 0 | N36: =IF($K$8="SIM",VLOOKUP($R$5,'ST CEREAL SABOR POUCH 170'!$A$1:$J$31,10,FALSE),VLOOKUP($R$5,'ST CEREAL SABOR POUCH 170'!$A$1:$J$31,9,FALSE)) -> 1.3094334 | O36: 0 | P36: =(L39+N39+O39)*12 -> 0 | R36: =Q39*M39 -> 0 | S36: =Q39*P39 -> 0
B37: Cereal Infantil Papapá Aveia - Multicereais sache 170g | D37: 5429 | E37: 12 x 170g | F37: 12 meses | G37: =VLOOKUP($R$5,'PSC PAPAPA'!$A$2:$L$31,11,FALSE) -> 9.99 | H37: 19.01.10.30 | I37: 7898969895422 | J37: 17898969895429 | K37: =VLOOKUP($R$5,'ST MULTI 170 POUCH'!A:B,2,FALSE) -> 0.12 | L37: =VLOOKUP($R$5,PREÇOS!$A$2:$L$31,11,FALSE) -> 6.765 | M37: =L40*12 -> 107.856 | N37: =IF($K$8="SIM",VLOOKUP($R$5,'ST MULTI 170 POUCH'!$A$1:$J$31,10,FALSE),VLOOKUP($R$5,'ST MULTI 170 POUCH'!$A$1:$J$31,9,FALSE)) -> 1.3094334 | O37: 0 | P37: =(L40+N40+O40)*12 -> 107.856 | R37: =Q40*M40 -> 0 | S37: =Q40*P40 -> 0
B38: Cereal Infantil Papapá Aveia - Multicereais sache 500g | D38: 5399 | E38: 12 x 500g | F38: 12 meses | G38: =VLOOKUP($R$5,'PSC PAPAPA'!$A$2:$L$31,12,FALSE) -> 23.99 | H38: 19.01.10.30 | I38: 7898969895392 | J38: 17898969895399 | K38: =VLOOKUP($R$5,'ST MULTI 500 POUCH'!A:B,2,FALSE) -> 0.12 | L38: =VLOOKUP($R$5,PREÇOS!$A$2:$L$31,12,FALSE) -> 16.1892 | M38: =L41*12 -> 107.856 | N38: =IF($K$8="SIM",VLOOKUP($R$5,'ST MULTI 500 POUCH'!$A$1:$J$31,10,FALSE),VLOOKUP($R$5,'ST MULTI 500 POUCH'!$A$1:$J$31,9,FALSE)) -> 3.1335816 | O38: 0 | P38: =(L41+N41+O41)*12 -> 107.856 | R38: =Q41*M41 -> 0 | S38: =Q41*P41 -> 0
B40: Biscoito Infantil Papapá Biscotti com Laranja e Cenoura 60g | D40: 5375 | E40: 12 x 60g | F40: 10 meses | G40: =VLOOKUP($R$5,'PSC PAPAPA'!$A$2:$L$31,8,FALSE) -> 13.49 | H40: 1905.90.20 | I40: 7898969895378 | J40: 17898969895375 | K40: =VLOOKUP($R$5,'ST BISCOTTI'!A:B,2,FALSE) -> 0.12 | L40: =VLOOKUP($R$5,PREÇOS!$A$2:$L$31,8,FALSE) -> 8.988 | M40: =L43*12 -> 107.856 | N40: =IF($K$8="SIM",VLOOKUP($R$5,'ST BISCOTTI'!$A$1:$J$31,10,FALSE),VLOOKUP($R$5,'ST BISCOTTI'!$A$1:$J$31,9,FALSE)) -> 0 | O40: 0 | P40: =(L43+N43+O43)*12 -> 107.856 | R40: =Q43*M43 -> 0 | S40: =Q43*P43 -> 0
B41: Biscoito Infantil Papapá Biscotti com Maçã e Canela 60g | D41: 5351 | E41: 12 x 60g | F41: 10 meses | G41: =VLOOKUP($R$5,'PSC PAPAPA'!$A$2:$L$31,8,FALSE) -> 13.49 | H41: 1905.90.20 | I41: 7898969895354 | J41: 17898969895351 | K41: =VLOOKUP($R$5,'ST BISCOTTI'!A:B,2,FALSE) -> 0.12 | L41: =VLOOKUP($R$5,PREÇOS!$A$2:$L$31,8,FALSE) -> 8.988 | M41: =L44*12 -> 107.856 | N41: =IF($K$8="SIM",VLOOKUP($R$5,'ST BISCOTTI'!$A$1:$J$31,10,FALSE),VLOOKUP($R$5,'ST BISCOTTI'!$A$1:$J$31,9,FALSE)) -> 0 | O41: 0 | P41: =(L44+N44+O44)*12 -> 107.856 | R41: =Q44*M44 -> 0 | S41: =Q44*P44 -> 0
B42: Biscoito Infantil Papapá Biscotti com Banana e Cacau 60g | D42: 5368 | E42: 12 x 60g | F42: 10 meses | G42: =VLOOKUP($R$5,'PSC PAPAPA'!$A$2:$L$31,8,FALSE) -> 13.49 | H42: 1905.90.20 | I42: 7898969895361 | J42: 17898969895368 | K42: =VLOOKUP($R$5,'ST BISCOTTI'!A:B,2,FALSE) -> 0.12 | L42: =VLOOKUP($R$5,PREÇOS!$A$2:$L$31,8,FALSE) -> 8.988 | M42: =L45*12 -> 0 | N42: =IF($K$8="SIM",VLOOKUP($R$5,'ST BISCOTTI'!$A$1:$J$31,10,FALSE),VLOOKUP($R$5,'ST BISCOTTI'!$A$1:$J$31,9,FALSE)) -> 0 | O42: 0 | P42: =(L45+N45+O45)*12 -> 0 | R42: =Q45*M45 -> 0 | S42: =Q45*P45 -> 0
B43: Biscoito Infantil Papapá Biscotti Goiaba 60g | D43: 5597 | E43: 12 x 60g | F43: 10 meses | G43: =VLOOKUP($R$5,'PSC PAPAPA'!$A$2:$L$31,8,FALSE) -> 13.49 | H43: 1905.90.20 | I43: 7898969895590 | J43: 17898969895597 | K43: =VLOOKUP($R$5,'ST BISCOTTI'!A:B,2,FALSE) -> 0.12 | L43: =VLOOKUP($R$5,PREÇOS!$A$2:$L$31,8,FALSE) -> 8.988 | M43: =L46*12 -> 155.28 | N43: =IF($K$8="SIM",VLOOKUP($R$5,'ST BISCOTTI'!$A$1:$J$31,10,FALSE),VLOOKUP($R$5,'ST BISCOTTI'!$A$1:$J$31,9,FALSE)) -> 0 | O43: 0 | P43: =(L46+N46+O46)*12 -> 155.28 | R43: =Q46*M46 -> 0 | S43: =Q46*P46 -> 0
B44: Biscoito Infantil Papapá Biscotti com Maracujá e Camomila 60g | D44: 5580 | E44: 12 x 60g | F44: 10 meses | G44: =VLOOKUP($R$5,'PSC PAPAPA'!$A$2:$L$31,8,FALSE) -> 13.49 | H44: 1905.90.20 | I44: 7898969895583 | J44: 17898969895580 | K44: =VLOOKUP($R$5,'ST BISCOTTI'!A:B,2,FALSE) -> 0.12 | L44: =VLOOKUP($R$5,PREÇOS!$A$2:$L$31,8,FALSE) -> 8.988 | M44: =L47*12 -> 155.28 | N44: =IF($K$8="SIM",VLOOKUP($R$5,'ST BISCOTTI'!$A$1:$J$31,10,FALSE),VLOOKUP($R$5,'ST BISCOTTI'!$A$1:$J$31,9,FALSE)) -> 0 | O44: 0 | P44: =(L47+N47+O47)*12 -> 155.28 | R44: =Q47*M47 -> 0 | S44: =Q47*P47 -> 0
B46: Sopinha Papapá Frango Arroz Legumes 240g (2x 120g) | D46: 5610 | E46: 6 x 240g | F46: 12 meses | G46: 18.99 | H46: 2104.20.00 | I46: 7898969895613 | J46: 17898969895610 | K46: =VLOOKUP($R$5,'ST BISCOTTI'!A:B,2,FALSE) -> 0.12 | L46: =VLOOKUP($R$5,PREÇOS!$A$2:$N$31,14,FALSE) -> 12.94 | M46: =L49*6 -> 77.64 | N46: 0 | O46: 0 | P46: =(L49+N49+O49)*6 -> 77.64 | R46: =Q49*M49 -> 0 | S46: =Q49*P49 -> 0
B47: Sopinha Papapá Carne Macarrao Legumes 240g (2x 120g) | D47: 5634 | E47: 6 x 240g | F47: 12 meses | G47: 18.99 | H47: 2104.20.00 | I47: 7898969895637 | J47: 17898969895634 | K47: =VLOOKUP($R$5,'ST BISCOTTI'!A:B,2,FALSE) -> 0.12 | L47: =VLOOKUP($R$5,PREÇOS!$A$2:$N$31,14,FALSE) -> 12.94 | M47: =L50*6 -> 0 | N47: 0 | O47: 0 | P47: =(L50+N50+O50)*6 -> 0 | R47: =Q50*M50 -> 0 | S47: =Q50*P50 -> 0
B48: Sopinha Papapá Carne Mandioq Leg 240g (2x 120g) | D48: 5627 | E48: 6 x 240g | F48: 12 meses | G48: 18.99 | H48: 2104.20.00 | I48: 7898969895620 | J48: 17898969895627 | K48: =VLOOKUP($R$5,'ST BISCOTTI'!A:B,2,FALSE) -> 0.12 | L48: =VLOOKUP($R$5,PREÇOS!$A$2:$N$31,14,FALSE) -> 12.94 | M48: =L51*6 -> 30.6 | N48: 0 | O48: 0 | P48: =(L51+N51+O51)*6 -> 36.994329 | R48: =Q51*M51 -> 0 | S48: =Q51*P51 -> 0
B49: Sopinha Papapá Feijão Carne Leg 240g (2x 120g) | D49: 5603 | E49: 6 x 240g | F49: 12 meses | G49: 18.99 | H49: 2104.20.00 | I49: 7898969895606 | J49: 17898969895603 | K49: =VLOOKUP($R$5,'ST BISCOTTI'!A:B,2,FALSE) -> 0.12 | L49: =VLOOKUP($R$5,PREÇOS!$A$2:$N$31,14,FALSE) -> 12.94 | M49: =L52*6 -> 30.6 | N49: 0 | O49: 0 | P49: =(L52+N52+O52)*6 -> 36.994329 | R49: =Q52*M52 -> 0 | S49: =Q52*P52 -> 0
...

Sheet Planilha1
C2: SIM
C3: NÃO

Sheet ST BISCOITINHOS
A1: Estado | B1: Aliquota interestadual | C1: Aliquota interna | D1: MVA (normal) | E1: MVA (simples) | F1: Ajustada (normal) | G1: Ajustada (simples) | H1: Preço | I1: ST Normal | J1: ST Simples
A2: AC | B2: 0.04 | C2: 0.04 | H2: =PREÇOS!D3 -> 13.3488 | I2: =IF(F2=0,,H2*(1+F2)*C2-(H2*B2)) -> 0 | J2: =IF(G2=0,IF(F2=0,,H2*(1+F2)*C2-(H2*B2)),H2*(1+G2)*C2-(H2*B2)) -> 0
A3: AL | B3: 0.04 | C3: 0.2 | D3: 0.3 | F3: 0.56 | H3: =PREÇOS!D4 -> 13.3488 | I3: =IF(F3=0,,H3*(1+F3)*C3-(H3*B3)) -> 3.6308736 | J3: =IF(G3=0,IF(F3=0,,H3*(1+F3)*C3-(H3*B3)),H3*(1+G3)*C3-(H3*B3)) -> 3.6308736
A4: AM | B4: 0.04 | C4: 0.04 | H4: =PREÇOS!D5 -> 13.3488 | I4: =IF(F4=0,,H4*(1+F4)*C4-(H4*B4)) -> 0 | J4: =IF(G4=0,IF(F4=0,,H4*(1+F4)*C4-(H4*B4)),H4*(1+G4)*C4-(H4*B4)) -> 0
A5: AP | B5: 0.04 | C5: 0.18 | D5: 0.34 | F5: 0.5688 | H5: =PREÇOS!D6 -> 13.3488 | I5: =IF(F5=0,,H5*(1+F5)*C5-(H5*B5)) -> 3.2355355 | J5: =IF(G5=0,IF(F5=0,,H5*(1+F5)*C5-(H5*B5)),H5*(1+G5)*C5-(H5*B5)) -> 3.2355355
A6: BA | B6: 0.04 | C6: 0.04 | H6: =PREÇOS!D7 -> 13.3488 | I6: =IF(F6=0,,H6*(1+F6)*C6-(H6*B6)) -> 0 | J6: =IF(G6=0,IF(F6=0,,H6*(1+F6)*C6-(H6*B6)),H6*(1+G6)*C6-(H6*B6)) -> 0
A7: CE | B7: 0.04 | C7: 0.04 | H7: =PREÇOS!D8 -> 13.3488 | I7: =IF(F7=0,,H7*(1+F7)*C7-(H7*B7)) -> 0 | J7: =IF(G7=0,IF(F7=0,,H7*(1+F7)*C7-(H7*B7)),H7*(1+G7)*C7-(H7*B7)) -> 0
A8: DF | B8: 0.04 | C8: 0.04 | H8: =PREÇOS!D9 -> 13.3488 | I8: =IF(F8=0,,H8*(1+F8)*C8-(H8*B8)) -> 0 | J8: =IF(G8=0,IF(F8=0,,H8*(1+F8)*C8-(H8*B8)),H8*(1+G8)*C8-(H8*B8)) -> 0
A9: ES | B9: 0.04 | C9: 0.04 | H9: =PREÇOS!D10 -> 13.3488 | I9: =IF(F9=0,,H9*(1+F9)*C9-(H9*B9)) -> 0 | J9: =IF(G9=0,IF(F9=0,,H9*(1+F9)*C9-(H9*B9)),H9*(1+G9)*C9-(H9*B9)) -> 0
A10: GO | B10: 0.04 | C10: 0.04 | H10: =PREÇOS!D11 -> 13.3488 | I10: =IF(F10=0,,H10*(1+F10)*C10-(H10*B10)) -> 0 | J10: =IF(G10=0,IF(F10=0,,H10*(1+F10)*C10-(H10*B10)),H10*(1+G10)*C10-(H10*B10)) -> 0
A11: MA | B11: 0.04 | C11: 0.04 | H11: =PREÇOS!D12 -> 13.3488 | I11: =IF(F11=0,,H11*(1+F11)*C11-(H11*B11)) -> 0 | J11: =IF(G11=0,IF(F11=0,,H11*(1+F11)*C11-(H11*B11)),H11*(1+G11)*C11-(H11*B11)) -> 0
A12: MG | B12: 0.04 | C12: 0.18 | D12: 0.25 | F12: 0.3636 | H12: =PREÇOS!D13 -> 13.3488 | I12: =IF(F12=0,,H12*(1+F12)*C12-(H12*B12)) -> 2.7424843 | J12: =IF(G12=0,IF(F12=0,,H12*(1+F12)*C12-(H12*B12)),H12*(1+G12)*C12-(H12*B12)) -> 2.7424843
A13: MS | B13: 0.04 | C13: 0.04 | H13: =PREÇOS!D14 -> 13.3488 | I13: =IF(F13=0,,H13*(1+F13)*C13-(H13*B13)) -> 0 | J13: =IF(G13=0,IF(F13=0,,H13*(1+F13)*C13-(H13*B13)),H13*(1+G13)*C13-(H13*B13)) -> 0
A14: MT | B14: 0.04 | C14: 0.04 | H14: =PREÇOS!D15 -> 13.3488 | I14: =IF(F14=0,,H14*(1+F14)*C14-(H14*B14)) -> 0 | J14: =IF(G14=0,IF(F14=0,,H14*(1+F14)*C14-(H14*B14)),H14*(1+G14)*C14-(H14*B14)) -> 0
A15: PA | B15: 0.04 | C15: 0.04 | H15: =PREÇOS!D16 -> 13.3488 | I15: =IF(F15=0,,H15*(1+F15)*C15-(H15*B15)) -> 0 | J15: =IF(G15=0,IF(F15=0,,H15*(1+F15)*C15-(H15*B15)),H15*(1+G15)*C15-(H15*B15)) -> 0
A16: PB | B16: 0.04 | C16: 0.04 | H16: =PREÇOS!D17 -> 13.3488 | I16: =IF(F16=0,,H16*(1+F16)*C16-(H16*B16)) -> 0 | J16: =IF(G16=0,IF(F16=0,,H16*(1+F16)*C16-(H16*B16)),H16*(1+G16)*C16-(H16*B16)) -> 0
A17: PE | B17: 0.04 | C17: 0.04 | H17: =PREÇOS!D18 -> 13.3488 | I17: =IF(F17=0,,H17*(1+F17)*C17-(H17*B17)) -> 0 | J17: =IF(G17=0,IF(F17=0,,H17*(1+F17)*C17-(H17*B17)),H17*(1+G17)*C17-(H17*B17)) -> 0
A18: PI | B18: 0.04 | C18: 0.04 | H18: =PREÇOS!D19 -> 13.3488 | I18: =IF(F18=0,,H18*(1+F18)*C18-(H18*B18)) -> 0 | J18: =IF(G18=0,IF(F18=0,,H18*(1+F18)*C18-(H18*B18)),H18*(1+G18)*C18-(H18*B18)) -> 0
A19: PR | B19: 0.12 | C19: 0.12 | H19: =PREÇOS!D20 -> 14.562327 | I19: =IF(F19=0,,H19*(1+F19)*C19-(H19*B19)) -> 0 | J19: =IF(G19=0,IF(F19=0,,H19*(1+F19)*C19-(H19*B19)),H19*(1+G19)*C19-(H19*B19)) -> 0
A20: RJ | B20: 0.04 | C20: 0.22 | D20: 0.352 | F20: 0.664 | H20: =PREÇOS!D21 -> 13.3488 | I20: =IF(F20=0,,H20*(1+F20)*C20-(H20*B20)) -> 4.3527767 | J20: =IF(G20=0,IF(F20=0,,H20*(1+F20)*C20-(H20*B20)),H20*(1+G20)*C20-(H20*B20)) -> 4.3527767
A21: RN | B21: 0.04 | C21: 0.04 | H21: =PREÇOS!D22 -> 13.3488 | I21: =IF(F21=0,,H21*(1+F21)*C21-(H21*B21)) -> 0 | J21: =IF(G21=0,IF(F21=0,,H21*(1+F21)*C21-(H21*B21)),H21*(1+G21)*C21-(H21*B21)) -> 0
A22: RO | B22: 0.04 | C22: 0.04 | H22: =PREÇOS!D23 -> 13.3488 | I22: =IF(F22=0,,H22*(1+F22)*C22-(H22*B22)) -> 0 | J22: =IF(G22=0,IF(F22=0,,H22*(1+F22)*C22-(H22*B22)),H22*(1+G22)*C22-(H22*B22)) -> 0
A23: RR | B23: 0.04 | C23: 0.04 | H23: =PREÇOS!D24 -> 13.3488 | I23: =IF(F23=0,,H23*(1+F23)*C23-(H23*B23)) -> 0 | J23: =IF(G23=0,IF(F23=0,,H23*(1+F23)*C23-(H23*B23)),H23*(1+G23)*C23-(H23*B23)) -> 0
A24: RS | B24: 0.04 | C24: 0.04 | H24: =PREÇOS!D25 -> 13.3488 | I24: =IF(F24=0,,H24*(1+F24)*C24-(H24*B24)) -> 0 | J24: =IF(G24=0,IF(F24=0,,H24*(1+F24)*C24-(H24*B24)),H24*(1+G24)*C24-(H24*B24)) -> 0
A25: SC | B25: 0.04 | C25: 0.04 | H25: =PREÇOS!D26 -> 13.3488 | I25: =IF(F25=0,,H25*(1+F25)*C25-(H25*B25)) -> 0 | J25: =IF(G25=0,IF(F25=0,,H25*(1+F25)*C25-(H25*B25)),H25*(1+G25)*C25-(H25*B25)) -> 0
A26: SE | B26: 0.04 | C26: 0.04 | H26: =PREÇOS!D27 -> 13.3488 | I26: =IF(F26=0,,H26*(1+F26)*C26-(H26*B26)) -> 0 | J26: =IF(G26=0,IF(F26=0,,H26*(1+F26)*C26-(H26*B26)),H26*(1+G26)*C26-(H26*B26)) -> 0
A27: SP | B27: 0.04 | C27: 0.18 | D27: 0.7539 | F27: 0.7539 | H27: =PREÇOS!D28 -> 13.3488 | I27: =IF(F27=0,,H27*(1+F27)*C27-(H27*B27)) -> 3.6802909 | J27: =IF(G27=0,IF(F27=0,,H27*(1+F27)*C27-(H27*B27)),H27*(1+G27)*C27-(H27*B27)) -> 3.6802909 | K27: =J27/H27 -> 0.275702
A28: SP/Atacado | B28: =B27 -> 0.04 | C28: =C27 -> 0.18 | D28: =D27 -> 0.7539 | E28: =E27 -> 0 | F28: =F27 -> 0.7539 | G28: =G27 -> 0 | H28: =PREÇOS!D29 -> 13.3488 | I28: =IF(F28=0,,H28*(1+F28)*C28-(H28*B28)) -> 3.6802909 | J28: =IF(G28=0,IF(F28=0,,H28*(1+F28)*C28-(H28*B28)),H28*(1+G28)*C28-(H28*B28)) -> 3.6802909
A29: TO | B29: 0.04 | C29: 0.04 | H29: =PREÇOS!D30 -> 13.3488 | I29: =IF(F29=0,,H29*(1+F29)*C29-(H29*B29)) -> 0 | J29: =IF(G29=0,IF(F29=0,,H29*(1+F29)*C29-(H29*B29)),H29*(1+G29)*C29-(H29*B29)) -> 0
A30: EX | H30: =PREÇOS!D31 -> 11.580084 | I30: =IF(F30=0,,H30*(1+F30)*C30-(H30*B30)) -> 0 | J30: =IF(G30=0,IF(F30=0,,H30*(1+F30)*C30-(H30*B30)),H30*(1+G30)*C30-(H30*B30)) -> 0

Sheet ST PAPAPASTA
A1: Estado | B1: Aliquota interestadual | C1: Aliquota interna | D1: MVA (normal) | E1: MVA (simples) | F1: Ajustada (normal) | G1: Ajustada (simples) | H1: Preço | I1: ST Normal | J1: ST Simples
A2: AC | B2: 0.07 | C2: 0.07 | H2: =PREÇOS!E3 -> 8.1556129 | I2: =IF(F2=0,,H2*(1+F2)*C2-(H2*B2)) -> 0 | J2: =IF(G2=0,IF(F2=0,,H2*(1+F2)*C2-(H2*B2)),H2*(1+G2)*C2-(H2*B2)) -> 0
A3: AL | B3: 0.07 | C3: 0.19 | D3: 0.2 | F3: 0.361 | H3: =PREÇOS!E4 -> 8.1556129 | I3: =IF(F3=0,,H3*(1+F3)*C3-(H3*B3)) -> 1.538067 | J3: =IF(G3=0,IF(F3=0,,H3*(1+F3)*C3-(H3*B3)),H3*(1+G3)*C3-(H3*B3)) -> 1.538067
A4: AM | B4: 0.07 | C4: 0.07 | H4: =PREÇOS!E5 -> 8.1556129 | I4: =IF(F4=0,,H4*(1+F4)*C4-(H4*B4)) -> 0 | J4: =IF(G4=0,IF(F4=0,,H4*(1+F4)*C4-(H4*B4)),H4*(1+G4)*C4-(H4*B4)) -> 0
A5: AP | B5: 0.07 | C5: 0.18 | D5: 0.38 | F5: 0.5651 | H5: =PREÇOS!E6 -> 8.1556129 | I5: =IF(F5=0,,H5*(1+F5)*C5-(H5*B5)) -> 1.7266901 | J5: =IF(G5=0,IF(F5=0,,H5*(1+F5)*C5-(H5*B5)),H5*(1+G5)*C5-(H5*B5)) -> 1.7266901
A6: BA | B6: 0.07 | C6: 0.07 | H6: =PREÇOS!E7 -> 8.1556129 | I6: =IF(F6=0,,H6*(1+F6)*C6-(H6*B6)) -> 0 | J6: =IF(G6=0,IF(F6=0,,H6*(1+F6)*C6-(H6*B6)),H6*(1+G6)*C6-(H6*B6)) -> 0
A7: CE | B7: 0.07 | C7: 0.07 | H7: =PREÇOS!E8 -> 8.1556129 | I7: =IF(F7=0,,H7*(1+F7)*C7-(H7*B7)) -> 0 | J7: =IF(G7=0,IF(F7=0,,H7*(1+F7)*C7-(H7*B7)),H7*(1+G7)*C7-(H7*B7)) -> 0
A8: DF | B8: 0.07 | C8: 0.07 | H8: =PREÇOS!E9 -> 8.1556129 | I8: =IF(F8=0,,H8*(1+F8)*C8-(H8*B8)) -> 0 | J8: =IF(G8=0,IF(F8=0,,H8*(1+F8)*C8-(H8*B8)),H8*(1+G8)*C8-(H8*B8)) -> 0
A9: ES | B9: 0.07 | C9: 0.07 | H9: =PREÇOS!E10 -> 8.1556129 | I9: =IF(F9=0,,H9*(1+F9)*C9-(H9*B9)) -> 0 | J9: =IF(G9=0,IF(F9=0,,H9*(1+F9)*C9-(H9*B9)),H9*(1+G9)*C9-(H9*B9)) -> 0
A10: GO | B10: 0.07 | C10: 0.07 | H10: =PREÇOS!E11 -> 8.1556129 | I10: =IF(F10=0,,H10*(1+F10)*C10-(H10*B10)) -> 0 | J10: =IF(G10=0,IF(F10=0,,H10*(1+F10)*C10-(H10*B10)),H10*(1+G10)*C10-(H10*B10)) -> 0
A11: MA | B11: 0.07 | C11: 0.07 | H11: =PREÇOS!E12 -> 8.1556129 | I11: =IF(F11=0,,H11*(1+F11)*C11-(H11*B11)) -> 0 | J11: =IF(G11=0,IF(F11=0,,H11*(1+F11)*C11-(H11*B11)),H11*(1+G11)*C11-(H11*B11)) -> 0
A12: MG | B12: 0.12 | C12: 0.18 | D12: 0.35 | F12: 0.35 | H12: =PREÇOS!E13 -> 8.619 | I12: =IF(F12=0,,H12*(1+F12)*C12-(H12*B12)) -> 1.060137 | J12: =IF(G12=0,IF(F12=0,,H12*(1+F12)*C12-(H12*B12)),H12*(1+G12)*C12-(H12*B12)) -> 1.060137
A13: MS | B13: 0.07 | C13: 0.07 | H13: =PREÇOS!E14 -> 8.1556129 | I13: =IF(F13=0,,H13*(1+F13)*C13-(H13*B13)) -> 0 | J13: =IF(G13=0,IF(F13=0,,H13*(1+F13)*C13-(H13*B13)),H13*(1+G13)*C13-(H13*B13)) -> 0
A14: MT | B14: 0.07 | C14: 0.17 | D14: 0.3545 | F14: 0.3545 | H14: =PREÇOS!E15 -> 8.1556129 | I14: =IF(F14=0,,H14*(1+F14)*C14-(H14*B14)) -> 1.3070593 | J14: =IF(G14=0,IF(F14=0,,H14*(1+F14)*C14-(H14*B14)),H14*(1+G14)*C14-(H14*B14)) -> 1.3070593
A15: PA | B15: 0.07 | C15: 0.07 | H15: =PREÇOS!E16 -> 8.1556129 | I15: =IF(F15=0,,H15*(1+F15)*C15-(H15*B15)) -> 0 | J15: =IF(G15=0,IF(F15=0,,H15*(1+F15)*C15-(H15*B15)),H15*(1+G15)*C15-(H15*B15)) -> 0
A16: PB | B16: 0.07 | C16: 0.07 | H16: =PREÇOS!E17 -> 8.1556129 | I16: =IF(F16=0,,H16*(1+F16)*C16-(H16*B16)) -> 0 | J16: =IF(G16=0,IF(F16=0,,H16*(1+F16)*C16-(H16*B16)),H16*(1+G16)*C16-(H16*B16)) -> 0
A17: PE | B17: 0.07 | C17: 0.07 | H17: =PREÇOS!E18 -> 8.1556129 | I17: =IF(F17=0,,H17*(1+F17)*C17-(H17*B17)) -> 0 | J17: =IF(G17=0,IF(F17=0,,H17*(1+F17)*C17-(H17*B17)),H17*(1+G17)*C17-(H17*B17)) -> 0
A18: PI | B18: 0.07 | C18: 0.07 | H18: =PREÇOS!E19 -> 8.1556129 | I18: =IF(F18=0,,H18*(1+F18)*C18-(H18*B18)) -> 0 | J18: =IF(G18=0,IF(F18=0,,H18*(1+F18)*C18-(H18*B18)),H18*(1+G18)*C18-(H18*B18)) -> 0
A19: PR | B19: 0.12 | C19: 0.12 | H19: =PREÇOS!E20 -> 8.619 | I19: =IF(F19=0,,H19*(1+F19)*C19-(H19*B19)) -> 0 | J19: =IF(G19=0,IF(F19=0,,H19*(1+F19)*C19-(H19*B19)),H19*(1+G19)*C19-(H19*B19)) -> 0
A20: RJ | B20: 0.12 | C20: 0.12 | H20: =PREÇOS!E21 -> 8.619 | I20: =IF(F20=0,,H20*(1+F20)*C20-(H20*B20)) -> 0 | J20: =IF(G20=0,IF(F20=0,,H20*(1+F20)*C20-(H20*B20)),H20*(1+G20)*C20-(H20*B20)) -> 0
A21: RN | B21: 0.07 | C21: 0.07 | H21: =PREÇOS!E22 -> 8.1556129 | I21: =IF(F21=0,,H21*(1+F21)*C21-(H21*B21)) -> 0 | J21: =IF(G21=0,IF(F21=0,,H21*(1+F21)*C21-(H21*B21)),H21*(1+G21)*C21-(H21*B21)) -> 0
A22: RO | B22: 0.07 | C22: 0.07 | H22: =PREÇOS!E23 -> 8.1556129 | I22: =IF(F22=0,,H22*(1+F22)*C22-(H22*B22)) -> 0 | J22: =IF(G22=0,IF(F22=0,,H22*(1+F22)*C22-(H22*B22)),H22*(1+G22)*C22-(H22*B22)) -> 0
A23: RR | B23: 0.07 | C23: 0.07 | H23: =PREÇOS!E24 -> 8.1556129 | I23: =IF(F23=0,,H23*(1+F23)*C23-(H23*B23)) -> 0 | J23: =IF(G23=0,IF(F23=0,,H23*(1+F23)*C23-(H23*B23)),H23*(1+G23)*C23-(H23*B23)) -> 0
A24: RS | B24: 0.12 | C24: 0.12 | H24: =PREÇOS!E25 -> 8.619 | I24: =IF(F24=0,,H24*(1+F24)*C24-(H24*B24)) -> 0 | J24: =IF(G24=0,IF(F24=0,,H24*(1+F24)*C24-(H24*B24)),H24*(1+G24)*C24-(H24*B24)) -> 0
A25: SC | B25: 0.12 | C25: 0.12 | H25: =PREÇOS!E26 -> 8.619 | I25: =IF(F25=0,,H25*(1+F25)*C25-(H25*B25)) -> 0 | J25: =IF(G25=0,IF(F25=0,,H25*(1+F25)*C25-(H25*B25)),H25*(1+G25)*C25-(H25*B25)) -> 0
A26: SE | B26: 0.07 | C26: 0.07 | H26: =PREÇOS!E27 -> 8.1556129 | I26: =IF(F26=0,,H26*(1+F26)*C26-(H26*B26)) -> 0 | J26: =IF(G26=0,IF(F26=0,,H26*(1+F26)*C26-(H26*B26)),H26*(1+G26)*C26-(H26*B26)) -> 0
A27: SP | B27: 0.12 | C27: 0.12 | H27: =PREÇOS!E28 -> 8.619 | I27: =IF(F27=0,,H27*(1+F27)*C27-(H27*B27)) -> 0 | J27: =IF(G27=0,IF(F27=0,,H27*(1+F27)*C27-(H27*B27)),H27*(1+G27)*C27-(H27*B27)) -> 0
A28: SP/Atacado | B28: =B27 -> 0.12 | C28: =C27 -> 0.12 | D28: =D27 -> 0 | E28: =E27 -> 0 | F28: =F27 -> 0 | G28: =G27 -> 0 | H28: =PREÇOS!E29 -> 8.619 | I28: =IF(F28=0,,H28*(1+F28)*C28-(H28*B28)) -> 0 | J28: =IF(G28=0,IF(F28=0,,H28*(1+F28)*C28-(H28*B28)),H28*(1+G28)*C28-(H28*B28)) -> 0
A29: TO | B29: 0.07 | C29: 0.07 | H29: =PREÇOS!E30 -> 8.1556129 | I29: =IF(F29=0,,H29*(1+F29)*C29-(H29*B29)) -> 0 | J29: =IF(G29=0,IF(F29=0,,H29*(1+F29)*C29-(H29*B29)),H29*(1+G29)*C29-(H29*B29)) -> 0
A30: EX | H30: =PREÇOS!E31 -> 6.4225452 | I30: =IF(F30=0,,H30*(1+F30)*C30-(H30*B30)) -> 0 | J30: =IF(G30=0,IF(F30=0,,H30*(1+F30)*C30-(H30*B30)),H30*(1+G30)*C30-(H30*B30)) -> 0

Sheet ST PALITINHOS
A1: Estado | B1: Aliquota interestadual | C1: Aliquota interna | D1: MVA (normal) | E1: MVA (simples) | F1: Ajustada (normal) | G1: Ajustada (simples) | H1: Preço | I1: ST Normal | J1: ST Simples
A2: AC | B2: 0.07 | C2: 0.07 | H2: =PREÇOS!C3 -> 3.7198452 | I2: =IF(F2=0,,H2*(1+F2)*C2-(H2*B2)) -> 0 | J2: =IF(G2=0,IF(F2=0,,H2*(1+F2)*C2-(H2*B2)),H2*(1+G2)*C2-(H2*B2)) -> 0
A3: AL | B3: 0.07 | C3: 0.19 | D3: 0.5432 | F3: 0.794 | H3: =PREÇOS!C4 -> 3.7198452 | I3: =IF(F3=0,,H3*(1+F3)*C3-(H3*B3)) -> 1.0075573 | J3: =IF(G3=0,IF(F3=0,,H3*(1+F3)*C3-(H3*B3)),H3*(1+G3)*C3-(H3*B3)) -> 1.0075573
A4: AM | B4: 0.07 | C4: 0.18 | H4: =PREÇOS!C5 -> 3.7198452 | I4: =IF(F4=0,,H4*(1+F4)*C4-(H4*B4)) -> 0 | J4: =IF(G4=0,IF(F4=0,,H4*(1+F4)*C4-(H4*B4)),H4*(1+G4)*C4-(H4*B4)) -> 0
A5: AP | B5: 0.07 | C5: 0.18 | D5: 0.41 | F5: 0.5991 | H5: =PREÇOS!C6 -> 3.7198452 | I5: =IF(F5=0,,H5*(1+F5)*C5-(H5*B5)) -> 0.81032363 | J5: =IF(G5=0,IF(F5=0,,H5*(1+F5)*C5-(H5*B5)),H5*(1+G5)*C5-(H5*B5)) -> 0.81032363
A6: BA | B6: 0.07 | C6: 0.07 | H6: =PREÇOS!C7 -> 3.7198452 | I6: =IF(F6=0,,H6*(1+F6)*C6-(H6*B6)) -> 0 | J6: =IF(G6=0,IF(F6=0,,H6*(1+F6)*C6-(H6*B6)),H6*(1+G6)*C6-(H6*B6)) -> 0
A7: CE | B7: 0.07 | C7: 0.07 | H7: =PREÇOS!C8 -> 3.7198452 | I7: =IF(F7=0,,H7*(1+F7)*C7-(H7*B7)) -> 0 | J7: =IF(G7=0,IF(F7=0,,H7*(1+F7)*C7-(H7*B7)),H7*(1+G7)*C7-(H7*B7)) -> 0
A8: DF | B8: 0.07 | C8: 0.07 | H8: =PREÇOS!C9 -> 3.7198452 | I8: =IF(F8=0,,H8*(1+F8)*C8-(H8*B8)) -> 0 | J8: =IF(G8=0,IF(F8=0,,H8*(1+F8)*C8-(H8*B8)),H8*(1+G8)*C8-(H8*B8)) -> 0
A9: ES | B9: 0.07 | C9: 0.07 | H9: =PREÇOS!C10 -> 3.7198452 | I9: =IF(F9=0,,H9*(1+F9)*C9-(H9*B9)) -> 0 | J9: =IF(G9=0,IF(F9=0,,H9*(1+F9)*C9-(H9*B9)),H9*(1+G9)*C9-(H9*B9)) -> 0
A10: GO | B10: 0.07 | C10: 0.07 | H10: =PREÇOS!C11 -> 3.7198452 | I10: =IF(F10=0,,H10*(1+F10)*C10-(H10*B10)) -> 0 | J10: =IF(G10=0,IF(F10=0,,H10*(1+F10)*C10-(H10*B10)),H10*(1+G10)*C10-(H10*B10)) -> 0
A11: MA | B11: 0.07 | C11: 0.07 | H11: =PREÇOS!C12 -> 3.7198452 | I11: =IF(F11=0,,H11*(1+F11)*C11-(H11*B11)) -> 0 | J11: =IF(G11=0,IF(F11=0,,H11*(1+F11)*C11-(H11*B11)),H11*(1+G11)*C11-(H11*B11)) -> 0
A12: MG | B12: 0.12 | C12: 0.18 | D12: 0.4 | F12: 0.5024 | H12: =PREÇOS!C13 -> 3.9312 | I12: =IF(F12=0,,H12*(1+F12)*C12-(H12*B12)) -> 0.59137828 | J12: =IF(G12=0,IF(F12=0,,H12*(1+F12)*C12-(H12*B12)),H12*(1+G12)*C12-(H12*B12)) -> 0.59137828
A13: MS | B13: 0.07 | C13: 0.07 | H13: =PREÇOS!C14 -> 3.7198452 | I13: =IF(F13=0,,H13*(1+F13)*C13-(H13*B13)) -> 0 | J13: =IF(G13=0,IF(F13=0,,H13*(1+F13)*C13-(H13*B13)),H13*(1+G13)*C13-(H13*B13)) -> 0
A14: MT | B14: 0.07 | C14: 0.17 | D14: 0.4552 | F14: 0.6305 | H14: =PREÇOS!C15 -> 3.7198452 | I14: =IF(F14=0,,H14*(1+F14)*C14-(H14*B14)) -> 0.77069612 | J14: =IF(G14=0,IF(F14=0,,H14*(1+F14)*C14-(H14*B14)),H14*(1+G14)*C14-(H14*B14)) -> 0.77069612
A15: PA | B15: 0.07 | C15: 0.07 | H15: =PREÇOS!C16 -> 3.7198452 | I15: =IF(F15=0,,H15*(1+F15)*C15-(H15*B15)) -> 0 | J15: =IF(G15=0,IF(F15=0,,H15*(1+F15)*C15-(H15*B15)),H15*(1+G15)*C15-(H15*B15)) -> 0
A16: PB | B16: 0.07 | C16: 0.07 | H16: =PREÇOS!C17 -> 3.7198452 | I16: =IF(F16=0,,H16*(1+F16)*C16-(H16*B16)) -> 0 | J16: =IF(G16=0,IF(F16=0,,H16*(1+F16)*C16-(H16*B16)),H16*(1+G16)*C16-(H16*B16)) -> 0
A17: PE | B17: 0.07 | C17: 0.07 | H17: =PREÇOS!C18 -> 3.7198452 | I17: =IF(F17=0,,H17*(1+F17)*C17-(H17*B17)) -> 0 | J17: =IF(G17=0,IF(F17=0,,H17*(1+F17)*C17-(H17*B17)),H17*(1+G17)*C17-(H17*B17)) -> 0
A18: PI | B18: 0.07 | C18: 0.07 | H18: =PREÇOS!C19 -> 3.7198452 | I18: =IF(F18=0,,H18*(1+F18)*C18-(H18*B18)) -> 0 | J18: =IF(G18=0,IF(F18=0,,H18*(1+F18)*C18-(H18*B18)),H18*(1+G18)*C18-(H18*B18)) -> 0
A19: PR | B19: 0.12 | C19: 0.195 | D19: 0.5432 | E19: 0.163 | F19: 0.687 | G19: 0.1968 | H19: =PREÇOS!C20 -> 3.9312 | I19: =IF(F19=0,,H19*(1+F19)*C19-(H19*B19)) -> 0.82148321 | J19: =IF(G19=0,IF(F19=0,,H19*(1+F19)*C19-(H19*B19)),H19*(1+G19)*C19-(H19*B19)) -> 0.44570373
A20: RJ | B20: 0.12 | C20: 0.22 | D20: 0.4698 | F20: 0.6582 | H20: =PREÇOS!C21 -> 3.9312 | I20: =IF(F20=0,,H20*(1+F20)*C20-(H20*B20)) -> 0.96237348 | J20: =IF(G20=0,IF(F20=0,,H20*(1+F20)*C20-(H20*B20)),H20*(1+G20)*C20-(H20*B20)) -> 0.96237348
A21: RN | B21: 0.07 | C21: 0.07 | H21: =PREÇOS!C22 -> 3.7198452 | I21: =IF(F21=0,,H21*(1+F21)*C21-(H21*B21)) -> 0 | J21: =IF(G21=0,IF(F21=0,,H21*(1+F21)*C21-(H21*B21)),H21*(1+G21)*C21-(H21*B21)) -> 0
A22: RO | B22: 0.07 | C22: 0.07 | H22: =PREÇOS!C23 -> 3.7198452 | I22: =IF(F22=0,,H22*(1+F22)*C22-(H22*B22)) -> 0 | J22: =IF(G22=0,IF(F22=0,,H22*(1+F22)*C22-(H22*B22)),H22*(1+G22)*C22-(H22*B22)) -> 0
A23: RR | B23: 0.07 | C23: 0.07 | H23: =PREÇOS!C24 -> 3.7198452 | I23: =IF(F23=0,,H23*(1+F23)*C23-(H23*B23)) -> 0 | J23: =IF(G23=0,IF(F23=0,,H23*(1+F23)*C23-(H23*B23)),H23*(1+G23)*C23-(H23*B23)) -> 0
A24: RS | B24: 0.12 | C24: 0.12 | H24: =PREÇOS!C25 -> 3.9312 | I24: =IF(F24=0,,H24*(1+F24)*C24-(H24*B24)) -> 0 | J24: =IF(G24=0,IF(F24=0,,H24*(1+F24)*C24-(H24*B24)),H24*(1+G24)*C24-(H24*B24)) -> 0
A25: SC | B25: 0.12 | C25: 0.12 | H25: =PREÇOS!C26 -> 3.9312 | I25: =IF(F25=0,,H25*(1+F25)*C25-(H25*B25)) -> 0 | J25: =IF(G25=0,IF(F25=0,,H25*(1+F25)*C25-(H25*B25)),H25*(1+G25)*C25-(H25*B25)) -> 0
A26: SE | B26: 0.07 | C26: 0.07 | H26: =PREÇOS!C27 -> 3.7198452 | I26: =IF(F26=0,,H26*(1+F26)*C26-(H26*B26)) -> 0 | J26: =IF(G26=0,IF(F26=0,,H26*(1+F26)*C26-(H26*B26)),H26*(1+G26)*C26-(H26*B26)) -> 0
A27: SP | B27: 0.12 | C27: 0.18 | H27: =PREÇOS!C28 -> 3.9312 | I27: =IF(F27=0,,H27*(1+F27)*C27-(H27*B27)) -> 0 | J27: =IF(G27=0,IF(F27=0,,H27*(1+F27)*C27-(H27*B27)),H27*(1+G27)*C27-(H27*B27)) -> 0 | K27: comunicado enviado 1/26 - suspensão da ST para palitinhos
A28: SP/Atacado | B28: =B27 -> 0.12 | C28: =C27 -> 0.18 | D28: =D27 -> 0 | E28: =E27 -> 0 | F28: =F27 -> 0 | G28: =G27 -> 0 | H28: =PREÇOS!C29 -> 3.9312 | I28: =IF(F28=0,,H28*(1+F28)*C28-(H28*B28)) -> 0 | J28: =IF(G28=0,IF(F28=0,,H28*(1+F28)*C28-(H28*B28)),H28*(1+G28)*C28-(H28*B28)) -> 0
A29: TO | B29: 0.07 | C29: 0.07 | H29: =PREÇOS!C30 -> 3.7198452 | I29: =IF(F29=0,,H29*(1+F29)*C29-(H29*B29)) -> 0 | J29: =IF(G29=0,IF(F29=0,,H29*(1+F29)*C29-(H29*B29)),H29*(1+G29)*C29-(H29*B29)) -> 0
A30: EX | H30: =PREÇOS!C31 -> 2.9293781 | I30: =IF(F30=0,,H30*(1+F30)*C30-(H30*B30)) -> 0 | J30: =IF(G30=0,IF(F30=0,,H30*(1+F30)*C30-(H30*B30)),H30*(1+G30)*C30-(H30*B30)) -> 0

Sheet ST BISCOTTI
A1: Estado | B1: Aliquota interestadual | C1: Aliquota interna | D1: MVA (normal) | E1: MVA (simples) | F1: Ajustada (normal) | G1: Ajustada (simples) | H1: Preço | I1: ST Normal | J1: ST Simples
A2: AC | B2: 0.07 | C2: 0.19 | H2: =PREÇOS!H3 -> 8.5047742 | I2: =IF(F2=0,,H2*(1+F2)*C2-(H2*B2)) -> 0 | J2: =IF(G2=0,IF(F2=0,,H2*(1+F2)*C2-(H2*B2)),H2*(1+G2)*C2-(H2*B2)) -> 0
A3: AL | B3: 0.07 | C3: 0.2 | F3: 0.5113 | H3: =PREÇOS!H4 -> 8.5047742 | I3: =IF(F3=0,,H3*(1+F3)*C3-(H3*B3)) -> 1.9753189 | J3: =IF(G3=0,IF(F3=0,,H3*(1+F3)*C3-(H3*B3)),H3*(1+G3)*C3-(H3*B3)) -> 1.9753189
A4: AM | B4: 0.07 | C4: 0.2 | H4: =PREÇOS!H5 -> 8.5047742 | I4: =IF(F4=0,,H4*(1+F4)*C4-(H4*B4)) -> 0 | J4: =IF(G4=0,IF(F4=0,,H4*(1+F4)*C4-(H4*B4)),H4*(1+G4)*C4-(H4*B4)) -> 0
A5: AP | B5: 0.07 | C5: 0.18 | F5: 0.5198 | H5: =PREÇOS!H6 -> 8.5047742 | I5: =IF(F5=0,,H5*(1+F5)*C5-(H5*B5)) -> 1.7312659 | J5: =IF(G5=0,IF(F5=0,,H5*(1+F5)*C5-(H5*B5)),H5*(1+G5)*C5-(H5*B5)) -> 1.7312659
A6: BA | B6: 0.07 | C6: 0.19 | H6: =PREÇOS!H7 -> 8.5047742 | I6: =IF(F6=0,,H6*(1+F6)*C6-(H6*B6)) -> 0 | J6: =IF(G6=0,IF(F6=0,,H6*(1+F6)*C6-(H6*B6)),H6*(1+G6)*C6-(H6*B6)) -> 0
A7: CE | B7: 0.07 | C7: 0.2 | H7: =PREÇOS!H8 -> 8.5047742 | I7: =IF(F7=0,,H7*(1+F7)*C7-(H7*B7)) -> 0 | J7: =IF(G7=0,IF(F7=0,,H7*(1+F7)*C7-(H7*B7)),H7*(1+G7)*C7-(H7*B7)) -> 0
A8: DF | B8: 0.07 | C8: 0.18 | H8: =PREÇOS!H9 -> 8.5047742 | I8: =IF(F8=0,,H8*(1+F8)*C8-(H8*B8)) -> 0 | J8: =IF(G8=0,IF(F8=0,,H8*(1+F8)*C8-(H8*B8)),H8*(1+G8)*C8-(H8*B8)) -> 0
A9: ES | B9: 0.07 | C9: 0.17 | H9: =PREÇOS!H10 -> 8.5047742 | I9: =IF(F9=0,,H9*(1+F9)*C9-(H9*B9)) -> 0 | J9: =IF(G9=0,IF(F9=0,,H9*(1+F9)*C9-(H9*B9)),H9*(1+G9)*C9-(H9*B9)) -> 0
A10: GO | B10: 0.07 | C10: 0.17 | H10: =PREÇOS!H11 -> 8.5047742 | I10: =IF(F10=0,,H10*(1+F10)*C10-(H10*B10)) -> 0 | J10: =IF(G10=0,IF(F10=0,,H10*(1+F10)*C10-(H10*B10)),H10*(1+G10)*C10-(H10*B10)) -> 0
A11: MA | B11: 0.07 | C11: 0.2 | H11: =PREÇOS!H12 -> 8.5047742 | I11: =IF(F11=0,,H11*(1+F11)*C11-(H11*B11)) -> 0 | J11: =IF(G11=0,IF(F11=0,,H11*(1+F11)*C11-(H11*B11)),H11*(1+G11)*C11-(H11*B11)) -> 0
A12: MG | B12: 0.12 | C12: 0.12 | F12: 0.25 | H12: =PREÇOS!H13 -> 8.988 | I12: =IF(F12=0,,H12*(1+F12)*C12-(H12*B12)) -> 0.26964 | J12: =IF(G12=0,IF(F12=0,,H12*(1+F12)*C12-(H12*B12)),H12*(1+G12)*C12-(H12*B12)) -> 0.26964
A13: MS | B13: 0.07 | C13: 0.17 | H13: =PREÇOS!H14 -> 8.5047742 | I13: =IF(F13=0,,H13*(1+F13)*C13-(H13*B13)) -> 0 | J13: =IF(G13=0,IF(F13=0,,H13*(1+F13)*C13-(H13*B13)),H13*(1+G13)*C13-(H13*B13)) -> 0
A14: MT | B14: 0.07 | C14: 0.17 | F14: 0.3978 | H14: =PREÇOS!H15 -> 8.5047742 | I14: =IF(F14=0,,H14*(1+F14)*C14-(H14*B14)) -> 1.4256213 | J14: =IF(G14=0,IF(F14=0,,H14*(1+F14)*C14-(H14*B14)),H14*(1+G14)*C14-(H14*B14)) -> 1.4256213
A15: PA | B15: 0.07 | C15: 0.19 | H15: =PREÇOS!H16 -> 8.5047742 | I15: =IF(F15=0,,H15*(1+F15)*C15-(H15*B15)) -> 0 | J15: =IF(G15=0,IF(F15=0,,H15*(1+F15)*C15-(H15*B15)),H15*(1+G15)*C15-(H15*B15)) -> 0
A16: PB | B16: 0.07 | C16: 0.18 | H16: =PREÇOS!H17 -> 8.5047742 | I16: =IF(F16=0,,H16*(1+F16)*C16-(H16*B16)) -> 0 | J16: =IF(G16=0,IF(F16=0,,H16*(1+F16)*C16-(H16*B16)),H16*(1+G16)*C16-(H16*B16)) -> 0
A17: PE | B17: 0.07 | C17: 0.18 | H17: =PREÇOS!H18 -> 8.5047742 | I17: =IF(F17=0,,H17*(1+F17)*C17-(H17*B17)) -> 0 | J17: =IF(G17=0,IF(F17=0,,H17*(1+F17)*C17-(H17*B17)),H17*(1+G17)*C17-(H17*B17)) -> 0
A18: PI | B18: 0.07 | C18: 0.21 | H18: =PREÇOS!H19 -> 8.5047742 | I18: =IF(F18=0,,H18*(1+F18)*C18-(H18*B18)) -> 0 | J18: =IF(G18=0,IF(F18=0,,H18*(1+F18)*C18-(H18*B18)),H18*(1+G18)*C18-(H18*B18)) -> 0
A19: PR | B19: 0.12 | C19: 0.12 | H19: =PREÇOS!H20 -> 8.988 | I19: =IF(F19=0,,H19*(1+F19)*C19-(H19*B19)) -> 0 | J19: =IF(G19=0,IF(F19=0,,H19*(1+F19)*C19-(H19*B19)),H19*(1+G19)*C19-(H19*B19)) -> 0
A20: RJ | B20: 0.12 | C20: 0.22 | F20: 0.5253 | H20: =PREÇOS!H21 -> 8.988 | I20: =IF(F20=0,,H20*(1+F20)*C20-(H20*B20)) -> 1.9375072 | J20: =IF(G20=0,IF(F20=0,,H20*(1+F20)*C20-(H20*B20)),H20*(1+G20)*C20-(H20*B20)) -> 1.9375072
A21: RN | B21: 0.07 | C21: 0.2 | H21: =PREÇOS!H22 -> 8.5047742 | I21: =IF(F21=0,,H21*(1+F21)*C21-(H21*B21)) -> 0 | J21: =IF(G21=0,IF(F21=0,,H21*(1+F21)*C21-(H21*B21)),H21*(1+G21)*C21-(H21*B21)) -> 0
A22: RO | B22: 0.07 | C22: 0.175 | H22: =PREÇOS!H23 -> 8.5047742 | I22: =IF(F22=0,,H22*(1+F22)*C22-(H22*B22)) -> 0 | J22: =IF(G22=0,IF(F22=0,,H22*(1+F22)*C22-(H22*B22)),H22*(1+G22)*C22-(H22*B22)) -> 0
A23: RR | B23: 0.07 | C23: 0.2 | H23: =PREÇOS!H24 -> 8.5047742 | I23: =IF(F23=0,,H23*(1+F23)*C23-(H23*B23)) -> 0 | J23: =IF(G23=0,IF(F23=0,,H23*(1+F23)*C23-(H23*B23)),H23*(1+G23)*C23-(H23*B23)) -> 0
A24: RS | B24: 0.12 | C24: 0.17 | H24: =PREÇOS!H25 -> 8.988 | I24: =IF(F24=0,,H24*(1+F24)*C24-(H24*B24)) -> 0 | J24: =IF(G24=0,IF(F24=0,,H24*(1+F24)*C24-(H24*B24)),H24*(1+G24)*C24-(H24*B24)) -> 0
A25: SC | B25: 0.12 | C25: 0.17 | H25: =PREÇOS!H26 -> 8.988 | I25: =IF(F25=0,,H25*(1+F25)*C25-(H25*B25)) -> 0 | J25: =IF(G25=0,IF(F25=0,,H25*(1+F25)*C25-(H25*B25)),H25*(1+G25)*C25-(H25*B25)) -> 0
A26: SE | B26: 0.07 | C26: 0.2 | H26: =PREÇOS!H27 -> 8.5047742 | I26: =IF(F26=0,,H26*(1+F26)*C26-(H26*B26)) -> 0 | J26: =IF(G26=0,IF(F26=0,,H26*(1+F26)*C26-(H26*B26)),H26*(1+G26)*C26-(H26*B26)) -> 0
A27: SP | B27: 0.12 | C27: 0.18 | D27: 0.6077 | F27: 0.6077 | H27: =PREÇOS!H28 -> 8.988 | I27: =IF(F27=0,,H27*(1+F27)*C27-(H27*B27)) -> 1.5224414 | J27: =IF(G27=0,IF(F27=0,,H27*(1+F27)*C27-(H27*B27)),H27*(1+G27)*C27-(H27*B27)) -> 1.5224414 | K27: =J27/H27 -> 0.169386
A28: SP/Atacado | B28: =B27 -> 0.12 | C28: =C27 -> 0.18 | D28: 0.6077 | E28: =E27 -> 0 | F28: 0.6077 | G28: =G27 -> 0 | H28: =PREÇOS!H29 -> 8.988 | I28: =IF(F28=0,,H28*(1+F28)*C28-(H28*B28)) -> 1.5224414 | J28: =IF(G28=0,IF(F28=0,,H28*(1+F28)*C28-(H28*B28)),H28*(1+G28)*C28-(H28*B28)) -> 1.5224414
A29: TO | B29: 0.07 | C29: 0.2 | H29: =PREÇOS!H30 -> 8.5047742 | I29: =IF(F29=0,,H29*(1+F29)*C29-(H29*B29)) -> 0 | J29: =IF(G29=0,IF(F29=0,,H29*(1+F29)*C29-(H29*B29)),H29*(1+G29)*C29-(H29*B29)) -> 0
A30: EX

Sheet ST CEREAL
A1: Estado | B1: Aliquota interestadual | C1: Aliquota interna | D1: MVA (normal) | E1: MVA (simples) | F1: Ajustada (normal) | G1: Ajustada (simples) | H1: Preço | I1: ST Normal | J1: ST Simples
A2: AC | B2: 0.07 | C2: 0.17 | H2: =PREÇOS!G3 -> 7.05 | I2: =IF(F2=0,,H2*(1+F2)*C2-(H2*B2)) -> 0 | J2: =IF(G2=0,IF(F2=0,,H2*(1+F2)*C2-(H2*B2)),H2*(1+G2)*C2-(H2*B2)) -> 0
A3: AL | B3: 0.07 | C3: 0.2 | F3: 0.71 | H3: =PREÇOS!G4 -> 7.05 | I3: =IF(F3=0,,H3*(1+F3)*C3-(H3*B3)) -> 1.9176 | J3: =IF(G3=0,IF(F3=0,,H3*(1+F3)*C3-(H3*B3)),H3*(1+G3)*C3-(H3*B3)) -> 1.9176
A4: AM | B4: 0.07 | C4: 0.2 | F4: 0.5538 | H4: =PREÇOS!G5 -> 7.05 | I4: =IF(F4=0,,H4*(1+F4)*C4-(H4*B4)) -> 1.697358 | J4: =IF(G4=0,IF(F4=0,,H4*(1+F4)*C4-(H4*B4)),H4*(1+G4)*C4-(H4*B4)) -> 1.697358
A5: AP | B5: 0.07 | C5: 0.18 | H5: =PREÇOS!G6 -> 7.05 | I5: =IF(F5=0,,H5*(1+F5)*C5-(H5*B5)) -> 0 | J5: =IF(G5=0,IF(F5=0,,H5*(1+F5)*C5-(H5*B5)),H5*(1+G5)*C5-(H5*B5)) -> 0
A6: BA | B6: 0.07 | C6: 0.19 | H6: =PREÇOS!G7 -> 7.05 | I6: =IF(F6=0,,H6*(1+F6)*C6-(H6*B6)) -> 0 | J6: =IF(G6=0,IF(F6=0,,H6*(1+F6)*C6-(H6*B6)),H6*(1+G6)*C6-(H6*B6)) -> 0
A7: CE | B7: 0.07 | C7: 0.2 | H7: =PREÇOS!G8 -> 7.05 | I7: =IF(F7=0,,H7*(1+F7)*C7-(H7*B7)) -> 0 | J7: =IF(G7=0,IF(F7=0,,H7*(1+F7)*C7-(H7*B7)),H7*(1+G7)*C7-(H7*B7)) -> 0
A8: DF | B8: 0.07 | C8: 0.18 | H8: =PREÇOS!G9 -> 7.05 | I8: =IF(F8=0,,H8*(1+F8)*C8-(H8*B8)) -> 0 | J8: =IF(G8=0,IF(F8=0,,H8*(1+F8)*C8-(H8*B8)),H8*(1+G8)*C8-(H8*B8)) -> 0
A9: ES | B9: 0.07 | C9: 0.17 | H9: =PREÇOS!G10 -> 7.05 | I9: =IF(F9=0,,H9*(1+F9)*C9-(H9*B9)) -> 0 | J9: =IF(G9=0,IF(F9=0,,H9*(1+F9)*C9-(H9*B9)),H9*(1+G9)*C9-(H9*B9)) -> 0
A10: GO | B10: 0.07 | C10: 0.17 | H10: =PREÇOS!G11 -> 7.05 | I10: =IF(F10=0,,H10*(1+F10)*C10-(H10*B10)) -> 0 | J10: =IF(G10=0,IF(F10=0,,H10*(1+F10)*C10-(H10*B10)),H10*(1+G10)*C10-(H10*B10)) -> 0
A11: MA | B11: 0.07 | C11: 0.2 | H11: =PREÇOS!G12 -> 7.05 | I11: =IF(F11=0,,H11*(1+F11)*C11-(H11*B11)) -> 0 | J11: =IF(G11=0,IF(F11=0,,H11*(1+F11)*C11-(H11*B11)),H11*(1+G11)*C11-(H11*B11)) -> 0
A12: MG | B12: 0.12 | C12: 0.18 | F12: 0.4488 | H12: =PREÇOS!G13 -> 7.5 | I12: =IF(F12=0,,H12*(1+F12)*C12-(H12*B12)) -> 1.05588 | J12: =IF(G12=0,IF(F12=0,,H12*(1+F12)*C12-(H12*B12)),H12*(1+G12)*C12-(H12*B12)) -> 1.05588
A13: MS | B13: 0.07 | C13: 0.17 | H13: =PREÇOS!G14 -> 7.05 | I13: =IF(F13=0,,H13*(1+F13)*C13-(H13*B13)) -> 0 | J13: =IF(G13=0,IF(F13=0,,H13*(1+F13)*C13-(H13*B13)),H13*(1+G13)*C13-(H13*B13)) -> 0
A14: MT | B14: 0.07 | C14: 0.17 | F14: 0.4552 | H14: =PREÇOS!G15 -> 7.05 | I14: =IF(F14=0,,H14*(1+F14)*C14-(H14*B14)) -> 1.2505572 | J14: =IF(G14=0,IF(F14=0,,H14*(1+F14)*C14-(H14*B14)),H14*(1+G14)*C14-(H14*B14)) -> 1.2505572
A15: PA | B15: 0.07 | C15: 0.19 | H15: =PREÇOS!G16 -> 7.05 | I15: =IF(F15=0,,H15*(1+F15)*C15-(H15*B15)) -> 0 | J15: =IF(G15=0,IF(F15=0,,H15*(1+F15)*C15-(H15*B15)),H15*(1+G15)*C15-(H15*B15)) -> 0
A16: PB | B16: 0.07 | C16: 0.18 | H16: =PREÇOS!G17 -> 7.05 | I16: =IF(F16=0,,H16*(1+F16)*C16-(H16*B16)) -> 0 | J16: =IF(G16=0,IF(F16=0,,H16*(1+F16)*C16-(H16*B16)),H16*(1+G16)*C16-(H16*B16)) -> 0
A17: PE | B17: 0.07 | C17: 0.18 | H17: =PREÇOS!G18 -> 7.05 | I17: =IF(F17=0,,H17*(1+F17)*C17-(H17*B17)) -> 0 | J17: =IF(G17=0,IF(F17=0,,H17*(1+F17)*C17-(H17*B17)),H17*(1+G17)*C17-(H17*B17)) -> 0
A18: PI | B18: 0.07 | C18: 0.21 | H18: =PREÇOS!G19 -> 7.05 | I18: =IF(F18=0,,H18*(1+F18)*C18-(H18*B18)) -> 0 | J18: =IF(G18=0,IF(F18=0,,H18*(1+F18)*C18-(H18*B18)),H18*(1+G18)*C18-(H18*B18)) -> 0
