Workbook

Sheet Tabelas
C1: BABY ROO COMERCIO DE ALIMENTOS EIRELI
C2: CNPJ: 34.282.307.0001-44
C3: INSC. ESTADUAL: 90821939-25
C4: ENDEREÇO: Rua Grã Nicco, 113 - sala 501, bloco 2 - Mossunguê, Curitiba - PR, 81200-200
B6: Nome / Razão Social: | J6: Nr. pedido | L6: E-mail XML:
B7: Endereço: | L7: Municipio: | Q7: UF: | R7: SP
B8: CNPJ: | G8: Inscrição Estadual: | J8: Regime SIMPLES? | K8: NÃO | L8: Fone contato com (DDD) | Q8: CEP:
B9: ESPECIAL
B10: Descrição | D10: Código | E10: Embalagem | F10: Validade | G10: PSC | H10: NCM | I10: Ean 13 | J10: Dun 14 | K10: Crédito ICMS (%) | L10: Valor Unit. | M10: Valor Caixa | N10: SUBSTITUIÇÃO TRIBUTÁRIA* | O10: IPI* | P10: Valor Caixa + ST + IPI | Q10: TOTAL Caixas | R10: Valor TOTAL | S10: Valor TOTAL + ST (*)
B11: Papinha Papapa Carne Arroz Legumes 120g | D11: 5313 | E11: 12 x 120g | F11: 12 meses | G11: =VLOOKUP($R$7,PSC!$A$2:$L$31,9,FALSE) -> 13.49 | H11: 2104.20.00 | I11: 7898969895316 | J11: 17898969895313 | K11: =VLOOKUP($R$7,'ST BISCOITINHOS'!A:B,2,FALSE) -> 0.04 | L11: =VLOOKUP($R$7,PREÇOS!$A$2:$L$31,9,FALSE) -> 8.9 | M11: =L11*12 -> 106.8 | N11: 0 | O11: 0 | P11: =(L11+N11+O11)*12 -> 106.8 | R11: =Q11*M11 -> 0 | S11: =Q11*P11 -> 0
B12: Papinha Papapa Frango Grão Vegetais 120g | D12: 5320 | E12: 12 x 120g | F12: 12 meses | G12: =VLOOKUP($R$7,PSC!$A$2:$L$31,9,FALSE) -> 13.49 | H12: 2104.20.00 | I12: 7898969895323 | J12: 17898969895320 | K12: =VLOOKUP($R$7,'ST BISCOITINHOS'!A:B,2,FALSE) -> 0.04 | L12: =VLOOKUP($R$7,PREÇOS!$A$2:$L$31,9,FALSE) -> 8.9 | M12: =L12*12 -> 106.8 | N12: 0 | O12: 0 | P12: =(L12+N12+O12)*12 -> 106.8 | R12: =Q12*M12 -> 0 | S12: =Q12*P12 -> 0
B14: Papinha Papapa Iogurte Frutas Amarelas e Banana 100g | D14: 5563 | E14: 16 x 100g | F14: 15 meses | G14: =VLOOKUP($R$7,PSC!$A$2:$M$31,13,FALSE) -> 9.49 | H14: 2104.20.00 | I14: 7898969895569 | J14: 27898969895563 | K14: =VLOOKUP($R$7,'ST BISCOITINHOS'!A:B,2,FALSE) -> 0.04 | L14: =VLOOKUP($R$7,PREÇOS!$A$2:$M$31,13,FALSE) -> 6.24 | M14: =L14*16 -> 99.84 | N14: 0 | O14: 0 | P14: =(L14+N14+O14)*16 -> 99.84 | R14: =Q14*M14 -> 0 | S14: =Q14*P14 -> 0
B15: Papinha Papapa Iogurte Frutas Vermelhas e Banana 100g | D15: 5570 | E15: 16 x 100g | F15: 15 meses | G15: =VLOOKUP($R$7,PSC!$A$2:$M$31,13,FALSE) -> 9.49 | H15: 2104.20.00 | I15: 7898969895576 | J15: 27898969895570 | K15: =VLOOKUP($R$7,'ST BISCOITINHOS'!A:B,2,FALSE) -> 0.04 | L15: =VLOOKUP($R$7,PREÇOS!$A$2:$M$31,13,FALSE) -> 6.24 | M15: =L15*16 -> 99.84 | N15: 0 | O15: 0 | P15: =(L15+N15+O15)*16 -> 99.84 | R15: =Q15*M15 -> 0 | S15: =Q15*P15 -> 0
B17: Papinha Papapá Org Maçã Ameixa 100g | D17: 17898994908729 | E17: 12 x 100g | F17: 16 meses | G17: =VLOOKUP($R$7,PSC!$A$2:$L$31,2,FALSE) -> 9.49 | H17: 2104.20.00 | I17: 7898994908722 | J17: 17898994908729 | K17: =VLOOKUP($R$7,'ST BISCOITINHOS'!A:B,2,FALSE) -> 0.04 | L17: =VLOOKUP($R$7,PREÇOS!$A$2:$L$31,2,FALSE) -> 6.24 | M17: =L17*12 -> 74.88 | N17: 0 | O17: 0 | P17: =(L17+N17+O17)*12 -> 74.88 | R17: =Q17*M17 -> 0 | S17: =Q17*P17 -> 0
B18: Papinha Papapá Org Banana Mirtilo Quinoa 100g | D18: 17898994908736 | E18: 12 x 100g | F18: 16 meses | G18: =VLOOKUP($R$7,PSC!$A$2:$L$31,2,FALSE) -> 9.49 | H18: 2104.20.00 | I18: 7898994908739 | J18: 17898994908736 | K18: =VLOOKUP($R$7,'ST BISCOITINHOS'!A:B,2,FALSE) -> 0.04 | L18: =VLOOKUP($R$7,PREÇOS!$A$2:$L$31,2,FALSE) -> 6.24 | M18: =L18*12 -> 74.88 | N18: 0 | O18: 0 | P18: =(L18+N18+O18)*12 -> 74.88 | R18: =Q18*M18 -> 0 | S18: =Q18*P18 -> 0
B19: Papinha Papapá Org Manga 100g | D19: 17898994908712 | E19: 12 x 100g | F19: 16 meses | G19: =VLOOKUP($R$7,PSC!$A$2:$L$31,2,FALSE) -> 9.49 | H19: 2104.20.00 | I19: 7898994908715 | J19: 17898994908712 | K19: =VLOOKUP($R$7,'ST BISCOITINHOS'!A:B,2,FALSE) -> 0.04 | L19: =VLOOKUP($R$7,PREÇOS!$A$2:$L$31,2,FALSE) -> 6.24 | M19: =L19*12 -> 74.88 | N19: 0 | O19: 0 | P19: =(L19+N19+O19)*12 -> 74.88 | R19: =Q19*M19 -> 0 | S19: =Q19*P19 -> 0
B20: Papinha Papapá Org Pera Espinafre Abobrinha 100g | D20: 17898994908750 | E20: 12 x 100g | F20: 16 meses | G20: =VLOOKUP($R$7,PSC!$A$2:$L$31,2,FALSE) -> 9.49 | H20: 2104.20.00 | I20: 7898994908753 | J20: 17898994908750 | K20: =VLOOKUP($R$7,'ST BISCOITINHOS'!A:B,2,FALSE) -> 0.04 | L20: =VLOOKUP($R$7,PREÇOS!$A$2:$L$31,2,FALSE) -> 6.24 | M20: =L20*12 -> 74.88 | N20: 0 | O20: 0 | P20: =(L20+N20+O20)*12 -> 74.88 | R20: =Q20*M20 -> 0 | S20: =Q20*P20 -> 0
B21: Papinha Papapá Org Maçã B. Doce Cenoura 100g | D21: 27898994908757 | E21: 12 x 100g | F21: 16 meses | G21: =VLOOKUP($R$7,PSC!$A$2:$L$31,2,FALSE) -> 9.49 | H21: 2104.20.00 | I21: 7898994908746 | J21: 27898994908757 | K21: =VLOOKUP($R$7,'ST BISCOITINHOS'!A:B,2,FALSE) -> 0.04 | L21: =VLOOKUP($R$7,PREÇOS!$A$2:$L$31,2,FALSE) -> 6.24 | M21: =L21*12 -> 74.88 | N21: 0 | O21: 0 | P21: =(L21+N21+O21)*12 -> 74.88 | R21: =Q21*M21 -> 0 | S21: =Q21*P21 -> 0
B22: Papinha Papapá Org Morango Maçã 100g | D22: 5306 | E22: 12 x 100g | F22: 16 meses | G22: =VLOOKUP($R$7,PSC!$A$2:$L$31,2,FALSE) -> 9.49 | H22: 2104.20.00 | I22: 7898969895309 | J22: 17898969895306 | K22: =VLOOKUP($R$7,'ST BISCOITINHOS'!A:B,2,FALSE) -> 0.04 | L22: =VLOOKUP($R$7,PREÇOS!$A$2:$L$31,2,FALSE) -> 6.24 | M22: =L22*12 -> 74.88 | N22: 0 | O22: 0 | P22: =(L22+N22+O22)*12 -> 74.88 | R22: =Q22*M22 -> 0 | S22: =Q22*P22 -> 0
B24: Biscoito inf Papapá org. Beterraba 20g | D24: 5085 | E24: 16 x 20g | F24: 9 meses | G24: =VLOOKUP($R$7,PSC!$A$2:$L$31,3,FALSE) -> 5.99 | H24: 1904.10.00 | I24: 7898969895088 | J24: 17898969895085 | K24: =VLOOKUP($R$7,'ST PALITINHOS'!A:B,2,FALSE) -> 0.12 | L24: =VLOOKUP($R$7,PREÇOS!$A$2:$L$31,3,FALSE) -> 3.9312 | M24: =L24*16 -> 62.8992 | N24: =IF($K$8="SIM",VLOOKUP($R$7,'ST PALITINHOS'!$A$1:$J$31,10,FALSE),VLOOKUP($R$7,'ST PALITINHOS'!$A$1:$J$31,9,FALSE)) -> 0 | O24: 0 | P24: =(L24+N24+O24)*16 -> 62.8992 | R24: =Q24*M24 -> 0 | S24: =Q24*P24 -> 0
B25: Biscoito inf Papapá org. Cenoura 20g | D25: 5078 | E25: 16 x 20g | F25: 9 meses | G25: =VLOOKUP($R$7,PSC!$A$2:$L$31,3,FALSE) -> 5.99 | H25: 1904.10.00 | I25: 7898969895071 | J25: 17898969895078 | K25: =VLOOKUP($R$7,'ST PALITINHOS'!A:B,2,FALSE) -> 0.12 | L25: =VLOOKUP($R$7,PREÇOS!$A$2:$L$31,3,FALSE) -> 3.9312 | M25: =L25*16 -> 62.8992 | N25: =IF($K$8="SIM",VLOOKUP($R$7,'ST PALITINHOS'!$A$1:$J$31,10,FALSE),VLOOKUP($R$7,'ST PALITINHOS'!$A$1:$J$31,9,FALSE)) -> 0 | O25: 0 | P25: =(L25+N25+O25)*16 -> 62.8992 | R25: =Q25*M25 -> 0 | S25: =Q25*P25 -> 0
B26: Biscoito inf Papapá org. Tomate/Manjericão 20g | D26: 5061 | E26: 16 x 20g | F26: 9 meses | G26: =VLOOKUP($R$7,PSC!$A$2:$L$31,3,FALSE) -> 5.99 | H26: 1904.10.00 | I26: 7898969895064 | J26: 17898969895061 | K26: =VLOOKUP($R$7,'ST PALITINHOS'!A:B,2,FALSE) -> 0.12 | L26: =VLOOKUP($R$7,PREÇOS!$A$2:$L$31,3,FALSE) -> 3.9312 | M26: =L26*16 -> 62.8992 | N26: =IF($K$8="SIM",VLOOKUP($R$7,'ST PALITINHOS'!$A$1:$J$31,10,FALSE),VLOOKUP($R$7,'ST PALITINHOS'!$A$1:$J$31,9,FALSE)) -> 0 | O26: 0 | P26: =(L26+N26+O26)*16 -> 62.8992 | R26: =Q26*M26 -> 0 | S26: =Q26*P26 -> 0
B28: Biscoito Inf Papapá dent. Maçã e Abóbora 36g | D28: 8774 | E28: 12 x 36g | F28: 15 meses | G28: =VLOOKUP($R$7,PSC!$A$2:$L$31,4,FALSE) -> 19.99 | H28: 1905.90.20 | I28: 7898994908777 | J28: 17898994908774 | K28: =VLOOKUP($R$7,'ST BISCOITINHOS'!A:B,2,FALSE) -> 0.04 | L28: =VLOOKUP($R$7,PREÇOS!$A$2:$L$31,4,FALSE) -> 13.3488 | M28: =L28*12 -> 160.1856 | N28: =IF($K$8="SIM",VLOOKUP($R$7,'ST BISCOITINHOS'!$A$1:$J$31,10,FALSE),VLOOKUP($R$7,'ST BISCOITINHOS'!$A$1:$J$31,9,FALSE)) -> 3.6802909 | O28: 0 | P28: =(L28+N28+O28)*12 -> 204.34909 | R28: =Q28*M28 -> 0 | S28: =Q28*P28 -> 0
B29: Biscoito Inf Papapá dent Vegetais 36g | D29: 8767 | E29: 12 x 36g | F29: 15 meses | G29: =VLOOKUP($R$7,PSC!$A$2:$L$31,4,FALSE) -> 19.99 | H29: 1905.90.20 | I29: 7898994908760 | J29: 17898994908767 | K29: =VLOOKUP($R$7,'ST BISCOITINHOS'!A:B,2,FALSE) -> 0.04 | L29: =VLOOKUP($R$7,PREÇOS!$A$2:$L$31,4,FALSE) -> 13.3488 | M29: =L29*12 -> 160.1856 | N29: =IF($K$8="SIM",VLOOKUP($R$7,'ST BISCOITINHOS'!$A$1:$J$31,10,FALSE),VLOOKUP($R$7,'ST BISCOITINHOS'!$A$1:$J$31,9,FALSE)) -> 3.6802909 | O29: 0 | P29: =(L29+N29+O29)*12 -> 204.34909 | R29: =Q29*M29 -> 0 | S29: =Q29*P29 -> 0
B31: Macarrao Inf Papapá m. Elbow Quinoa 200g | D31: 5290 | E31: 12 x 200g | F31: 14 meses | G31: =VLOOKUP($R$7,PSC!$A$2:$L$31,5,FALSE) -> 12.49 | H31: 19.02.19.00 | I31: 7898969895293 | J31: 17898969895293 | K31: =VLOOKUP($R$7,'ST PAPAPASTA'!A:B,2,FALSE) -> 0.12 | L31: =VLOOKUP($R$7,PREÇOS!$A$2:$L$31,5,FALSE) -> 8.619 | M31: =L31*12 -> 103.428 | N31: =IF($K$8="SIM",VLOOKUP($R$7,'ST PAPAPASTA'!$A$1:$J$31,10,FALSE),VLOOKUP($R$7,'ST PAPAPASTA'!$A$1:$J$31,9,FALSE)) -> 0 | O31: 0 | P31: =(L31+N31+O31)*12 -> 103.428 | R31: =Q31*M31 -> 0 | S31: =Q31*P31 -> 0
B32: Macarrao Inf Papapá m. Fusilli Vegetais 200g | D32: 5283 | E32: 12 x 200g | F32: 14 meses | G32: =VLOOKUP($R$7,PSC!$A$2:$L$31,5,FALSE) -> 12.49 | H32: 19.02.19.00 | I32: 7898969895286 | J32: 17898969895286 | K32: =VLOOKUP($R$7,'ST PAPAPASTA'!A:B,2,FALSE) -> 0.12 | L32: =VLOOKUP($R$7,PREÇOS!$A$2:$L$31,5,FALSE) -> 8.619 | M32: =L32*12 -> 103.428 | N32: =IF($K$8="SIM",VLOOKUP($R$7,'ST PAPAPASTA'!$A$1:$J$31,10,FALSE),VLOOKUP($R$7,'ST PAPAPASTA'!$A$1:$J$31,9,FALSE)) -> 0 | O32: 0 | P32: =(L32+N32+O32)*12 -> 103.428 | R32: =Q32*M32 -> 0 | S32: =Q32*P32 -> 0
B34: Sopinha Papapá org Lentinha Carne Legumes 180g | D34: 5276 | E34: 6 x 180g | F34: 16 meses | G34: =VLOOKUP($R$7,PSC!$A$2:$L$31,6,FALSE) -> 18.99 | H34: 2104.20.00 | I34: 7898969895279 | J34: 17898969895276 | K34: =VLOOKUP($R$7,'ST PAPAPASTA'!A:B,2,FALSE) -> 0.12 | L34: =VLOOKUP($R$7,PREÇOS!$A$2:$L$31,6,FALSE) -> 12.39 | M34: =L34*6 -> 74.34 | N34: 0 | O34: 0 | P34: =(L34+N34+O34)*6 -> 74.34 | R34: =Q34*M34 -> 0 | S34: =Q34*P34 -> 0
B35: Risotinho Papapá org Arroz quinoa frango 180g | D35: 5269 | E35: 6 x 180g | F35: 16 meses | G35: =VLOOKUP($R$7,PSC!$A$2:$L$31,6,FALSE) -> 18.99 | H35: 2104.20.00 | I35: 7898969895262 | J35: 17898969895269 | K35: =VLOOKUP($R$7,'ST PAPAPASTA'!A:B,2,FALSE) -> 0.12 | L35: =VLOOKUP($R$7,PREÇOS!$A$2:$L$31,6,FALSE) -> 12.39 | M35: =L35*6 -> 74.34 | N35: 0 | O35: 0 | P35: =(L35+N35+O35)*6 -> 74.34 | R35: =Q35*M35 -> 0 | S35: =Q35*P35 -> 0
B36: Caseirinho Papapá org Arroz feijão carne leg. 180g | D36: 5252 | E36: 6 x 180g | F36: 16 meses | G36: =VLOOKUP($R$7,PSC!$A$2:$L$31,6,FALSE) -> 18.99 | H36: 2104.20.00 | I36: 7898969895255 | J36: 17898969895252 | K36: =VLOOKUP($R$7,'ST PAPAPASTA'!A:B,2,FALSE) -> 0.12 | L36: =VLOOKUP($R$7,PREÇOS!$A$2:$L$31,6,FALSE) -> 12.39 | M36: =L36*6 -> 74.34 | N36: 0 | O36: 0 | P36: =(L36+N36+O36)*6 -> 74.34 | R36: =Q36*M36 -> 0 | S36: =Q36*P36 -> 0
B38: Cereal Infantil Papapá Aveia - Morango e Beterraba sache 170g | D38: 5402 | E38: 12 x 170g | F38: 12 meses | G38: =VLOOKUP($R$7,PSC!$A$2:$L$31,10,FALSE) -> 9.99 | H38: 19.01.10.30 | I38: 7898969895408 | J38: 27898969895402 | K38: =VLOOKUP($R$7,'ST CEREAL SABOR POUCH 170'!A:B,2,FALSE) -> 0.12 | L38: =VLOOKUP($R$7,PREÇOS!$A$2:$L$31,10,FALSE) -> 6.765 | M38: =L38*12 -> 81.18 | N38: =IF($K$8="SIM",VLOOKUP($R$7,'ST CEREAL SABOR POUCH 170'!$A$1:$J$31,10,FALSE),VLOOKUP($R$7,'ST CEREAL SABOR POUCH 170'!$A$1:$J$31,9,FALSE)) -> 0.9696951 | O38: 0 | P38: =(L38+N38+O38)*12 -> 92.816341 | R38: =Q38*M38 -> 0 | S38: =Q38*P38 -> 0
B39: Cereal Infantil Papapá Aveia - Banana e Ameixa sache 170g | D39: 5419 | E39: 12 x 170g | F39: 12 meses | G39: =VLOOKUP($R$7,PSC!$A$2:$L$31,10,FALSE) -> 9.99 | H39: 19.01.10.30 | I39: 7898969895415 | J39: 27898969895419 | K39: =VLOOKUP($R$7,'ST CEREAL SABOR POUCH 170'!A:B,2,FALSE) -> 0.12 | L39: =VLOOKUP($R$7,PREÇOS!$A$2:$L$31,10,FALSE) -> 6.765 | M39: =L39*12 -> 81.18 | N39: =IF($K$8="SIM",VLOOKUP($R$7,'ST CEREAL SABOR POUCH 170'!$A$1:$J$31,10,FALSE),VLOOKUP($R$7,'ST CEREAL SABOR POUCH 170'!$A$1:$J$31,9,FALSE)) -> 0.9696951 | O39: 0 | P39: =(L39+N39+O39)*12 -> 92.816341 | R39: =Q39*M39 -> 0 | S39: =Q39*P39 -> 0
B40: Cereal Infantil Papapá Aveia - Multicereais sache 170g | D40: 5429 | E40: 12 x 170g | F40: 12 meses | G40: =VLOOKUP($R$7,PSC!$A$2:$L$31,11,FALSE) -> 9.99 | H40: 19.01.10.30 | I40: 7898969895422 | J40: 17898969895429 | K40: =VLOOKUP($R$7,'ST MULTI 170 POUCH'!A:B,2,FALSE) -> 0.12 | L40: =VLOOKUP($R$7,PREÇOS!$A$2:$L$31,11,FALSE) -> 6.765 | M40: =L40*12 -> 81.18 | N40: =IF($K$8="SIM",VLOOKUP($R$7,'ST MULTI 170 POUCH'!$A$1:$J$31,10,FALSE),VLOOKUP($R$7,'ST MULTI 170 POUCH'!$A$1:$J$31,9,FALSE)) -> 0.9696951 | O40: 0 | P40: =(L40+N40+O40)*12 -> 92.816341 | R40: =Q40*M40 -> 0 | S40: =Q40*P40 -> 0
B41: Cereal Infantil Papapá Aveia - Multicereais sache 500g | D41: 5399 | E41: 12 x 500g | F41: 12 meses | G41: =VLOOKUP($R$7,PSC!$A$2:$L$31,12,FALSE) -> 23.99 | H41: 19.01.10.30 | I41: 7898969895392 | J41: 17898969895399 | K41: =VLOOKUP($R$7,'ST MULTI 500 POUCH'!A:B,2,FALSE) -> 0.12 | L41: =VLOOKUP($R$7,PREÇOS!$A$2:$L$31,12,FALSE) -> 16.1892 | M41: =L41*12 -> 194.2704 | N41: =IF($K$8="SIM",VLOOKUP($R$7,'ST MULTI 500 POUCH'!$A$1:$J$31,10,FALSE),VLOOKUP($R$7,'ST MULTI 500 POUCH'!$A$1:$J$31,9,FALSE)) -> 2.3205599 | O41: 0 | P41: =(L41+N41+O41)*12 -> 222.11712 | R41: =Q41*M41 -> 0 | S41: =Q41*P41 -> 0
B43: Biscoito Infantil Papapá Biscotti com Laranja e Cenoura 60g | D43: 5375 | E43: 12 x 60g | F43: 10 meses | G43: =VLOOKUP($R$7,PSC!$A$2:$L$31,8,FALSE) -> 13.49 | H43: 1905.90.20 | I43: 7898969895378 | J43: 17898969895375 | K43: =VLOOKUP($R$7,'ST BISCOTTI'!A:B,2,FALSE) -> 0.12 | L43: =VLOOKUP($R$7,PREÇOS!$A$2:$L$31,8,FALSE) -> 8.988 | M43: =L43*12 -> 107.856 | N43: =IF($K$8="SIM",VLOOKUP($R$7,'ST BISCOTTI'!$A$1:$J$31,10,FALSE),VLOOKUP($R$7,'ST BISCOTTI'!$A$1:$J$31,9,FALSE)) -> 1.5224414 | O43: 0 | P43: =(L43+N43+O43)*12 -> 126.1253 | R43: =Q43*M43 -> 0 | S43: =Q43*P43 -> 0
B44: Biscoito Infantil Papapá Biscotti com Maçã e Canela 60g | D44: 5351 | E44: 12 x 60g | F44: 10 meses | G44: =VLOOKUP($R$7,PSC!$A$2:$L$31,8,FALSE) -> 13.49 | H44: 1905.90.20 | I44: 7898969895354 | J44: 17898969895351 | K44: =VLOOKUP($R$7,'ST BISCOTTI'!A:B,2,FALSE) -> 0.12 | L44: =VLOOKUP($R$7,PREÇOS!$A$2:$L$31,8,FALSE) -> 8.988 | M44: =L44*12 -> 107.856 | N44: =IF($K$8="SIM",VLOOKUP($R$7,'ST BISCOTTI'!$A$1:$J$31,10,FALSE),VLOOKUP($R$7,'ST BISCOTTI'!$A$1:$J$31,9,FALSE)) -> 1.5224414 | O44: 0 | P44: =(L44+N44+O44)*12 -> 126.1253 | R44: =Q44*M44 -> 0 | S44: =Q44*P44 -> 0
B45: Biscoito Infantil Papapá Biscotti com Banana e Cacau 60g | D45: 5368 | E45: 12 x 60g | F45: 10 meses | G45: =VLOOKUP($R$7,PSC!$A$2:$L$31,8,FALSE) -> 13.49 | H45: 1905.90.20 | I45: 7898969895361 | J45: 17898969895368 | K45: =VLOOKUP($R$7,'ST BISCOTTI'!A:B,2,FALSE) -> 0.12 | L45: =VLOOKUP($R$7,PREÇOS!$A$2:$L$31,8,FALSE) -> 8.988 | M45: =L45*12 -> 107.856 | N45: =IF($K$8="SIM",VLOOKUP($R$7,'ST BISCOTTI'!$A$1:$J$31,10,FALSE),VLOOKUP($R$7,'ST BISCOTTI'!$A$1:$J$31,9,FALSE)) -> 1.5224414 | O45: 0 | P45: =(L45+N45+O45)*12 -> 126.1253 | R45: =Q45*M45 -> 0 | S45: =Q45*P45 -> 0
B46: Biscoito Infantil Papapá Biscotti Goiaba 60g | D46: 5597 | E46: 12 x 60g | F46: 10 meses | G46: =VLOOKUP($R$7,PSC!$A$2:$L$31,8,FALSE) -> 13.49 | H46: 1905.90.20 | I46: 7898969895590 | J46: 17898969895597 | K46: =VLOOKUP($R$7,'ST BISCOTTI'!A:B,2,FALSE) -> 0.12 | L46: =VLOOKUP($R$7,PREÇOS!$A$2:$L$31,8,FALSE) -> 8.988 | M46: =L46*12 -> 107.856 | N46: =IF($K$8="SIM",VLOOKUP($R$7,'ST BISCOTTI'!$A$1:$J$31,10,FALSE),VLOOKUP($R$7,'ST BISCOTTI'!$A$1:$J$31,9,FALSE)) -> 1.5224414 | O46: 0 | P46: =(L46+N46+O46)*12 -> 126.1253 | R46: =Q46*M46 -> 0 | S46: =Q46*P46 -> 0
B47: Biscoito Infantil Papapá Biscotti com Maracujá e Camomila 60g | D47: 5580 | E47: 12 x 60g | F47: 10 meses | G47: =VLOOKUP($R$7,PSC!$A$2:$L$31,8,FALSE) -> 13.49 | H47: 1905.90.20 | I47: 7898969895583 | J47: 17898969895580 | K47: =VLOOKUP($R$7,'ST BISCOTTI'!A:B,2,FALSE) -> 0.12 | L47: =VLOOKUP($R$7,PREÇOS!$A$2:$L$31,8,FALSE) -> 8.988 | M47: =L47*12 -> 107.856 | N47: =IF($K$8="SIM",VLOOKUP($R$7,'ST BISCOTTI'!$A$1:$J$31,10,FALSE),VLOOKUP($R$7,'ST BISCOTTI'!$A$1:$J$31,9,FALSE)) -> 1.5224414 | O47: 0 | P47: =(L47+N47+O47)*12 -> 126.1253 | R47: =Q47*M47 -> 0 | S47: =Q47*P47 -> 0
B49: Sopinha Papapá Frango Arroz Legumes 240g (2x 120g) | D49: 5610 | E49: 6 x 240g | F49: 12 meses | G49: 18.99 | H49: 2104.20.00 | I49: 7898969895613 | J49: 17898969895610 | K49: =VLOOKUP($R$7,'ST BISCOTTI'!A:B,2,FALSE) -> 0.12 | L49: =VLOOKUP($R$7,PREÇOS!$A$2:$N$31,14,FALSE) -> 12.94 | M49: =L49*6 -> 77.64 | N49: 0 | O49: 0 | P49: =(L49+N49+O49)*6 -> 77.64 | R49: =Q49*M49 -> 0 | S49: =Q49*P49 -> 0
B50: Sopinha Papapá Carne Macarrao Legumes 240g (2x 120g) | D50: 5634 | E50: 6 x 240g | F50: 12 meses | G50: 18.99 | H50: 2104.20.00 | I50: 7898969895637 | J50: 17898969895634 | K50: =VLOOKUP($R$7,'ST BISCOTTI'!A:B,2,FALSE) -> 0.12 | L50: =VLOOKUP($R$7,PREÇOS!$A$2:$N$31,14,FALSE) -> 12.94 | M50: =L50*6 -> 77.64 | N50: 0 | O50: 0 | P50: =(L50+N50+O50)*6 -> 77.64 | R50: =Q50*M50 -> 0 | S50: =Q50*P50 -> 0
...

Sheet Planilha1
C2: SIM
C3: NÃO

Sheet ST BISCOITINHOS
A1: Estado | B1: Aliquota interestadual | C1: Aliquota interna | D1: MVA (normal) | E1: MVA (simples) | F1: Ajustada (normal) | G1: Ajustada (simples) | H1: Preço | I1: ST Normal | J1: ST Simples
A2: AC | B2: 0.04 | C2: 0.04 | H2: =PREÇOS!D3 -> 13.3488 | I2: =IF(F2=0,,H2*(1+F2)*C2-(H2*B2)) -> 0 | J2: =IF(G2=0,IF(F2=0,,H2*(1+F2)*C2-(H2*B2)),H2*(1+G2)*C2-(H2*B2)) -> 0
A3: AL | B3: 0.04 | C3: 0.2 | D3: 0.3 | F3: 0.56 | H3: =PREÇOS!D4 -> 13.3488 | I3: =IF(F3=0,,H3*(1+F3)*C3-(H3*B3)) -> 3.6308736 | J3: =IF(G3=0,IF(F3=0,,H3*(1+F3)*C3-(H3*B3)),H3*(1+G3)*C3-(H3*B3)) -> 3.6308736
A4: AM | B4: 0.04 | C4: 0.04 | H4: =PREÇOS!D5 -> 13.3488 | I4: =IF(F4=0,,H4*(1+F4)*C4-(H4*B4)) -> 0 | J4: =IF(G4=0,IF(F4=0,,H4*(1+F4)*C4-(H4*B4)),H4*(1+G4)*C4-(H4*B4)) -> 0
A5: AP | B5: 0.04 | C5: 0.18 | D5: 0.34 | F5: 0.5688 | H5: =PREÇOS!D6 -> 13.3488 | I5: =IF(F5=0,,H5*(1+F5)*C5-(H5*B5)) -> 3.2355355 | J5: =IF(G5=0,IF(F5=0,,H5*(1+F5)*C5-(H5*B5)),H5*(1+G5)*C5-(H5*B5)) -> 3.2355355
A6: BA | B6: 0.04 | C6: 0.04 | H6: =PREÇOS!D7 -> 13.3488 | I6: =IF(F6=0,,H6*(1+F6)*C6-(H6*B6)) -> 0 | J6: =IF(G6=0,IF(F6=0,,H6*(1+F6)*C6-(H6*B6)),H6*(1+G6)*C6-(H6*B6)) -> 0
A7: CE | B7: 0.04 | C7: 0.04 | H7: =PREÇOS!D8 -> 13.3488 | I7: =IF(F7=0,,H7*(1+F7)*C7-(H7*B7)) -> 0 | J7: =IF(G7=0,IF(F7=0,,H7*(1+F7)*C7-(H7*B7)),H7*(1+G7)*C7-(H7*B7)) -> 0
A8: DF | B8: 0.04 | C8: 0.04 | H8: =PREÇOS!D9 -> 13.3488 | I8: =IF(F8=0,,H8*(1+F8)*C8-(H8*B8)) -> 0 | J8: =IF(G8=0,IF(F8=0,,H8*(1+F8)*C8-(H8*B8)),H8*(1+G8)*C8-(H8*B8)) -> 0
A9: ES | B9: 0.04 | C9: 0.04 | H9: =PREÇOS!D10 -> 13.3488 | I9: =IF(F9=0,,H9*(1+F9)*C9-(H9*B9)) -> 0 | J9: =IF(G9=0,IF(F9=0,,H9*(1+F9)*C9-(H9*B9)),H9*(1+G9)*C9-(H9*B9)) -> 0
A10: GO | B10: 0.04 | C10: 0.04 | H10: =PREÇOS!D11 -> 13.3488 | I10: =IF(F10=0,,H10*(1+F10)*C10-(H10*B10)) -> 0 | J10: =IF(G10=0,IF(F10=0,,H10*(1+F10)*C10-(H10*B10)),H10*(1+G10)*C10-(H10*B10)) -> 0
A11: MA | B11: 0.04 | C11: 0.04 | H11: =PREÇOS!D12 -> 13.3488 | I11: =IF(F11=0,,H11*(1+F11)*C11-(H11*B11)) -> 0 | J11: =IF(G11=0,IF(F11=0,,H11*(1+F11)*C11-(H11*B11)),H11*(1+G11)*C11-(H11*B11)) -> 0
A12: MG | B12: 0.04 | C12: 0.18 | D12: 0.25 | F12: 0.3636 | H12: =PREÇOS!D13 -> 13.3488 | I12: =IF(F12=0,,H12*(1+F12)*C12-(H12*B12)) -> 2.7424843 | J12: =IF(G12=0,IF(F12=0,,H12*(1+F12)*C12-(H12*B12)),H12*(1+G12)*C12-(H12*B12)) -> 2.7424843
A13: MS | B13: 0.04 | C13: 0.04 | H13: =PREÇOS!D14 -> 13.3488 | I13: =IF(F13=0,,H13*(1+F13)*C13-(H13*B13)) -> 0 | J13: =IF(G13=0,IF(F13=0,,H13*(1+F13)*C13-(H13*B13)),H13*(1+G13)*C13-(H13*B13)) -> 0
A14: MT | B14: 0.04 | C14: 0.04 | H14: =PREÇOS!D15 -> 13.3488 | I14: =IF(F14=0,,H14*(1+F14)*C14-(H14*B14)) -> 0 | J14: =IF(G14=0,IF(F14=0,,H14*(1+F14)*C14-(H14*B14)),H14*(1+G14)*C14-(H14*B14)) -> 0
A15: PA | B15: 0.04 | C15: 0.04 | H15: =PREÇOS!D16 -> 13.3488 | I15: =IF(F15=0,,H15*(1+F15)*C15-(H15*B15)) -> 0 | J15: =IF(G15=0,IF(F15=0,,H15*(1+F15)*C15-(H15*B15)),H15*(1+G15)*C15-(H15*B15)) -> 0
A16: PB | B16: 0.04 | C16: 0.04 | H16: =PREÇOS!D17 -> 13.3488 | I16: =IF(F16=0,,H16*(1+F16)*C16-(H16*B16)) -> 0 | J16: =IF(G16=0,IF(F16=0,,H16*(1+F16)*C16-(H16*B16)),H16*(1+G16)*C16-(H16*B16)) -> 0
A17: PE | B17: 0.04 | C17: 0.04 | H17: =PREÇOS!D18 -> 13.3488 | I17: =IF(F17=0,,H17*(1+F17)*C17-(H17*B17)) -> 0 | J17: =IF(G17=0,IF(F17=0,,H17*(1+F17)*C17-(H17*B17)),H17*(1+G17)*C17-(H17*B17)) -> 0
A18: PI | B18: 0.04 | C18: 0.04 | H18: =PREÇOS!D19 -> 13.3488 | I18: =IF(F18=0,,H18*(1+F18)*C18-(H18*B18)) -> 0 | J18: =IF(G18=0,IF(F18=0,,H18*(1+F18)*C18-(H18*B18)),H18*(1+G18)*C18-(H18*B18)) -> 0
A19: PR | B19: 0.12 | C19: 0.12 | H19: =PREÇOS!D20 -> 14.562327 | I19: =IF(F19=0,,H19*(1+F19)*C19-(H19*B19)) -> 0 | J19: =IF(G19=0,IF(F19=0,,H19*(1+F19)*C19-(H19*B19)),H19*(1+G19)*C19-(H19*B19)) -> 0
A20: RJ | B20: 0.04 | C20: 0.22 | D20: 0.352 | F20: 0.664 | H20: =PREÇOS!D21 -> 13.3488 | I20: =IF(F20=0,,H20*(1+F20)*C20-(H20*B20)) -> 4.3527767 | J20: =IF(G20=0,IF(F20=0,,H20*(1+F20)*C20-(H20*B20)),H20*(1+G20)*C20-(H20*B20)) -> 4.3527767
A21: RN | B21: 0.04 | C21: 0.04 | H21: =PREÇOS!D22 -> 13.3488 | I21: =IF(F21=0,,H21*(1+F21)*C21-(H21*B21)) -> 0 | J21: =IF(G21=0,IF(F21=0,,H21*(1+F21)*C21-(H21*B21)),H21*(1+G21)*C21-(H21*B21)) -> 0
A22: RO | B22: 0.04 | C22: 0.04 | H22: =PREÇOS!D23 -> 13.3488 | I22: =IF(F22=0,,H22*(1+F22)*C22-(H22*B22)) -> 0 | J22: =IF(G22=0,IF(F22=0,,H22*(1+F22)*C22-(H22*B22)),H22*(1+G22)*C22-(H22*B22)) -> 0
A23: RR | B23: 0.04 | C23: 0.04 | H23: =PREÇOS!D24 -> 13.3488 | I23: =IF(F23=0,,H23*(1+F23)*C23-(H23*B23)) -> 0 | J23: =IF(G23=0,IF(F23=0,,H23*(1+F23)*C23-(H23*B23)),H23*(1+G23)*C23-(H23*B23)) -> 0
A24: RS | B24: 0.04 | C24: 0.04 | H24: =PREÇOS!D25 -> 13.3488 | I24: =IF(F24=0,,H24*(1+F24)*C24-(H24*B24)) -> 0 | J24: =IF(G24=0,IF(F24=0,,H24*(1+F24)*C24-(H24*B24)),H24*(1+G24)*C24-(H24*B24)) -> 0
A25: SC | B25: 0.04 | C25: 0.04 | H25: =PREÇOS!D26 -> 13.3488 | I25: =IF(F25=0,,H25*(1+F25)*C25-(H25*B25)) -> 0 | J25: =IF(G25=0,IF(F25=0,,H25*(1+F25)*C25-(H25*B25)),H25*(1+G25)*C25-(H25*B25)) -> 0
A26: SE | B26: 0.04 | C26: 0.04 | H26: =PREÇOS!D27 -> 13.3488 | I26: =IF(F26=0,,H26*(1+F26)*C26-(H26*B26)) -> 0 | J26: =IF(G26=0,IF(F26=0,,H26*(1+F26)*C26-(H26*B26)),H26*(1+G26)*C26-(H26*B26)) -> 0
A27: SP | B27: 0.04 | C27: 0.18 | D27: 0.7539 | F27: 0.7539 | H27: =PREÇOS!D28 -> 13.3488 | I27: =IF(F27=0,,H27*(1+F27)*C27-(H27*B27)) -> 3.6802909 | J27: =IF(G27=0,IF(F27=0,,H27*(1+F27)*C27-(H27*B27)),H27*(1+G27)*C27-(H27*B27)) -> 3.6802909 | K27: =J27/H27 -> 0.275702
A28: SP/Atacado | B28: =B27 -> 0.04 | C28: =C27 -> 0.18 | D28: =D27 -> 0.7539 | E28: =E27 -> 0 | F28: =F27 -> 0.7539 | G28: =G27 -> 0 | H28: =PREÇOS!D29 -> 13.3488 | I28: =IF(F28=0,,H28*(1+F28)*C28-(H28*B28)) -> 3.6802909 | J28: =IF(G28=0,IF(F28=0,,H28*(1+F28)*C28-(H28*B28)),H28*(1+G28)*C28-(H28*B28)) -> 3.6802909
A29: TO | B29: 0.04 | C29: 0.04 | H29: =PREÇOS!D30 -> 13.3488 | I29: =IF(F29=0,,H29*(1+F29)*C29-(H29*B29)) -> 0 | J29: =IF(G29=0,IF(F29=0,,H29*(1+F29)*C29-(H29*B29)),H29*(1+G29)*C29-(H29*B29)) -> 0
A30: EX | H30: =PREÇOS!D31 -> 11.580084 | I30: =IF(F30=0,,H30*(1+F30)*C30-(H30*B30)) -> 0 | J30: =IF(G30=0,IF(F30=0,,H30*(1+F30)*C30-(H30*B30)),H30*(1+G30)*C30-(H30*B30)) -> 0

Sheet ST PAPAPASTA
A1: Estado | B1: Aliquota interestadual | C1: Aliquota interna | D1: MVA (normal) | E1: MVA (simples) | F1: Ajustada (normal) | G1: Ajustada (simples) | H1: Preço | I1: ST Normal | J1: ST Simples
A2: AC | B2: 0.07 | C2: 0.07 | H2: =PREÇOS!E3 -> 8.1556129 | I2: =IF(F2=0,,H2*(1+F2)*C2-(H2*B2)) -> 0 | J2: =IF(G2=0,IF(F2=0,,H2*(1+F2)*C2-(H2*B2)),H2*(1+G2)*C2-(H2*B2)) -> 0
A3: AL | B3: 0.07 | C3: 0.19 | D3: 0.2 | F3: 0.361 | H3: =PREÇOS!E4 -> 8.1556129 | I3: =IF(F3=0,,H3*(1+F3)*C3-(H3*B3)) -> 1.538067 | J3: =IF(G3=0,IF(F3=0,,H3*(1+F3)*C3-(H3*B3)),H3*(1+G3)*C3-(H3*B3)) -> 1.538067
A4: AM | B4: 0.07 | C4: 0.07 | H4: =PREÇOS!E5 -> 8.1556129 | I4: =IF(F4=0,,H4*(1+F4)*C4-(H4*B4)) -> 0 | J4: =IF(G4=0,IF(F4=0,,H4*(1+F4)*C4-(H4*B4)),H4*(1+G4)*C4-(H4*B4)) -> 0
A5: AP | B5: 0.07 | C5: 0.18 | D5: 0.38 | F5: 0.5651 | H5: =PREÇOS!E6 -> 8.1556129 | I5: =IF(F5=0,,H5*(1+F5)*C5-(H5*B5)) -> 1.7266901 | J5: =IF(G5=0,IF(F5=0,,H5*(1+F5)*C5-(H5*B5)),H5*(1+G5)*C5-(H5*B5)) -> 1.7266901
A6: BA | B6: 0.07 | C6: 0.07 | H6: =PREÇOS!E7 -> 8.1556129 | I6: =IF(F6=0,,H6*(1+F6)*C6-(H6*B6)) -> 0 | J6: =IF(G6=0,IF(F6=0,,H6*(1+F6)*C6-(H6*B6)),H6*(1+G6)*C6-(H6*B6)) -> 0
A7: CE | B7: 0.07 | C7: 0.07 | H7: =PREÇOS!E8 -> 8.1556129 | I7: =IF(F7=0,,H7*(1+F7)*C7-(H7*B7)) -> 0 | J7: =IF(G7=0,IF(F7=0,,H7*(1+F7)*C7-(H7*B7)),H7*(1+G7)*C7-(H7*B7)) -> 0
A8: DF | B8: 0.07 | C8: 0.07 | H8: =PREÇOS!E9 -> 8.1556129 | I8: =IF(F8=0,,H8*(1+F8)*C8-(H8*B8)) -> 0 | J8: =IF(G8=0,IF(F8=0,,H8*(1+F8)*C8-(H8*B8)),H8*(1+G8)*C8-(H8*B8)) -> 0
A9: ES | B9: 0.07 | C9: 0.07 | H9: =PREÇOS!E10 -> 8.1556129 | I9: =IF(F9=0,,H9*(1+F9)*C9-(H9*B9)) -> 0 | J9: =IF(G9=0,IF(F9=0,,H9*(1+F9)*C9-(H9*B9)),H9*(1+G9)*C9-(H9*B9)) -> 0
A10: GO | B10: 0.07 | C10: 0.07 | H10: =PREÇOS!E11 -> 8.1556129 | I10: =IF(F10=0,,H10*(1+F10)*C10-(H10*B10)) -> 0 | J10: =IF(G10=0,IF(F10=0,,H10*(1+F10)*C10-(H10*B10)),H10*(1+G10)*C10-(H10*B10)) -> 0
A11: MA | B11: 0.07 | C11: 0.07 | H11: =PREÇOS!E12 -> 8.1556129 | I11: =IF(F11=0,,H11*(1+F11)*C11-(H11*B11)) -> 0 | J11: =IF(G11=0,IF(F11=0,,H11*(1+F11)*C11-(H11*B11)),H11*(1+G11)*C11-(H11*B11)) -> 0
A12: MG | B12: 0.12 | C12: 0.18 | D12: 0.35 | F12: 0.35 | H12: =PREÇOS!E13 -> 8.619 | I12: =IF(F12=0,,H12*(1+F12)*C12-(H12*B12)) -> 1.060137 | J12: =IF(G12=0,IF(F12=0,,H12*(1+F12)*C12-(H12*B12)),H12*(1+G12)*C12-(H12*B12)) -> 1.060137
A13: MS | B13: 0.07 | C13: 0.07 | H13: =PREÇOS!E14 -> 8.1556129 | I13: =IF(F13=0,,H13*(1+F13)*C13-(H13*B13)) -> 0 | J13: =IF(G13=0,IF(F13=0,,H13*(1+F13)*C13-(H13*B13)),H13*(1+G13)*C13-(H13*B13)) -> 0
A14: MT | B14: 0.07 | C14: 0.17 | D14: 0.3545 | F14: 0.3545 | H14: =PREÇOS!E15 -> 8.1556129 | I14: =IF(F14=0,,H14*(1+F14)*C14-(H14*B14)) -> 1.3070593 | J14: =IF(G14=0,IF(F14=0,,H14*(1+F14)*C14-(H14*B14)),H14*(1+G14)*C14-(H14*B14)) -> 1.3070593
A15: PA | B15: 0.07 | C15: 0.07 | H15: =PREÇOS!E16 -> 8.1556129 | I15: =IF(F15=0,,H15*(1+F15)*C15-(H15*B15)) -> 0 | J15: =IF(G15=0,IF(F15=0,,H15*(1+F15)*C15-(H15*B15)),H15*(1+G15)*C15-(H15*B15)) -> 0
A16: PB | B16: 0.07 | C16: 0.07 | H16: =PREÇOS!E17 -> 8.1556129 | I16: =IF(F16=0,,H16*(1+F16)*C16-(H16*B16)) -> 0 | J16: =IF(G16=0,IF(F16=0,,H16*(1+F16)*C16-(H16*B16)),H16*(1+G16)*C16-(H16*B16)) -> 0
A17: PE | B17: 0.07 | C17: 0.07 | H17: =PREÇOS!E18 -> 8.1556129 | I17: =IF(F17=0,,H17*(1+F17)*C17-(H17*B17)) -> 0 | J17: =IF(G17=0,IF(F17=0,,H17*(1+F17)*C17-(H17*B17)),H17*(1+G17)*C17-(H17*B17)) -> 0
A18: PI | B18: 0.07 | C18: 0.07 | H18: =PREÇOS!E19 -> 8.1556129 | I18: =IF(F18=0,,H18*(1+F18)*C18-(H18*B18)) -> 0 | J18: =IF(G18=0,IF(F18=0,,H18*(1+F18)*C18-(H18*B18)),H18*(1+G18)*C18-(H18*B18)) -> 0
A19: PR | B19: 0.12 | C19: 0.12 | H19: =PREÇOS!E20 -> 8.619 | I19: =IF(F19=0,,H19*(1+F19)*C19-(H19*B19)) -> 0 | J19: =IF(G19=0,IF(F19=0,,H19*(1+F19)*C19-(H19*B19)),H19*(1+G19)*C19-(H19*B19)) -> 0
A20: RJ | B20: 0.12 | C20: 0.12 | H20: =PREÇOS!E21 -> 8.619 | I20: =IF(F20=0,,H20*(1+F20)*C20-(H20*B20)) -> 0 | J20: =IF(G20=0,IF(F20=0,,H20*(1+F20)*C20-(H20*B20)),H20*(1+G20)*C20-(H20*B20)) -> 0
A21: RN | B21: 0.07 | C21: 0.07 | H21: =PREÇOS!E22 -> 8.1556129 | I21: =IF(F21=0,,H21*(1+F21)*C21-(H21*B21)) -> 0 | J21: =IF(G21=0,IF(F21=0,,H21*(1+F21)*C21-(H21*B21)),H21*(1+G21)*C21-(H21*B21)) -> 0
A22: RO | B22: 0.07 | C22: 0.07 | H22: =PREÇOS!E23 -> 8.1556129 | I22: =IF(F22=0,,H22*(1+F22)*C22-(H22*B22)) -> 0 | J22: =IF(G22=0,IF(F22=0,,H22*(1+F22)*C22-(H22*B22)),H22*(1+G22)*C22-(H22*B22)) -> 0
A23: RR | B23: 0.07 | C23: 0.07 | H23: =PREÇOS!E24 -> 8.1556129 | I23: =IF(F23=0,,H23*(1+F23)*C23-(H23*B23)) -> 0 | J23: =IF(G23=0,IF(F23=0,,H23*(1+F23)*C23-(H23*B23)),H23*(1+G23)*C23-(H23*B23)) -> 0
A24: RS | B24: 0.12 | C24: 0.12 | H24: =PREÇOS!E25 -> 8.619 | I24: =IF(F24=0,,H24*(1+F24)*C24-(H24*B24)) -> 0 | J24: =IF(G24=0,IF(F24=0,,H24*(1+F24)*C24-(H24*B24)),H24*(1+G24)*C24-(H24*B24)) -> 0
A25: SC | B25: 0.12 | C25: 0.12 | H25: =PREÇOS!E26 -> 8.619 | I25: =IF(F25=0,,H25*(1+F25)*C25-(H25*B25)) -> 0 | J25: =IF(G25=0,IF(F25=0,,H25*(1+F25)*C25-(H25*B25)),H25*(1+G25)*C25-(H25*B25)) -> 0
A26: SE | B26: 0.07 | C26: 0.07 | H26: =PREÇOS!E27 -> 8.1556129 | I26: =IF(F26=0,,H26*(1+F26)*C26-(H26*B26)) -> 0 | J26: =IF(G26=0,IF(F26=0,,H26*(1+F26)*C26-(H26*B26)),H26*(1+G26)*C26-(H26*B26)) -> 0
A27: SP | B27: 0.12 | C27: 0.12 | H27: =PREÇOS!E28 -> 8.619 | I27: =IF(F27=0,,H27*(1+F27)*C27-(H27*B27)) -> 0 | J27: =IF(G27=0,IF(F27=0,,H27*(1+F27)*C27-(H27*B27)),H27*(1+G27)*C27-(H27*B27)) -> 0
A28: SP/Atacado | B28: =B27 -> 0.12 | C28: =C27 -> 0.12 | D28: =D27 -> 0 | E28: =E27 -> 0 | F28: =F27 -> 0 | G28: =G27 -> 0 | H28: =PREÇOS!E29 -> 8.619 | I28: =IF(F28=0,,H28*(1+F28)*C28-(H28*B28)) -> 0 | J28: =IF(G28=0,IF(F28=0,,H28*(1+F28)*C28-(H28*B28)),H28*(1+G28)*C28-(H28*B28)) -> 0
A29: TO | B29: 0.07 | C29: 0.07 | H29: =PREÇOS!E30 -> 8.1556129 | I29: =IF(F29=0,,H29*(1+F29)*C29-(H29*B29)) -> 0 | J29: =IF(G29=0,IF(F29=0,,H29*(1+F29)*C29-(H29*B29)),H29*(1+G29)*C29-(H29*B29)) -> 0
A30: EX | H30: =PREÇOS!E31 -> 6.4225452 | I30: =IF(F30=0,,H30*(1+F30)*C30-(H30*B30)) -> 0 | J30: =IF(G30=0,IF(F30=0,,H30*(1+F30)*C30-(H30*B30)),H30*(1+G30)*C30-(H30*B30)) -> 0

Sheet ST PALITINHOS
A1: Estado | B1: Aliquota interestadual | C1: Aliquota interna | D1: MVA (normal) | E1: MVA (simples) | F1: Ajustada (normal) | G1: Ajustada (simples) | H1: Preço | I1: ST Normal | J1: ST Simples
A2: AC | B2: 0.07 | C2: 0.07 | H2: =PREÇOS!C3 -> 3.7198452 | I2: =IF(F2=0,,H2*(1+F2)*C2-(H2*B2)) -> 0 | J2: =IF(G2=0,IF(F2=0,,H2*(1+F2)*C2-(H2*B2)),H2*(1+G2)*C2-(H2*B2)) -> 0
A3: AL | B3: 0.07 | C3: 0.19 | D3: 0.5432 | F3: 0.794 | H3: =PREÇOS!C4 -> 3.7198452 | I3: =IF(F3=0,,H3*(1+F3)*C3-(H3*B3)) -> 1.0075573 | J3: =IF(G3=0,IF(F3=0,,H3*(1+F3)*C3-(H3*B3)),H3*(1+G3)*C3-(H3*B3)) -> 1.0075573
A4: AM | B4: 0.07 | C4: 0.18 | H4: =PREÇOS!C5 -> 3.7198452 | I4: =IF(F4=0,,H4*(1+F4)*C4-(H4*B4)) -> 0 | J4: =IF(G4=0,IF(F4=0,,H4*(1+F4)*C4-(H4*B4)),H4*(1+G4)*C4-(H4*B4)) -> 0
A5: AP | B5: 0.07 | C5: 0.18 | D5: 0.41 | F5: 0.5991 | H5: =PREÇOS!C6 -> 3.7198452 | I5: =IF(F5=0,,H5*(1+F5)*C5-(H5*B5)) -> 0.81032363 | J5: =IF(G5=0,IF(F5=0,,H5*(1+F5)*C5-(H5*B5)),H5*(1+G5)*C5-(H5*B5)) -> 0.81032363
A6: BA | B6: 0.07 | C6: 0.07 | H6: =PREÇOS!C7 -> 3.7198452 | I6: =IF(F6=0,,H6*(1+F6)*C6-(H6*B6)) -> 0 | J6: =IF(G6=0,IF(F6=0,,H6*(1+F6)*C6-(H6*B6)),H6*(1+G6)*C6-(H6*B6)) -> 0
A7: CE | B7: 0.07 | C7: 0.07 | H7: =PREÇOS!C8 -> 3.7198452 | I7: =IF(F7=0,,H7*(1+F7)*C7-(H7*B7)) -> 0 | J7: =IF(G7=0,IF(F7=0,,H7*(1+F7)*C7-(H7*B7)),H7*(1+G7)*C7-(H7*B7)) -> 0
A8: DF | B8: 0.07 | C8: 0.07 | H8: =PREÇOS!C9 -> 3.7198452 | I8: =IF(F8=0,,H8*(1+F8)*C8-(H8*B8)) -> 0 | J8: =IF(G8=0,IF(F8=0,,H8*(1+F8)*C8-(H8*B8)),H8*(1+G8)*C8-(H8*B8)) -> 0
A9: ES | B9: 0.07 | C9: 0.07 | H9: =PREÇOS!C10 -> 3.7198452 | I9: =IF(F9=0,,H9*(1+F9)*C9-(H9*B9)) -> 0 | J9: =IF(G9=0,IF(F9=0,,H9*(1+F9)*C9-(H9*B9)),H9*(1+G9)*C9-(H9*B9)) -> 0
A10: GO | B10: 0.07 | C10: 0.07 | H10: =PREÇOS!C11 -> 3.7198452 | I10: =IF(F10=0,,H10*(1+F10)*C10-(H10*B10)) -> 0 | J10: =IF(G10=0,IF(F10=0,,H10*(1+F10)*C10-(H10*B10)),H10*(1+G10)*C10-(H10*B10)) -> 0
A11: MA | B11: 0.07 | C11: 0.07 | H11: =PREÇOS!C12 -> 3.7198452 | I11: =IF(F11=0,,H11*(1+F11)*C11-(H11*B11)) -> 0 | J11: =IF(G11=0,IF(F11=0,,H11*(1+F11)*C11-(H11*B11)),H11*(1+G11)*C11-(H11*B11)) -> 0
A12: MG | B12: 0.12 | C12: 0.18 | D12: 0.4 | F12: 0.5024 | H12: =PREÇOS!C13 -> 3.9312 | I12: =IF(F12=0,,H12*(1+F12)*C12-(H12*B12)) -> 0.59137828 | J12: =IF(G12=0,IF(F12=0,,H12*(1+F12)*C12-(H12*B12)),H12*(1+G12)*C12-(H12*B12)) -> 0.59137828
A13: MS | B13: 0.07 | C13: 0.07 | H13: =PREÇOS!C14 -> 3.7198452 | I13: =IF(F13=0,,H13*(1+F13)*C13-(H13*B13)) -> 0 | J13: =IF(G13=0,IF(F13=0,,H13*(1+F13)*C13-(H13*B13)),H13*(1+G13)*C13-(H13*B13)) -> 0
A14: MT | B14: 0.07 | C14: 0.17 | D14: 0.4552 | F14: 0.6305 | H14: =PREÇOS!C15 -> 3.7198452 | I14: =IF(F14=0,,H14*(1+F14)*C14-(H14*B14)) -> 0.77069612 | J14: =IF(G14=0,IF(F14=0,,H14*(1+F14)*C14-(H14*B14)),H14*(1+G14)*C14-(H14*B14)) -> 0.77069612
A15: PA | B15: 0.07 | C15: 0.07 | H15: =PREÇOS!C16 -> 3.7198452 | I15: =IF(F15=0,,H15*(1+F15)*C15-(H15*B15)) -> 0 | J15: =IF(G15=0,IF(F15=0,,H15*(1+F15)*C15-(H15*B15)),H15*(1+G15)*C15-(H15*B15)) -> 0
A16: PB | B16: 0.07 | C16: 0.07 | H16: =PREÇOS!C17 -> 3.7198452 | I16: =IF(F16=0,,H16*(1+F16)*C16-(H16*B16)) -> 0 | J16: =IF(G16=0,IF(F16=0,,H16*(1+F16)*C16-(H16*B16)),H16*(1+G16)*C16-(H16*B16)) -> 0
A17: PE | B17: 0.07 | C17: 0.07 | H17: =PREÇOS!C18 -> 3.7198452 | I17: =IF(F17=0,,H17*(1+F17)*C17-(H17*B17)) -> 0 | J17: =IF(G17=0,IF(F17=0,,H17*(1+F17)*C17-(H17*B17)),H17*(1+G17)*C17-(H17*B17)) -> 0
A18: PI | B18: 0.07 | C18: 0.07 | H18: =PREÇOS!C19 -> 3.7198452 | I18: =IF(F18=0,,H18*(1+F18)*C18-(H18*B18)) -> 0 | J18: =IF(G18=0,IF(F18=0,,H18*(1+F18)*C18-(H18*B18)),H18*(1+G18)*C18-(H18*B18)) -> 0
A19: PR | B19: 0.12 | C19: 0.195 | D19: 0.5432 | E19: 0.163 | F19: 0.687 | G19: 0.1968 | H19: =PREÇOS!C20 -> 3.9312 | I19: =IF(F19=0,,H19*(1+F19)*C19-(H19*B19)) -> 0.82148321 | J19: =IF(G19=0,IF(F19=0,,H19*(1+F19)*C19-(H19*B19)),H19*(1+G19)*C19-(H19*B19)) -> 0.44570373
A20: RJ | B20: 0.12 | C20: 0.22 | D20: 0.4698 | F20: 0.6582 | H20: =PREÇOS!C21 -> 3.9312 | I20: =IF(F20=0,,H20*(1+F20)*C20-(H20*B20)) -> 0.96237348 | J20: =IF(G20=0,IF(F20=0,,H20*(1+F20)*C20-(H20*B20)),H20*(1+G20)*C20-(H20*B20)) -> 0.96237348
A21: RN | B21: 0.07 | C21: 0.07 | H21: =PREÇOS!C22 -> 3.7198452 | I21: =IF(F21=0,,H21*(1+F21)*C21-(H21*B21)) -> 0 | J21: =IF(G21=0,IF(F21=0,,H21*(1+F21)*C21-(H21*B21)),H21*(1+G21)*C21-(H21*B21)) -> 0
A22: RO | B22: 0.07 | C22: 0.07 | H22: =PREÇOS!C23 -> 3.7198452 | I22: =IF(F22=0,,H22*(1+F22)*C22-(H22*B22)) -> 0 | J22: =IF(G22=0,IF(F22=0,,H22*(1+F22)*C22-(H22*B22)),H22*(1+G22)*C22-(H22*B22)) -> 0
A23: RR | B23: 0.07 | C23: 0.07 | H23: =PREÇOS!C24 -> 3.7198452 | I23: =IF(F23=0,,H23*(1+F23)*C23-(H23*B23)) -> 0 | J23: =IF(G23=0,IF(F23=0,,H23*(1+F23)*C23-(H23*B23)),H23*(1+G23)*C23-(H23*B23)) -> 0
A24: RS | B24: 0.12 | C24: 0.12 | H24: =PREÇOS!C25 -> 3.9312 | I24: =IF(F24=0,,H24*(1+F24)*C24-(H24*B24)) -> 0 | J24: =IF(G24=0,IF(F24=0,,H24*(1+F24)*C24-(H24*B24)),H24*(1+G24)*C24-(H24*B24)) -> 0
A25: SC | B25: 0.12 | C25: 0.12 | H25: =PREÇOS!C26 -> 3.9312 | I25: =IF(F25=0,,H25*(1+F25)*C25-(H25*B25)) -> 0 | J25: =IF(G25=0,IF(F25=0,,H25*(1+F25)*C25-(H25*B25)),H25*(1+G25)*C25-(H25*B25)) -> 0
A26: SE | B26: 0.07 | C26: 0.07 | H26: =PREÇOS!C27 -> 3.7198452 | I26: =IF(F26=0,,H26*(1+F26)*C26-(H26*B26)) -> 0 | J26: =IF(G26=0,IF(F26=0,,H26*(1+F26)*C26-(H26*B26)),H26*(1+G26)*C26-(H26*B26)) -> 0
A27: SP | B27: 0.12 | C27: 0.18 | H27: =PREÇOS!C28 -> 3.9312 | I27: =IF(F27=0,,H27*(1+F27)*C27-(H27*B27)) -> 0 | J27: =IF(G27=0,IF(F27=0,,H27*(1+F27)*C27-(H27*B27)),H27*(1+G27)*C27-(H27*B27)) -> 0 | K27: comunicado enviado 1/26 - suspensão da ST para palitinhos
A28: SP/Atacado | B28: =B27 -> 0.12 | C28: =C27 -> 0.18 | D28: =D27 -> 0 | E28: =E27 -> 0 | F28: =F27 -> 0 | G28: =G27 -> 0 | H28: =PREÇOS!C29 -> 3.9312 | I28: =IF(F28=0,,H28*(1+F28)*C28-(H28*B28)) -> 0 | J28: =IF(G28=0,IF(F28=0,,H28*(1+F28)*C28-(H28*B28)),H28*(1+G28)*C28-(H28*B28)) -> 0
A29: TO | B29: 0.07 | C29: 0.07 | H29: =PREÇOS!C30 -> 3.7198452 | I29: =IF(F29=0,,H29*(1+F29)*C29-(H29*B29)) -> 0 | J29: =IF(G29=0,IF(F29=0,,H29*(1+F29)*C29-(H29*B29)),H29*(1+G29)*C29-(H29*B29)) -> 0
A30: EX | H30: =PREÇOS!C31 -> 2.9293781 | I30: =IF(F30=0,,H30*(1+F30)*C30-(H30*B30)) -> 0 | J30: =IF(G30=0,IF(F30=0,,H30*(1+F30)*C30-(H30*B30)),H30*(1+G30)*C30-(H30*B30)) -> 0

Sheet ST EXTRUSADOS
A1: Estado | B1: Aliquota interestadual | C1: Aliquota interna | D1: MVA (normal) | E1: MVA (simples) | F1: Ajustada (normal) | G1: Ajustada (simples) | H1: Preço | I1: ST Normal | J1: ST Simples
A2: AC | B2: 0.07 | C2: 0.07 | H2: =PREÇOS!O3 -> 4.8258065 | I2: =IF(F2=0,,H2*(1+F2)*C2-(H2*B2)) -> 0 | J2: =IF(G2=0,IF(F2=0,,H2*(1+F2)*C2-(H2*B2)),H2*(1+G2)*C2-(H2*B2)) -> 0
A3: AL | B3: 0.07 | C3: 0.19 | D3: 0.5432 | F3: 0.794 | H3: =PREÇOS!O4 -> 4.8258065 | I3: =IF(F3=0,,H3*(1+F3)*C3-(H3*B3)) -> 1.3071179 | J3: =IF(G3=0,IF(F3=0,,H3*(1+F3)*C3-(H3*B3)),H3*(1+G3)*C3-(H3*B3)) -> 1.3071179
A4: AM | B4: 0.07 | C4: 0.18 | H4: =PREÇOS!O5 -> 4.8258065 | I4: =IF(F4=0,,H4*(1+F4)*C4-(H4*B4)) -> 0 | J4: =IF(G4=0,IF(F4=0,,H4*(1+F4)*C4-(H4*B4)),H4*(1+G4)*C4-(H4*B4)) -> 0
A5: AP | B5: 0.07 | C5: 0.18 | D5: 0.41 | F5: 0.5991 | H5: =PREÇOS!O6 -> 4.8258065 | I5: =IF(F5=0,,H5*(1+F5)*C5-(H5*B5)) -> 1.051244 | J5: =IF(G5=0,IF(F5=0,,H5*(1+F5)*C5-(H5*B5)),H5*(1+G5)*C5-(H5*B5)) -> 1.051244
A6: BA | B6: 0.07 | C6: 0.07 | H6: =PREÇOS!O7 -> 4.8258065 | I6: =IF(F6=0,,H6*(1+F6)*C6-(H6*B6)) -> 0 | J6: =IF(G6=0,IF(F6=0,,H6*(1+F6)*C6-(H6*B6)),H6*(1+G6)*C6-(H6*B6)) -> 0
A7: CE | B7: 0.07 | C7: 0.07 | H7: =PREÇOS!O8 -> 4.8258065 | I7: =IF(F7=0,,H7*(1+F7)*C7-(H7*B7)) -> 0 | J7: =IF(G7=0,IF(F7=0,,H7*(1+F7)*C7-(H7*B7)),H7*(1+G7)*C7-(H7*B7)) -> 0
A8: DF | B8: 0.07 | C8: 0.07 | H8: =PREÇOS!O9 -> 4.8258065 | I8: =IF(F8=0,,H8*(1+F8)*C8-(H8*B8)) -> 0 | J8: =IF(G8=0,IF(F8=0,,H8*(1+F8)*C8-(H8*B8)),H8*(1+G8)*C8-(H8*B8)) -> 0
A9: ES | B9: 0.07 | C9: 0.07 | H9: =PREÇOS!O10 -> 4.8258065 | I9: =IF(F9=0,,H9*(1+F9)*C9-(H9*B9)) -> 0 | J9: =IF(G9=0,IF(F9=0,,H9*(1+F9)*C9-(H9*B9)),H9*(1+G9)*C9-(H9*B9)) -> 0
A10: GO | B10: 0.07 | C10: 0.07 | H10: =PREÇOS!O11 -> 4.8258065 | I10: =IF(F10=0,,H10*(1+F10)*C10-(H10*B10)) -> 0 | J10: =IF(G10=0,IF(F10=0,,H10*(1+F10)*C10-(H10*B10)),H10*(1+G10)*C10-(H10*B10)) -> 0
A11: MA | B11: 0.07 | C11: 0.07 | H11: =PREÇOS!O12 -> 4.8258065 | I11: =IF(F11=0,,H11*(1+F11)*C11-(H11*B11)) -> 0 | J11: =IF(G11=0,IF(F11=0,,H11*(1+F11)*C11-(H11*B11)),H11*(1+G11)*C11-(H11*B11)) -> 0
A12: MG | B12: 0.12 | C12: 0.18 | D12: 0.4 | F12: 0.5024 | H12: =PREÇOS!O13 -> 5.1 | I12: =IF(F12=0,,H12*(1+F12)*C12-(H12*B12)) -> 0.7672032 | J12: =IF(G12=0,IF(F12=0,,H12*(1+F12)*C12-(H12*B12)),H12*(1+G12)*C12-(H12*B12)) -> 0.7672032
A13: MS | B13: 0.07 | C13: 0.07 | H13: =PREÇOS!O14 -> 4.8258065 | I13: =IF(F13=0,,H13*(1+F13)*C13-(H13*B13)) -> 0 | J13: =IF(G13=0,IF(F13=0,,H13*(1+F13)*C13-(H13*B13)),H13*(1+G13)*C13-(H13*B13)) -> 0
A14: MT | B14: 0.07 | C14: 0.17 | D14: 0.4552 | F14: 0.6305 | H14: =PREÇOS!O15 -> 4.8258065 | I14: =IF(F14=0,,H14*(1+F14)*C14-(H14*B14)) -> 0.99983471 | J14: =IF(G14=0,IF(F14=0,,H14*(1+F14)*C14-(H14*B14)),H14*(1+G14)*C14-(H14*B14)) -> 0.99983471
A15: PA | B15: 0.07 | C15: 0.07 | H15: =PREÇOS!O16 -> 4.8258065 | I15: =IF(F15=0,,H15*(1+F15)*C15-(H15*B15)) -> 0 | J15: =IF(G15=0,IF(F15=0,,H15*(1+F15)*C15-(H15*B15)),H15*(1+G15)*C15-(H15*B15)) -> 0
A16: PB | B16: 0.07 | C16: 0.07 | H16: =PREÇOS!O17 -> 4.8258065 | I16: =IF(F16=0,,H16*(1+F16)*C16-(H16*B16)) -> 0 | J16: =IF(G16=0,IF(F16=0,,H16*(1+F16)*C16-(H16*B16)),H16*(1+G16)*C16-(H16*B16)) -> 0
A17: PE | B17: 0.07 | C17: 0.07 | H17: =PREÇOS!O18 -> 4.8258065 | I17: =IF(F17=0,,H17*(1+F17)*C17-(H17*B17)) -> 0 | J17: =IF(G17=0,IF(F17=0,,H17*(1+F17)*C17-(H17*B17)),H17*(1+G17)*C17-(H17*B17)) -> 0
A18: PI | B18: 0.07 | C18: 0.07 | H18: =PREÇOS!O19 -> 4.8258065 | I18: =IF(F18=0,,H18*(1+F18)*C18-(H18*B18)) -> 0 | J18: =IF(G18=0,IF(F18=0,,H18*(1+F18)*C18-(H18*B18)),H18*(1+G18)*C18-(H18*B18)) -> 0
A19: PR | B19: 0.12 | C19: 0.195 | D19: 0.5432 | E19: 0.163 | F19: 0.687 | G19: 0.1968 | H19: =PREÇOS!O20 -> 5.1 | I19: =IF(F19=0,,H19*(1+F19)*C19-(H19*B19)) -> 1.0657215 | J19: =IF(G19=0,IF(F19=0,,H19*(1+F19)*C19-(H19*B19)),H19*(1+G19)*C19-(H19*B19)) -> 0.5782176
A20: RJ | B20: 0.12 | C20: 0.22 | D20: 0.4698 | F20: 0.6582 | H20: =PREÇOS!O21 -> 5.1 | I20: =IF(F20=0,,H20*(1+F20)*C20-(H20*B20)) -> 1.2485004 | J20: =IF(G20=0,IF(F20=0,,H20*(1+F20)*C20-(H20*B20)),H20*(1+G20)*C20-(H20*B20)) -> 1.2485004
A21: RN | B21: 0.07 | C21: 0.07 | H21: =PREÇOS!O22 -> 4.8258065 | I21: =IF(F21=0,,H21*(1+F21)*C21-(H21*B21)) -> 0 | J21: =IF(G21=0,IF(F21=0,,H21*(1+F21)*C21-(H21*B21)),H21*(1+G21)*C21-(H21*B21)) -> 0
A22: RO | B22: 0.07 | C22: 0.07 | H22: =PREÇOS!O23 -> 4.8258065 | I22: =IF(F22=0,,H22*(1+F22)*C22-(H22*B22)) -> 0 | J22: =IF(G22=0,IF(F22=0,,H22*(1+F22)*C22-(H22*B22)),H22*(1+G22)*C22-(H22*B22)) -> 0
A23: RR | B23: 0.07 | C23: 0.07 | H23: =PREÇOS!O24 -> 4.8258065 | I23: =IF(F23=0,,H23*(1+F23)*C23-(H23*B23)) -> 0 | J23: =IF(G23=0,IF(F23=0,,H23*(1+F23)*C23-(H23*B23)),H23*(1+G23)*C23-(H23*B23)) -> 0
A24: RS | B24: 0.12 | C24: 0.12 | H24: =PREÇOS!O25 -> 5.1 | I24: =IF(F24=0,,H24*(1+F24)*C24-(H24*B24)) -> 0 | J24: =IF(G24=0,IF(F24=0,,H24*(1+F24)*C24-(H24*B24)),H24*(1+G24)*C24-(H24*B24)) -> 0
A25: SC | B25: 0.12 | C25: 0.12 | H25: =PREÇOS!O26 -> 5.1 | I25: =IF(F25=0,,H25*(1+F25)*C25-(H25*B25)) -> 0 | J25: =IF(G25=0,IF(F25=0,,H25*(1+F25)*C25-(H25*B25)),H25*(1+G25)*C25-(H25*B25)) -> 0
A26: SE | B26: 0.07 | C26: 0.07 | H26: =PREÇOS!O27 -> 4.8258065 | I26: =IF(F26=0,,H26*(1+F26)*C26-(H26*B26)) -> 0 | J26: =IF(G26=0,IF(F26=0,,H26*(1+F26)*C26-(H26*B26)),H26*(1+G26)*C26-(H26*B26)) -> 0
A27: SP | B27: 0.12 | C27: 0.18 | H27: =PREÇOS!O28 -> 5.1 | I27: =IF(F27=0,,H27*(1+F27)*C27-(H27*B27)) -> 0 | J27: =IF(G27=0,IF(F27=0,,H27*(1+F27)*C27-(H27*B27)),H27*(1+G27)*C27-(H27*B27)) -> 0 | K27: comunicado enviado 1/26 - suspensão da ST para palitinhos
A28: SP/Atacado | B28: =B27 -> 0.12 | C28: =C27 -> 0.18 | D28: =D27 -> 0 | E28: =E27 -> 0 | F28: =F27 -> 0 | G28: =G27 -> 0 | H28: =PREÇOS!O29 -> 5.1 | I28: =IF(F28=0,,H28*(1+F28)*C28-(H28*B28)) -> 0 | J28: =IF(G28=0,IF(F28=0,,H28*(1+F28)*C28-(H28*B28)),H28*(1+G28)*C28-(H28*B28)) -> 0
A29: TO | B29: 0.07 | C29: 0.07 | H29: =PREÇOS!O30 -> 4.8258065 | I29: =IF(F29=0,,H29*(1+F29)*C29-(H29*B29)) -> 0 | J29: =IF(G29=0,IF(F29=0,,H29*(1+F29)*C29-(H29*B29)),H29*(1+G29)*C29-(H29*B29)) -> 0
A30: EX | H30: =PREÇOS!O31 -> 3.8003226 | I30: =IF(F30=0,,H30*(1+F30)*C30-(H30*B30)) -> 0 | J30: =IF(G30=0,IF(F30=0,,H30*(1+F30)*C30-(H30*B30)),H30*(1+G30)*C30-(H30*B30)) -> 0

Sheet ST BISCOTTI
A1: Estado | B1: Aliquota interestadual | C1: Aliquota interna | D1: MVA (normal) | E1: MVA (simples) | F1: Ajustada (normal) | G1: Ajustada (simples) | H1: Preço | I1: ST Normal | J1: ST Simples
A2: AC | B2: 0.07 | C2: 0.19 | H2: =PREÇOS!H3 -> 8.5047742 | I2: =IF(F2=0,,H2*(1+F2)*C2-(H2*B2)) -> 0 | J2: =IF(G2=0,IF(F2=0,,H2*(1+F2)*C2-(H2*B2)),H2*(1+G2)*C2-(H2*B2)) -> 0
A3: AL | B3: 0.07 | C3: 0.2 | F3: 0.5113 | H3: =PREÇOS!H4 -> 8.5047742 | I3: =IF(F3=0,,H3*(1+F3)*C3-(H3*B3)) -> 1.9753189 | J3: =IF(G3=0,IF(F3=0,,H3*(1+F3)*C3-(H3*B3)),H3*(1+G3)*C3-(H3*B3)) -> 1.9753189
A4: AM | B4: 0.07 | C4: 0.2 | H4: =PREÇOS!H5 -> 8.5047742 | I4: =IF(F4=0,,H4*(1+F4)*C4-(H4*B4)) -> 0 | J4: =IF(G4=0,IF(F4=0,,H4*(1+F4)*C4-(H4*B4)),H4*(1+G4)*C4-(H4*B4)) -> 0
A5: AP | B5: 0.07 | C5: 0.18 | F5: 0.5198 | H5: =PREÇOS!H6 -> 8.5047742 | I5: =IF(F5=0,,H5*(1+F5)*C5-(H5*B5)) -> 1.7312659 | J5: =IF(G5=0,IF(F5=0,,H5*(1+F5)*C5-(H5*B5)),H5*(1+G5)*C5-(H5*B5)) -> 1.7312659
A6: BA | B6: 0.07 | C6: 0.19 | H6: =PREÇOS!H7 -> 8.5047742 | I6: =IF(F6=0,,H6*(1+F6)*C6-(H6*B6)) -> 0 | J6: =IF(G6=0,IF(F6=0,,H6*(1+F6)*C6-(H6*B6)),H6*(1+G6)*C6-(H6*B6)) -> 0
A7: CE | B7: 0.07 | C7: 0.2 | H7: =PREÇOS!H8 -> 8.5047742 | I7: =IF(F7=0,,H7*(1+F7)*C7-(H7*B7)) -> 0 | J7: =IF(G7=0,IF(F7=0,,H7*(1+F7)*C7-(H7*B7)),H7*(1+G7)*C7-(H7*B7)) -> 0
A8: DF | B8: 0.07 | C8: 0.18 | H8: =PREÇOS!H9 -> 8.5047742 | I8: =IF(F8=0,,H8*(1+F8)*C8-(H8*B8)) -> 0 | J8: =IF(G8=0,IF(F8=0,,H8*(1+F8)*C8-(H8*B8)),H8*(1+G8)*C8-(H8*B8)) -> 0
A9: ES | B9: 0.07 | C9: 0.17 | H9: =PREÇOS!H10 -> 8.5047742 | I9: =IF(F9=0,,H9*(1+F9)*C9-(H9*B9)) -> 0 | J9: =IF(G9=0,IF(F9=0,,H9*(1+F9)*C9-(H9*B9)),H9*(1+G9)*C9-(H9*B9)) -> 0
A10: GO | B10: 0.07 | C10: 0.17 | H10: =PREÇOS!H11 -> 8.5047742 | I10: =IF(F10=0,,H10*(1+F10)*C10-(H10*B10)) -> 0 | J10: =IF(G10=0,IF(F10=0,,H10*(1+F10)*C10-(H10*B10)),H10*(1+G10)*C10-(H10*B10)) -> 0
A11: MA | B11: 0.07 | C11: 0.2 | H11: =PREÇOS!H12 -> 8.5047742 | I11: =IF(F11=0,,H11*(1+F11)*C11-(H11*B11)) -> 0 | J11: =IF(G11=0,IF(F11=0,,H11*(1+F11)*C11-(H11*B11)),H11*(1+G11)*C11-(H11*B11)) -> 0
A12: MG | B12: 0.12 | C12: 0.12 | F12: 0.25 | H12: =PREÇOS!H13 -> 8.988 | I12: =IF(F12=0,,H12*(1+F12)*C12-(H12*B12)) -> 0.26964 | J12: =IF(G12=0,IF(F12=0,,H12*(1+F12)*C12-(H12*B12)),H12*(1+G12)*C12-(H12*B12)) -> 0.26964
A13: MS | B13: 0.07 | C13: 0.17 | H13: =PREÇOS!H14 -> 8.5047742 | I13: =IF(F13=0,,H13*(1+F13)*C13-(H13*B13)) -> 0 | J13: =IF(G13=0,IF(F13=0,,H13*(1+F13)*C13-(H13*B13)),H13*(1+G13)*C13-(H13*B13)) -> 0
A14: MT | B14: 0.07 | C14: 0.17 | F14: 0.3978 | H14: =PREÇOS!H15 -> 8.5047742 | I14: =IF(F14=0,,H14*(1+F14)*C14-(H14*B14)) -> 1.4256213 | J14: =IF(G14=0,IF(F14=0,,H14*(1+F14)*C14-(H14*B14)),H14*(1+G14)*C14-(H14*B14)) -> 1.4256213
A15: PA | B15: 0.07 | C15: 0.19 | H15: =PREÇOS!H16 -> 8.5047742 | I15: =IF(F15=0,,H15*(1+F15)*C15-(H15*B15)) -> 0 | J15: =IF(G15=0,IF(F15=0,,H15*(1+F15)*C15-(H15*B15)),H15*(1+G15)*C15-(H15*B15)) -> 0
A16: PB | B16: 0.07 | C16: 0.18 | H16: =PREÇOS!H17 -> 8.5047742 | I16: =IF(F16=0,,H16*(1+F16)*C16-(H16*B16)) -> 0 | J16: =IF(G16=0,IF(F16=0,,H16*(1+F16)*C16-(H16*B16)),H16*(1+G16)*C16-(H16*B16)) -> 0
A17: PE | B17: 0.07 | C17: 0.18 | H17: =PREÇOS!H18 -> 8.5047742 | I17: =IF(F17=0,,H17*(1+F17)*C17-(H17*B17)) -> 0 | J17: =IF(G17=0,IF(F17=0,,H17*(1+F17)*C17-(H17*B17)),H17*(1+G17)*C17-(H17*B17)) -> 0
A18: PI | B18: 0.07 | C18: 0.21 | H18: =PREÇOS!H19 -> 8.5047742 | I18: =IF(F18=0,,H18*(1+F18)*C18-(H18*B18)) -> 0 | J18: =IF(G18=0,IF(F18=0,,H18*(1+F18)*C18-(H18*B18)),H18*(1+G18)*C18-(H18*B18)) -> 0
A19: PR | B19: 0.12 | C19: 0.12 | H19: =PREÇOS!H20 -> 8.988 | I19: =IF(F19=0,,H19*(1+F19)*C19-(H19*B19)) -> 0 | J19: =IF(G19=0,IF(F19=0,,H19*(1+F19)*C19-(H19*B19)),H19*(1+G19)*C19-(H19*B19)) -> 0
A20: RJ | B20: 0.12 | C20: 0.22 | F20: 0.5253 | H20: =PREÇOS!H21 -> 8.988 | I20: =IF(F20=0,,H20*(1+F20)*C20-(H20*B20)) -> 1.9375072 | J20: =IF(G20=0,IF(F20=0,,H20*(1+F20)*C20-(H20*B20)),H20*(1+G20)*C20-(H20*B20)) -> 1.9375072
A21: RN | B21: 0.07 | C21: 0.2 | H21: =PREÇOS!H22 -> 8.5047742 | I21: =IF(F21=0,,H21*(1+F21)*C21-(H21*B21)) -> 0 | J21: =IF(G21=0,IF(F21=0,,H21*(1+F21)*C21-(H21*B21)),H21*(1+G21)*C21-(H21*B21)) -> 0
A22: RO | B22: 0.07 | C22: 0.175 | H22: =PREÇOS!H23 -> 8.5047742 | I22: =IF(F22=0,,H22*(1+F22)*C22-(H22*B22)) -> 0 | J22: =IF(G22=0,IF(F22=0,,H22*(1+F22)*C22-(H22*B22)),H22*(1+G22)*C22-(H22*B22)) -> 0
A23: RR | B23: 0.07 | C23: 0.2 | H23: =PREÇOS!H24 -> 8.5047742 | I23: =IF(F23=0,,H23*(1+F23)*C23-(H23*B23)) -> 0 | J23: =IF(G23=0,IF(F23=0,,H23*(1+F23)*C23-(H23*B23)),H23*(1+G23)*C23-(H23*B23)) -> 0
A24: RS | B24: 0.12 | C24: 0.17 | H24: =PREÇOS!H25 -> 8.988 | I24: =IF(F24=0,,H24*(1+F24)*C24-(H24*B24)) -> 0 | J24: =IF(G24=0,IF(F24=0,,H24*(1+F24)*C24-(H24*B24)),H24*(1+G24)*C24-(H24*B24)) -> 0
A25: SC | B25: 0.12 | C25: 0.17 | H25: =PREÇOS!H26 -> 8.988 | I25: =IF(F25=0,,H25*(1+F25)*C25-(H25*B25)) -> 0 | J25: =IF(G25=0,IF(F25=0,,H25*(1+F25)*C25-(H25*B25)),H25*(1+G25)*C25-(H25*B25)) -> 0
A26: SE | B26: 0.07 | C26: 0.2 | H26: =PREÇOS!H27 -> 8.5047742 | I26: =IF(F26=0,,H26*(1+F26)*C26-(H26*B26)) -> 0 | J26: =IF(G26=0,IF(F26=0,,H26*(1+F26)*C26-(H26*B26)),H26*(1+G26)*C26-(H26*B26)) -> 0
A27: SP | B27: 0.12 | C27: 0.18 | D27: 0.6077 | F27: 0.6077 | H27: =PREÇOS!H28 -> 8.988 | I27: =IF(F27=0,,H27*(1+F27)*C27-(H27*B27)) -> 1.5224414 | J27: =IF(G27=0,IF(F27=0,,H27*(1+F27)*C27-(H27*B27)),H27*(1+G27)*C27-(H27*B27)) -> 1.5224414 | K27: =J27/H27 -> 0.169386
A28: SP/Atacado | B28: =B27 -> 0.12 | C28: =C27 -> 0.18 | D28: 0.6077 | E28: =E27 -> 0 | F28: 0.6077 | G28: =G27 -> 0 | H28: =PREÇOS!H29 -> 8.988 | I28: =IF(F28=0,,H28*(1+F28)*C28-(H28*B28)) -> 1.5224414 | J28: =IF(G28=0,IF(F28=0,,H28*(1+F28)*C28-(H28*B28)),H28*(1+G28)*C28-(H28*B28)) -> 1.5224414
A29: TO | B29: 0.07 | C29: 0.2 | H29: =PREÇOS!H30 -> 8.5047742 | I29: =IF(F29=0,,H29*(1+F29)*C29-(H29*B29)) -> 0 | J29: =IF(G29=0,IF(F29=0,,H29*(1+F29)*C29-(H29*B29)),H29*(1+G29)*C29-(H29*B29)) -> 0
A30: EX

Sheet ST CEREAL
A1: Estado | B1: Aliquota interestadual | C1: Aliquota interna | D1: MVA (normal) | E1: MVA (simples) | F1: Ajustada (normal) | G1: Ajustada (simples) | H1: Preço | I1: ST Normal | J1: ST Simples
A2: AC | B2: 0.07 | C2: 0.17 | H2: =PREÇOS!G3 -> 7.05 | I2: =IF(F2=0,,H2*(1+F2)*C2-(H2*B2)) -> 0 | J2: =IF(G2=0,IF(F2=0,,H2*(1+F2)*C2-(H2*B2)),H2*(1+G2)*C2-(H2*B2)) -> 0
A3: AL | B3: 0.07 | C3: 0.2 | F3: 0.71 | H3: =PREÇOS!G4 -> 7.05 | I3: =IF(F3=0,,H3*(1+F3)*C3-(H3*B3)) -> 1.9176 | J3: =IF(G3=0,IF(F3=0,,H3*(1+F3)*C3-(H3*B3)),H3*(1+G3)*C3-(H3*B3)) -> 1.9176
A4: AM | B4: 0.07 | C4: 0.2 | F4: 0.5538 | H4: =PREÇOS!G5 -> 7.05 | I4: =IF(F4=0,,H4*(1+F4)*C4-(H4*B4)) -> 1.697358 | J4: =IF(G4=0,IF(F4=0,,H4*(1+F4)*C4-(H4*B4)),H4*(1+G4)*C4-(H4*B4)) -> 1.697358
A5: AP | B5: 0.07 | C5: 0.18 | H5: =PREÇOS!G6 -> 7.05 | I5: =IF(F5=0,,H5*(1+F5)*C5-(H5*B5)) -> 0 | J5: =IF(G5=0,IF(F5=0,,H5*(1+F5)*C5-(H5*B5)),H5*(1+G5)*C5-(H5*B5)) -> 0
A6: BA | B6: 0.07 | C6: 0.19 | H6: =PREÇOS!G7 -> 7.05 | I6: =IF(F6=0,,H6*(1+F6)*C6-(H6*B6)) -> 0 | J6: =IF(G6=0,IF(F6=0,,H6*(1+F6)*C6-(H6*B6)),H6*(1+G6)*C6-(H6*B6)) -> 0
A7: CE | B7: 0.07 | C7: 0.2 | H7: =PREÇOS!G8 -> 7.05 | I7: =IF(F7=0,,H7*(1+F7)*C7-(H7*B7)) -> 0 | J7: =IF(G7=0,IF(F7=0,,H7*(1+F7)*C7-(H7*B7)),H7*(1+G7)*C7-(H7*B7)) -> 0
A8: DF | B8: 0.07 | C8: 0.18 | H8: =PREÇOS!G9 -> 7.05 | I8: =IF(F8=0,,H8*(1+F8)*C8-(H8*B8)) -> 0 | J8: =IF(G8=0,IF(F8=0,,H8*(1+F8)*C8-(H8*B8)),H8*(1+G8)*C8-(H8*B8)) -> 0
A9: ES | B9: 0.07 | C9: 0.17 | H9: =PREÇOS!G10 -> 7.05 | I9: =IF(F9=0,,H9*(1+F9)*C9-(H9*B9)) -> 0 | J9: =IF(G9=0,IF(F9=0,,H9*(1+F9)*C9-(H9*B9)),H9*(1+G9)*C9-(H9*B9)) -> 0
A10: GO | B10: 0.07 | C10: 0.17 | H10: =PREÇOS!G11 -> 7.05 | I10: =IF(F10=0,,H10*(1+F10)*C10-(H10*B10)) -> 0 | J10: =IF(G10=0,IF(F10=0,,H10*(1+F10)*C10-(H10*B10)),H10*(1+G10)*C10-(H10*B10)) -> 0
A11: MA | B11: 0.07 | C11: 0.2 | H11: =PREÇOS!G12 -> 7.05 | I11: =IF(F11=0,,H11*(1+F11)*C11-(H11*B11)) -> 0 | J11: =IF(G11=0,IF(F11=0,,H11*(1+F11)*C11-(H11*B11)),H11*(1+G11)*C11-(H11*B11)) -> 0
A12: MG | B12: 0.12 | C12: 0.18 | F12: 0.4488 | H12: =PREÇOS!G13 -> 7.5 | I12: =IF(F12=0,,H12*(1+F12)*C12-(H12*B12)) -> 1.05588 | J12: =IF(G12=0,IF(F12=0,,H12*(1+F12)*C12-(H12*B12)),H12*(1+G12)*C12-(H12*B12)) -> 1.05588
A13: MS | B13: 0.07 | C13: 0.17 | H13: =PREÇOS!G14 -> 7.05 | I13: =IF(F13=0,,H13*(1+F13)*C13-(H13*B13)) -> 0 | J13: =IF(G13=0,IF(F13=0,,H13*(1+F13)*C13-(H13*B13)),H13*(1+G13)*C13-(H13*B13)) -> 0
A14: MT | B14: 0.07 | C14: 0.17 | F14: 0.4552 | H14: =PREÇOS!G15 -> 7.05 | I14: =IF(F14=0,,H14*(1+F14)*C14-(H14*B14)) -> 1.2505572 | J14: =IF(G14=0,IF(F14=0,,H14*(1+F14)*C14-(H14*B14)),H14*(1+G14)*C14-(H14*B14)) -> 1.2505572
A15: PA | B15: 0.07 | C15: 0.19 | H15: =PREÇOS!G16 -> 7.05 | I15: =IF(F15=0,,H15*(1+F15)*C15-(H15*B15)) -> 0 | J15: =IF(G15=0,IF(F15=0,,H15*(1+F15)*C15-(H15*B15)),H15*(1+G15)*C15-(H15*B15)) -> 0
A16: PB | B16: 0.07 | C16: 0.18 | H16: =PREÇOS!G17 -> 7.05 | I16: =IF(F16=0,,H16*(1+F16)*C16-(H16*B16)) -> 0 | J16: =IF(G16=0,IF(F16=0,,H16*(1+F16)*C16-(H16*B16)),H16*(1+G16)*C16-(H16*B16)) -> 0
A17: PE | B17: 0.07 | C17: 0.18 | H17: =PREÇOS!G18 -> 7.05 | I17: =IF(F17=0,,H17*(1+F17)*C17-(H17*B17)) -> 0 | J17: =IF(G17=0,IF(F17=0,,H17*(1+F17)*C17-(H17*B17)),H17*(1+G17)*C17-(H17*B17)) -> 0
A18: PI | B18: 0.07 | C18: 0.21 | H18: =PREÇOS!G19 -> 7.05 | I18: =IF(F18=0,,H18*(1+F18)*C18-(H18*B18)) -> 0 | J18: =IF(G18=0,IF(F18=0,,H18*(1+F18)*C18-(H18*B18)),H18*(1+G18)*C18-(H18*B18)) -> 0
A19: PR | B19: 0.12 | C19: 0.195 | F19: 0.608 | H19: =PREÇOS!G20 -> 7.5 | I19: =IF(F19=0,,H19*(1+F19)*C19-(H19*B19)) -> 1.4517 | J19: =IF(G19=0,IF(F19=0,,H19*(1+F19)*C19-(H19*B19)),H19*(1+G19)*C19-(H19*B19)) -> 1.4517
A20: RJ | B20: 0.12 | C20: 0.22 | F20: 0.5473 | H20: =PREÇOS!G21 -> 7.5 | I20: =IF(F20=0,,H20*(1+F20)*C20-(H20*B20)) -> 1.653045 | J20: =IF(G20=0,IF(F20=0,,H20*(1+F20)*C20-(H20*B20)),H20*(1+G20)*C20-(H20*B20)) -> 1.653045
A21: RN | B21: 0.07 | C21: 0.2 | H21: =PREÇOS!G22 -> 7.05 | I21: =IF(F21=0,,H21*(1+F21)*C21-(H21*B21)) -> 0 | J21: =IF(G21=0,IF(F21=0,,H21*(1+F21)*C21-(H21*B21)),H21*(1+G21)*C21-(H21*B21)) -> 0
A22: RO | B22: 0.07 | C22: 0.175 | H22: =PREÇOS!G23 -> 7.05 | I22: =IF(F22=0,,H22*(1+F22)*C22-(H22*B22)) -> 0 | J22: =IF(G22=0,IF(F22=0,,H22*(1+F22)*C22-(H22*B22)),H22*(1+G22)*C22-(H22*B22)) -> 0
A23: RR | B23: 0.07 | C23: 0.2 | H23: =PREÇOS!G24 -> 7.05 | I23: =IF(F23=0,,H23*(1+F23)*C23-(H23*B23)) -> 0 | J23: =IF(G23=0,IF(F23=0,,H23*(1+F23)*C23-(H23*B23)),H23*(1+G23)*C23-(H23*B23)) -> 0
A24: RS | B24: 0.12 | C24: 0.17 | H24: =PREÇOS!G25 -> 7.5 | I24: =IF(F24=0,,H24*(1+F24)*C24-(H24*B24)) -> 0 | J24: =IF(G24=0,IF(F24=0,,H24*(1+F24)*C24-(H24*B24)),H24*(1+G24)*C24-(H24*B24)) -> 0
A25: SC | B25: 0.12 | C25: 0.17 | H25: =PREÇOS!G26 -> 7.5 | I25: =IF(F25=0,,H25*(1+F25)*C25-(H25*B25)) -> 0 | J25: =IF(G25=0,IF(F25=0,,H25*(1+F25)*C25-(H25*B25)),H25*(1+G25)*C25-(H25*B25)) -> 0
A26: SE | B26: 0.07 | C26: 0.2 | H26: =PREÇOS!G27 -> 7.05 | I26: =IF(F26=0,,H26*(1+F26)*C26-(H26*B26)) -> 0 | J26: =IF(G26=0,IF(F26=0,,H26*(1+F26)*C26-(H26*B26)),H26*(1+G26)*C26-(H26*B26)) -> 0
A27: SP | B27: 0.12 | C27: 0.18 | F27: 0.463 | H27: =PREÇOS!G28 -> 7.5 | I27: =IF(F27=0,,H27*(1+F27)*C27-(H27*B27)) -> 1.07505 | J27: =IF(G27=0,IF(F27=0,,H27*(1+F27)*C27-(H27*B27)),H27*(1+G27)*C27-(H27*B27)) -> 1.07505
A28: SP/Atacado | B28: =B27 -> 0.12 | C28: =C27 -> 0.18 | D28: =D27 -> 0 | E28: =E27 -> 0 | F28: =F27 -> 0.463 | G28: =G27 -> 0 | H28: =PREÇOS!G29 -> 7.5 | I28: =IF(F28=0,,H28*(1+F28)*C28-(H28*B28)) -> 1.07505 | J28: =IF(G28=0,IF(F28=0,,H28*(1+F28)*C28-(H28*B28)),H28*(1+G28)*C28-(H28*B28)) -> 1.07505
A29: TO | B29: 0.07 | C29: 0.2 | H29: =PREÇOS!G30 -> 7.05 | I29: =IF(F29=0,,H29*(1+F29)*C29-(H29*B29)) -> 0 | J29: =IF(G29=0,IF(F29=0,,H29*(1+F29)*C29-(H29*B29)),H29*(1+G29)*C29-(H29*B29)) -> 0
A30: EX | H30: =PREÇOS!G31 -> 5.9 | I30: =IF(F30=0,,H30*(1+F30)*C30-(H30*B30)) -> 0 | J30: =IF(G30=0,IF(F30=0,,H30*(1+F30)*C30-(H30*B30)),H30*(1+G30)*C30-(H30*B30)) -> 0

Sheet ST CEREAL SABOR POUCH 170
A1: Estado | B1: Aliquota interestadual | C1: Aliquota interna | D1: MVA (normal) | E1: MVA (simples) | F1: Ajustada (normal) | G1: Ajustada (simples) | H1: Preço | I1: ST Normal | J1: ST Simples
A2: AC | B2: 0.07 | C2: 0.17 | H2: =PREÇOS!J3 -> 6.4012903 | I2: =IF(F2=0,,H2*(1+F2)*C2-(H2*B2)) -> 0 | J2: =IF(G2=0,IF(F2=0,,H2*(1+F2)*C2-(H2*B2)),H2*(1+G2)*C2-(H2*B2)) -> 0
A3: AL | B3: 0.07 | C3: 0.2 | F3: 0.71 | H3: =PREÇOS!J4 -> 6.4012903 | I3: =IF(F3=0,,H3*(1+F3)*C3-(H3*B3)) -> 1.741151 | J3: =IF(G3=0,IF(F3=0,,H3*(1+F3)*C3-(H3*B3)),H3*(1+G3)*C3-(H3*B3)) -> 1.741151
A4: AM | B4: 0.07 | C4: 0.2 | F4: 0.5538 | H4: =PREÇOS!J5 -> 6.4012903 | I4: =IF(F4=0,,H4*(1+F4)*C4-(H4*B4)) -> 1.5411747 | J4: =IF(G4=0,IF(F4=0,,H4*(1+F4)*C4-(H4*B4)),H4*(1+G4)*C4-(H4*B4)) -> 1.5411747
A5: AP | B5: 0.07 | C5: 0.18 | H5: =PREÇOS!J6 -> 6.4012903 | I5: =IF(F5=0,,H5*(1+F5)*C5-(H5*B5)) -> 0 | J5: =IF(G5=0,IF(F5=0,,H5*(1+F5)*C5-(H5*B5)),H5*(1+G5)*C5-(H5*B5)) -> 0
A6: BA | B6: 0.07 | C6: 0.19 | H6: =PREÇOS!J7 -> 6.4012903 | I6: =IF(F6=0,,H6*(1+F6)*C6-(H6*B6)) -> 0 | J6: =IF(G6=0,IF(F6=0,,H6*(1+F6)*C6-(H6*B6)),H6*(1+G6)*C6-(H6*B6)) -> 0
A7: CE | B7: 0.07 | C7: 0.2 | H7: =PREÇOS!J8 -> 6.4012903 | I7: =IF(F7=0,,H7*(1+F7)*C7-(H7*B7)) -> 0 | J7: =IF(G7=0,IF(F7=0,,H7*(1+F7)*C7-(H7*B7)),H7*(1+G7)*C7-(H7*B7)) -> 0
A8: DF | B8: 0.07 | C8: 0.18 | H8: =PREÇOS!J9 -> 6.4012903 | I8: =IF(F8=0,,H8*(1+F8)*C8-(H8*B8)) -> 0 | J8: =IF(G8=0,IF(F8=0,,H8*(1+F8)*C8-(H8*B8)),H8*(1+G8)*C8-(H8*B8)) -> 0
A9: ES | B9: 0.07 | C9: 0.17 | H9: =PREÇOS!J10 -> 6.4012903 | I9: =IF(F9=0,,H9*(1+F9)*C9-(H9*B9)) -> 0 | J9: =IF(G9=0,IF(F9=0,,H9*(1+F9)*C9-(H9*B9)),H9*(1+G9)*C9-(H9*B9)) -> 0
A10: GO | B10: 0.07 | C10: 0.17 | H10: =PREÇOS!J11 -> 6.4012903 | I10: =IF(F10=0,,H10*(1+F10)*C10-(H10*B10)) -> 0 | J10: =IF(G10=0,IF(F10=0,,H10*(1+F10)*C10-(H10*B10)),H10*(1+G10)*C10-(H10*B10)) -> 0
A11: MA | B11: 0.07 | C11: 0.2 | H11: =PREÇOS!J12 -> 6.4012903 | I11: =IF(F11=0,,H11*(1+F11)*C11-(H11*B11)) -> 0 | J11: =IF(G11=0,IF(F11=0,,H11*(1+F11)*C11-(H11*B11)),H11*(1+G11)*C11-(H11*B11)) -> 0
A12: MG | B12: 0.12 | C12: 0.18 | F12: 0.4488 | H12: =PREÇOS!J13 -> 6.765 | I12: =IF(F12=0,,H12*(1+F12)*C12-(H12*B12)) -> 0.95240376 | J12: =IF(G12=0,IF(F12=0,,H12*(1+F12)*C12-(H12*B12)),H12*(1+G12)*C12-(H12*B12)) -> 0.95240376
A13: MS | B13: 0.07 | C13: 0.17 | H13: =PREÇOS!J14 -> 6.4012903 | I13: =IF(F13=0,,H13*(1+F13)*C13-(H13*B13)) -> 0 | J13: =IF(G13=0,IF(F13=0,,H13*(1+F13)*C13-(H13*B13)),H13*(1+G13)*C13-(H13*B13)) -> 0
A14: MT | B14: 0.07 | C14: 0.17 | F14: 0.4552 | H14: =PREÇOS!J15 -> 6.4012903 | I14: =IF(F14=0,,H14*(1+F14)*C14-(H14*B14)) -> 1.1354865 | J14: =IF(G14=0,IF(F14=0,,H14*(1+F14)*C14-(H14*B14)),H14*(1+G14)*C14-(H14*B14)) -> 1.1354865
A15: PA | B15: 0.07 | C15: 0.19 | H15: =PREÇOS!J16 -> 6.4012903 | I15: =IF(F15=0,,H15*(1+F15)*C15-(H15*B15)) -> 0 | J15: =IF(G15=0,IF(F15=0,,H15*(1+F15)*C15-(H15*B15)),H15*(1+G15)*C15-(H15*B15)) -> 0
A16: PB | B16: 0.07 | C16: 0.18 | H16: =PREÇOS!J17 -> 6.4012903 | I16: =IF(F16=0,,H16*(1+F16)*C16-(H16*B16)) -> 0 | J16: =IF(G16=0,IF(F16=0,,H16*(1+F16)*C16-(H16*B16)),H16*(1+G16)*C16-(H16*B16)) -> 0
A17: PE | B17: 0.07 | C17: 0.18 | H17: =PREÇOS!J18 -> 6.4012903 | I17: =IF(F17=0,,H17*(1+F17)*C17-(H17*B17)) -> 0 | J17: =IF(G17=0,IF(F17=0,,H17*(1+F17)*C17-(H17*B17)),H17*(1+G17)*C17-(H17*B17)) -> 0
A18: PI | B18: 0.07 | C18: 0.21 | H18: =PREÇOS!J19 -> 6.4012903 | I18: =IF(F18=0,,H18*(1+F18)*C18-(H18*B18)) -> 0 | J18: =IF(G18=0,IF(F18=0,,H18*(1+F18)*C18-(H18*B18)),H18*(1+G18)*C18-(H18*B18)) -> 0
A19: PR | B19: 0.12 | C19: 0.195 | F19: 0.608 | H19: =PREÇOS!J20 -> 6.765 | I19: =IF(F19=0,,H19*(1+F19)*C19-(H19*B19)) -> 1.3094334 | J19: =IF(G19=0,IF(F19=0,,H19*(1+F19)*C19-(H19*B19)),H19*(1+G19)*C19-(H19*B19)) -> 1.3094334
A20: RJ | B20: 0.12 | C20: 0.22 | F20: 0.5473 | H20: =PREÇOS!J21 -> 6.765 | I20: =IF(F20=0,,H20*(1+F20)*C20-(H20*B20)) -> 1.4910466 | J20: =IF(G20=0,IF(F20=0,,H20*(1+F20)*C20-(H20*B20)),H20*(1+G20)*C20-(H20*B20)) -> 1.4910466
A21: RN | B21: 0.07 | C21: 0.2 | H21: =PREÇOS!J22 -> 6.4012903 | I21: =IF(F21=0,,H21*(1+F21)*C21-(H21*B21)) -> 0 | J21: =IF(G21=0,IF(F21=0,,H21*(1+F21)*C21-(H21*B21)),H21*(1+G21)*C21-(H21*B21)) -> 0
A22: RO | B22: 0.07 | C22: 0.175 | H22: =PREÇOS!J23 -> 6.4012903 | I22: =IF(F22=0,,H22*(1+F22)*C22-(H22*B22)) -> 0 | J22: =IF(G22=0,IF(F22=0,,H22*(1+F22)*C22-(H22*B22)),H22*(1+G22)*C22-(H22*B22)) -> 0
A23: RR | B23: 0.07 | C23: 0.2 | H23: =PREÇOS!J24 -> 6.4012903 | I23: =IF(F23=0,,H23*(1+F23)*C23-(H23*B23)) -> 0 | J23: =IF(G23=0,IF(F23=0,,H23*(1+F23)*C23-(H23*B23)),H23*(1+G23)*C23-(H23*B23)) -> 0
A24: RS | B24: 0.12 | C24: 0.17 | H24: =PREÇOS!J25 -> 6.765 | I24: =IF(F24=0,,H24*(1+F24)*C24-(H24*B24)) -> 0 | J24: =IF(G24=0,IF(F24=0,,H24*(1+F24)*C24-(H24*B24)),H24*(1+G24)*C24-(H24*B24)) -> 0
A25: SC | B25: 0.12 | C25: 0.17 | H25: =PREÇOS!J26 -> 6.765 | I25: =IF(F25=0,,H25*(1+F25)*C25-(H25*B25)) -> 0 | J25: =IF(G25=0,IF(F25=0,,H25*(1+F25)*C25-(H25*B25)),H25*(1+G25)*C25-(H25*B25)) -> 0
A26: SE | B26: 0.07 | C26: 0.2 | H26: =PREÇOS!J27 -> 6.4012903 | I26: =IF(F26=0,,H26*(1+F26)*C26-(H26*B26)) -> 0 | J26: =IF(G26=0,IF(F26=0,,H26*(1+F26)*C26-(H26*B26)),H26*(1+G26)*C26-(H26*B26)) -> 0
A27: SP | B27: 0.12 | C27: 0.18 | F27: 0.463 | H27: =PREÇOS!J28 -> 6.765 | I27: =IF(F27=0,,H27*(1+F27)*C27-(H27*B27)) -> 0.9696951 | J27: =IF(G27=0,IF(F27=0,,H27*(1+F27)*C27-(H27*B27)),H27*(1+G27)*C27-(H27*B27)) -> 0.9696951
A28: SP/Atacado | B28: =B27 -> 0.12 | C28: =C27 -> 0.18 | D28: =D27 -> 0 | E28: =E27 -> 0 | F28: =F27 -> 0.463 | G28: =G27 -> 0 | H28: =PREÇOS!J29 -> 6.765 | I28: =IF(F28=0,,H28*(1+F28)*C28-(H28*B28)) -> 0.9696951 | J28: =IF(G28=0,IF(F28=0,,H28*(1+F28)*C28-(H28*B28)),H28*(1+G28)*C28-(H28*B28)) -> 0.9696951
A29: TO | B29: 0.07 | C29: 0.2 | H29: =PREÇOS!J30 -> 6.4012903 | I29: =IF(F29=0,,H29*(1+F29)*C29-(H29*B29)) -> 0 | J29: =IF(G29=0,IF(F29=0,,H29*(1+F29)*C29-(H29*B29)),H29*(1+G29)*C29-(H29*B29)) -> 0
A30: EX | H30: =PREÇOS!J31 -> 5.0410161 | I30: =IF(F30=0,,H30*(1+F30)*C30-(H30*B30)) -> 0 | J30: =IF(G30=0,IF(F30=0,,H30*(1+F30)*C30-(H30*B30)),H30*(1+G30)*C30-(H30*B30)) -> 0

Sheet ST MULTI 170 POUCH
A1: Estado | B1: Aliquota interestadual | C1: Aliquota interna | D1: MVA (normal) | E1: MVA (simples) | F1: Ajustada (normal) | G1: Ajustada (simples) | H1: Preço | I1: ST Normal | J1: ST Simples
A2: AC | B2: 0.07 | C2: 0.17 | H2: =PREÇOS!K3 -> 6.4012903 | I2: =IF(F2=0,,H2*(1+F2)*C2-(H2*B2)) -> 0 | J2: =IF(G2=0,IF(F2=0,,H2*(1+F2)*C2-(H2*B2)),H2*(1+G2)*C2-(H2*B2)) -> 0
A3: AL | B3: 0.07 | C3: 0.2 | F3: 0.71 | H3: =PREÇOS!K4 -> 6.4012903 | I3: =IF(F3=0,,H3*(1+F3)*C3-(H3*B3)) -> 1.741151 | J3: =IF(G3=0,IF(F3=0,,H3*(1+F3)*C3-(H3*B3)),H3*(1+G3)*C3-(H3*B3)) -> 1.741151
A4: AM | B4: 0.07 | C4: 0.2 | F4: 0.5538 | H4: =PREÇOS!K5 -> 6.4012903 | I4: =IF(F4=0,,H4*(1+F4)*C4-(H4*B4)) -> 1.5411747 | J4: =IF(G4=0,IF(F4=0,,H4*(1+F4)*C4-(H4*B4)),H4*(1+G4)*C4-(H4*B4)) -> 1.5411747
