Workbook

Sheet TABELA
D2: PREENCHA O SEU ESTADO E SE ESTÁ ENQUADRADO NO REGIME SIMPLES OU NÃO
J3: CNPJ:
J5: UF: | K5: PR
J7: Regime SIMPLES? | K7: NÃO
E8: PEDIDOS SÃO FEITOS SOMENTE EM CAIXA | L8: (*) quando inside ST o valor do imposto é adicionado nesta coluna
B9: =PREÇOS!A1 -> 0325E
B10: Descrição | D10: Código | E10: QUANTIDADE (Caixas) | F10: Valor UN | G10: SUBSTITUIÇÃO TRIBUTÁRIA UN | H10: Valor UN + ST | I10: Valor Caixa | J10: Valor Caixa + ST | K10: Valor TOTAL | L10: Valor TOTAL + ST (*) | M10: Preço sugerido
B11: Papinha Papapa Carne Arroz Legumes 120g | D11: 5313 | F11: =VLOOKUP($K$5,PREÇOS!$A$2:$L$31,9,FALSE) -> 7.6855 | G11: 0 | H11: =SUM(F11:G11) -> 7.6855 | I11: =F11*12 -> 92.226 | J11: =(F11+G11)*12 -> 92.226 | K11: =E11*I11 -> 0 | L11: =E11*J11 -> 0 | M11: =VLOOKUP($K$5,PSC!$A$2:$L$31,9,FALSE) -> 12.49
B12: Papinha Papapa Frango Grão Vegetais 120g | D12: 5320 | F12: =VLOOKUP($K$5,PREÇOS!$A$2:$L$31,9,FALSE) -> 7.6855 | G12: 0 | H12: =SUM(F12:G12) -> 7.6855 | I12: =F12*12 -> 92.226 | J12: =(F12+G12)*12 -> 92.226 | K12: =E12*I12 -> 0 | L12: =E12*J12 -> 0 | M12: =VLOOKUP($K$5,PSC!$A$2:$L$31,9,FALSE) -> 12.49
B14: Papinha Papapa Iogurte Frutas Amarelas e Banana 100g | D14: 5566 | F14: =VLOOKUP($K$5,PREÇOS!$A$2:$M$31,13,FALSE) -> 5.3865 | G14: 0 | H14: =SUM(F14:G14) -> 5.3865 | I14: =F14*16 -> 86.184 | J14: =I14 -> 86.184 | K14: =E14*I14 -> 0 | L14: =E14*J14 -> 0 | M14: =VLOOKUP($K$5,PSC!$A$2:$M$31,13,FALSE) -> 9.49
B15: Papinha Papapa Iogurte Frutas Vermelhas e Banana 100g | D15: 5573 | F15: =VLOOKUP($K$5,PREÇOS!$A$2:$M$31,13,FALSE) -> 5.3865 | G15: 0 | H15: =SUM(F15:G15) -> 5.3865 | I15: =F15*16 -> 86.184 | J15: =I15 -> 86.184 | K15: =E15*I15 -> 0 | L15: =E15*J15 -> 0 | M15: =VLOOKUP($K$5,PSC!$A$2:$M$31,13,FALSE) -> 9.49
B17: Papinha Papapá Org Maçã Ameixa 100g | D17: 17898994908729 | F17: =VLOOKUP($K$5,PREÇOS!$A$2:$L$31,2,FALSE) -> 5.928 | G17: 0 | H17: =SUM(F17:G17) -> 5.928 | I17: =F17*12 -> 71.136 | J17: =I17 -> 71.136 | K17: =E17*I17 -> 0 | L17: =E17*J17 -> 0 | M17: =VLOOKUP($K$5,PSC!$A$2:$L$31,2,FALSE) -> 9.49
B18: Papinha Papapá Org Banana Mirtilo Quinoa 100g | D18: 17898994908736 | F18: =VLOOKUP($K$5,PREÇOS!$A$2:$L$31,2,FALSE) -> 5.928 | G18: 0 | H18: =SUM(F18:G18) -> 5.928 | I18: =F18*12 -> 71.136 | J18: =I18 -> 71.136 | K18: =E18*I18 -> 0 | L18: =E18*J18 -> 0 | M18: =VLOOKUP($K$5,PSC!$A$2:$L$31,2,FALSE) -> 9.49
B19: Papinha Papapá Org Manga 100g | D19: 17898994908712 | F19: =VLOOKUP($K$5,PREÇOS!$A$2:$L$31,2,FALSE) -> 5.928 | G19: 0 | H19: =SUM(F19:G19) -> 5.928 | I19: =F19*12 -> 71.136 | J19: =I19 -> 71.136 | K19: =E19*I19 -> 0 | L19: =E19*J19 -> 0 | M19: =VLOOKUP($K$5,PSC!$A$2:$L$31,2,FALSE) -> 9.49
B20: Papinha Papapá Org Pera Espinafre Abobrinha 100g | D20: 17898994908750 | F20: =VLOOKUP($K$5,PREÇOS!$A$2:$L$31,2,FALSE) -> 5.928 | G20: 0 | H20: =SUM(F20:G20) -> 5.928 | I20: =F20*12 -> 71.136 | J20: =I20 -> 71.136 | K20: =E20*I20 -> 0 | L20: =E20*J20 -> 0 | M20: =VLOOKUP($K$5,PSC!$A$2:$L$31,2,FALSE) -> 9.49
B21: Papinha Papapá Org Maçã B. Doce Cenoura 100g | D21: 27898994908757 | F21: =VLOOKUP($K$5,PREÇOS!$A$2:$L$31,2,FALSE) -> 5.928 | G21: 0 | H21: =SUM(F21:G21) -> 5.928 | I21: =F21*12 -> 71.136 | J21: =I21 -> 71.136 | K21: =E21*I21 -> 0 | L21: =E21*J21 -> 0 | M21: =VLOOKUP($K$5,PSC!$A$2:$L$31,2,FALSE) -> 9.49
B22: Papinha Papapá Org Morango Maçã 100g | D22: 5306 | F22: =VLOOKUP($K$5,PREÇOS!$A$2:$L$31,2,FALSE) -> 5.928 | G22: 0 | H22: =SUM(F22:G22) -> 5.928 | I22: =F22*12 -> 71.136 | J22: =I22 -> 71.136 | K22: =E22*I22 -> 0 | L22: =E22*J22 -> 0 | M22: =VLOOKUP($K$5,PSC!$A$2:$L$31,2,FALSE) -> 9.49
B24: Biscoito inf Papapá Palitinho de Vegetais org. Beterraba 20g | D24: 5085 | F24: =VLOOKUP($K$5,PREÇOS!$A$2:$L$31,3,FALSE) -> 3.591 | G24: =IF($K$7="SIM",VLOOKUP($K$5,'ST PALITINHOS'!$A$1:$J$31,10,FALSE),VLOOKUP($K$5,'ST PALITINHOS'!$A$1:$J$31,9,FALSE)) -> 0.75039331 | H24: =SUM(F24:G24) -> 4.3413933 | I24: =F24*16 -> 57.456 | J24: =(F24+G24)*16 -> 69.462293 | K24: =E24*I24 -> 0 | L24: =E24*J24 -> 0 | M24: =VLOOKUP($K$5,PSC!$A$2:$L$31,3,FALSE) -> 5.79
B25: Biscoito inf Papapá Palitinho de Vegetais org. Cenoura 20g | D25: 5078 | F25: =VLOOKUP($K$5,PREÇOS!$A$2:$L$31,3,FALSE) -> 3.591 | G25: =IF($K$7="SIM",VLOOKUP($K$5,'ST PALITINHOS'!$A$1:$J$31,10,FALSE),VLOOKUP($K$5,'ST PALITINHOS'!$A$1:$J$31,9,FALSE)) -> 0.75039331 | H25: =SUM(F25:G25) -> 4.3413933 | I25: =F25*16 -> 57.456 | J25: =(F25+G25)*16 -> 69.462293 | K25: =E25*I25 -> 0 | L25: =E25*J25 -> 0 | M25: =VLOOKUP($K$5,PSC!$A$2:$L$31,3,FALSE) -> 5.79
B26: Biscoito inf Papapá Palitinho de Vegetais org. Tomate/Manjericão 20g | D26: 5061 | F26: =VLOOKUP($K$5,PREÇOS!$A$2:$L$31,3,FALSE) -> 3.591 | G26: =IF($K$7="SIM",VLOOKUP($K$5,'ST PALITINHOS'!$A$1:$J$31,10,FALSE),VLOOKUP($K$5,'ST PALITINHOS'!$A$1:$J$31,9,FALSE)) -> 0.75039331 | H26: =SUM(F26:G26) -> 4.3413933 | I26: =F26*16 -> 57.456 | J26: =(F26+G26)*16 -> 69.462293 | K26: =E26*I26 -> 0 | L26: =E26*J26 -> 0 | M26: =VLOOKUP($K$5,PSC!$A$2:$L$31,3,FALSE) -> 5.79
B28: Biscoito Inf Papapá dent. Maçã e Abóbora 36g | D28: 8774 | F28: =VLOOKUP($K$5,PREÇOS!$A$2:$L$31,4,FALSE) -> 11.951 | G28: =IF($K$7="SIM",VLOOKUP($K$5,'ST BISCOITINHOS'!$A$1:$J$31,10,FALSE),VLOOKUP($K$5,'ST BISCOITINHOS'!$A$1:$J$31,9,FALSE)) -> 0 | H28: =SUM(F28:G28) -> 11.951 | I28: =F28*12 -> 143.412 | J28: =(F28+G28)*12 -> 143.412 | K28: =E28*I28 -> 0 | L28: =E28*J28 -> 0 | M28: =VLOOKUP($K$5,PSC!$A$2:$L$31,4,FALSE) -> 19.99
B29: Biscoito Inf Papapá dent Vegetais 36g | D29: 8767 | F29: =VLOOKUP($K$5,PREÇOS!$A$2:$L$31,4,FALSE) -> 11.951 | G29: =IF($K$7="SIM",VLOOKUP($K$5,'ST BISCOITINHOS'!$A$1:$J$31,10,FALSE),VLOOKUP($K$5,'ST BISCOITINHOS'!$A$1:$J$31,9,FALSE)) -> 0 | H29: =SUM(F29:G29) -> 11.951 | I29: =F29*12 -> 143.412 | J29: =(F29+G29)*12 -> 143.412 | K29: =E29*I29 -> 0 | L29: =E29*J29 -> 0 | M29: =VLOOKUP($K$5,PSC!$A$2:$L$31,4,FALSE) -> 19.99
B31: Macarrao Inf Papapá m. Elbow Quinoa 200g | D31: 5290 | F31: =VLOOKUP($K$5,PREÇOS!$A$2:$L$31,5,FALSE) -> 8.0275 | G31: =IF($K$7="SIM",VLOOKUP($K$5,'ST PAPAPASTA'!$A$1:$J$31,10,FALSE),VLOOKUP($K$5,'ST PAPAPASTA'!$A$1:$J$31,9,FALSE)) -> 0 | H31: =SUM(F31:G31) -> 8.0275 | I31: =F31*12 -> 96.33 | J31: =(F31+G31)*12 -> 96.33 | K31: =E31*I31 -> 0 | L31: =E31*J31 -> 0 | M31: =VLOOKUP($K$5,PSC!$A$2:$L$31,5,FALSE) -> 13.69
B32: Macarrao Inf Papapá m. Fusilli Vegetais 200g | D32: 5283 | F32: =VLOOKUP($K$5,PREÇOS!$A$2:$L$31,5,FALSE) -> 8.0275 | G32: =IF($K$7="SIM",VLOOKUP($K$5,'ST PAPAPASTA'!$A$1:$J$31,10,FALSE),VLOOKUP($K$5,'ST PAPAPASTA'!$A$1:$J$31,9,FALSE)) -> 0 | H32: =SUM(F32:G32) -> 8.0275 | I32: =F32*12 -> 96.33 | J32: =(F32+G32)*12 -> 96.33 | K32: =E32*I32 -> 0 | L32: =E32*J32 -> 0 | M32: =VLOOKUP($K$5,PSC!$A$2:$L$31,5,FALSE) -> 13.69
B34: Sopinha Papapá org Lentinha Carne Legumes 180g | D34: 5276 | F34: =VLOOKUP($K$5,PREÇOS!$A$2:$L$31,6,FALSE) -> 11.21 | G34: 0 | H34: =SUM(F34:G34) -> 11.21 | I34: =F34*6 -> 67.26 | J34: =(F34+G34)*6 -> 67.26 | K34: =E34*I34 -> 0 | L34: =E34*J34 -> 0 | M34: =VLOOKUP($K$5,PSC!$A$2:$L$31,6,FALSE) -> 17.99
B35: Risotinho Papapá org Arroz quinoa frango 180g | D35: 5269 | F35: =VLOOKUP($K$5,PREÇOS!$A$2:$L$31,6,FALSE) -> 11.21 | G35: 0 | H35: =SUM(F35:G35) -> 11.21 | I35: =F35*6 -> 67.26 | J35: =(F35+G35)*6 -> 67.26 | K35: =E35*I35 -> 0 | L35: =E35*J35 -> 0 | M35: =VLOOKUP($K$5,PSC!$A$2:$L$31,6,FALSE) -> 17.99
B36: Caseirinho Papapá org Arroz feijão carne leg. 180g | D36: 5252 | F36: =VLOOKUP($K$5,PREÇOS!$A$2:$L$31,6,FALSE) -> 11.21 | G36: 0 | H36: =SUM(F36:G36) -> 11.21 | I36: =F36*6 -> 67.26 | J36: =(F36+G36)*6 -> 67.26 | K36: =E36*I36 -> 0 | L36: =E36*J36 -> 0 | M36: =VLOOKUP($K$5,PSC!$A$2:$L$31,6,FALSE) -> 17.99
B38: Cereal Infantil Papapá Aveia - Morango e Beterraba 170g caixa | D38: 3344 | F38: =VLOOKUP($K$5,PREÇOS!$A$2:$L$31,7,FALSE) -> 7.885 | G38: =IF($K$7="SIM",VLOOKUP($K$5,'ST CEREAL'!$A$1:$J$31,10,FALSE),VLOOKUP($K$5,'ST CEREAL'!$A$1:$J$31,9,FALSE)) -> 1.5262206 | H38: =SUM(F38:G38) -> 9.4112206 | I38: =F38*12 -> 94.62 | J38: =(F38+G38)*12 -> 112.93465 | K38: =E38*I38 -> 0 | L38: =E38*J38 -> 0 | M38: =VLOOKUP($K$5,PSC!$A$2:$L$31,7,FALSE) -> 13.89
B39: Cereal Infantil Papapá Aveia - Banana e Ameixa 170g caixa | D39: 3343 | F39: =VLOOKUP($K$5,PREÇOS!$A$2:$L$31,7,FALSE) -> 7.885 | G39: =IF($K$7="SIM",VLOOKUP($K$5,'ST CEREAL'!$A$1:$J$31,10,FALSE),VLOOKUP($K$5,'ST CEREAL'!$A$1:$J$31,9,FALSE)) -> 1.5262206 | H39: =SUM(F39:G39) -> 9.4112206 | I39: =F39*12 -> 94.62 | J39: =(F39+G39)*12 -> 112.93465 | K39: =E39*I39 -> 0 | L39: =E39*J39 -> 0 | M39: =VLOOKUP($K$5,PSC!$A$2:$L$31,7,FALSE) -> 13.89
B40: Cereal Infantil Papapá Aveia - Multicereais 170g caixa | D40: 5382 | F40: =VLOOKUP($K$5,PREÇOS!$A$2:$L$31,7,FALSE) -> 7.885 | G40: =IF($K$7="SIM",VLOOKUP($K$5,'ST CEREAL'!$A$1:$J$31,10,FALSE),VLOOKUP($K$5,'ST CEREAL'!$A$1:$J$31,9,FALSE)) -> 1.5262206 | H40: =SUM(F40:G40) -> 9.4112206 | I40: =F40*12 -> 94.62 | J40: =(F40+G40)*12 -> 112.93465 | K40: =E40*I40 -> 0 | L40: =E40*J40 -> 0 | M40: =VLOOKUP($K$5,PSC!$A$2:$L$31,7,FALSE) -> 13.89
B41: Cereal Infantil Papapá Aveia - Morango e Beterraba sache 170g | D41: 5402 | F41: =VLOOKUP($K$5,PREÇOS!$A$2:$L$31,10,FALSE) -> 5.8425 | G41: =IF($K$7="SIM",VLOOKUP($K$5,'ST CEREAL'!$A$1:$J$31,10,FALSE),VLOOKUP($K$5,'ST CEREAL'!$A$1:$J$31,9,FALSE)) -> 1.5262206 | H41: =SUM(F41:G41) -> 7.3687206 | I41: =F41*12 -> 70.11 | J41: =(F41+G41)*12 -> 88.424647 | K41: =E41*I41 -> 0 | L41: =E41*J41 -> 0 | M41: =VLOOKUP($K$5,PSC!$A$2:$L$31,10,FALSE) -> 9.99
B42: Cereal Infantil Papapá Aveia - Banana e Ameixa sache 170g | D42: 5419 | F42: =VLOOKUP($K$5,PREÇOS!$A$2:$L$31,10,FALSE) -> 5.8425 | G42: =IF($K$7="SIM",VLOOKUP($K$5,'ST CEREAL'!$A$1:$J$31,10,FALSE),VLOOKUP($K$5,'ST CEREAL'!$A$1:$J$31,9,FALSE)) -> 1.5262206 | H42: =SUM(F42:G42) -> 7.3687206 | I42: =F42*12 -> 70.11 | J42: =(F42+G42)*12 -> 88.424647 | K42: =E42*I42 -> 0 | L42: =E42*J42 -> 0 | M42: =VLOOKUP($K$5,PSC!$A$2:$L$31,10,FALSE) -> 9.99
B43: Cereal Infantil Papapá Aveia - Multicereais sache 170g | D43: 5429 | F43: =VLOOKUP($K$5,PREÇOS!$A$2:$L$31,11,FALSE) -> 5.8425 | G43: =IF($K$7="SIM",VLOOKUP($K$5,'ST CEREAL'!$A$1:$J$31,10,FALSE),VLOOKUP($K$5,'ST CEREAL'!$A$1:$J$31,9,FALSE)) -> 1.5262206 | H43: =SUM(F43:G43) -> 7.3687206 | I43: =F43*12 -> 70.11 | J43: =(F43+G43)*12 -> 88.424647 | K43: =E43*I43 -> 0 | L43: =E43*J43 -> 0 | M43: =VLOOKUP($K$5,PSC!$A$2:$L$31,11,FALSE) -> 9.99
B44: Cereal Infantil Papapá Aveia - Multicereais sache 500g | D44: 5399 | F44: =VLOOKUP($K$5,PREÇOS!$A$2:$L$31,12,FALSE) -> 14.2405 | G44: =IF($K$7="SIM",VLOOKUP($K$5,'ST CEREAL'!$A$1:$J$31,10,FALSE),VLOOKUP($K$5,'ST CEREAL'!$A$1:$J$31,9,FALSE)) -> 1.5262206 | H44: =SUM(F44:G44) -> 15.766721 | I44: =F44*12 -> 170.886 | J44: =(F44+G44)*12 -> 189.20065 | K44: =E44*I44 -> 0 | L44: =E44*J44 -> 0 | M44: =VLOOKUP($K$5,PSC!$A$2:$L$31,12,FALSE) -> 24.99
B46: Biscoito Infantil Papapá Biscotti com Laranja e Cenoura 60g | D46: 5375 | F46: =VLOOKUP($K$5,PREÇOS!$A$2:$L$31,8,FALSE) -> 7.98 | G46: =IF($K$7="SIM",VLOOKUP($K$5,'ST BISCOTTI'!$A$1:$J$31,10,FALSE),VLOOKUP($K$5,'ST BISCOTTI'!$A$1:$J$31,9,FALSE)) -> 0 | H46: =SUM(F46:G46) -> 7.98 | I46: =F46*12 -> 95.76 | J46: =(F46+G46)*12 -> 95.76 | K46: =E46*I46 -> 0 | L46: =E46*J46 -> 0 | M46: =VLOOKUP($K$5,PSC!$A$2:$L$31,8,FALSE) -> 13.49
B47: Biscoito Infantil Papapá Biscotti com Maçã e Canela 60g | D47: 5351 | F47: =VLOOKUP($K$5,PREÇOS!$A$2:$L$31,8,FALSE) -> 7.98 | G47: =IF($K$7="SIM",VLOOKUP($K$5,'ST BISCOTTI'!$A$1:$J$31,10,FALSE),VLOOKUP($K$5,'ST BISCOTTI'!$A$1:$J$31,9,FALSE)) -> 0 | H47: =SUM(F47:G47) -> 7.98 | I47: =F47*12 -> 95.76 | J47: =(F47+G47)*12 -> 95.76 | K47: =E47*I47 -> 0 | L47: =E47*J47 -> 0 | M47: =VLOOKUP($K$5,PSC!$A$2:$L$31,8,FALSE) -> 13.49
B48: Biscoito Infantil Papapá Biscotti com Banana e Cacau 60g | D48: 5368 | F48: =VLOOKUP($K$5,PREÇOS!$A$2:$L$31,8,FALSE) -> 7.98 | G48: =IF($K$7="SIM",VLOOKUP($K$5,'ST BISCOTTI'!$A$1:$J$31,10,FALSE),VLOOKUP($K$5,'ST BISCOTTI'!$A$1:$J$31,9,FALSE)) -> 0 | H48: =SUM(F48:G48) -> 7.98 | I48: =F48*12 -> 95.76 | J48: =(F48+G48)*12 -> 95.76 | K48: =E48*I48 -> 0 | L48: =E48*J48 -> 0 | M48: =VLOOKUP($K$5,PSC!$A$2:$L$31,8,FALSE) -> 13.49
B49: Biscoito Infantil Papapá Biscotti Goiaba 60g | D49: 5597 | F49: =VLOOKUP($K$5,PREÇOS!$A$2:$L$31,8,FALSE) -> 7.98 | G49: =IF($K$7="SIM",VLOOKUP($K$5,'ST BISCOTTI'!$A$1:$J$31,10,FALSE),VLOOKUP($K$5,'ST BISCOTTI'!$A$1:$J$31,9,FALSE)) -> 0 | H49: =SUM(F49:G49) -> 7.98 | I49: =F49*12 -> 95.76 | J49: =(F49+G49)*12 -> 95.76 | K49: =E49*I49 -> 0 | L49: =E49*J49 -> 0 | M49: =VLOOKUP($K$5,PSC!$A$2:$L$31,8,FALSE) -> 13.49
B50: Biscoito Infantil Papapá Biscotti com Maracujá e Camomila 60g | D50: 5580 | F50: =VLOOKUP($K$5,PREÇOS!$A$2:$L$31,8,FALSE) -> 7.98 | G50: =IF($K$7="SIM",VLOOKUP($K$5,'ST BISCOTTI'!$A$1:$J$31,10,FALSE),VLOOKUP($K$5,'ST BISCOTTI'!$A$1:$J$31,9,FALSE)) -> 0 | H50: =SUM(F50:G50) -> 7.98 | I50: =F50*12 -> 95.76 | J50: =(F50+G50)*12 -> 95.76 | K50: =E50*I50 -> 0 | L50: =E50*J50 -> 0 | M50: =VLOOKUP($K$5,PSC!$A$2:$L$31,8,FALSE) -> 13.49
B52: Sopinha Papapá Frango Arroz Legumes 240g (2x 120g) | D52: 5610 | F52: =VLOOKUP($K$5,PREÇOS!$A$2:$N$31,14,FALSE) -> 11.704 | G52: 0 | H52: =SUM(F52:G52) -> 11.704 | I52: =F52*6 -> 70.224 | J52: =(F52+G52)*6 -> 70.224 | K52: =E52*I52 -> 0 | L52: =E52*J52 -> 0 | M52: =VLOOKUP($K$5,PSC!$A$2:$N$31,14,FALSE) -> 18.99
...

Sheet DADOS
C1: BABY ROO COMERCIO DE ALIMENTOS EIRELI
C2: CNPJ: 34.282.307.0001-44 | H2: UF: | I2: =TABELA!K5 -> PR
C3: INSC. ESTADUAL: 90821939-25
C4: ENDEREÇO: Rua Grã Nicco, 113 - sala 501, bloco 2 - Mossunguê, Curitiba - PR, 81200-200
B6: =PREÇOS!A1 -> 0325E
B7: Descrição | D7: Código | E7: Embalagem | F7: Validade | G7: NCM | H7: Ean 13 | I7: Dun 14 | J7: Crédito ICMS (%)
B8: Papinha Papapa Carne Arroz Legumes 120g | D8: 5313 | E8: 12 x 120g | F8: 12 meses | G8: 2104.20.00 | H8: 7898969895316 | I8: 17898969895313 | J8: =VLOOKUP($I$2,'ST BISCOITINHOS'!A:B,2,FALSE) -> 0.12
B9: Papinha Papapa Frango Grão Vegetais 120g | D9: 5320 | E9: 12 x 120g | F9: 12 meses | G9: 2104.20.00 | H9: 7898969895323 | I9: 17898969895320 | J9: =VLOOKUP($I$2,'ST BISCOITINHOS'!A:B,2,FALSE) -> 0.12
B11: Papinha Papapa Iogurte Frutas Amarelas e Banana 100g | D11: 5566 | E11: 16 x 100g | F11: 15 meses | G11: 2104.20.00 | H11: 7898969895569 | I11: 27898969895563 | J11: =VLOOKUP($I$2,'ST BISCOITINHOS'!A:B,2,FALSE) -> 0.12
B12: Papinha Papapa Iogurte Frutas Vermelhas e Banana 100g | D12: 5573 | E12: 16 x 100g | F12: 15 meses | G12: 2104.20.00 | H12: 7898969895576 | I12: 27898969895570 | J12: =VLOOKUP($I$2,'ST BISCOITINHOS'!A:B,2,FALSE) -> 0.12
B14: Papinha Papapá Org Maçã Ameixa 100g | D14: 17898994908729 | E14: 12 x 100g | F14: 16 meses | G14: 2104.20.00 | H14: 7898994908722 | I14: 17898994908729 | J14: =VLOOKUP($I$2,'ST BISCOITINHOS'!A:B,2,FALSE) -> 0.12
B15: Papinha Papapá Org Banana Mirtilo Quinoa 100g | D15: 17898994908736 | E15: 12 x 100g | F15: 16 meses | G15: 2104.20.00 | H15: 7898994908739 | I15: 17898994908736 | J15: =VLOOKUP($I$2,'ST BISCOITINHOS'!A:B,2,FALSE) -> 0.12
B16: Papinha Papapá Org Manga 100g | D16: 17898994908712 | E16: 12 x 100g | F16: 16 meses | G16: 2104.20.00 | H16: 7898994908715 | I16: 17898994908712 | J16: =VLOOKUP($I$2,'ST BISCOITINHOS'!A:B,2,FALSE) -> 0.12
B17: Papinha Papapá Org Pera Espinafre Abobrinha 100g | D17: 17898994908750 | E17: 12 x 100g | F17: 16 meses | G17: 2104.20.00 | H17: 7898994908753 | I17: 17898994908750 | J17: =VLOOKUP($I$2,'ST BISCOITINHOS'!A:B,2,FALSE) -> 0.12
B18: Papinha Papapá Org Maçã B. Doce Cenoura 100g | D18: 27898994908757 | E18: 12 x 100g | F18: 16 meses | G18: 2104.20.00 | H18: 7898994908746 | I18: 27898994908757 | J18: =VLOOKUP($I$2,'ST BISCOITINHOS'!A:B,2,FALSE) -> 0.12
B19: Papinha Papapá Org Morango Maçã 100g | D19: 5306 | E19: 12 x 100g | F19: 16 meses | G19: 2104.20.00 | H19: 7898969895309 | I19: 17898969895306 | J19: =VLOOKUP($I$2,'ST BISCOITINHOS'!A:B,2,FALSE) -> 0.12
B21: Biscoito inf Papapá Palitinho de Vegetais org. Beterraba 20g | D21: 5085 | E21: 16 x 20g | F21: 9 meses | G21: 1904.10.00 | H21: 7898969895088 | I21: 17898969895085 | J21: =VLOOKUP($I$2,'ST PALITINHOS'!A:B,2,FALSE) -> 0.12
B22: Biscoito inf Papapá Palitinho de Vegetais org. Cenoura 20g | D22: 5078 | E22: 16 x 20g | F22: 9 meses | G22: 1904.10.00 | H22: 7898969895071 | I22: 17898969895078 | J22: =VLOOKUP($I$2,'ST PALITINHOS'!A:B,2,FALSE) -> 0.12
B23: Biscoito inf Papapá Palitinho de Vegetais org. Tomate/Manjericão 20g | D23: 5061 | E23: 16 x 20g | F23: 9 meses | G23: 1904.10.00 | H23: 7898969895064 | I23: 17898969895061 | J23: =VLOOKUP($I$2,'ST PALITINHOS'!A:B,2,FALSE) -> 0.12
B25: Biscoito Inf Papapá dent. Maçã e Abóbora 36g | D25: 8774 | E25: 12 x 36g | F25: 15 meses | G25: 1905.90.20 | H25: 7898994908777 | I25: 17898994908774 | J25: =VLOOKUP($I$2,'ST BISCOITINHOS'!A:B,2,FALSE) -> 0.12
B26: Biscoito Inf Papapá dent Vegetais 36g | D26: 8767 | E26: 12 x 36g | F26: 15 meses | G26: 1905.90.20 | H26: 7898994908760 | I26: 17898994908767 | J26: =VLOOKUP($I$2,'ST BISCOITINHOS'!A:B,2,FALSE) -> 0.12
B28: Macarrao Inf Papapá m. Elbow Quinoa 200g | D28: 5290 | E28: 12 x 200g | F28: 14 meses | G28: 19.02.19.00 | H28: 7898969895293 | I28: 17898969895293 | J28: =VLOOKUP($I$2,'ST PAPAPASTA'!A:B,2,FALSE) -> 0.12
B29: Macarrao Inf Papapá m. Fusilli Vegetais 200g | D29: 5283 | E29: 12 x 200g | F29: 14 meses | G29: 19.02.19.00 | H29: 7898969895286 | I29: 17898969895286 | J29: =VLOOKUP($I$2,'ST PAPAPASTA'!A:B,2,FALSE) -> 0.12
B31: Sopinha Papapá org Lentinha Carne Legumes 180g | D31: 5276 | E31: 6 x 180g | F31: 16 meses | G31: 2104.20.00 | H31: 7898969895279 | I31: 17898969895276 | J31: =VLOOKUP($I$2,'ST PAPAPASTA'!A:B,2,FALSE) -> 0.12
B32: Risotinho Papapá org Arroz quinoa frango 180g | D32: 5269 | E32: 6 x 180g | F32: 16 meses | G32: 2104.20.00 | H32: 7898969895262 | I32: 17898969895269 | J32: =VLOOKUP($I$2,'ST PAPAPASTA'!A:B,2,FALSE) -> 0.12
B33: Caseirinho Papapá org Arroz feijão carne leg. 180g | D33: 5252 | E33: 6 x 180g | F33: 16 meses | G33: 2104.20.00 | H33: 7898969895255 | I33: 17898969895252 | J33: =VLOOKUP($I$2,'ST PAPAPASTA'!A:B,2,FALSE) -> 0.12
B35: Cereal Infantil Papapá Aveia - Morango e Beterraba 170g caixa | D35: 3344 | E35: 12 x 170g | F35: 12 meses | G35: 19.01.10.30 | H35: 7898969895330 | I35: 17898969895337 | J35: =VLOOKUP($I$2,'ST CEREAL'!A:B,2,FALSE) -> 0.12
B36: Cereal Infantil Papapá Aveia - Banana e Ameixa 170g caixa | D36: 3343 | E36: 12 x 170g | F36: 12 meses | G36: 19.01.10.30 | H36: 7898969895347 | I36: 17898969895344 | J36: =VLOOKUP($I$2,'ST CEREAL'!A:B,2,FALSE) -> 0.12
B37: Cereal Infantil Papapá Aveia - Multicereais 170g caixa | D37: 5382 | E37: 12 x 170g | F37: 12 meses | G37: 19.01.10.30 | H37: 7898969895385 | I37: 17898969895382 | J37: =VLOOKUP($I$2,'ST CEREAL'!A:B,2,FALSE) -> 0.12
B38: Cereal Infantil Papapá Aveia - Morango e Beterraba sache 170g | D38: 5402 | E38: 12 x 170g | F38: 12 meses | G38: 19.01.10.30 | H38: 7898969895408 | I38: 27898969895402 | J38: =VLOOKUP($I$2,'ST CEREAL SABOR POUCH 170'!A:B,2,FALSE) -> 0.12
B39: Cereal Infantil Papapá Aveia - Banana e Ameixa sache 170g | D39: 5419 | E39: 12 x 170g | F39: 12 meses | G39: 19.01.10.30 | H39: 7898969895415 | I39: 27898969895419 | J39: =VLOOKUP($I$2,'ST CEREAL SABOR POUCH 170'!A:B,2,FALSE) -> 0.12
B40: Cereal Infantil Papapá Aveia - Multicereais sache 170g | D40: 5429 | E40: 12 x 170g | F40: 12 meses | G40: 19.01.10.30 | H40: 7898969895422 | I40: 17898969895429 | J40: =VLOOKUP($I$2,'ST MULTI 170 POUCH'!A:B,2,FALSE) -> 0.12
B41: Cereal Infantil Papapá Aveia - Multicereais sache 500g | D41: 5399 | E41: 12 x 500g | F41: 12 meses | G41: 19.01.10.30 | H41: 7898969895392 | I41: 17898969895399 | J41: =VLOOKUP($I$2,'ST MULTI 500 POUCH'!A:B,2,FALSE) -> 0.12
B43: Biscoito Infantil Papapá Biscotti com Laranja e Cenoura 60g | D43: 5375 | E43: 12 x 60g | F43: 10 meses | G43: 1905.90.20 | H43: 7898969895378 | I43: 17898969895375 | J43: =VLOOKUP($I$2,'ST BISCOTTI'!A:B,2,FALSE) -> 0.12
B44: Biscoito Infantil Papapá Biscotti com Maçã e Canela 60g | D44: 5351 | E44: 12 x 60g | F44: 10 meses | G44: 1905.90.20 | H44: 7898969895354 | I44: 17898969895351 | J44: =VLOOKUP($I$2,'ST BISCOTTI'!A:B,2,FALSE) -> 0.12
B45: Biscoito Infantil Papapá Biscotti com Banana e Cacau 60g | D45: 5368 | E45: 12 x 60g | F45: 10 meses | G45: 1905.90.20 | H45: 7898969895361 | I45: 17898969895368 | J45: =VLOOKUP($I$2,'ST BISCOTTI'!A:B,2,FALSE) -> 0.12
B46: Biscoito Infantil Papapá Biscotti Goiaba 60g | D46: 5597 | E46: 12 x 60g | F46: 10 meses | G46: 1905.90.20 | H46: 7898969895590 | I46: 17898969895597 | J46: =VLOOKUP($I$2,'ST BISCOTTI'!A:B,2,FALSE) -> 0.12
B47: Biscoito Infantil Papapá Biscotti com Maracujá e Camomila 60g | D47: 5580 | E47: 12 x 60g | F47: 10 meses | G47: 1905.90.20 | H47: 7898969895583 | I47: 17898969895580 | J47: =VLOOKUP($I$2,'ST BISCOTTI'!A:B,2,FALSE) -> 0.12
B49: Sopinha Papapá Frango Arroz Legumes 240g (2x 120g) | D49: 5610 | E49: 6 x 240g | F49: 12 meses | G49: 2104.20.00 | H49: 7898969895613 | I49: 17898969895610 | J49: =VLOOKUP($I$2,'[2]ST BISCOTTI'!A:B,2,FALSE) -> 0.12
B50: Sopinha Papapá Carne Macarrao Legumes 240g (2x 120g) | D50: 5634 | E50: 6 x 240g | F50: 12 meses | G50: 2104.20.00 | H50: 7898969895637 | I50: 17898969895634 | J50: =VLOOKUP($I$2,'[2]ST BISCOTTI'!A:B,2,FALSE) -> 0.12
...

Sheet Planilha1
C2: SIM
C3: NÃO

Sheet ST BISCOITINHOS
A1: Estado | B1: Aliquota interestadual | C1: Aliquota interna | D1: MVA (normal) | E1: MVA (simples) | F1: Ajustada (normal) | G1: Ajustada (simples) | H1: Preço | I1: ST Normal | J1: ST Simples
A2: AC | B2: 0.04 | C2: 0.04 | H2: =PREÇOS!D3 -> 10.8965 | I2: =IF(F2=0,,H2*(1+F2)*C2-(H2*B2)) -> 0 | J2: =IF(G2=0,IF(F2=0,,H2*(1+F2)*C2-(H2*B2)),H2*(1+G2)*C2-(H2*B2)) -> 0
A3: AL | B3: 0.04 | C3: 0.2 | D3: 0.3 | F3: 0.56 | H3: =PREÇOS!D4 -> 10.8965 | I3: =IF(F3=0,,H3*(1+F3)*C3-(H3*B3)) -> 2.963848 | J3: =IF(G3=0,IF(F3=0,,H3*(1+F3)*C3-(H3*B3)),H3*(1+G3)*C3-(H3*B3)) -> 2.963848
A4: AM | B4: 0.04 | C4: 0.04 | H4: =PREÇOS!D5 -> 10.8965 | I4: =IF(F4=0,,H4*(1+F4)*C4-(H4*B4)) -> 0 | J4: =IF(G4=0,IF(F4=0,,H4*(1+F4)*C4-(H4*B4)),H4*(1+G4)*C4-(H4*B4)) -> 0
A5: AP | B5: 0.04 | C5: 0.18 | D5: 0.34 | F5: 0.5688 | H5: =PREÇOS!D6 -> 10.8965 | I5: =IF(F5=0,,H5*(1+F5)*C5-(H5*B5)) -> 2.6411373 | J5: =IF(G5=0,IF(F5=0,,H5*(1+F5)*C5-(H5*B5)),H5*(1+G5)*C5-(H5*B5)) -> 2.6411373
A6: BA | B6: 0.04 | C6: 0.04 | H6: =PREÇOS!D7 -> 10.8965 | I6: =IF(F6=0,,H6*(1+F6)*C6-(H6*B6)) -> 0 | J6: =IF(G6=0,IF(F6=0,,H6*(1+F6)*C6-(H6*B6)),H6*(1+G6)*C6-(H6*B6)) -> 0
A7: CE | B7: 0.04 | C7: 0.04 | H7: =PREÇOS!D8 -> 10.8965 | I7: =IF(F7=0,,H7*(1+F7)*C7-(H7*B7)) -> 0 | J7: =IF(G7=0,IF(F7=0,,H7*(1+F7)*C7-(H7*B7)),H7*(1+G7)*C7-(H7*B7)) -> 0
A8: DF | B8: 0.04 | C8: 0.04 | H8: =PREÇOS!D9 -> 10.8965 | I8: =IF(F8=0,,H8*(1+F8)*C8-(H8*B8)) -> 0 | J8: =IF(G8=0,IF(F8=0,,H8*(1+F8)*C8-(H8*B8)),H8*(1+G8)*C8-(H8*B8)) -> 0
A9: ES | B9: 0.04 | C9: 0.04 | H9: =PREÇOS!D10 -> 10.8965 | I9: =IF(F9=0,,H9*(1+F9)*C9-(H9*B9)) -> 0 | J9: =IF(G9=0,IF(F9=0,,H9*(1+F9)*C9-(H9*B9)),H9*(1+G9)*C9-(H9*B9)) -> 0
A10: GO | B10: 0.04 | C10: 0.04 | H10: =PREÇOS!D11 -> 10.8965 | I10: =IF(F10=0,,H10*(1+F10)*C10-(H10*B10)) -> 0 | J10: =IF(G10=0,IF(F10=0,,H10*(1+F10)*C10-(H10*B10)),H10*(1+G10)*C10-(H10*B10)) -> 0
A11: MA | B11: 0.04 | C11: 0.04 | H11: =PREÇOS!D12 -> 10.8965 | I11: =IF(F11=0,,H11*(1+F11)*C11-(H11*B11)) -> 0 | J11: =IF(G11=0,IF(F11=0,,H11*(1+F11)*C11-(H11*B11)),H11*(1+G11)*C11-(H11*B11)) -> 0
A12: MG | B12: 0.04 | C12: 0.18 | D12: 0.25 | F12: 0.3636 | H12: =PREÇOS!D13 -> 10.8965 | I12: =IF(F12=0,,H12*(1+F12)*C12-(H12*B12)) -> 2.2386641 | J12: =IF(G12=0,IF(F12=0,,H12*(1+F12)*C12-(H12*B12)),H12*(1+G12)*C12-(H12*B12)) -> 2.2386641
A13: MS | B13: 0.04 | C13: 0.04 | H13: =PREÇOS!D14 -> 10.8965 | I13: =IF(F13=0,,H13*(1+F13)*C13-(H13*B13)) -> 0 | J13: =IF(G13=0,IF(F13=0,,H13*(1+F13)*C13-(H13*B13)),H13*(1+G13)*C13-(H13*B13)) -> 0
A14: MT | B14: 0.04 | C14: 0.04 | H14: =PREÇOS!D15 -> 10.8965 | I14: =IF(F14=0,,H14*(1+F14)*C14-(H14*B14)) -> 0 | J14: =IF(G14=0,IF(F14=0,,H14*(1+F14)*C14-(H14*B14)),H14*(1+G14)*C14-(H14*B14)) -> 0
A15: PA | B15: 0.04 | C15: 0.04 | H15: =PREÇOS!D16 -> 10.8965 | I15: =IF(F15=0,,H15*(1+F15)*C15-(H15*B15)) -> 0 | J15: =IF(G15=0,IF(F15=0,,H15*(1+F15)*C15-(H15*B15)),H15*(1+G15)*C15-(H15*B15)) -> 0
A16: PB | B16: 0.04 | C16: 0.04 | H16: =PREÇOS!D17 -> 10.8965 | I16: =IF(F16=0,,H16*(1+F16)*C16-(H16*B16)) -> 0 | J16: =IF(G16=0,IF(F16=0,,H16*(1+F16)*C16-(H16*B16)),H16*(1+G16)*C16-(H16*B16)) -> 0
A17: PE | B17: 0.04 | C17: 0.04 | H17: =PREÇOS!D18 -> 10.8965 | I17: =IF(F17=0,,H17*(1+F17)*C17-(H17*B17)) -> 0 | J17: =IF(G17=0,IF(F17=0,,H17*(1+F17)*C17-(H17*B17)),H17*(1+G17)*C17-(H17*B17)) -> 0
A18: PI | B18: 0.04 | C18: 0.04 | H18: =PREÇOS!D19 -> 10.8965 | I18: =IF(F18=0,,H18*(1+F18)*C18-(H18*B18)) -> 0 | J18: =IF(G18=0,IF(F18=0,,H18*(1+F18)*C18-(H18*B18)),H18*(1+G18)*C18-(H18*B18)) -> 0
A19: PR | B19: 0.12 | C19: 0.12 | H19: =PREÇOS!D20 -> 11.951 | I19: =IF(F19=0,,H19*(1+F19)*C19-(H19*B19)) -> 0 | J19: =IF(G19=0,IF(F19=0,,H19*(1+F19)*C19-(H19*B19)),H19*(1+G19)*C19-(H19*B19)) -> 0
A20: RJ | B20: 0.04 | C20: 0.22 | D20: 0.352 | F20: 0.664 | H20: =PREÇOS!D21 -> 10.8965 | I20: =IF(F20=0,,H20*(1+F20)*C20-(H20*B20)) -> 3.5531307 | J20: =IF(G20=0,IF(F20=0,,H20*(1+F20)*C20-(H20*B20)),H20*(1+G20)*C20-(H20*B20)) -> 3.5531307
A21: RN | B21: 0.04 | C21: 0.04 | H21: =PREÇOS!D22 -> 10.8965 | I21: =IF(F21=0,,H21*(1+F21)*C21-(H21*B21)) -> 0 | J21: =IF(G21=0,IF(F21=0,,H21*(1+F21)*C21-(H21*B21)),H21*(1+G21)*C21-(H21*B21)) -> 0
A22: RO | B22: 0.04 | C22: 0.04 | H22: =PREÇOS!D23 -> 10.8965 | I22: =IF(F22=0,,H22*(1+F22)*C22-(H22*B22)) -> 0 | J22: =IF(G22=0,IF(F22=0,,H22*(1+F22)*C22-(H22*B22)),H22*(1+G22)*C22-(H22*B22)) -> 0
A23: RR | B23: 0.04 | C23: 0.04 | H23: =PREÇOS!D24 -> 10.8965 | I23: =IF(F23=0,,H23*(1+F23)*C23-(H23*B23)) -> 0 | J23: =IF(G23=0,IF(F23=0,,H23*(1+F23)*C23-(H23*B23)),H23*(1+G23)*C23-(H23*B23)) -> 0
A24: RS | B24: 0.04 | C24: 0.04 | H24: =PREÇOS!D25 -> 10.8965 | I24: =IF(F24=0,,H24*(1+F24)*C24-(H24*B24)) -> 0 | J24: =IF(G24=0,IF(F24=0,,H24*(1+F24)*C24-(H24*B24)),H24*(1+G24)*C24-(H24*B24)) -> 0
A25: SC | B25: 0.04 | C25: 0.04 | H25: =PREÇOS!D26 -> 10.8965 | I25: =IF(F25=0,,H25*(1+F25)*C25-(H25*B25)) -> 0 | J25: =IF(G25=0,IF(F25=0,,H25*(1+F25)*C25-(H25*B25)),H25*(1+G25)*C25-(H25*B25)) -> 0
A26: SE | B26: 0.04 | C26: 0.04 | H26: =PREÇOS!D27 -> 10.8965 | I26: =IF(F26=0,,H26*(1+F26)*C26-(H26*B26)) -> 0 | J26: =IF(G26=0,IF(F26=0,,H26*(1+F26)*C26-(H26*B26)),H26*(1+G26)*C26-(H26*B26)) -> 0
A27: SP | B27: 0.04 | C27: 0.18 | D27: 0.4832 | F27: 0.618 | H27: =PREÇOS!D28 -> 10.8965 | I27: =IF(F27=0,,H27*(1+F27)*C27-(H27*B27)) -> 2.7376367 | J27: =IF(G27=0,IF(F27=0,,H27*(1+F27)*C27-(H27*B27)),H27*(1+G27)*C27-(H27*B27)) -> 2.7376367
A28: SP/Atacado | B28: =B27 -> 0.04 | C28: =C27 -> 0.18 | D28: =D27 -> 0.4832 | E28: =E27 -> 0 | F28: =F27 -> 0.618 | G28: =G27 -> 0 | H28: =PREÇOS!D29 -> 10.8965 | I28: =IF(F28=0,,H28*(1+F28)*C28-(H28*B28)) -> 2.7376367 | J28: =IF(G28=0,IF(F28=0,,H28*(1+F28)*C28-(H28*B28)),H28*(1+G28)*C28-(H28*B28)) -> 2.7376367
A29: TO | B29: 0.04 | C29: 0.04 | H29: =PREÇOS!D30 -> 10.8965 | I29: =IF(F29=0,,H29*(1+F29)*C29-(H29*B29)) -> 0 | J29: =IF(G29=0,IF(F29=0,,H29*(1+F29)*C29-(H29*B29)),H29*(1+G29)*C29-(H29*B29)) -> 0
A30: EX | H30: =PREÇOS!D31 -> 0 | I30: =IF(F30=0,,H30*(1+F30)*C30-(H30*B30)) -> 0 | J30: =IF(G30=0,IF(F30=0,,H30*(1+F30)*C30-(H30*B30)),H30*(1+G30)*C30-(H30*B30)) -> 0

Sheet ST PAPAPASTA
A1: Estado | B1: Aliquota interestadual | C1: Aliquota interna | D1: MVA (normal) | E1: MVA (simples) | F1: Ajustada (normal) | G1: Ajustada (simples) | H1: Preço | I1: ST Normal | J1: ST Simples
A2: AC | B2: 0.07 | C2: 0.07 | H2: =PREÇOS!E3 -> 7.5335 | I2: =IF(F2=0,,H2*(1+F2)*C2-(H2*B2)) -> 0 | J2: =IF(G2=0,IF(F2=0,,H2*(1+F2)*C2-(H2*B2)),H2*(1+G2)*C2-(H2*B2)) -> 0
A3: AL | B3: 0.07 | C3: 0.19 | D3: 0.2 | F3: 0.361 | H3: =PREÇOS!E4 -> 7.5335 | I3: =IF(F3=0,,H3*(1+F3)*C3-(H3*B3)) -> 1.4207428 | J3: =IF(G3=0,IF(F3=0,,H3*(1+F3)*C3-(H3*B3)),H3*(1+G3)*C3-(H3*B3)) -> 1.4207428
A4: AM | B4: 0.07 | C4: 0.07 | H4: =PREÇOS!E5 -> 7.5335 | I4: =IF(F4=0,,H4*(1+F4)*C4-(H4*B4)) -> 0 | J4: =IF(G4=0,IF(F4=0,,H4*(1+F4)*C4-(H4*B4)),H4*(1+G4)*C4-(H4*B4)) -> 0
A5: AP | B5: 0.07 | C5: 0.18 | D5: 0.38 | F5: 0.5651 | H5: =PREÇOS!E6 -> 7.5335 | I5: =IF(F5=0,,H5*(1+F5)*C5-(H5*B5)) -> 1.5949776 | J5: =IF(G5=0,IF(F5=0,,H5*(1+F5)*C5-(H5*B5)),H5*(1+G5)*C5-(H5*B5)) -> 1.5949776
A6: BA | B6: 0.07 | C6: 0.07 | H6: =PREÇOS!E7 -> 7.5335 | I6: =IF(F6=0,,H6*(1+F6)*C6-(H6*B6)) -> 0 | J6: =IF(G6=0,IF(F6=0,,H6*(1+F6)*C6-(H6*B6)),H6*(1+G6)*C6-(H6*B6)) -> 0
A7: CE | B7: 0.07 | C7: 0.07 | H7: =PREÇOS!E8 -> 7.5335 | I7: =IF(F7=0,,H7*(1+F7)*C7-(H7*B7)) -> 0 | J7: =IF(G7=0,IF(F7=0,,H7*(1+F7)*C7-(H7*B7)),H7*(1+G7)*C7-(H7*B7)) -> 0
A8: DF | B8: 0.07 | C8: 0.07 | H8: =PREÇOS!E9 -> 7.5335 | I8: =IF(F8=0,,H8*(1+F8)*C8-(H8*B8)) -> 0 | J8: =IF(G8=0,IF(F8=0,,H8*(1+F8)*C8-(H8*B8)),H8*(1+G8)*C8-(H8*B8)) -> 0
A9: ES | B9: 0.07 | C9: 0.07 | H9: =PREÇOS!E10 -> 7.5335 | I9: =IF(F9=0,,H9*(1+F9)*C9-(H9*B9)) -> 0 | J9: =IF(G9=0,IF(F9=0,,H9*(1+F9)*C9-(H9*B9)),H9*(1+G9)*C9-(H9*B9)) -> 0
A10: GO | B10: 0.07 | C10: 0.07 | H10: =PREÇOS!E11 -> 7.5335 | I10: =IF(F10=0,,H10*(1+F10)*C10-(H10*B10)) -> 0 | J10: =IF(G10=0,IF(F10=0,,H10*(1+F10)*C10-(H10*B10)),H10*(1+G10)*C10-(H10*B10)) -> 0
A11: MA | B11: 0.07 | C11: 0.07 | H11: =PREÇOS!E12 -> 7.5335 | I11: =IF(F11=0,,H11*(1+F11)*C11-(H11*B11)) -> 0 | J11: =IF(G11=0,IF(F11=0,,H11*(1+F11)*C11-(H11*B11)),H11*(1+G11)*C11-(H11*B11)) -> 0
A12: MG | B12: 0.12 | C12: 0.18 | D12: 0.35 | F12: 0.35 | H12: =PREÇOS!E13 -> 8.0275 | I12: =IF(F12=0,,H12*(1+F12)*C12-(H12*B12)) -> 0.9873825 | J12: =IF(G12=0,IF(F12=0,,H12*(1+F12)*C12-(H12*B12)),H12*(1+G12)*C12-(H12*B12)) -> 0.9873825
A13: MS | B13: 0.07 | C13: 0.07 | H13: =PREÇOS!E14 -> 7.5335 | I13: =IF(F13=0,,H13*(1+F13)*C13-(H13*B13)) -> 0 | J13: =IF(G13=0,IF(F13=0,,H13*(1+F13)*C13-(H13*B13)),H13*(1+G13)*C13-(H13*B13)) -> 0
A14: MT | B14: 0.07 | C14: 0.17 | D14: 0.3545 | F14: 0.3545 | H14: =PREÇOS!E15 -> 7.5335 | I14: =IF(F14=0,,H14*(1+F14)*C14-(H14*B14)) -> 1.2073564 | J14: =IF(G14=0,IF(F14=0,,H14*(1+F14)*C14-(H14*B14)),H14*(1+G14)*C14-(H14*B14)) -> 1.2073564
A15: PA | B15: 0.07 | C15: 0.07 | H15: =PREÇOS!E16 -> 7.5335 | I15: =IF(F15=0,,H15*(1+F15)*C15-(H15*B15)) -> 0 | J15: =IF(G15=0,IF(F15=0,,H15*(1+F15)*C15-(H15*B15)),H15*(1+G15)*C15-(H15*B15)) -> 0
A16: PB | B16: 0.07 | C16: 0.07 | H16: =PREÇOS!E17 -> 7.5335 | I16: =IF(F16=0,,H16*(1+F16)*C16-(H16*B16)) -> 0 | J16: =IF(G16=0,IF(F16=0,,H16*(1+F16)*C16-(H16*B16)),H16*(1+G16)*C16-(H16*B16)) -> 0
A17: PE | B17: 0.07 | C17: 0.07 | H17: =PREÇOS!E18 -> 7.5335 | I17: =IF(F17=0,,H17*(1+F17)*C17-(H17*B17)) -> 0 | J17: =IF(G17=0,IF(F17=0,,H17*(1+F17)*C17-(H17*B17)),H17*(1+G17)*C17-(H17*B17)) -> 0
A18: PI | B18: 0.07 | C18: 0.07 | H18: =PREÇOS!E19 -> 7.5335 | I18: =IF(F18=0,,H18*(1+F18)*C18-(H18*B18)) -> 0 | J18: =IF(G18=0,IF(F18=0,,H18*(1+F18)*C18-(H18*B18)),H18*(1+G18)*C18-(H18*B18)) -> 0
A19: PR | B19: 0.12 | C19: 0.12 | H19: =PREÇOS!E20 -> 8.0275 | I19: =IF(F19=0,,H19*(1+F19)*C19-(H19*B19)) -> 0 | J19: =IF(G19=0,IF(F19=0,,H19*(1+F19)*C19-(H19*B19)),H19*(1+G19)*C19-(H19*B19)) -> 0
A20: RJ | B20: 0.12 | C20: 0.12 | H20: =PREÇOS!E21 -> 8.0275 | I20: =IF(F20=0,,H20*(1+F20)*C20-(H20*B20)) -> 0 | J20: =IF(G20=0,IF(F20=0,,H20*(1+F20)*C20-(H20*B20)),H20*(1+G20)*C20-(H20*B20)) -> 0
A21: RN | B21: 0.07 | C21: 0.07 | H21: =PREÇOS!E22 -> 7.5335 | I21: =IF(F21=0,,H21*(1+F21)*C21-(H21*B21)) -> 0 | J21: =IF(G21=0,IF(F21=0,,H21*(1+F21)*C21-(H21*B21)),H21*(1+G21)*C21-(H21*B21)) -> 0
A22: RO | B22: 0.07 | C22: 0.07 | H22: =PREÇOS!E23 -> 7.5335 | I22: =IF(F22=0,,H22*(1+F22)*C22-(H22*B22)) -> 0 | J22: =IF(G22=0,IF(F22=0,,H22*(1+F22)*C22-(H22*B22)),H22*(1+G22)*C22-(H22*B22)) -> 0
A23: RR | B23: 0.07 | C23: 0.07 | H23: =PREÇOS!E24 -> 7.5335 | I23: =IF(F23=0,,H23*(1+F23)*C23-(H23*B23)) -> 0 | J23: =IF(G23=0,IF(F23=0,,H23*(1+F23)*C23-(H23*B23)),H23*(1+G23)*C23-(H23*B23)) -> 0
A24: RS | B24: 0.12 | C24: 0.12 | H24: =PREÇOS!E25 -> 8.0275 | I24: =IF(F24=0,,H24*(1+F24)*C24-(H24*B24)) -> 0 | J24: =IF(G24=0,IF(F24=0,,H24*(1+F24)*C24-(H24*B24)),H24*(1+G24)*C24-(H24*B24)) -> 0
A25: SC | B25: 0.12 | C25: 0.12 | H25: =PREÇOS!E26 -> 8.0275 | I25: =IF(F25=0,,H25*(1+F25)*C25-(H25*B25)) -> 0 | J25: =IF(G25=0,IF(F25=0,,H25*(1+F25)*C25-(H25*B25)),H25*(1+G25)*C25-(H25*B25)) -> 0
A26: SE | B26: 0.07 | C26: 0.07 | H26: =PREÇOS!E27 -> 7.5335 | I26: =IF(F26=0,,H26*(1+F26)*C26-(H26*B26)) -> 0 | J26: =IF(G26=0,IF(F26=0,,H26*(1+F26)*C26-(H26*B26)),H26*(1+G26)*C26-(H26*B26)) -> 0
A27: SP | B27: 0.12 | C27: 0.12 | H27: =PREÇOS!E28 -> 8.0275 | I27: =IF(F27=0,,H27*(1+F27)*C27-(H27*B27)) -> 0 | J27: =IF(G27=0,IF(F27=0,,H27*(1+F27)*C27-(H27*B27)),H27*(1+G27)*C27-(H27*B27)) -> 0
A28: SP/Atacado | B28: =B27 -> 0.12 | C28: =C27 -> 0.12 | D28: =D27 -> 0 | E28: =E27 -> 0 | F28: =F27 -> 0 | G28: =G27 -> 0 | H28: =PREÇOS!E29 -> 8.0275 | I28: =IF(F28=0,,H28*(1+F28)*C28-(H28*B28)) -> 0 | J28: =IF(G28=0,IF(F28=0,,H28*(1+F28)*C28-(H28*B28)),H28*(1+G28)*C28-(H28*B28)) -> 0
A29: TO | B29: 0.07 | C29: 0.07 | H29: =PREÇOS!E30 -> 7.5335 | I29: =IF(F29=0,,H29*(1+F29)*C29-(H29*B29)) -> 0 | J29: =IF(G29=0,IF(F29=0,,H29*(1+F29)*C29-(H29*B29)),H29*(1+G29)*C29-(H29*B29)) -> 0
A30: EX | H30: =PREÇOS!E31 -> 0 | I30: =IF(F30=0,,H30*(1+F30)*C30-(H30*B30)) -> 0 | J30: =IF(G30=0,IF(F30=0,,H30*(1+F30)*C30-(H30*B30)),H30*(1+G30)*C30-(H30*B30)) -> 0

Sheet ST PALITINHOS
A1: Estado | B1: Aliquota interestadual | C1: Aliquota interna | D1: MVA (normal) | E1: MVA (simples) | F1: Ajustada (normal) | G1: Ajustada (simples) | H1: Preço | I1: ST Normal | J1: ST Simples
A2: AC | B2: 0.07 | C2: 0.07 | H2: =PREÇOS!C3 -> 3.3915 | I2: =IF(F2=0,,H2*(1+F2)*C2-(H2*B2)) -> 0 | J2: =IF(G2=0,IF(F2=0,,H2*(1+F2)*C2-(H2*B2)),H2*(1+G2)*C2-(H2*B2)) -> 0
A3: AL | B3: 0.07 | C3: 0.19 | D3: 0.5432 | F3: 0.794 | H3: =PREÇOS!C4 -> 3.3915 | I3: =IF(F3=0,,H3*(1+F3)*C3-(H3*B3)) -> 0.91862169 | J3: =IF(G3=0,IF(F3=0,,H3*(1+F3)*C3-(H3*B3)),H3*(1+G3)*C3-(H3*B3)) -> 0.91862169
A4: AM | B4: 0.07 | C4: 0.18 | H4: =PREÇOS!C5 -> 3.3915 | I4: =IF(F4=0,,H4*(1+F4)*C4-(H4*B4)) -> 0 | J4: =IF(G4=0,IF(F4=0,,H4*(1+F4)*C4-(H4*B4)),H4*(1+G4)*C4-(H4*B4)) -> 0
A5: AP | B5: 0.07 | C5: 0.18 | D5: 0.41 | F5: 0.5991 | H5: =PREÇOS!C6 -> 3.3915 | I5: =IF(F5=0,,H5*(1+F5)*C5-(H5*B5)) -> 0.73879758 | J5: =IF(G5=0,IF(F5=0,,H5*(1+F5)*C5-(H5*B5)),H5*(1+G5)*C5-(H5*B5)) -> 0.73879758
A6: BA | B6: 0.07 | C6: 0.07 | H6: =PREÇOS!C7 -> 3.3915 | I6: =IF(F6=0,,H6*(1+F6)*C6-(H6*B6)) -> 0 | J6: =IF(G6=0,IF(F6=0,,H6*(1+F6)*C6-(H6*B6)),H6*(1+G6)*C6-(H6*B6)) -> 0
A7: CE | B7: 0.07 | C7: 0.07 | H7: =PREÇOS!C8 -> 3.3915 | I7: =IF(F7=0,,H7*(1+F7)*C7-(H7*B7)) -> 0 | J7: =IF(G7=0,IF(F7=0,,H7*(1+F7)*C7-(H7*B7)),H7*(1+G7)*C7-(H7*B7)) -> 0
A8: DF | B8: 0.07 | C8: 0.07 | H8: =PREÇOS!C9 -> 3.3915 | I8: =IF(F8=0,,H8*(1+F8)*C8-(H8*B8)) -> 0 | J8: =IF(G8=0,IF(F8=0,,H8*(1+F8)*C8-(H8*B8)),H8*(1+G8)*C8-(H8*B8)) -> 0
A9: ES | B9: 0.07 | C9: 0.07 | H9: =PREÇOS!C10 -> 3.3915 | I9: =IF(F9=0,,H9*(1+F9)*C9-(H9*B9)) -> 0 | J9: =IF(G9=0,IF(F9=0,,H9*(1+F9)*C9-(H9*B9)),H9*(1+G9)*C9-(H9*B9)) -> 0
A10: GO | B10: 0.07 | C10: 0.07 | H10: =PREÇOS!C11 -> 3.3915 | I10: =IF(F10=0,,H10*(1+F10)*C10-(H10*B10)) -> 0 | J10: =IF(G10=0,IF(F10=0,,H10*(1+F10)*C10-(H10*B10)),H10*(1+G10)*C10-(H10*B10)) -> 0
A11: MA | B11: 0.07 | C11: 0.07 | H11: =PREÇOS!C12 -> 3.3915 | I11: =IF(F11=0,,H11*(1+F11)*C11-(H11*B11)) -> 0 | J11: =IF(G11=0,IF(F11=0,,H11*(1+F11)*C11-(H11*B11)),H11*(1+G11)*C11-(H11*B11)) -> 0
A12: MG | B12: 0.12 | C12: 0.18 | D12: 0.4 | F12: 0.5024 | H12: =PREÇOS!C13 -> 3.591 | I12: =IF(F12=0,,H12*(1+F12)*C12-(H12*B12)) -> 0.54020131 | J12: =IF(G12=0,IF(F12=0,,H12*(1+F12)*C12-(H12*B12)),H12*(1+G12)*C12-(H12*B12)) -> 0.54020131
A13: MS | B13: 0.07 | C13: 0.07 | H13: =PREÇOS!C14 -> 3.3915 | I13: =IF(F13=0,,H13*(1+F13)*C13-(H13*B13)) -> 0 | J13: =IF(G13=0,IF(F13=0,,H13*(1+F13)*C13-(H13*B13)),H13*(1+G13)*C13-(H13*B13)) -> 0
A14: MT | B14: 0.07 | C14: 0.17 | D14: 0.4552 | F14: 0.6305 | H14: =PREÇOS!C15 -> 3.3915 | I14: =IF(F14=0,,H14*(1+F14)*C14-(H14*B14)) -> 0.70266793 | J14: =IF(G14=0,IF(F14=0,,H14*(1+F14)*C14-(H14*B14)),H14*(1+G14)*C14-(H14*B14)) -> 0.70266793
A15: PA | B15: 0.07 | C15: 0.07 | H15: =PREÇOS!C16 -> 3.3915 | I15: =IF(F15=0,,H15*(1+F15)*C15-(H15*B15)) -> 0 | J15: =IF(G15=0,IF(F15=0,,H15*(1+F15)*C15-(H15*B15)),H15*(1+G15)*C15-(H15*B15)) -> 0
A16: PB | B16: 0.07 | C16: 0.07 | H16: =PREÇOS!C17 -> 3.3915 | I16: =IF(F16=0,,H16*(1+F16)*C16-(H16*B16)) -> 0 | J16: =IF(G16=0,IF(F16=0,,H16*(1+F16)*C16-(H16*B16)),H16*(1+G16)*C16-(H16*B16)) -> 0
A17: PE | B17: 0.07 | C17: 0.07 | H17: =PREÇOS!C18 -> 3.3915 | I17: =IF(F17=0,,H17*(1+F17)*C17-(H17*B17)) -> 0 | J17: =IF(G17=0,IF(F17=0,,H17*(1+F17)*C17-(H17*B17)),H17*(1+G17)*C17-(H17*B17)) -> 0
A18: PI | B18: 0.07 | C18: 0.07 | H18: =PREÇOS!C19 -> 3.3915 | I18: =IF(F18=0,,H18*(1+F18)*C18-(H18*B18)) -> 0 | J18: =IF(G18=0,IF(F18=0,,H18*(1+F18)*C18-(H18*B18)),H18*(1+G18)*C18-(H18*B18)) -> 0
A19: PR | B19: 0.12 | C19: 0.195 | D19: 0.5432 | E19: 0.163 | F19: 0.687 | G19: 0.1968 | H19: =PREÇOS!C20 -> 3.591 | I19: =IF(F19=0,,H19*(1+F19)*C19-(H19*B19)) -> 0.75039331 | J19: =IF(G19=0,IF(F19=0,,H19*(1+F19)*C19-(H19*B19)),H19*(1+G19)*C19-(H19*B19)) -> 0.40713322
A20: RJ | B20: 0.12 | C20: 0.22 | D20: 0.4698 | F20: 0.6582 | H20: =PREÇOS!C21 -> 3.591 | I20: =IF(F20=0,,H20*(1+F20)*C20-(H20*B20)) -> 0.87909116 | J20: =IF(G20=0,IF(F20=0,,H20*(1+F20)*C20-(H20*B20)),H20*(1+G20)*C20-(H20*B20)) -> 0.87909116
A21: RN | B21: 0.07 | C21: 0.07 | H21: =PREÇOS!C22 -> 3.3915 | I21: =IF(F21=0,,H21*(1+F21)*C21-(H21*B21)) -> 0 | J21: =IF(G21=0,IF(F21=0,,H21*(1+F21)*C21-(H21*B21)),H21*(1+G21)*C21-(H21*B21)) -> 0
A22: RO | B22: 0.07 | C22: 0.07 | H22: =PREÇOS!C23 -> 3.3915 | I22: =IF(F22=0,,H22*(1+F22)*C22-(H22*B22)) -> 0 | J22: =IF(G22=0,IF(F22=0,,H22*(1+F22)*C22-(H22*B22)),H22*(1+G22)*C22-(H22*B22)) -> 0
A23: RR | B23: 0.07 | C23: 0.07 | H23: =PREÇOS!C24 -> 3.3915 | I23: =IF(F23=0,,H23*(1+F23)*C23-(H23*B23)) -> 0 | J23: =IF(G23=0,IF(F23=0,,H23*(1+F23)*C23-(H23*B23)),H23*(1+G23)*C23-(H23*B23)) -> 0
A24: RS | B24: 0.12 | C24: 0.12 | H24: =PREÇOS!C25 -> 3.591 | I24: =IF(F24=0,,H24*(1+F24)*C24-(H24*B24)) -> 0 | J24: =IF(G24=0,IF(F24=0,,H24*(1+F24)*C24-(H24*B24)),H24*(1+G24)*C24-(H24*B24)) -> 0
A25: SC | B25: 0.12 | C25: 0.12 | H25: =PREÇOS!C26 -> 3.591 | I25: =IF(F25=0,,H25*(1+F25)*C25-(H25*B25)) -> 0 | J25: =IF(G25=0,IF(F25=0,,H25*(1+F25)*C25-(H25*B25)),H25*(1+G25)*C25-(H25*B25)) -> 0
A26: SE | B26: 0.07 | C26: 0.07 | H26: =PREÇOS!C27 -> 3.3915 | I26: =IF(F26=0,,H26*(1+F26)*C26-(H26*B26)) -> 0 | J26: =IF(G26=0,IF(F26=0,,H26*(1+F26)*C26-(H26*B26)),H26*(1+G26)*C26-(H26*B26)) -> 0
A27: SP | B27: 0.12 | C27: 0.18 | D27: 0.8807 | F27: 0.8807 | H27: =PREÇOS!C28 -> 3.591 | I27: =IF(F27=0,,H27*(1+F27)*C27-(H27*B27)) -> 0.78472687 | J27: =IF(G27=0,IF(F27=0,,H27*(1+F27)*C27-(H27*B27)),H27*(1+G27)*C27-(H27*B27)) -> 0.78472687
A28: SP/Atacado | B28: =B27 -> 0.12 | C28: =C27 -> 0.18 | D28: =D27 -> 0.8807 | E28: =E27 -> 0 | F28: =F27 -> 0.8807 | G28: =G27 -> 0 | H28: =PREÇOS!C29 -> 3.591 | I28: =IF(F28=0,,H28*(1+F28)*C28-(H28*B28)) -> 0.78472687 | J28: =IF(G28=0,IF(F28=0,,H28*(1+F28)*C28-(H28*B28)),H28*(1+G28)*C28-(H28*B28)) -> 0.78472687
A29: TO | B29: 0.07 | C29: 0.07 | H29: =PREÇOS!C30 -> 3.3915 | I29: =IF(F29=0,,H29*(1+F29)*C29-(H29*B29)) -> 0 | J29: =IF(G29=0,IF(F29=0,,H29*(1+F29)*C29-(H29*B29)),H29*(1+G29)*C29-(H29*B29)) -> 0
A30: EX | H30: =PREÇOS!C31 -> 0 | I30: =IF(F30=0,,H30*(1+F30)*C30-(H30*B30)) -> 0 | J30: =IF(G30=0,IF(F30=0,,H30*(1+F30)*C30-(H30*B30)),H30*(1+G30)*C30-(H30*B30)) -> 0

Sheet ST BISCOTTI
A1: Estado | B1: Aliquota interestadual | C1: Aliquota interna | D1: MVA (normal) | E1: MVA (simples) | F1: Ajustada (normal) | G1: Ajustada (simples) | H1: Preço | I1: ST Normal | J1: ST Simples
A2: AC | B2: 0.07 | C2: =VLOOKUP(A2,[1]DIFAL!$C$13:$H$39,6,) -> 0.19 | H2: =PREÇOS!H3 -> 7.5335 | I2: =IF(F2=0,,H2*(1+F2)*C2-(H2*B2)) -> 0 | J2: =IF(G2=0,IF(F2=0,,H2*(1+F2)*C2-(H2*B2)),H2*(1+G2)*C2-(H2*B2)) -> 0
A3: AL | B3: 0.07 | C3: 0.2 | F3: 0.5113 | H3: =PREÇOS!H4 -> 7.5335 | I3: =IF(F3=0,,H3*(1+F3)*C3-(H3*B3)) -> 1.7497307 | J3: =IF(G3=0,IF(F3=0,,H3*(1+F3)*C3-(H3*B3)),H3*(1+G3)*C3-(H3*B3)) -> 1.7497307
A4: AM | B4: 0.07 | C4: =VLOOKUP(A4,[1]DIFAL!$C$13:$H$39,6,) -> 0.2 | H4: =PREÇOS!H5 -> 7.5335 | I4: =IF(F4=0,,H4*(1+F4)*C4-(H4*B4)) -> 0 | J4: =IF(G4=0,IF(F4=0,,H4*(1+F4)*C4-(H4*B4)),H4*(1+G4)*C4-(H4*B4)) -> 0
A5: AP | B5: 0.07 | C5: =VLOOKUP(A5,[1]DIFAL!$C$13:$H$39,5,) -> 0.18 | F5: 0.5198 | H5: =PREÇOS!H6 -> 7.5335 | I5: =IF(F5=0,,H5*(1+F5)*C5-(H5*B5)) -> 1.5335494 | J5: =IF(G5=0,IF(F5=0,,H5*(1+F5)*C5-(H5*B5)),H5*(1+G5)*C5-(H5*B5)) -> 1.5335494
A6: BA | B6: 0.07 | C6: =VLOOKUP(A6,[1]DIFAL!$C$13:$H$39,6,) -> 0.19 | H6: =PREÇOS!H7 -> 7.5335 | I6: =IF(F6=0,,H6*(1+F6)*C6-(H6*B6)) -> 0 | J6: =IF(G6=0,IF(F6=0,,H6*(1+F6)*C6-(H6*B6)),H6*(1+G6)*C6-(H6*B6)) -> 0
A7: CE | B7: 0.07 | C7: =VLOOKUP(A7,[1]DIFAL!$C$13:$H$39,6,) -> 0.2 | H7: =PREÇOS!H8 -> 7.5335 | I7: =IF(F7=0,,H7*(1+F7)*C7-(H7*B7)) -> 0 | J7: =IF(G7=0,IF(F7=0,,H7*(1+F7)*C7-(H7*B7)),H7*(1+G7)*C7-(H7*B7)) -> 0
A8: DF | B8: 0.07 | C8: =VLOOKUP(A8,[1]DIFAL!$C$13:$H$39,5,) -> 0.18 | H8: =PREÇOS!H9 -> 7.5335 | I8: =IF(F8=0,,H8*(1+F8)*C8-(H8*B8)) -> 0 | J8: =IF(G8=0,IF(F8=0,,H8*(1+F8)*C8-(H8*B8)),H8*(1+G8)*C8-(H8*B8)) -> 0
A9: ES | B9: 0.07 | C9: =VLOOKUP(A9,[1]DIFAL!$C$13:$H$39,5,) -> 0.17 | H9: =PREÇOS!H10 -> 7.5335 | I9: =IF(F9=0,,H9*(1+F9)*C9-(H9*B9)) -> 0 | J9: =IF(G9=0,IF(F9=0,,H9*(1+F9)*C9-(H9*B9)),H9*(1+G9)*C9-(H9*B9)) -> 0
A10: GO | B10: 0.07 | C10: =VLOOKUP(A10,[1]DIFAL!$C$13:$H$39,5,) -> 0.17 | H10: =PREÇOS!H11 -> 7.5335 | I10: =IF(F10=0,,H10*(1+F10)*C10-(H10*B10)) -> 0 | J10: =IF(G10=0,IF(F10=0,,H10*(1+F10)*C10-(H10*B10)),H10*(1+G10)*C10-(H10*B10)) -> 0
A11: MA | B11: 0.07 | C11: =VLOOKUP(A11,[1]DIFAL!$C$13:$H$39,6,) -> 0.2 | H11: =PREÇOS!H12 -> 7.5335 | I11: =IF(F11=0,,H11*(1+F11)*C11-(H11*B11)) -> 0 | J11: =IF(G11=0,IF(F11=0,,H11*(1+F11)*C11-(H11*B11)),H11*(1+G11)*C11-(H11*B11)) -> 0
A12: MG | B12: 0.12 | C12: 0.12 | F12: 0.25 | H12: =PREÇOS!H13 -> 7.98 | I12: =IF(F12=0,,H12*(1+F12)*C12-(H12*B12)) -> 0.2394 | J12: =IF(G12=0,IF(F12=0,,H12*(1+F12)*C12-(H12*B12)),H12*(1+G12)*C12-(H12*B12)) -> 0.2394
A13: MS | B13: 0.07 | C13: =VLOOKUP(A13,[1]DIFAL!$C$13:$H$39,5,) -> 0.17 | H13: =PREÇOS!H14 -> 7.5335 | I13: =IF(F13=0,,H13*(1+F13)*C13-(H13*B13)) -> 0 | J13: =IF(G13=0,IF(F13=0,,H13*(1+F13)*C13-(H13*B13)),H13*(1+G13)*C13-(H13*B13)) -> 0
A14: MT | B14: 0.07 | C14: =VLOOKUP(A14,[1]DIFAL!$C$13:$H$39,5,) -> 0.17 | F14: 0.3978 | H14: =PREÇOS!H15 -> 7.5335 | I14: =IF(F14=0,,H14*(1+F14)*C14-(H14*B14)) -> 1.2628105 | J14: =IF(G14=0,IF(F14=0,,H14*(1+F14)*C14-(H14*B14)),H14*(1+G14)*C14-(H14*B14)) -> 1.2628105
A15: PA | B15: 0.07 | C15: =VLOOKUP(A15,[1]DIFAL!$C$13:$H$39,6,) -> 0.19 | H15: =PREÇOS!H16 -> 7.5335 | I15: =IF(F15=0,,H15*(1+F15)*C15-(H15*B15)) -> 0 | J15: =IF(G15=0,IF(F15=0,,H15*(1+F15)*C15-(H15*B15)),H15*(1+G15)*C15-(H15*B15)) -> 0
A16: PB | B16: 0.07 | C16: =VLOOKUP(A16,[1]DIFAL!$C$13:$H$39,5,) -> 0.18 | H16: =PREÇOS!H17 -> 7.5335 | I16: =IF(F16=0,,H16*(1+F16)*C16-(H16*B16)) -> 0 | J16: =IF(G16=0,IF(F16=0,,H16*(1+F16)*C16-(H16*B16)),H16*(1+G16)*C16-(H16*B16)) -> 0
A17: PE | B17: 0.07 | C17: =VLOOKUP(A17,[1]DIFAL!$C$13:$H$39,5,) -> 0.18 | H17: =PREÇOS!H18 -> 7.5335 | I17: =IF(F17=0,,H17*(1+F17)*C17-(H17*B17)) -> 0 | J17: =IF(G17=0,IF(F17=0,,H17*(1+F17)*C17-(H17*B17)),H17*(1+G17)*C17-(H17*B17)) -> 0
A18: PI | B18: 0.07 | C18: =VLOOKUP(A18,[1]DIFAL!$C$13:$H$39,6,) -> 0.21 | H18: =PREÇOS!H19 -> 7.5335 | I18: =IF(F18=0,,H18*(1+F18)*C18-(H18*B18)) -> 0 | J18: =IF(G18=0,IF(F18=0,,H18*(1+F18)*C18-(H18*B18)),H18*(1+G18)*C18-(H18*B18)) -> 0
A19: PR | B19: 0.12 | C19: 0.12 | H19: =PREÇOS!H20 -> 7.98 | I19: =IF(F19=0,,H19*(1+F19)*C19-(H19*B19)) -> 0 | J19: =IF(G19=0,IF(F19=0,,H19*(1+F19)*C19-(H19*B19)),H19*(1+G19)*C19-(H19*B19)) -> 0
A20: RJ | B20: 0.12 | C20: 0.22 | F20: 0.5253 | H20: =PREÇOS!H21 -> 7.98 | I20: =IF(F20=0,,H20*(1+F20)*C20-(H20*B20)) -> 1.7202167 | J20: =IF(G20=0,IF(F20=0,,H20*(1+F20)*C20-(H20*B20)),H20*(1+G20)*C20-(H20*B20)) -> 1.7202167
A21: RN | B21: 0.07 | C21: =VLOOKUP(A21,[1]DIFAL!$C$13:$H$39,6,) -> 0.2 | H21: =PREÇOS!H22 -> 7.5335 | I21: =IF(F21=0,,H21*(1+F21)*C21-(H21*B21)) -> 0 | J21: =IF(G21=0,IF(F21=0,,H21*(1+F21)*C21-(H21*B21)),H21*(1+G21)*C21-(H21*B21)) -> 0
A22: RO | B22: 0.07 | C22: =VLOOKUP(A22,[1]DIFAL!$C$13:$H$39,5,) -> 0.175 | H22: =PREÇOS!H23 -> 7.5335 | I22: =IF(F22=0,,H22*(1+F22)*C22-(H22*B22)) -> 0 | J22: =IF(G22=0,IF(F22=0,,H22*(1+F22)*C22-(H22*B22)),H22*(1+G22)*C22-(H22*B22)) -> 0
A23: RR | B23: 0.07 | C23: =VLOOKUP(A23,[1]DIFAL!$C$13:$H$39,6,) -> 0.2 | H23: =PREÇOS!H24 -> 7.5335 | I23: =IF(F23=0,,H23*(1+F23)*C23-(H23*B23)) -> 0 | J23: =IF(G23=0,IF(F23=0,,H23*(1+F23)*C23-(H23*B23)),H23*(1+G23)*C23-(H23*B23)) -> 0
A24: RS | B24: 0.12 | C24: =VLOOKUP(A24,[1]DIFAL!$C$13:$H$39,5,) -> 0.17 | H24: =PREÇOS!H25 -> 7.98 | I24: =IF(F24=0,,H24*(1+F24)*C24-(H24*B24)) -> 0 | J24: =IF(G24=0,IF(F24=0,,H24*(1+F24)*C24-(H24*B24)),H24*(1+G24)*C24-(H24*B24)) -> 0
A25: SC | B25: 0.12 | C25: =VLOOKUP(A25,[1]DIFAL!$C$13:$H$39,5,) -> 0.17 | H25: =PREÇOS!H26 -> 7.98 | I25: =IF(F25=0,,H25*(1+F25)*C25-(H25*B25)) -> 0 | J25: =IF(G25=0,IF(F25=0,,H25*(1+F25)*C25-(H25*B25)),H25*(1+G25)*C25-(H25*B25)) -> 0
A26: SE | B26: 0.07 | C26: 0.2 | H26: =PREÇOS!H27 -> 7.5335 | I26: =IF(F26=0,,H26*(1+F26)*C26-(H26*B26)) -> 0 | J26: =IF(G26=0,IF(F26=0,,H26*(1+F26)*C26-(H26*B26)),H26*(1+G26)*C26-(H26*B26)) -> 0
A27: SP | B27: 0.12 | C27: =VLOOKUP(A27,[1]DIFAL!$C$13:$H$39,5,) -> 0.18 | D27: 0.5917 | F27: 0.5917 | H27: =PREÇOS!H28 -> 7.98 | I27: =IF(F27=0,,H27*(1+F27)*C27-(H27*B27)) -> 1.3287179 | J27: =IF(G27=0,IF(F27=0,,H27*(1+F27)*C27-(H27*B27)),H27*(1+G27)*C27-(H27*B27)) -> 1.3287179
A28: SP/Atacado | B28: =B27 -> 0.12 | C28: =C27 -> 0.18 | D28: 0.4832 | E28: =E27 -> 0 | F28: 0.4832 | G28: =G27 -> 0 | H28: =PREÇOS!H29 -> 7.98 | I28: =IF(F28=0,,H28*(1+F28)*C28-(H28*B28)) -> 1.1728685 | J28: =IF(G28=0,IF(F28=0,,H28*(1+F28)*C28-(H28*B28)),H28*(1+G28)*C28-(H28*B28)) -> 1.1728685
A29: TO | B29: 0.07 | C29: =VLOOKUP(A29,[1]DIFAL!$C$13:$H$39,6,) -> 0.2 | H29: =PREÇOS!H30 -> 7.5335 | I29: =IF(F29=0,,H29*(1+F29)*C29-(H29*B29)) -> 0 | J29: =IF(G29=0,IF(F29=0,,H29*(1+F29)*C29-(H29*B29)),H29*(1+G29)*C29-(H29*B29)) -> 0
A30: EX

Sheet ST CEREAL
A1: Estado | B1: Aliquota interestadual | C1: Aliquota interna | D1: MVA (normal) | E1: MVA (simples) | F1: Ajustada (normal) | G1: Ajustada (simples) | H1: Preço | I1: ST Normal | J1: ST Simples
A2: AC | B2: =VLOOKUP(A2,[1]DIFAL!$C$13:$E$39,3,0) -> 0.07 | C2: 0.17 | H2: =PREÇOS!G3 -> 7.4575 | I2: =IF(F2=0,,H2*(1+F2)*C2-(H2*B2)) -> 0 | J2: =IF(G2=0,IF(F2=0,,H2*(1+F2)*C2-(H2*B2)),H2*(1+G2)*C2-(H2*B2)) -> 0
A3: AL | B3: =VLOOKUP(A3,[1]DIFAL!$C$13:$E$39,3,0) -> 0.07 | C3: 0.2 | F3: 0.71 | H3: =PREÇOS!G4 -> 7.4575 | I3: =IF(F3=0,,H3*(1+F3)*C3-(H3*B3)) -> 2.02844 | J3: =IF(G3=0,IF(F3=0,,H3*(1+F3)*C3-(H3*B3)),H3*(1+G3)*C3-(H3*B3)) -> 2.02844
A4: AM | B4: =VLOOKUP(A4,[1]DIFAL!$C$13:$E$39,3,0) -> 0.07 | C4: 0.2 | F4: 0.5538 | H4: =PREÇOS!G5 -> 7.4575 | I4: =IF(F4=0,,H4*(1+F4)*C4-(H4*B4)) -> 1.7954677 | J4: =IF(G4=0,IF(F4=0,,H4*(1+F4)*C4-(H4*B4)),H4*(1+G4)*C4-(H4*B4)) -> 1.7954677
A5: AP | B5: =VLOOKUP(A5,[1]DIFAL!$C$13:$E$39,3,0) -> 0.07 | C5: 0.18 | H5: =PREÇOS!G6 -> 7.4575 | I5: =IF(F5=0,,H5*(1+F5)*C5-(H5*B5)) -> 0 | J5: =IF(G5=0,IF(F5=0,,H5*(1+F5)*C5-(H5*B5)),H5*(1+G5)*C5-(H5*B5)) -> 0
A6: BA | B6: =VLOOKUP(A6,[1]DIFAL!$C$13:$E$39,3,0) -> 0.07 | C6: 0.19 | H6: =PREÇOS!G7 -> 7.4575 | I6: =IF(F6=0,,H6*(1+F6)*C6-(H6*B6)) -> 0 | J6: =IF(G6=0,IF(F6=0,,H6*(1+F6)*C6-(H6*B6)),H6*(1+G6)*C6-(H6*B6)) -> 0
A7: CE | B7: =VLOOKUP(A7,[1]DIFAL!$C$13:$E$39,3,0) -> 0.07 | C7: 0.2 | H7: =PREÇOS!G8 -> 7.4575 | I7: =IF(F7=0,,H7*(1+F7)*C7-(H7*B7)) -> 0 | J7: =IF(G7=0,IF(F7=0,,H7*(1+F7)*C7-(H7*B7)),H7*(1+G7)*C7-(H7*B7)) -> 0
A8: DF | B8: =VLOOKUP(A8,[1]DIFAL!$C$13:$E$39,3,0) -> 0.07 | C8: 0.18 | H8: =PREÇOS!G9 -> 7.4575 | I8: =IF(F8=0,,H8*(1+F8)*C8-(H8*B8)) -> 0 | J8: =IF(G8=0,IF(F8=0,,H8*(1+F8)*C8-(H8*B8)),H8*(1+G8)*C8-(H8*B8)) -> 0
A9: ES | B9: =VLOOKUP(A9,[1]DIFAL!$C$13:$E$39,3,0) -> 0.07 | C9: 0.17 | H9: =PREÇOS!G10 -> 7.4575 | I9: =IF(F9=0,,H9*(1+F9)*C9-(H9*B9)) -> 0 | J9: =IF(G9=0,IF(F9=0,,H9*(1+F9)*C9-(H9*B9)),H9*(1+G9)*C9-(H9*B9)) -> 0
A10: GO | B10: =VLOOKUP(A10,[1]DIFAL!$C$13:$E$39,3,0) -> 0.07 | C10: 0.17 | H10: =PREÇOS!G11 -> 7.4575 | I10: =IF(F10=0,,H10*(1+F10)*C10-(H10*B10)) -> 0 | J10: =IF(G10=0,IF(F10=0,,H10*(1+F10)*C10-(H10*B10)),H10*(1+G10)*C10-(H10*B10)) -> 0
A11: MA | B11: =VLOOKUP(A11,[1]DIFAL!$C$13:$E$39,3,0) -> 0.07 | C11: 0.2 | H11: =PREÇOS!G12 -> 7.4575 | I11: =IF(F11=0,,H11*(1+F11)*C11-(H11*B11)) -> 0 | J11: =IF(G11=0,IF(F11=0,,H11*(1+F11)*C11-(H11*B11)),H11*(1+G11)*C11-(H11*B11)) -> 0
A12: MG | B12: =VLOOKUP(A12,[1]DIFAL!$C$13:$E$39,3,0) -> 0.12 | C12: 0.18 | F12: 0.4488 | H12: =PREÇOS!G13 -> 7.885 | I12: =IF(F12=0,,H12*(1+F12)*C12-(H12*B12)) -> 1.1100818 | J12: =IF(G12=0,IF(F12=0,,H12*(1+F12)*C12-(H12*B12)),H12*(1+G12)*C12-(H12*B12)) -> 1.1100818
A13: MS | B13: =VLOOKUP(A13,[1]DIFAL!$C$13:$E$39,3,0) -> 0.07 | C13: 0.17 | H13: =PREÇOS!G14 -> 7.4575 | I13: =IF(F13=0,,H13*(1+F13)*C13-(H13*B13)) -> 0 | J13: =IF(G13=0,IF(F13=0,,H13*(1+F13)*C13-(H13*B13)),H13*(1+G13)*C13-(H13*B13)) -> 0
A14: MT | B14: =VLOOKUP(A14,[1]DIFAL!$C$13:$E$39,3,0) -> 0.07 | C14: 0.17 | F14: 0.4552 | H14: =PREÇOS!G15 -> 7.4575 | I14: =IF(F14=0,,H14*(1+F14)*C14-(H14*B14)) -> 1.3228412 | J14: =IF(G14=0,IF(F14=0,,H14*(1+F14)*C14-(H14*B14)),H14*(1+G14)*C14-(H14*B14)) -> 1.3228412
A15: PA | B15: =VLOOKUP(A15,[1]DIFAL!$C$13:$E$39,3,0) -> 0.07 | C15: 0.19 | H15: =PREÇOS!G16 -> 7.4575 | I15: =IF(F15=0,,H15*(1+F15)*C15-(H15*B15)) -> 0 | J15: =IF(G15=0,IF(F15=0,,H15*(1+F15)*C15-(H15*B15)),H15*(1+G15)*C15-(H15*B15)) -> 0
A16: PB | B16: =VLOOKUP(A16,[1]DIFAL!$C$13:$E$39,3,0) -> 0.07 | C16: 0.18 | H16: =PREÇOS!G17 -> 7.4575 | I16: =IF(F16=0,,H16*(1+F16)*C16-(H16*B16)) -> 0 | J16: =IF(G16=0,IF(F16=0,,H16*(1+F16)*C16-(H16*B16)),H16*(1+G16)*C16-(H16*B16)) -> 0
A17: PE | B17: =VLOOKUP(A17,[1]DIFAL!$C$13:$E$39,3,0) -> 0.07 | C17: 0.18 | H17: =PREÇOS!G18 -> 7.4575 | I17: =IF(F17=0,,H17*(1+F17)*C17-(H17*B17)) -> 0 | J17: =IF(G17=0,IF(F17=0,,H17*(1+F17)*C17-(H17*B17)),H17*(1+G17)*C17-(H17*B17)) -> 0
A18: PI | B18: =VLOOKUP(A18,[1]DIFAL!$C$13:$E$39,3,0) -> 0.07 | C18: 0.21 | H18: =PREÇOS!G19 -> 7.4575 | I18: =IF(F18=0,,H18*(1+F18)*C18-(H18*B18)) -> 0 | J18: =IF(G18=0,IF(F18=0,,H18*(1+F18)*C18-(H18*B18)),H18*(1+G18)*C18-(H18*B18)) -> 0
A19: PR | B19: 0.12 | C19: 0.195 | F19: 0.608 | H19: =PREÇOS!G20 -> 7.885 | I19: =IF(F19=0,,H19*(1+F19)*C19-(H19*B19)) -> 1.5262206 | J19: =IF(G19=0,IF(F19=0,,H19*(1+F19)*C19-(H19*B19)),H19*(1+G19)*C19-(H19*B19)) -> 1.5262206
A20: RJ | B20: =VLOOKUP(A20,[1]DIFAL!$C$13:$E$39,3,0) -> 0.12 | C20: 0.22 | F20: 0.5473 | H20: =PREÇOS!G21 -> 7.885 | I20: =IF(F20=0,,H20*(1+F20)*C20-(H20*B20)) -> 1.7379013 | J20: =IF(G20=0,IF(F20=0,,H20*(1+F20)*C20-(H20*B20)),H20*(1+G20)*C20-(H20*B20)) -> 1.7379013
A21: RN | B21: =VLOOKUP(A21,[1]DIFAL!$C$13:$E$39,3,0) -> 0.07 | C21: 0.2 | H21: =PREÇOS!G22 -> 7.4575 | I21: =IF(F21=0,,H21*(1+F21)*C21-(H21*B21)) -> 0 | J21: =IF(G21=0,IF(F21=0,,H21*(1+F21)*C21-(H21*B21)),H21*(1+G21)*C21-(H21*B21)) -> 0
A22: RO | B22: =VLOOKUP(A22,[1]DIFAL!$C$13:$E$39,3,0) -> 0.07 | C22: 0.175 | H22: =PREÇOS!G23 -> 7.4575 | I22: =IF(F22=0,,H22*(1+F22)*C22-(H22*B22)) -> 0 | J22: =IF(G22=0,IF(F22=0,,H22*(1+F22)*C22-(H22*B22)),H22*(1+G22)*C22-(H22*B22)) -> 0
A23: RR | B23: =VLOOKUP(A23,[1]DIFAL!$C$13:$E$39,3,0) -> 0.07 | C23: 0.2 | H23: =PREÇOS!G24 -> 7.4575 | I23: =IF(F23=0,,H23*(1+F23)*C23-(H23*B23)) -> 0 | J23: =IF(G23=0,IF(F23=0,,H23*(1+F23)*C23-(H23*B23)),H23*(1+G23)*C23-(H23*B23)) -> 0
A24: RS | B24: =VLOOKUP(A24,[1]DIFAL!$C$13:$E$39,3,0) -> 0.12 | C24: 0.17 | H24: =PREÇOS!G25 -> 7.885 | I24: =IF(F24=0,,H24*(1+F24)*C24-(H24*B24)) -> 0 | J24: =IF(G24=0,IF(F24=0,,H24*(1+F24)*C24-(H24*B24)),H24*(1+G24)*C24-(H24*B24)) -> 0
A25: SC | B25: =VLOOKUP(A25,[1]DIFAL!$C$13:$E$39,3,0) -> 0.12 | C25: 0.17 | H25: =PREÇOS!G26 -> 7.885 | I25: =IF(F25=0,,H25*(1+F25)*C25-(H25*B25)) -> 0 | J25: =IF(G25=0,IF(F25=0,,H25*(1+F25)*C25-(H25*B25)),H25*(1+G25)*C25-(H25*B25)) -> 0
A26: SE | B26: =VLOOKUP(A26,[1]DIFAL!$C$13:$E$39,3,0) -> 0.07 | C26: 0.2 | H26: =PREÇOS!G27 -> 7.4575 | I26: =IF(F26=0,,H26*(1+F26)*C26-(H26*B26)) -> 0 | J26: =IF(G26=0,IF(F26=0,,H26*(1+F26)*C26-(H26*B26)),H26*(1+G26)*C26-(H26*B26)) -> 0
A27: SP | B27: =VLOOKUP(A27,[1]DIFAL!$C$13:$E$39,3,0) -> 0.12 | C27: 0.18 | F27: 0.463 | H27: =PREÇOS!G28 -> 7.885 | I27: =IF(F27=0,,H27*(1+F27)*C27-(H27*B27)) -> 1.1302359 | J27: =IF(G27=0,IF(F27=0,,H27*(1+F27)*C27-(H27*B27)),H27*(1+G27)*C27-(H27*B27)) -> 1.1302359
A28: SP/Atacado | B28: =B27 -> 0.12 | C28: =C27 -> 0.18 | D28: =D27 -> 0 | E28: =E27 -> 0 | F28: =F27 -> 0.463 | G28: =G27 -> 0 | H28: =PREÇOS!G29 -> 7.885 | I28: =IF(F28=0,,H28*(1+F28)*C28-(H28*B28)) -> 1.1302359 | J28: =IF(G28=0,IF(F28=0,,H28*(1+F28)*C28-(H28*B28)),H28*(1+G28)*C28-(H28*B28)) -> 1.1302359
A29: TO | B29: =VLOOKUP(A29,[1]DIFAL!$C$13:$E$39,3,0) -> 0.07 | C29: 0.2 | H29: =PREÇOS!G30 -> 7.4575 | I29: =IF(F29=0,,H29*(1+F29)*C29-(H29*B29)) -> 0 | J29: =IF(G29=0,IF(F29=0,,H29*(1+F29)*C29-(H29*B29)),H29*(1+G29)*C29-(H29*B29)) -> 0
A30: EX | H30: =PREÇOS!G31 -> 0 | I30: =IF(F30=0,,H30*(1+F30)*C30-(H30*B30)) -> 0 | J30: =IF(G30=0,IF(F30=0,,H30*(1+F30)*C30-(H30*B30)),H30*(1+G30)*C30-(H30*B30)) -> 0

Sheet ST CEREAL SABOR POUCH 170
A1: Estado | B1: Aliquota interestadual | C1: Aliquota interna | D1: MVA (normal) | E1: MVA (simples) | F1: Ajustada (normal) | G1: Ajustada (simples) | H1: Preço | I1: ST Normal | J1: ST Simples
A2: AC | B2: =VLOOKUP(A2,[1]DIFAL!$C$13:$E$39,3,0) -> 0.07 | C2: 0.17 | H2: =PREÇOS!J3 -> 6.0325 | I2: =IF(F2=0,,H2*(1+F2)*C2-(H2*B2)) -> 0 | J2: =IF(G2=0,IF(F2=0,,H2*(1+F2)*C2-(H2*B2)),H2*(1+G2)*C2-(H2*B2)) -> 0
A3: AL | B3: =VLOOKUP(A3,[1]DIFAL!$C$13:$E$39,3,0) -> 0.07 | C3: 0.2 | F3: 0.71 | H3: =PREÇOS!J4 -> 6.0325 | I3: =IF(F3=0,,H3*(1+F3)*C3-(H3*B3)) -> 1.64084 | J3: =IF(G3=0,IF(F3=0,,H3*(1+F3)*C3-(H3*B3)),H3*(1+G3)*C3-(H3*B3)) -> 1.64084
A4: AM | B4: =VLOOKUP(A4,[1]DIFAL!$C$13:$E$39,3,0) -> 0.07 | C4: 0.2 | F4: 0.5538 | H4: =PREÇOS!J5 -> 6.0325 | I4: =IF(F4=0,,H4*(1+F4)*C4-(H4*B4)) -> 1.4523847 | J4: =IF(G4=0,IF(F4=0,,H4*(1+F4)*C4-(H4*B4)),H4*(1+G4)*C4-(H4*B4)) -> 1.4523847
A5: AP | B5: =VLOOKUP(A5,[1]DIFAL!$C$13:$E$39,3,0) -> 0.07 | C5: 0.18 | H5: =PREÇOS!J6 -> 6.0325 | I5: =IF(F5=0,,H5*(1+F5)*C5-(H5*B5)) -> 0 | J5: =IF(G5=0,IF(F5=0,,H5*(1+F5)*C5-(H5*B5)),H5*(1+G5)*C5-(H5*B5)) -> 0
A6: BA | B6: =VLOOKUP(A6,[1]DIFAL!$C$13:$E$39,3,0) -> 0.07 | C6: 0.19 | H6: =PREÇOS!J7 -> 6.0325 | I6: =IF(F6=0,,H6*(1+F6)*C6-(H6*B6)) -> 0 | J6: =IF(G6=0,IF(F6=0,,H6*(1+F6)*C6-(H6*B6)),H6*(1+G6)*C6-(H6*B6)) -> 0
A7: CE | B7: =VLOOKUP(A7,[1]DIFAL!$C$13:$E$39,3,0) -> 0.07 | C7: 0.2 | H7: =PREÇOS!J8 -> 6.0325 | I7: =IF(F7=0,,H7*(1+F7)*C7-(H7*B7)) -> 0 | J7: =IF(G7=0,IF(F7=0,,H7*(1+F7)*C7-(H7*B7)),H7*(1+G7)*C7-(H7*B7)) -> 0
A8: DF | B8: =VLOOKUP(A8,[1]DIFAL!$C$13:$E$39,3,0) -> 0.07 | C8: 0.18 | H8: =PREÇOS!J9 -> 6.0325 | I8: =IF(F8=0,,H8*(1+F8)*C8-(H8*B8)) -> 0 | J8: =IF(G8=0,IF(F8=0,,H8*(1+F8)*C8-(H8*B8)),H8*(1+G8)*C8-(H8*B8)) -> 0
A9: ES | B9: =VLOOKUP(A9,[1]DIFAL!$C$13:$E$39,3,0) -> 0.07 | C9: 0.17 | H9: =PREÇOS!J10 -> 5.529 | I9: =IF(F9=0,,H9*(1+F9)*C9-(H9*B9)) -> 0 | J9: =IF(G9=0,IF(F9=0,,H9*(1+F9)*C9-(H9*B9)),H9*(1+G9)*C9-(H9*B9)) -> 0
A10: GO | B10: =VLOOKUP(A10,[1]DIFAL!$C$13:$E$39,3,0) -> 0.07 | C10: 0.17 | H10: =PREÇOS!J11 -> 6.0325 | I10: =IF(F10=0,,H10*(1+F10)*C10-(H10*B10)) -> 0 | J10: =IF(G10=0,IF(F10=0,,H10*(1+F10)*C10-(H10*B10)),H10*(1+G10)*C10-(H10*B10)) -> 0
A11: MA | B11: =VLOOKUP(A11,[1]DIFAL!$C$13:$E$39,3,0) -> 0.07 | C11: 0.2 | H11: =PREÇOS!J12 -> 6.0325 | I11: =IF(F11=0,,H11*(1+F11)*C11-(H11*B11)) -> 0 | J11: =IF(G11=0,IF(F11=0,,H11*(1+F11)*C11-(H11*B11)),H11*(1+G11)*C11-(H11*B11)) -> 0
A12: MG | B12: =VLOOKUP(A12,[1]DIFAL!$C$13:$E$39,3,0) -> 0.12 | C12: 0.18 | F12: 0.4488 | H12: =PREÇOS!J13 -> 5.8425 | I12: =IF(F12=0,,H12*(1+F12)*C12-(H12*B12)) -> 0.82253052 | J12: =IF(G12=0,IF(F12=0,,H12*(1+F12)*C12-(H12*B12)),H12*(1+G12)*C12-(H12*B12)) -> 0.82253052
A13: MS | B13: =VLOOKUP(A13,[1]DIFAL!$C$13:$E$39,3,0) -> 0.07 | C13: 0.17 | H13: =PREÇOS!J14 -> 6.0325 | I13: =IF(F13=0,,H13*(1+F13)*C13-(H13*B13)) -> 0 | J13: =IF(G13=0,IF(F13=0,,H13*(1+F13)*C13-(H13*B13)),H13*(1+G13)*C13-(H13*B13)) -> 0
A14: MT | B14: =VLOOKUP(A14,[1]DIFAL!$C$13:$E$39,3,0) -> 0.07 | C14: 0.17 | F14: 0.4552 | H14: =PREÇOS!J15 -> 6.0325 | I14: =IF(F14=0,,H14*(1+F14)*C14-(H14*B14)) -> 1.070069 | J14: =IF(G14=0,IF(F14=0,,H14*(1+F14)*C14-(H14*B14)),H14*(1+G14)*C14-(H14*B14)) -> 1.070069
A15: PA | B15: =VLOOKUP(A15,[1]DIFAL!$C$13:$E$39,3,0) -> 0.07 | C15: 0.19 | H15: =PREÇOS!J16 -> 6.0325 | I15: =IF(F15=0,,H15*(1+F15)*C15-(H15*B15)) -> 0 | J15: =IF(G15=0,IF(F15=0,,H15*(1+F15)*C15-(H15*B15)),H15*(1+G15)*C15-(H15*B15)) -> 0
A16: PB | B16: =VLOOKUP(A16,[1]DIFAL!$C$13:$E$39,3,0) -> 0.07 | C16: 0.18 | H16: =PREÇOS!J17 -> 6.0325 | I16: =IF(F16=0,,H16*(1+F16)*C16-(H16*B16)) -> 0 | J16: =IF(G16=0,IF(F16=0,,H16*(1+F16)*C16-(H16*B16)),H16*(1+G16)*C16-(H16*B16)) -> 0
A17: PE | B17: =VLOOKUP(A17,[1]DIFAL!$C$13:$E$39,3,0) -> 0.07 | C17: 0.18 | H17: =PREÇOS!J18 -> 6.0325 | I17: =IF(F17=0,,H17*(1+F17)*C17-(H17*B17)) -> 0 | J17: =IF(G17=0,IF(F17=0,,H17*(1+F17)*C17-(H17*B17)),H17*(1+G17)*C17-(H17*B17)) -> 0
A18: PI | B18: =VLOOKUP(A18,[1]DIFAL!$C$13:$E$39,3,0) -> 0.07 | C18: 0.21 | H18: =PREÇOS!J19 -> 6.0325 | I18: =IF(F18=0,,H18*(1+F18)*C18-(H18*B18)) -> 0 | J18: =IF(G18=0,IF(F18=0,,H18*(1+F18)*C18-(H18*B18)),H18*(1+G18)*C18-(H18*B18)) -> 0
A19: PR | B19: 0.12 | C19: 0.195 | F19: 0.608 | H19: =PREÇOS!J20 -> 5.8425 | I19: =IF(F19=0,,H19*(1+F19)*C19-(H19*B19)) -> 1.1308743 | J19: =IF(G19=0,IF(F19=0,,H19*(1+F19)*C19-(H19*B19)),H19*(1+G19)*C19-(H19*B19)) -> 1.1308743
A20: RJ | B20: =VLOOKUP(A20,[1]DIFAL!$C$13:$E$39,3,0) -> 0.12 | C20: 0.22 | F20: 0.5473 | H20: =PREÇOS!J21 -> 5.8425 | I20: =IF(F20=0,,H20*(1+F20)*C20-(H20*B20)) -> 1.2877221 | J20: =IF(G20=0,IF(F20=0,,H20*(1+F20)*C20-(H20*B20)),H20*(1+G20)*C20-(H20*B20)) -> 1.2877221
A21: RN | B21: =VLOOKUP(A21,[1]DIFAL!$C$13:$E$39,3,0) -> 0.07 | C21: 0.2 | H21: =PREÇOS!J22 -> 6.0325 | I21: =IF(F21=0,,H21*(1+F21)*C21-(H21*B21)) -> 0 | J21: =IF(G21=0,IF(F21=0,,H21*(1+F21)*C21-(H21*B21)),H21*(1+G21)*C21-(H21*B21)) -> 0
A22: RO | B22: =VLOOKUP(A22,[1]DIFAL!$C$13:$E$39,3,0) -> 0.07 | C22: 0.175 | H22: =PREÇOS!J23 -> 6.0325 | I22: =IF(F22=0,,H22*(1+F22)*C22-(H22*B22)) -> 0 | J22: =IF(G22=0,IF(F22=0,,H22*(1+F22)*C22-(H22*B22)),H22*(1+G22)*C22-(H22*B22)) -> 0
A23: RR | B23: =VLOOKUP(A23,[1]DIFAL!$C$13:$E$39,3,0) -> 0.07 | C23: 0.2 | H23: =PREÇOS!J24 -> 6.0325 | I23: =IF(F23=0,,H23*(1+F23)*C23-(H23*B23)) -> 0 | J23: =IF(G23=0,IF(F23=0,,H23*(1+F23)*C23-(H23*B23)),H23*(1+G23)*C23-(H23*B23)) -> 0
A24: RS | B24: =VLOOKUP(A24,[1]DIFAL!$C$13:$E$39,3,0) -> 0.12 | C24: 0.17 | H24: =PREÇOS!J25 -> 5.8425 | I24: =IF(F24=0,,H24*(1+F24)*C24-(H24*B24)) -> 0 | J24: =IF(G24=0,IF(F24=0,,H24*(1+F24)*C24-(H24*B24)),H24*(1+G24)*C24-(H24*B24)) -> 0
A25: SC | B25: =VLOOKUP(A25,[1]DIFAL!$C$13:$E$39,3,0) -> 0.12 | C25: 0.17 | H25: =PREÇOS!J26 -> 5.8425 | I25: =IF(F25=0,,H25*(1+F25)*C25-(H25*B25)) -> 0 | J25: =IF(G25=0,IF(F25=0,,H25*(1+F25)*C25-(H25*B25)),H25*(1+G25)*C25-(H25*B25)) -> 0
A26: SE | B26: =VLOOKUP(A26,[1]DIFAL!$C$13:$E$39,3,0) -> 0.07 | C26: 0.2 | H26: =PREÇOS!J27 -> 6.0325 | I26: =IF(F26=0,,H26*(1+F26)*C26-(H26*B26)) -> 0 | J26: =IF(G26=0,IF(F26=0,,H26*(1+F26)*C26-(H26*B26)),H26*(1+G26)*C26-(H26*B26)) -> 0
A27: SP | B27: =VLOOKUP(A27,[1]DIFAL!$C$13:$E$39,3,0) -> 0.12 | C27: 0.18 | F27: 0.463 | H27: =PREÇOS!J28 -> 5.8425 | I27: =IF(F27=0,,H27*(1+F27)*C27-(H27*B27)) -> 0.83746395 | J27: =IF(G27=0,IF(F27=0,,H27*(1+F27)*C27-(H27*B27)),H27*(1+G27)*C27-(H27*B27)) -> 0.83746395
A28: SP/Atacado | B28: =B27 -> 0.12 | C28: =C27 -> 0.18 | D28: =D27 -> 0 | E28: =E27 -> 0 | F28: =F27 -> 0.463 | G28: =G27 -> 0 | H28: =PREÇOS!J29 -> 5.8425 | I28: =IF(F28=0,,H28*(1+F28)*C28-(H28*B28)) -> 0.83746395 | J28: =IF(G28=0,IF(F28=0,,H28*(1+F28)*C28-(H28*B28)),H28*(1+G28)*C28-(H28*B28)) -> 0.83746395
